Workbook
Name rhc_tier1: Inputs!$B$5
Name rhc_tier2: Inputs!$B$6
Name wage_index: Inputs!$B$7
Name labor_share: Inputs!$B$8
Name tier1_pct: Inputs!$B$9
Name seq: Inputs!$B$10
Name writeoff_pct: Inputs!$B$11
Name blended_actual: Inputs!$B$12
Name medicare_cap: Inputs!$B$13
Name rhc_escalation: Inputs!$B$14
Name avg_days_month: Inputs!$B$25
Name capture_rate: Inputs!$B$28
Name census_scenario: Inputs!$B$29
Name rn_caseload: Inputs!$B$70
Name aide_caseload: Inputs!$B$71
Name visits_rn_day: Inputs!$B$72
Name visits_aide_day: Inputs!$B$73
Name merit: Inputs!$B$74
Name benefits_load: Inputs!$B$77
Name health_pm: Inputs!$B$78
Name med_director: Inputs!$B$81
Name med_director2: Inputs!$B$82
Name med_director2_start: Inputs!$B$83
Name supplies_pd: Inputs!$B$86
Name dme_pd: Inputs!$B$87
Name pharmacy_pd: Inputs!$B$88
Name ga_utilities: Inputs!$B$91
Name ga_internet: Inputs!$B$92
Name ga_telephone: Inputs!$B$93
Name ga_bvtm: Inputs!$B$94
Name ga_emr: Inputs!$B$95
Name ga_pcr: Inputs!$B$96
Name ga_cc: Inputs!$B$97
Name ga_liability: Inputs!$B$98
Name ga_training: Inputs!$B$99
Name ga_other: Inputs!$B$100
Name ga_bankfees: Inputs!$B$101
Name ga_rent: Inputs!$B$102
Name ga_marketing: Inputs!$B$103
Name billing_fee_pct: Inputs!$B$106
Name qr_fee_pct: Inputs!$B$107
Name sba_principal: Inputs!$B$110
Name sba_rate: Inputs!$B$111
Name sba_term_mo: Inputs!$B$112
Name equity: Inputs!$B$113
Name loc_limit: Inputs!$B$114
Name loc_rate: Inputs!$B$115
Name min_cash: Inputs!$B$116
Name capex: Inputs!$B$117
Name deprec_yrs: Inputs!$B$118
Name tx_tax: Inputs!$B$119
Name license_cost: Inputs!$B$120
Name license_rate: Inputs!$B$121
Name license_term: Inputs!$B$122
Name license_amort_yrs: Inputs!$B$123
Name su_enroll: Inputs!$B$126
Name su_license: Inputs!$B$127
Name su_emr: Inputs!$B$128
Name su_supplies: Inputs!$B$129
Name su_legal: Inputs!$B$130

Sheet Inputs
A1: AZALEA HOSPICE & PALLIATIVE CARE - Tyler, TX
A2: Assumptions Engine - CHOW relaunch of Hickory Hospice (San Antonio + Tyler alternative-delivery) | blue = input | black = formula | green = cross-sheet link
A4: A. GEOGRAPHY & MEDICARE RHC RATES (FY2026, 100% Medicare)
A5: RHC per-diem, days 1-60 ($/day) | B5: 230.83
A6: RHC per-diem, days 61+ ($/day) | B6: 182.36
A7: Tyler CBSA 46340 wage index | B7: 0.88
A8: RHC labor share | B8: 0.68
A9: % patient-days in Tier 1 (days 1-60) | B9: 0.4
A10: Sequestration reduction | B10: 0.02
A11: Write-offs (% of gross) | B11: 0.0015
A12: Blended NET rate per PD - ACTUAL ($/day) | B12: 181
A13: Medicare aggregate cap / beneficiary ($/yr) | B13: 35361.44
A14: Medicare RHC rate escalation (annual) | B14: 0.025
A16: A2. DERIVED RATE BUILD (formulas)
A17: Wage-index adjustment factor | B17: =Inputs!$B$8*Inputs!$B$7+(1-Inputs!$B$8)
A18: Wage-adjusted rate, days 1-60 | B18: =Inputs!$B$5*Inputs!$B$17
A19: Wage-adjusted rate, days 61+ | B19: =Inputs!$B$6*Inputs!$B$17
A20: Blended GROSS rate ($/PD) | B20: =Inputs!$B$9*Inputs!$B$18+(1-Inputs!$B$9)*Inputs!$B$19
A21: Blended NET rate ($/PD) [model] | B21: =Inputs!$B$20*(1-Inputs!$B$10-Inputs!$B$11)
A22: Validation: model net rate vs actual $181 | B22: =Inputs!$B$21-Inputs!$B$12 | C22: should be near $0
A24: B. TIMING
A25: Average days per month | B25: 30.4
A27: C. CENSUS - PATIENT-MIGRATION RAMP (front-loaded M1-M2)
A28: Patient-migration capture rate | B28: 1
A29: Census scenario (1=Base flat, 2=Upside growth) | B29: 1
A31: ADC path - BASE (100% capture, flat steady-state) | C31: 12 | D31: 19.8 | E31: 22 | F31: 22.2 | G31: 22.4 | H31: 22.7 | I31: 22.9 | J31: 23.1 | K31: 23.3 | L31: 23.6 | M31: 23.8 | N31: 24 | O31: 30.5 | P31: 37 | Q31: 43.5 | R31: 50 | S31: 51.5 | T31: 53 | U31: 54.5 | V31: 56
A32: ADC path - UPSIDE (referral growth) | C32: 12 | D32: 19.8 | E32: 22 | F32: 23 | G32: 24 | H32: 25 | I32: 26 | J32: 27 | K32: 28 | L32: 29 | M32: 30 | N32: 31 | O32: 33 | P32: 35 | Q32: 37 | R32: 39 | S32: 44 | T32: 50 | U32: 55 | V32: 60
A33: EFFECTIVE ADC = chosen path x capture | C33: =IF(Inputs!$B$29=2,C32,C31)*Inputs!$B$28 | D33: =IF(Inputs!$B$29=2,D32,D31)*Inputs!$B$28 | E33: =IF(Inputs!$B$29=2,E32,E31)*Inputs!$B$28 | F33: =IF(Inputs!$B$29=2,F32,F31)*Inputs!$B$28 | G33: =IF(Inputs!$B$29=2,G32,G31)*Inputs!$B$28 | H33: =IF(Inputs!$B$29=2,H32,H31)*Inputs!$B$28 | I33: =IF(Inputs!$B$29=2,I32,I31)*Inputs!$B$28 | J33: =IF(Inputs!$B$29=2,J32,J31)*Inputs!$B$28 | ... V33: =IF(Inputs!$B$29=2,V32,V31)*Inputs!$B$28
A35: D. STAGGERED FT ROSTER (named hires)
A36: Name | B36: Role | C36: Annual salary | D36: Start month | E36: Cost group | F36: Status
A37: Brad Woodard | B37: Administrator / Director | C37: 120000 | D37: 1 | E37: Indirect (SG&A) | F37: Filled
A38: Angie Frost | B38: RN Case Manager | C38: 77504 | D38: 1 | E38: Direct (COGS) | F38: Filled
A39: Tanisha Robison | B39: CNA / Hospice Aide | C39: 46511 | D39: 1 | E39: Direct (COGS) | F39: Filled
A40: Dana Davenport | B40: Director of Clinical Services | C40: 110000 | D40: 2 | E40: Indirect (SG&A) | F40: Filled
A41: Silas Shelton | B41: Administrator | C41: 130000 | D41: 3 | E41: Indirect (SG&A) | F41: Filled
A42: Jodi McCollum | B42: RN Case Manager (2nd seat) | C42: 75008 | D42: 4 | E42: Direct (COGS) | F42: OPEN REQ
A43: Director of Business Development | B43: Sales / referrals (growth driver) | C43: 95000 | D43: 6 | E43: Indirect (SG&A) | F43: Filled
A44: Capacity hire - 2nd CNA | B44: CNA / Hospice Aide (capacity-driven, triggers ADC>=25) | C44: 46511 | D44: 13 | E44: Direct (COGS) | F44: Filled
A45: FT Social Worker (MSW) | B45: Core IDG MSW (converts PRN SW to salaried) | C45: 58000 | D45: 14 | E45: Direct (COGS) | F45: Filled
A46: FT LVN - visits / on-call | B46: Core IDG LVN (converts PRN LVN to salaried) | C46: 52000 | D46: 16 | E46: Direct (COGS) | F46: Filled
...

Sheet Dashboard
A1: AZALEA HOSPICE & PALLIATIVE CARE - Tyler, TX
A2: Operations Dashboard - live KPIs (all formula-driven from the engine)
A4: KEY PERFORMANCE INDICATORS
A5: Y3 run-rate net revenue | C5: Y3 EBITDA margin | E5: Min cash balance
A6: =SUM('Operating Budget'!S6:V6) | C6: =SUM('Operating Budget'!S24:V24)/SUM('Operating Budget'!S6:V6) | E6: =MIN('Cash Flow & BS'!C21:V21)
A8: Min DSCR (Y1 monthly) | C8: Peak working-capital draw | E8: Blended net rate / PD
A9: =MIN('Debt Schedule'!C29:N29) | C9: =MAX('Cash Flow & BS'!C20:V20) | E9: =Inputs!$B$21

Sheet Actuals vs Budget
A1: AZALEA HOSPICE & PALLIATIVE CARE - Tyler, TX
A2: Monthly Actuals vs Budget - enter month actuals (blue); variance auto-flags > 10%
A4: Reporting month (1-12) | B4: 3
A6: Line | B6: Budget | C6: Actual | D6: Variance | E6: Flag
A7: Net revenue | B7: =INDEX('Operating Budget'!C6:N6,$B$4) | C7: 0 | D7: =IF(B7=0,0,(C7-B7)/B7) | E7: =IF(ABS(D7)>0.1,"FLAG >10%","ok")
A8: Total COGS | B8: =INDEX('Operating Budget'!C14:N14,$B$4) | C8: 0 | D8: =IF(B8=0,0,(C8-B8)/B8) | E8: =IF(ABS(D8)>0.1,"FLAG >10%","ok")
A9: Gross profit | B9: =INDEX('Operating Budget'!C15:N15,$B$4) | C9: 0 | D9: =IF(B9=0,0,(C9-B9)/B9) | E9: =IF(ABS(D9)>0.1,"FLAG >10%","ok")
A10: Total SG&A | B10: =INDEX('Operating Budget'!C23:N23,$B$4) | C10: 0 | D10: =IF(B10=0,0,(C10-B10)/B10) | E10: =IF(ABS(D10)>0.1,"FLAG >10%","ok")
A11: EBITDA | B11: =INDEX('Operating Budget'!C24:N24,$B$4) | C11: 0 | D11: =IF(B11=0,0,(C11-B11)/B11) | E11: =IF(ABS(D11)>0.1,"FLAG >10%","ok")
A12: Net income | B12: =INDEX('Operating Budget'!C34:N34,$B$4) | C12: 0 | D12: =IF(B12=0,0,(C12-B12)/B12) | E12: =IF(ABS(D12)>0.1,"FLAG >10%","ok")
A14: Budget pulls the selected month from the engine; enter actuals from the close. Flag fires when |variance| > 10%.

Sheet Staffing Tracker
A1: AZALEA HOSPICE & PALLIATIVE CARE - Tyler, TX
A2: Staffing Tracker - staggered-hire calendar | capacity vs demand | open requisitions
A4: HIRE CALENDAR
A5: Name | B5: Role | C5: Annual salary | D5: Start month | E5: Status
A6: Brad Woodard | B6: Administrator / Director | C6: =Inputs!$C$37 | D6: =Inputs!$D$37 | E6: Filled
A7: Angie Frost | B7: RN Case Manager | C7: =Inputs!$C$38 | D7: =Inputs!$D$38 | E7: Filled
A8: Tanisha Robison | B8: CNA / Hospice Aide | C8: =Inputs!$C$39 | D8: =Inputs!$D$39 | E8: Filled
A9: Dana Davenport | B9: Director of Clinical Services | C9: =Inputs!$C$40 | D9: =Inputs!$D$40 | E9: Filled
A10: Silas Shelton | B10: Administrator | C10: =Inputs!$C$41 | D10: =Inputs!$D$41 | E10: Filled
A11: Jodi McCollum | B11: RN Case Manager (2nd seat) | C11: =Inputs!$C$42 | D11: =Inputs!$D$42 | E11: OPEN REQ
A12: Director of Business Development | B12: Sales / referrals (growth driver) | C12: =Inputs!$C$43 | D12: =Inputs!$D$43 | E12: Filled
A13: Capacity hire - 2nd CNA | B13: CNA / Hospice Aide (capacity-driven, triggers ADC>=25) | C13: =Inputs!$C$44 | D13: =Inputs!$D$44 | E13: Filled
A14: FT Social Worker (MSW) | B14: Core IDG MSW (converts PRN SW to salaried) | C14: =Inputs!$C$45 | D14: =Inputs!$D$45 | E14: Filled
A15: FT LVN - visits / on-call | B15: Core IDG LVN (converts PRN LVN to salaried) | C15: =Inputs!$C$46 | D15: =Inputs!$D$46 | E15: Filled
A16: FT Chaplain | B16: Core IDG spiritual care (converts PRN chaplain to FT) | C16: =Inputs!$C$47 | D16: =Inputs!$D$47 | E16: Filled
A17: Capacity hire - 3rd RN | B17: RN Case Manager (capacity-driven, ADC>=30) | C17: =Inputs!$C$48 | D17: =Inputs!$D$48 | E17: Filled
A18: Capacity hire - 3rd CNA | B18: CNA / Hospice Aide (capacity-driven, ADC>=32) | C18: =Inputs!$C$49 | D18: =Inputs!$D$49 | E18: Filled
A19: Capacity hire - 4th RN | B19: RN Case Manager (capacity-driven, ADC>=38) | C19: =Inputs!$C$50 | D19: =Inputs!$D$50 | E19: Filled
A20: Capacity hire - 4th CNA | B20: CNA / Hospice Aide (capacity-driven, ADC>=40) | C20: =Inputs!$C$51 | D20: =Inputs!$D$51 | E20: Filled
A21: Capacity hire - 5th RN | B21: RN Case Manager (capacity-driven, ADC>=48) | C21: =Inputs!$C$52 | D21: =Inputs!$D$52 | E21: Filled
A22: Capacity hire - 5th CNA | B22: CNA / Hospice Aide (capacity-driven, ADC>=50) | C22: =Inputs!$C$53 | D22: =Inputs!$D$53 | E22: Filled
A23: Capacity hire - 6th CNA | B23: CNA / Hospice Aide (capacity-driven, ADC>=54) | C23: =Inputs!$C$54 | D23: =Inputs!$D$54 | E23: Filled
A24: Capacity hire - 6th RN | B24: RN Case Manager (capacity-driven, ADC>=55) | C24: =Inputs!$C$55 | D24: =Inputs!$D$55 | E24: Filled
A25: Quality / Compliance Manager | B25: QAPI program | CoP compliance | surveys | C25: =Inputs!$C$56 | D25: =Inputs!$D$56 | E25: Filled
A26: Intake / Admissions Coordinator | B26: Referral intake | IDG admit coordination | C26: =Inputs!$C$57 | D26: =Inputs!$D$57 | E26: Filled
A27: Volunteer Coordinator | B27: Medicare CoP requirement | volunteer hours | C27: =Inputs!$C$58 | D27: =Inputs!$D$58 | E27: Filled
A29: CAPACITY vs DEMAND (steady-state ADC 22)
A30: RN case managers needed = ADC ÷ caseload | C30: =ROUNDUP('Revenue Model'!E10/Inputs!$B$70,0)
A31: Aides needed = ADC ÷ caseload | C31: =ROUNDUP('Revenue Model'!E10/Inputs!$B$71,0)
A32: Target visits / RN / day | C32: =Inputs!$B$72
A33: Target visits / aide / day | C33: =Inputs!$B$73
A35: Jodi McCollum's 2nd RN-CM seat is funded but vacant - modeled to start M4 as census coverage requires. Track real churn beyond this one open req.

Sheet Cap & Payroll
A1: AZALEA HOSPICE & PALLIATIVE CARE - Tyler, TX
A2: Medicare Cap Monitor (inherited day-counts) + Payroll Reconciliation
A4: MEDICARE AGGREGATE CAP - by year
C5: Year 1 | D5: Year 2 | E5: Year 3
A6: Unique beneficiaries (est.) | C6: 40 | D6: 55 | E6: 60
A7: Cap allowable = beneficiaries x cap | C7: =C6*Inputs!$B$13 | D7: =D6*Inputs!$B$13 | E7: =E6*Inputs!$B$13
A8: Gross Medicare revenue | C8: =SUM('Revenue Model'!C14:N14) | D8: =SUM('Revenue Model'!O14:R14) | E8: =SUM('Revenue Model'!S14:V14)
A9: Cap headroom (allowable - gross) | C9: =C7-C8 | D9: =D7-D8 | E9: =E7-E8
A11: PAYROLL RECONCILIATION (actual semi-monthly vs model)
A12: Run | B12: 1st half | C12: 2nd half | D12: Month total
A13: Apr 2025 | B13: 22921.54 | C13: 22765.1 | D13: =B13+C13
A14: May 2025 | B14: 22117.27 | C14: 21499.29 | D14: =B14+C14
A15: Jun 2025 | B15: 31000 | C15: 27000 | D15: =B15+C15
A16: Model total labor (M3 steady) | D16: ='Staffing & Payroll'!E53+'Staffing & Payroll'!E54
A18: Cap monitor uses inherited mid-episode day-counts (estimate beneficiaries), not fresh admits. Payroll ties the 3 actual semi-monthly runs to the model's loaded labor.

Sheet Revenue Model
A1: AZALEA HOSPICE & PALLIATIVE CARE - Tyler, TX
A2: Revenue Model - 100% Medicare RHC | accrual basis
A4: RHC RATE (per patient-day) - linked from Inputs
A5: Blended GROSS rate ($/PD) | B5: =Inputs!$B$20
A6: Blended NET rate ($/PD) | B6: =Inputs!$B$21
A8: ($ per period) | C8: YEAR 1 - monthly | O8: YEAR 2 - quarterly | S8: YEAR 3 - quarterly
C9: M1 | D9: M2 | E9: M3 | F9: M4 | G9: M5 | H9: M6 | I9: M7 | J9: M8 | K9: M9 | L9: M10 | M9: M11 | N9: M12 | O9: Y2 Q1 | P9: Y2 Q2 | Q9: Y2 Q3 | R9: Y2 Q4 | S9: Y3 Q1 | T9: Y3 Q2 | U9: Y3 Q3 | V9: Y3 Q4
A10: Average daily census (ADC) | C10: =Inputs!C$33 | D10: =Inputs!D$33 | E10: =Inputs!E$33 | F10: =Inputs!F$33 | G10: =Inputs!G$33 | H10: =Inputs!H$33 | I10: =Inputs!I$33 | J10: =Inputs!J$33 | ... V10: =Inputs!V$33
A11: Days in period | C11: =Inputs!$B$25*1 | D11: =Inputs!$B$25*1 | E11: =Inputs!$B$25*1 | F11: =Inputs!$B$25*1 | G11: =Inputs!$B$25*1 | H11: =Inputs!$B$25*1 | I11: =Inputs!$B$25*1 | J11: =Inputs!$B$25*1 | ... N11: =Inputs!$B$25*1 | O11: =Inputs!$B$25*3 | P11: =Inputs!$B$25*3 | Q11: =Inputs!$B$25*3 | R11: =Inputs!$B$25*3 | S11: =Inputs!$B$25*3 | T11: =Inputs!$B$25*3 | U11: =Inputs!$B$25*3 | V11: =Inputs!$B$25*3
A12: Patient-days | C12: =C10*C11 | D12: =D10*D11 | E12: =E10*E11 | F12: =F10*F11 | G12: =G10*G11 | H12: =H10*H11 | I12: =I10*I11 | J12: =J10*J11 | ... V12: =V10*V11
A13: Rate escalation factor (Y1 = 1.000, Y2+ compounded) | C13: =1 | D13: =1 | E13: =1 | F13: =1 | G13: =1 | H13: =1 | I13: =1 | J13: =1 | ... N13: =1 | O13: =(1+Inputs!$B$14)^1 | P13: =(1+Inputs!$B$14)^1 | Q13: =(1+Inputs!$B$14)^1 | R13: =(1+Inputs!$B$14)^1 | S13: =(1+Inputs!$B$14)^2 | T13: =(1+Inputs!$B$14)^2 | U13: =(1+Inputs!$B$14)^2 | V13: =(1+Inputs!$B$14)^2
A14: Gross Medicare revenue | C14: =C12*Inputs!$B$20*C13 | D14: =D12*Inputs!$B$20*D13 | E14: =E12*Inputs!$B$20*E13 | F14: =F12*Inputs!$B$20*F13 | G14: =G12*Inputs!$B$20*G13 | H14: =H12*Inputs!$B$20*H13 | I14: =I12*Inputs!$B$20*I13 | J14: =J12*Inputs!$B$20*J13 | ... V14: =V12*Inputs!$B$20*V13
A15: Less: sequestration | C15: =-C14*Inputs!$B$10 | D15: =-D14*Inputs!$B$10 | E15: =-E14*Inputs!$B$10 | F15: =-F14*Inputs!$B$10 | G15: =-G14*Inputs!$B$10 | H15: =-H14*Inputs!$B$10 | I15: =-I14*Inputs!$B$10 | J15: =-J14*Inputs!$B$10 | ... V15: =-V14*Inputs!$B$10
A16: Less: write-offs | C16: =-C14*Inputs!$B$11 | D16: =-D14*Inputs!$B$11 | E16: =-E14*Inputs!$B$11 | F16: =-F14*Inputs!$B$11 | G16: =-G14*Inputs!$B$11 | H16: =-H14*Inputs!$B$11 | I16: =-I14*Inputs!$B$11 | J16: =-J14*Inputs!$B$11 | ... V16: =-V14*Inputs!$B$11
A17: NET REVENUE | C17: =C14*(1-Inputs!$B$10-Inputs!$B$11) | D17: =D14*(1-Inputs!$B$10-Inputs!$B$11) | E17: =E14*(1-Inputs!$B$10-Inputs!$B$11) | F17: =F14*(1-Inputs!$B$10-Inputs!$B$11) | G17: =G14*(1-Inputs!$B$10-Inputs!$B$11) | H17: =H14*(1-Inputs!$B$10-Inputs!$B$11) | I17: =I14*(1-Inputs!$B$10-Inputs!$B$11) | J17: =J14*(1-Inputs!$B$10-Inputs!$B$11) | ... V17: =V14*(1-Inputs!$B$10-Inputs!$B$11)
A19: Memo: net revenue per patient-day | C19: =IF(C12=0,0,C17/C12) | D19: =IF(D12=0,0,D17/D12) | E19: =IF(E12=0,0,E17/E12) | F19: =IF(F12=0,0,F17/F12) | G19: =IF(G12=0,0,G17/G12) | H19: =IF(H12=0,0,H17/H12) | I19: =IF(I12=0,0,I17/I12) | J19: =IF(J12=0,0,J17/J12) | ... V19: =IF(V12=0,0,V17/V12)

Sheet Staffing & Payroll
A1: AZALEA HOSPICE & PALLIATIVE CARE - Tyler, TX
A2: Staffing & Payroll - staggered hires + census-driven PRN | burden on W-2 only | Med Director 1099 (no benefits)
A4: ($ per period) | C4: YEAR 1 - monthly | O4: YEAR 2 - quarterly | S4: YEAR 3 - quarterly
C5: M1 | D5: M2 | E5: M3 | F5: M4 | G5: M5 | H5: M6 | I5: M7 | J5: M8 | K5: M9 | L5: M10 | M5: M11 | N5: M12 | O5: Y2 Q1 | P5: Y2 Q2 | Q5: Y2 Q3 | R5: Y2 Q4 | S5: Y3 Q1 | T5: Y3 Q2 | U5: Y3 Q3 | V5: Y3 Q4
A6: ADC (driver) | C6: ='Revenue Model'!C10 | D6: ='Revenue Model'!D10 | E6: ='Revenue Model'!E10 | F6: ='Revenue Model'!F10 | G6: ='Revenue Model'!G10 | H6: ='Revenue Model'!H10 | I6: ='Revenue Model'!I10 | J6: ='Revenue Model'!J10 | ... V6: ='Revenue Model'!V10
A7: DIRECT-CARE FT SALARIES (Cost of Care)
A8: Brad Woodard - Administrator / Director | C8: =IF(1>=Inputs!$D$37,Inputs!$C$37/12*1*1,0) | D8: =IF(2>=Inputs!$D$37,Inputs!$C$37/12*1*1,0) | E8: =IF(3>=Inputs!$D$37,Inputs!$C$37/12*1*1,0) | F8: =IF(4>=Inputs!$D$37,Inputs!$C$37/12*1*1,0) | G8: =IF(5>=Inputs!$D$37,Inputs!$C$37/12*1*1,0) | H8: =IF(6>=Inputs!$D$37,Inputs!$C$37/12*1*1,0) | I8: =IF(7>=Inputs!$D$37,Inputs!$C$37/12*1*1,0) | J8: =IF(8>=Inputs!$D$37,Inputs!$C$37/12*1*1,0) | K8: =IF(9>=Inputs!$D$37,Inputs!$C$37/12*1*1,0) | L8: =IF(10>=Inputs!$D$37,Inputs!$C$37/12*1*1,0) | M8: =IF(11>=Inputs!$D$37,Inputs!$C$37/12*1*1,0) | N8: =IF(12>=Inputs!$D$37,Inputs!$C$37/12*1*1,0) | O8: =IF(15>=Inputs!$D$37,Inputs!$C$37/12*3*(1+Inputs!$B$74)^1,0) | P8: =IF(18>=Inputs!$D$37,Inputs!$C$37/12*3*(1+Inputs!$B$74)^1,0) | Q8: =IF(21>=Inputs!$D$37,Inputs!$C$37/12*3*(1+Inputs!$B$74)^1,0) | R8: =IF(24>=Inputs!$D$37,Inputs!$C$37/12*3*(1+Inputs!$B$74)^1,0) | S8: =IF(27>=Inputs!$D$37,Inputs!$C$37/12*3*(1+Inputs!$B$74)^2,0) | T8: =IF(30>=Inputs!$D$37,Inputs!$C$37/12*3*(1+Inputs!$B$74)^2,0) | U8: =IF(33>=Inputs!$D$37,Inputs!$C$37/12*3*(1+Inputs!$B$74)^2,0) | V8: =IF(36>=Inputs!$D$37,Inputs!$C$37/12*3*(1+Inputs!$B$74)^2,0)
A9: Angie Frost - RN Case Manager | C9: =IF(1>=Inputs!$D$38,Inputs!$C$38/12*1*1,0) | D9: =IF(2>=Inputs!$D$38,Inputs!$C$38/12*1*1,0) | E9: =IF(3>=Inputs!$D$38,Inputs!$C$38/12*1*1,0) | F9: =IF(4>=Inputs!$D$38,Inputs!$C$38/12*1*1,0) | G9: =IF(5>=Inputs!$D$38,Inputs!$C$38/12*1*1,0) | H9: =IF(6>=Inputs!$D$38,Inputs!$C$38/12*1*1,0) | I9: =IF(7>=Inputs!$D$38,Inputs!$C$38/12*1*1,0) | J9: =IF(8>=Inputs!$D$38,Inputs!$C$38/12*1*1,0) | K9: =IF(9>=Inputs!$D$38,Inputs!$C$38/12*1*1,0) | L9: =IF(10>=Inputs!$D$38,Inputs!$C$38/12*1*1,0) | M9: =IF(11>=Inputs!$D$38,Inputs!$C$38/12*1*1,0) | N9: =IF(12>=Inputs!$D$38,Inputs!$C$38/12*1*1,0) | O9: =IF(15>=Inputs!$D$38,Inputs!$C$38/12*3*(1+Inputs!$B$74)^1,0) | P9: =IF(18>=Inputs!$D$38,Inputs!$C$38/12*3*(1+Inputs!$B$74)^1,0) | Q9: =IF(21>=Inputs!$D$38,Inputs!$C$38/12*3*(1+Inputs!$B$74)^1,0) | R9: =IF(24>=Inputs!$D$38,Inputs!$C$38/12*3*(1+Inputs!$B$74)^1,0) | S9: =IF(27>=Inputs!$D$38,Inputs!$C$38/12*3*(1+Inputs!$B$74)^2,0) | T9: =IF(30>=Inputs!$D$38,Inputs!$C$38/12*3*(1+Inputs!$B$74)^2,0) | U9: =IF(33>=Inputs!$D$38,Inputs!$C$38/12*3*(1+Inputs!$B$74)^2,0) | V9: =IF(36>=Inputs!$D$38,Inputs!$C$38/12*3*(1+Inputs!$B$74)^2,0)
A10: Tanisha Robison - CNA / Hospice Aide | C10: =IF(1>=Inputs!$D$39,Inputs!$C$39/12*1*1,0) | D10: =IF(2>=Inputs!$D$39,Inputs!$C$39/12*1*1,0) | E10: =IF(3>=Inputs!$D$39,Inputs!$C$39/12*1*1,0) | F10: =IF(4>=Inputs!$D$39,Inputs!$C$39/12*1*1,0) | G10: =IF(5>=Inputs!$D$39,Inputs!$C$39/12*1*1,0) | H10: =IF(6>=Inputs!$D$39,Inputs!$C$39/12*1*1,0) | I10: =IF(7>=Inputs!$D$39,Inputs!$C$39/12*1*1,0) | J10: =IF(8>=Inputs!$D$39,Inputs!$C$39/12*1*1,0) | K10: =IF(9>=Inputs!$D$39,Inputs!$C$39/12*1*1,0) | L10: =IF(10>=Inputs!$D$39,Inputs!$C$39/12*1*1,0) | M10: =IF(11>=Inputs!$D$39,Inputs!$C$39/12*1*1,0) | N10: =IF(12>=Inputs!$D$39,Inputs!$C$39/12*1*1,0) | O10: =IF(15>=Inputs!$D$39,Inputs!$C$39/12*3*(1+Inputs!$B$74)^1,0) | P10: =IF(18>=Inputs!$D$39,Inputs!$C$39/12*3*(1+Inputs!$B$74)^1,0) | Q10: =IF(21>=Inputs!$D$39,Inputs!$C$39/12*3*(1+Inputs!$B$74)^1,0) | R10: =IF(24>=Inputs!$D$39,Inputs!$C$39/12*3*(1+Inputs!$B$74)^1,0) | S10: =IF(27>=Inputs!$D$39,Inputs!$C$39/12*3*(1+Inputs!$B$74)^2,0) | T10: =IF(30>=Inputs!$D$39,Inputs!$C$39/12*3*(1+Inputs!$B$74)^2,0) | U10: =IF(33>=Inputs!$D$39,Inputs!$C$39/12*3*(1+Inputs!$B$74)^2,0) | V10: =IF(36>=Inputs!$D$39,Inputs!$C$39/12*3*(1+Inputs!$B$74)^2,0)
A11: Dana Davenport - Director of Clinical Services | C11: =IF(1>=Inputs!$D$40,Inputs!$C$40/12*1*1,0) | D11: =IF(2>=Inputs!$D$40,Inputs!$C$40/12*1*1,0) | E11: =IF(3>=Inputs!$D$40,Inputs!$C$40/12*1*1,0) | F11: =IF(4>=Inputs!$D$40,Inputs!$C$40/12*1*1,0) | G11: =IF(5>=Inputs!$D$40,Inputs!$C$40/12*1*1,0) | H11: =IF(6>=Inputs!$D$40,Inputs!$C$40/12*1*1,0) | I11: =IF(7>=Inputs!$D$40,Inputs!$C$40/12*1*1,0) | J11: =IF(8>=Inputs!$D$40,Inputs!$C$40/12*1*1,0) | K11: =IF(9>=Inputs!$D$40,Inputs!$C$40/12*1*1,0) | L11: =IF(10>=Inputs!$D$40,Inputs!$C$40/12*1*1,0) | M11: =IF(11>=Inputs!$D$40,Inputs!$C$40/12*1*1,0) | N11: =IF(12>=Inputs!$D$40,Inputs!$C$40/12*1*1,0) | O11: =IF(15>=Inputs!$D$40,Inputs!$C$40/12*3*(1+Inputs!$B$74)^1,0) | P11: =IF(18>=Inputs!$D$40,Inputs!$C$40/12*3*(1+Inputs!$B$74)^1,0) | Q11: =IF(21>=Inputs!$D$40,Inputs!$C$40/12*3*(1+Inputs!$B$74)^1,0) | R11: =IF(24>=Inputs!$D$40,Inputs!$C$40/12*3*(1+Inputs!$B$74)^1,0) | S11: =IF(27>=Inputs!$D$40,Inputs!$C$40/12*3*(1+Inputs!$B$74)^2,0) | T11: =IF(30>=Inputs!$D$40,Inputs!$C$40/12*3*(1+Inputs!$B$74)^2,0) | U11: =IF(33>=Inputs!$D$40,Inputs!$C$40/12*3*(1+Inputs!$B$74)^2,0) | V11: =IF(36>=Inputs!$D$40,Inputs!$C$40/12*3*(1+Inputs!$B$74)^2,0)
A12: Silas Shelton - Administrator | C12: =IF(1>=Inputs!$D$41,Inputs!$C$41/12*1*1,0) | D12: =IF(2>=Inputs!$D$41,Inputs!$C$41/12*1*1,0) | E12: =IF(3>=Inputs!$D$41,Inputs!$C$41/12*1*1,0) | F12: =IF(4>=Inputs!$D$41,Inputs!$C$41/12*1*1,0) | G12: =IF(5>=Inputs!$D$41,Inputs!$C$41/12*1*1,0) | H12: =IF(6>=Inputs!$D$41,Inputs!$C$41/12*1*1,0) | I12: =IF(7>=Inputs!$D$41,Inputs!$C$41/12*1*1,0) | J12: =IF(8>=Inputs!$D$41,Inputs!$C$41/12*1*1,0) | K12: =IF(9>=Inputs!$D$41,Inputs!$C$41/12*1*1,0) | L12: =IF(10>=Inputs!$D$41,Inputs!$C$41/12*1*1,0) | M12: =IF(11>=Inputs!$D$41,Inputs!$C$41/12*1*1,0) | N12: =IF(12>=Inputs!$D$41,Inputs!$C$41/12*1*1,0) | O12: =IF(15>=Inputs!$D$41,Inputs!$C$41/12*3*(1+Inputs!$B$74)^1,0) | P12: =IF(18>=Inputs!$D$41,Inputs!$C$41/12*3*(1+Inputs!$B$74)^1,0) | Q12: =IF(21>=Inputs!$D$41,Inputs!$C$41/12*3*(1+Inputs!$B$74)^1,0) | R12: =IF(24>=Inputs!$D$41,Inputs!$C$41/12*3*(1+Inputs!$B$74)^1,0) | S12: =IF(27>=Inputs!$D$41,Inputs!$C$41/12*3*(1+Inputs!$B$74)^2,0) | T12: =IF(30>=Inputs!$D$41,Inputs!$C$41/12*3*(1+Inputs!$B$74)^2,0) | U12: =IF(33>=Inputs!$D$41,Inputs!$C$41/12*3*(1+Inputs!$B$74)^2,0) | V12: =IF(36>=Inputs!$D$41,Inputs!$C$41/12*3*(1+Inputs!$B$74)^2,0)
A13: Jodi McCollum - RN Case Manager (2nd seat) [OPEN REQ] | C13: =IF(1>=Inputs!$D$42,Inputs!$C$42/12*1*1,0) | D13: =IF(2>=Inputs!$D$42,Inputs!$C$42/12*1*1,0) | E13: =IF(3>=Inputs!$D$42,Inputs!$C$42/12*1*1,0) | F13: =IF(4>=Inputs!$D$42,Inputs!$C$42/12*1*1,0) | G13: =IF(5>=Inputs!$D$42,Inputs!$C$42/12*1*1,0) | H13: =IF(6>=Inputs!$D$42,Inputs!$C$42/12*1*1,0) | I13: =IF(7>=Inputs!$D$42,Inputs!$C$42/12*1*1,0) | J13: =IF(8>=Inputs!$D$42,Inputs!$C$42/12*1*1,0) | K13: =IF(9>=Inputs!$D$42,Inputs!$C$42/12*1*1,0) | L13: =IF(10>=Inputs!$D$42,Inputs!$C$42/12*1*1,0) | M13: =IF(11>=Inputs!$D$42,Inputs!$C$42/12*1*1,0) | N13: =IF(12>=Inputs!$D$42,Inputs!$C$42/12*1*1,0) | O13: =IF(15>=Inputs!$D$42,Inputs!$C$42/12*3*(1+Inputs!$B$74)^1,0) | P13: =IF(18>=Inputs!$D$42,Inputs!$C$42/12*3*(1+Inputs!$B$74)^1,0) | Q13: =IF(21>=Inputs!$D$42,Inputs!$C$42/12*3*(1+Inputs!$B$74)^1,0) | R13: =IF(24>=Inputs!$D$42,Inputs!$C$42/12*3*(1+Inputs!$B$74)^1,0) | S13: =IF(27>=Inputs!$D$42,Inputs!$C$42/12*3*(1+Inputs!$B$74)^2,0) | T13: =IF(30>=Inputs!$D$42,Inputs!$C$42/12*3*(1+Inputs!$B$74)^2,0) | U13: =IF(33>=Inputs!$D$42,Inputs!$C$42/12*3*(1+Inputs!$B$74)^2,0) | V13: =IF(36>=Inputs!$D$42,Inputs!$C$42/12*3*(1+Inputs!$B$74)^2,0)
A14: Director of Business Development - Sales / referrals (growth driver) | C14: =IF(1>=Inputs!$D$43,Inputs!$C$43/12*1*1,0) | D14: =IF(2>=Inputs!$D$43,Inputs!$C$43/12*1*1,0) | E14: =IF(3>=Inputs!$D$43,Inputs!$C$43/12*1*1,0) | F14: =IF(4>=Inputs!$D$43,Inputs!$C$43/12*1*1,0) | G14: =IF(5>=Inputs!$D$43,Inputs!$C$43/12*1*1,0) | H14: =IF(6>=Inputs!$D$43,Inputs!$C$43/12*1*1,0) | I14: =IF(7>=Inputs!$D$43,Inputs!$C$43/12*1*1,0) | J14: =IF(8>=Inputs!$D$43,Inputs!$C$43/12*1*1,0) | K14: =IF(9>=Inputs!$D$43,Inputs!$C$43/12*1*1,0) | L14: =IF(10>=Inputs!$D$43,Inputs!$C$43/12*1*1,0) | M14: =IF(11>=Inputs!$D$43,Inputs!$C$43/12*1*1,0) | N14: =IF(12>=Inputs!$D$43,Inputs!$C$43/12*1*1,0) | O14: =IF(15>=Inputs!$D$43,Inputs!$C$43/12*3*(1+Inputs!$B$74)^1,0) | P14: =IF(18>=Inputs!$D$43,Inputs!$C$43/12*3*(1+Inputs!$B$74)^1,0) | Q14: =IF(21>=Inputs!$D$43,Inputs!$C$43/12*3*(1+Inputs!$B$74)^1,0) | R14: =IF(24>=Inputs!$D$43,Inputs!$C$43/12*3*(1+Inputs!$B$74)^1,0) | S14: =IF(27>=Inputs!$D$43,Inputs!$C$43/12*3*(1+Inputs!$B$74)^2,0) | T14: =IF(30>=Inputs!$D$43,Inputs!$C$43/12*3*(1+Inputs!$B$74)^2,0) | U14: =IF(33>=Inputs!$D$43,Inputs!$C$43/12*3*(1+Inputs!$B$74)^2,0) | V14: =IF(36>=Inputs!$D$43,Inputs!$C$43/12*3*(1+Inputs!$B$74)^2,0)
A15: Capacity hire - 2nd CNA - CNA / Hospice Aide (capacity-driven, triggers ADC>=25) | C15: =IF(1>=Inputs!$D$44,Inputs!$C$44/12*1*1,0) | D15: =IF(2>=Inputs!$D$44,Inputs!$C$44/12*1*1,0) | E15: =IF(3>=Inputs!$D$44,Inputs!$C$44/12*1*1,0) | F15: =IF(4>=Inputs!$D$44,Inputs!$C$44/12*1*1,0) | G15: =IF(5>=Inputs!$D$44,Inputs!$C$44/12*1*1,0) | H15: =IF(6>=Inputs!$D$44,Inputs!$C$44/12*1*1,0) | I15: =IF(7>=Inputs!$D$44,Inputs!$C$44/12*1*1,0) | J15: =IF(8>=Inputs!$D$44,Inputs!$C$44/12*1*1,0) | K15: =IF(9>=Inputs!$D$44,Inputs!$C$44/12*1*1,0) | L15: =IF(10>=Inputs!$D$44,Inputs!$C$44/12*1*1,0) | M15: =IF(11>=Inputs!$D$44,Inputs!$C$44/12*1*1,0) | N15: =IF(12>=Inputs!$D$44,Inputs!$C$44/12*1*1,0) | O15: =IF(15>=Inputs!$D$44,Inputs!$C$44/12*3*(1+Inputs!$B$74)^1,0) | P15: =IF(18>=Inputs!$D$44,Inputs!$C$44/12*3*(1+Inputs!$B$74)^1,0) | Q15: =IF(21>=Inputs!$D$44,Inputs!$C$44/12*3*(1+Inputs!$B$74)^1,0) | R15: =IF(24>=Inputs!$D$44,Inputs!$C$44/12*3*(1+Inputs!$B$74)^1,0) | S15: =IF(27>=Inputs!$D$44,Inputs!$C$44/12*3*(1+Inputs!$B$74)^2,0) | T15: =IF(30>=Inputs!$D$44,Inputs!$C$44/12*3*(1+Inputs!$B$74)^2,0) | U15: =IF(33>=Inputs!$D$44,Inputs!$C$44/12*3*(1+Inputs!$B$74)^2,0) | V15: =IF(36>=Inputs!$D$44,Inputs!$C$44/12*3*(1+Inputs!$B$74)^2,0)
A16: FT Social Worker (MSW) - Core IDG MSW (converts PRN SW to salaried) | C16: =IF(1>=Inputs!$D$45,Inputs!$C$45/12*1*1,0) | D16: =IF(2>=Inputs!$D$45,Inputs!$C$45/12*1*1,0) | E16: =IF(3>=Inputs!$D$45,Inputs!$C$45/12*1*1,0) | F16: =IF(4>=Inputs!$D$45,Inputs!$C$45/12*1*1,0) | G16: =IF(5>=Inputs!$D$45,Inputs!$C$45/12*1*1,0) | H16: =IF(6>=Inputs!$D$45,Inputs!$C$45/12*1*1,0) | I16: =IF(7>=Inputs!$D$45,Inputs!$C$45/12*1*1,0) | J16: =IF(8>=Inputs!$D$45,Inputs!$C$45/12*1*1,0) | K16: =IF(9>=Inputs!$D$45,Inputs!$C$45/12*1*1,0) | L16: =IF(10>=Inputs!$D$45,Inputs!$C$45/12*1*1,0) | M16: =IF(11>=Inputs!$D$45,Inputs!$C$45/12*1*1,0) | N16: =IF(12>=Inputs!$D$45,Inputs!$C$45/12*1*1,0) | O16: =IF(15>=Inputs!$D$45,Inputs!$C$45/12*3*(1+Inputs!$B$74)^1,0) | P16: =IF(18>=Inputs!$D$45,Inputs!$C$45/12*3*(1+Inputs!$B$74)^1,0) | Q16: =IF(21>=Inputs!$D$45,Inputs!$C$45/12*3*(1+Inputs!$B$74)^1,0) | R16: =IF(24>=Inputs!$D$45,Inputs!$C$45/12*3*(1+Inputs!$B$74)^1,0) | S16: =IF(27>=Inputs!$D$45,Inputs!$C$45/12*3*(1+Inputs!$B$74)^2,0) | T16: =IF(30>=Inputs!$D$45,Inputs!$C$45/12*3*(1+Inputs!$B$74)^2,0) | U16: =IF(33>=Inputs!$D$45,Inputs!$C$45/12*3*(1+Inputs!$B$74)^2,0) | V16: =IF(36>=Inputs!$D$45,Inputs!$C$45/12*3*(1+Inputs!$B$74)^2,0)
A17: FT LVN - visits / on-call - Core IDG LVN (converts PRN LVN to salaried) | C17: =IF(1>=Inputs!$D$46,Inputs!$C$46/12*1*1,0) | D17: =IF(2>=Inputs!$D$46,Inputs!$C$46/12*1*1,0) | E17: =IF(3>=Inputs!$D$46,Inputs!$C$46/12*1*1,0) | F17: =IF(4>=Inputs!$D$46,Inputs!$C$46/12*1*1,0) | G17: =IF(5>=Inputs!$D$46,Inputs!$C$46/12*1*1,0) | H17: =IF(6>=Inputs!$D$46,Inputs!$C$46/12*1*1,0) | I17: =IF(7>=Inputs!$D$46,Inputs!$C$46/12*1*1,0) | J17: =IF(8>=Inputs!$D$46,Inputs!$C$46/12*1*1,0) | K17: =IF(9>=Inputs!$D$46,Inputs!$C$46/12*1*1,0) | L17: =IF(10>=Inputs!$D$46,Inputs!$C$46/12*1*1,0) | M17: =IF(11>=Inputs!$D$46,Inputs!$C$46/12*1*1,0) | N17: =IF(12>=Inputs!$D$46,Inputs!$C$46/12*1*1,0) | O17: =IF(15>=Inputs!$D$46,Inputs!$C$46/12*3*(1+Inputs!$B$74)^1,0) | P17: =IF(18>=Inputs!$D$46,Inputs!$C$46/12*3*(1+Inputs!$B$74)^1,0) | Q17: =IF(21>=Inputs!$D$46,Inputs!$C$46/12*3*(1+Inputs!$B$74)^1,0) | R17: =IF(24>=Inputs!$D$46,Inputs!$C$46/12*3*(1+Inputs!$B$74)^1,0) | S17: =IF(27>=Inputs!$D$46,Inputs!$C$46/12*3*(1+Inputs!$B$74)^2,0) | T17: =IF(30>=Inputs!$D$46,Inputs!$C$46/12*3*(1+Inputs!$B$74)^2,0) | U17: =IF(33>=Inputs!$D$46,Inputs!$C$46/12*3*(1+Inputs!$B$74)^2,0) | V17: =IF(36>=Inputs!$D$46,Inputs!$C$46/12*3*(1+Inputs!$B$74)^2,0)
A18: FT Chaplain - Core IDG spiritual care (converts PRN chaplain to FT) | C18: =IF(1>=Inputs!$D$47,Inputs!$C$47/12*1*1,0) | D18: =IF(2>=Inputs!$D$47,Inputs!$C$47/12*1*1,0) | E18: =IF(3>=Inputs!$D$47,Inputs!$C$47/12*1*1,0) | F18: =IF(4>=Inputs!$D$47,Inputs!$C$47/12*1*1,0) | G18: =IF(5>=Inputs!$D$47,Inputs!$C$47/12*1*1,0) | H18: =IF(6>=Inputs!$D$47,Inputs!$C$47/12*1*1,0) | I18: =IF(7>=Inputs!$D$47,Inputs!$C$47/12*1*1,0) | J18: =IF(8>=Inputs!$D$47,Inputs!$C$47/12*1*1,0) | K18: =IF(9>=Inputs!$D$47,Inputs!$C$47/12*1*1,0) | L18: =IF(10>=Inputs!$D$47,Inputs!$C$47/12*1*1,0) | M18: =IF(11>=Inputs!$D$47,Inputs!$C$47/12*1*1,0) | N18: =IF(12>=Inputs!$D$47,Inputs!$C$47/12*1*1,0) | O18: =IF(15>=Inputs!$D$47,Inputs!$C$47/12*3*(1+Inputs!$B$74)^1,0) | P18: =IF(18>=Inputs!$D$47,Inputs!$C$47/12*3*(1+Inputs!$B$74)^1,0) | Q18: =IF(21>=Inputs!$D$47,Inputs!$C$47/12*3*(1+Inputs!$B$74)^1,0) | R18: =IF(24>=Inputs!$D$47,Inputs!$C$47/12*3*(1+Inputs!$B$74)^1,0) | S18: =IF(27>=Inputs!$D$47,Inputs!$C$47/12*3*(1+Inputs!$B$74)^2,0) | T18: =IF(30>=Inputs!$D$47,Inputs!$C$47/12*3*(1+Inputs!$B$74)^2,0) | U18: =IF(33>=Inputs!$D$47,Inputs!$C$47/12*3*(1+Inputs!$B$74)^2,0) | V18: =IF(36>=Inputs!$D$47,Inputs!$C$47/12*3*(1+Inputs!$B$74)^2,0)
A19: Capacity hire - 3rd RN - RN Case Manager (capacity-driven, ADC>=30) | C19: =IF(1>=Inputs!$D$48,Inputs!$C$48/12*1*1,0) | D19: =IF(2>=Inputs!$D$48,Inputs!$C$48/12*1*1,0) | E19: =IF(3>=Inputs!$D$48,Inputs!$C$48/12*1*1,0) | F19: =IF(4>=Inputs!$D$48,Inputs!$C$48/12*1*1,0) | G19: =IF(5>=Inputs!$D$48,Inputs!$C$48/12*1*1,0) | H19: =IF(6>=Inputs!$D$48,Inputs!$C$48/12*1*1,0) | I19: =IF(7>=Inputs!$D$48,Inputs!$C$48/12*1*1,0) | J19: =IF(8>=Inputs!$D$48,Inputs!$C$48/12*1*1,0) | K19: =IF(9>=Inputs!$D$48,Inputs!$C$48/12*1*1,0) | L19: =IF(10>=Inputs!$D$48,Inputs!$C$48/12*1*1,0) | M19: =IF(11>=Inputs!$D$48,Inputs!$C$48/12*1*1,0) | N19: =IF(12>=Inputs!$D$48,Inputs!$C$48/12*1*1,0) | O19: =IF(15>=Inputs!$D$48,Inputs!$C$48/12*3*(1+Inputs!$B$74)^1,0) | P19: =IF(18>=Inputs!$D$48,Inputs!$C$48/12*3*(1+Inputs!$B$74)^1,0) | Q19: =IF(21>=Inputs!$D$48,Inputs!$C$48/12*3*(1+Inputs!$B$74)^1,0) | R19: =IF(24>=Inputs!$D$48,Inputs!$C$48/12*3*(1+Inputs!$B$74)^1,0) | S19: =IF(27>=Inputs!$D$48,Inputs!$C$48/12*3*(1+Inputs!$B$74)^2,0) | T19: =IF(30>=Inputs!$D$48,Inputs!$C$48/12*3*(1+Inputs!$B$74)^2,0) | U19: =IF(33>=Inputs!$D$48,Inputs!$C$48/12*3*(1+Inputs!$B$74)^2,0) | V19: =IF(36>=Inputs!$D$48,Inputs!$C$48/12*3*(1+Inputs!$B$74)^2,0)
A20: Capacity hire - 3rd CNA - CNA / Hospice Aide (capacity-driven, ADC>=32) | C20: =IF(1>=Inputs!$D$49,Inputs!$C$49/12*1*1,0) | D20: =IF(2>=Inputs!$D$49,Inputs!$C$49/12*1*1,0) | E20: =IF(3>=Inputs!$D$49,Inputs!$C$49/12*1*1,0) | F20: =IF(4>=Inputs!$D$49,Inputs!$C$49/12*1*1,0) | G20: =IF(5>=Inputs!$D$49,Inputs!$C$49/12*1*1,0) | H20: =IF(6>=Inputs!$D$49,Inputs!$C$49/12*1*1,0) | I20: =IF(7>=Inputs!$D$49,Inputs!$C$49/12*1*1,0) | J20: =IF(8>=Inputs!$D$49,Inputs!$C$49/12*1*1,0) | K20: =IF(9>=Inputs!$D$49,Inputs!$C$49/12*1*1,0) | L20: =IF(10>=Inputs!$D$49,Inputs!$C$49/12*1*1,0) | M20: =IF(11>=Inputs!$D$49,Inputs!$C$49/12*1*1,0) | N20: =IF(12>=Inputs!$D$49,Inputs!$C$49/12*1*1,0) | O20: =IF(15>=Inputs!$D$49,Inputs!$C$49/12*3*(1+Inputs!$B$74)^1,0) | P20: =IF(18>=Inputs!$D$49,Inputs!$C$49/12*3*(1+Inputs!$B$74)^1,0) | Q20: =IF(21>=Inputs!$D$49,Inputs!$C$49/12*3*(1+Inputs!$B$74)^1,0) | R20: =IF(24>=Inputs!$D$49,Inputs!$C$49/12*3*(1+Inputs!$B$74)^1,0) | S20: =IF(27>=Inputs!$D$49,Inputs!$C$49/12*3*(1+Inputs!$B$74)^2,0) | T20: =IF(30>=Inputs!$D$49,Inputs!$C$49/12*3*(1+Inputs!$B$74)^2,0) | U20: =IF(33>=Inputs!$D$49,Inputs!$C$49/12*3*(1+Inputs!$B$74)^2,0) | V20: =IF(36>=Inputs!$D$49,Inputs!$C$49/12*3*(1+Inputs!$B$74)^2,0)
A21: Capacity hire - 4th RN - RN Case Manager (capacity-driven, ADC>=38) | C21: =IF(1>=Inputs!$D$50,Inputs!$C$50/12*1*1,0) | D21: =IF(2>=Inputs!$D$50,Inputs!$C$50/12*1*1,0) | E21: =IF(3>=Inputs!$D$50,Inputs!$C$50/12*1*1,0) | F21: =IF(4>=Inputs!$D$50,Inputs!$C$50/12*1*1,0) | G21: =IF(5>=Inputs!$D$50,Inputs!$C$50/12*1*1,0) | H21: =IF(6>=Inputs!$D$50,Inputs!$C$50/12*1*1,0) | I21: =IF(7>=Inputs!$D$50,Inputs!$C$50/12*1*1,0) | J21: =IF(8>=Inputs!$D$50,Inputs!$C$50/12*1*1,0) | K21: =IF(9>=Inputs!$D$50,Inputs!$C$50/12*1*1,0) | L21: =IF(10>=Inputs!$D$50,Inputs!$C$50/12*1*1,0) | M21: =IF(11>=Inputs!$D$50,Inputs!$C$50/12*1*1,0) | N21: =IF(12>=Inputs!$D$50,Inputs!$C$50/12*1*1,0) | O21: =IF(15>=Inputs!$D$50,Inputs!$C$50/12*3*(1+Inputs!$B$74)^1,0) | P21: =IF(18>=Inputs!$D$50,Inputs!$C$50/12*3*(1+Inputs!$B$74)^1,0) | Q21: =IF(21>=Inputs!$D$50,Inputs!$C$50/12*3*(1+Inputs!$B$74)^1,0) | R21: =IF(24>=Inputs!$D$50,Inputs!$C$50/12*3*(1+Inputs!$B$74)^1,0) | S21: =IF(27>=Inputs!$D$50,Inputs!$C$50/12*3*(1+Inputs!$B$74)^2,0) | T21: =IF(30>=Inputs!$D$50,Inputs!$C$50/12*3*(1+Inputs!$B$74)^2,0) | U21: =IF(33>=Inputs!$D$50,Inputs!$C$50/12*3*(1+Inputs!$B$74)^2,0) | V21: =IF(36>=Inputs!$D$50,Inputs!$C$50/12*3*(1+Inputs!$B$74)^2,0)
A22: Capacity hire - 4th CNA - CNA / Hospice Aide (capacity-driven, ADC>=40) | C22: =IF(1>=Inputs!$D$51,Inputs!$C$51/12*1*1,0) | D22: =IF(2>=Inputs!$D$51,Inputs!$C$51/12*1*1,0) | E22: =IF(3>=Inputs!$D$51,Inputs!$C$51/12*1*1,0) | F22: =IF(4>=Inputs!$D$51,Inputs!$C$51/12*1*1,0) | G22: =IF(5>=Inputs!$D$51,Inputs!$C$51/12*1*1,0) | H22: =IF(6>=Inputs!$D$51,Inputs!$C$51/12*1*1,0) | I22: =IF(7>=Inputs!$D$51,Inputs!$C$51/12*1*1,0) | J22: =IF(8>=Inputs!$D$51,Inputs!$C$51/12*1*1,0) | K22: =IF(9>=Inputs!$D$51,Inputs!$C$51/12*1*1,0) | L22: =IF(10>=Inputs!$D$51,Inputs!$C$51/12*1*1,0) | M22: =IF(11>=Inputs!$D$51,Inputs!$C$51/12*1*1,0) | N22: =IF(12>=Inputs!$D$51,Inputs!$C$51/12*1*1,0) | O22: =IF(15>=Inputs!$D$51,Inputs!$C$51/12*3*(1+Inputs!$B$74)^1,0) | P22: =IF(18>=Inputs!$D$51,Inputs!$C$51/12*3*(1+Inputs!$B$74)^1,0) | Q22: =IF(21>=Inputs!$D$51,Inputs!$C$51/12*3*(1+Inputs!$B$74)^1,0) | R22: =IF(24>=Inputs!$D$51,Inputs!$C$51/12*3*(1+Inputs!$B$74)^1,0) | S22: =IF(27>=Inputs!$D$51,Inputs!$C$51/12*3*(1+Inputs!$B$74)^2,0) | T22: =IF(30>=Inputs!$D$51,Inputs!$C$51/12*3*(1+Inputs!$B$74)^2,0) | U22: =IF(33>=Inputs!$D$51,Inputs!$C$51/12*3*(1+Inputs!$B$74)^2,0) | V22: =IF(36>=Inputs!$D$51,Inputs!$C$51/12*3*(1+Inputs!$B$74)^2,0)
A23: Capacity hire - 5th RN - RN Case Manager (capacity-driven, ADC>=48) | C23: =IF(1>=Inputs!$D$52,Inputs!$C$52/12*1*1,0) | D23: =IF(2>=Inputs!$D$52,Inputs!$C$52/12*1*1,0) | E23: =IF(3>=Inputs!$D$52,Inputs!$C$52/12*1*1,0) | F23: =IF(4>=Inputs!$D$52,Inputs!$C$52/12*1*1,0) | G23: =IF(5>=Inputs!$D$52,Inputs!$C$52/12*1*1,0) | H23: =IF(6>=Inputs!$D$52,Inputs!$C$52/12*1*1,0) | I23: =IF(7>=Inputs!$D$52,Inputs!$C$52/12*1*1,0) | J23: =IF(8>=Inputs!$D$52,Inputs!$C$52/12*1*1,0) | K23: =IF(9>=Inputs!$D$52,Inputs!$C$52/12*1*1,0) | L23: =IF(10>=Inputs!$D$52,Inputs!$C$52/12*1*1,0) | M23: =IF(11>=Inputs!$D$52,Inputs!$C$52/12*1*1,0) | N23: =IF(12>=Inputs!$D$52,Inputs!$C$52/12*1*1,0) | O23: =IF(15>=Inputs!$D$52,Inputs!$C$52/12*3*(1+Inputs!$B$74)^1,0) | P23: =IF(18>=Inputs!$D$52,Inputs!$C$52/12*3*(1+Inputs!$B$74)^1,0) | Q23: =IF(21>=Inputs!$D$52,Inputs!$C$52/12*3*(1+Inputs!$B$74)^1,0) | R23: =IF(24>=Inputs!$D$52,Inputs!$C$52/12*3*(1+Inputs!$B$74)^1,0) | S23: =IF(27>=Inputs!$D$52,Inputs!$C$52/12*3*(1+Inputs!$B$74)^2,0) | T23: =IF(30>=Inputs!$D$52,Inputs!$C$52/12*3*(1+Inputs!$B$74)^2,0) | U23: =IF(33>=Inputs!$D$52,Inputs!$C$52/12*3*(1+Inputs!$B$74)^2,0) | V23: =IF(36>=Inputs!$D$52,Inputs!$C$52/12*3*(1+Inputs!$B$74)^2,0)
A24: Capacity hire - 5th CNA - CNA / Hospice Aide (capacity-driven, ADC>=50) | C24: =IF(1>=Inputs!$D$53,Inputs!$C$53/12*1*1,0) | D24: =IF(2>=Inputs!$D$53,Inputs!$C$53/12*1*1,0) | E24: =IF(3>=Inputs!$D$53,Inputs!$C$53/12*1*1,0) | F24: =IF(4>=Inputs!$D$53,Inputs!$C$53/12*1*1,0) | G24: =IF(5>=Inputs!$D$53,Inputs!$C$53/12*1*1,0) | H24: =IF(6>=Inputs!$D$53,Inputs!$C$53/12*1*1,0) | I24: =IF(7>=Inputs!$D$53,Inputs!$C$53/12*1*1,0) | J24: =IF(8>=Inputs!$D$53,Inputs!$C$53/12*1*1,0) | K24: =IF(9>=Inputs!$D$53,Inputs!$C$53/12*1*1,0) | L24: =IF(10>=Inputs!$D$53,Inputs!$C$53/12*1*1,0) | M24: =IF(11>=Inputs!$D$53,Inputs!$C$53/12*1*1,0) | N24: =IF(12>=Inputs!$D$53,Inputs!$C$53/12*1*1,0) | O24: =IF(15>=Inputs!$D$53,Inputs!$C$53/12*3*(1+Inputs!$B$74)^1,0) | P24: =IF(18>=Inputs!$D$53,Inputs!$C$53/12*3*(1+Inputs!$B$74)^1,0) | Q24: =IF(21>=Inputs!$D$53,Inputs!$C$53/12*3*(1+Inputs!$B$74)^1,0) | R24: =IF(24>=Inputs!$D$53,Inputs!$C$53/12*3*(1+Inputs!$B$74)^1,0) | S24: =IF(27>=Inputs!$D$53,Inputs!$C$53/12*3*(1+Inputs!$B$74)^2,0) | T24: =IF(30>=Inputs!$D$53,Inputs!$C$53/12*3*(1+Inputs!$B$74)^2,0) | U24: =IF(33>=Inputs!$D$53,Inputs!$C$53/12*3*(1+Inputs!$B$74)^2,0) | V24: =IF(36>=Inputs!$D$53,Inputs!$C$53/12*3*(1+Inputs!$B$74)^2,0)
A25: Capacity hire - 6th CNA - CNA / Hospice Aide (capacity-driven, ADC>=54) | C25: =IF(1>=Inputs!$D$54,Inputs!$C$54/12*1*1,0) | D25: =IF(2>=Inputs!$D$54,Inputs!$C$54/12*1*1,0) | E25: =IF(3>=Inputs!$D$54,Inputs!$C$54/12*1*1,0) | F25: =IF(4>=Inputs!$D$54,Inputs!$C$54/12*1*1,0) | G25: =IF(5>=Inputs!$D$54,Inputs!$C$54/12*1*1,0) | H25: =IF(6>=Inputs!$D$54,Inputs!$C$54/12*1*1,0) | I25: =IF(7>=Inputs!$D$54,Inputs!$C$54/12*1*1,0) | J25: =IF(8>=Inputs!$D$54,Inputs!$C$54/12*1*1,0) | K25: =IF(9>=Inputs!$D$54,Inputs!$C$54/12*1*1,0) | L25: =IF(10>=Inputs!$D$54,Inputs!$C$54/12*1*1,0) | M25: =IF(11>=Inputs!$D$54,Inputs!$C$54/12*1*1,0) | N25: =IF(12>=Inputs!$D$54,Inputs!$C$54/12*1*1,0) | O25: =IF(15>=Inputs!$D$54,Inputs!$C$54/12*3*(1+Inputs!$B$74)^1,0) | P25: =IF(18>=Inputs!$D$54,Inputs!$C$54/12*3*(1+Inputs!$B$74)^1,0) | Q25: =IF(21>=Inputs!$D$54,Inputs!$C$54/12*3*(1+Inputs!$B$74)^1,0) | R25: =IF(24>=Inputs!$D$54,Inputs!$C$54/12*3*(1+Inputs!$B$74)^1,0) | S25: =IF(27>=Inputs!$D$54,Inputs!$C$54/12*3*(1+Inputs!$B$74)^2,0) | T25: =IF(30>=Inputs!$D$54,Inputs!$C$54/12*3*(1+Inputs!$B$74)^2,0) | U25: =IF(33>=Inputs!$D$54,Inputs!$C$54/12*3*(1+Inputs!$B$74)^2,0) | V25: =IF(36>=Inputs!$D$54,Inputs!$C$54/12*3*(1+Inputs!$B$74)^2,0)
A26: Capacity hire - 6th RN - RN Case Manager (capacity-driven, ADC>=55) | C26: =IF(1>=Inputs!$D$55,Inputs!$C$55/12*1*1,0) | D26: =IF(2>=Inputs!$D$55,Inputs!$C$55/12*1*1,0) | E26: =IF(3>=Inputs!$D$55,Inputs!$C$55/12*1*1,0) | F26: =IF(4>=Inputs!$D$55,Inputs!$C$55/12*1*1,0) | G26: =IF(5>=Inputs!$D$55,Inputs!$C$55/12*1*1,0) | H26: =IF(6>=Inputs!$D$55,Inputs!$C$55/12*1*1,0) | I26: =IF(7>=Inputs!$D$55,Inputs!$C$55/12*1*1,0) | J26: =IF(8>=Inputs!$D$55,Inputs!$C$55/12*1*1,0) | K26: =IF(9>=Inputs!$D$55,Inputs!$C$55/12*1*1,0) | L26: =IF(10>=Inputs!$D$55,Inputs!$C$55/12*1*1,0) | M26: =IF(11>=Inputs!$D$55,Inputs!$C$55/12*1*1,0) | N26: =IF(12>=Inputs!$D$55,Inputs!$C$55/12*1*1,0) | O26: =IF(15>=Inputs!$D$55,Inputs!$C$55/12*3*(1+Inputs!$B$74)^1,0) | P26: =IF(18>=Inputs!$D$55,Inputs!$C$55/12*3*(1+Inputs!$B$74)^1,0) | Q26: =IF(21>=Inputs!$D$55,Inputs!$C$55/12*3*(1+Inputs!$B$74)^1,0) | R26: =IF(24>=Inputs!$D$55,Inputs!$C$55/12*3*(1+Inputs!$B$74)^1,0) | S26: =IF(27>=Inputs!$D$55,Inputs!$C$55/12*3*(1+Inputs!$B$74)^2,0) | T26: =IF(30>=Inputs!$D$55,Inputs!$C$55/12*3*(1+Inputs!$B$74)^2,0) | U26: =IF(33>=Inputs!$D$55,Inputs!$C$55/12*3*(1+Inputs!$B$74)^2,0) | V26: =IF(36>=Inputs!$D$55,Inputs!$C$55/12*3*(1+Inputs!$B$74)^2,0)
A27: Quality / Compliance Manager - QAPI program | CoP compliance | surveys | C27: =IF(1>=Inputs!$D$56,Inputs!$C$56/12*1*1,0) | D27: =IF(2>=Inputs!$D$56,Inputs!$C$56/12*1*1,0) | E27: =IF(3>=Inputs!$D$56,Inputs!$C$56/12*1*1,0) | F27: =IF(4>=Inputs!$D$56,Inputs!$C$56/12*1*1,0) | G27: =IF(5>=Inputs!$D$56,Inputs!$C$56/12*1*1,0) | H27: =IF(6>=Inputs!$D$56,Inputs!$C$56/12*1*1,0) | I27: =IF(7>=Inputs!$D$56,Inputs!$C$56/12*1*1,0) | J27: =IF(8>=Inputs!$D$56,Inputs!$C$56/12*1*1,0) | K27: =IF(9>=Inputs!$D$56,Inputs!$C$56/12*1*1,0) | L27: =IF(10>=Inputs!$D$56,Inputs!$C$56/12*1*1,0) | M27: =IF(11>=Inputs!$D$56,Inputs!$C$56/12*1*1,0) | N27: =IF(12>=Inputs!$D$56,Inputs!$C$56/12*1*1,0) | O27: =IF(15>=Inputs!$D$56,Inputs!$C$56/12*3*(1+Inputs!$B$74)^1,0) | P27: =IF(18>=Inputs!$D$56,Inputs!$C$56/12*3*(1+Inputs!$B$74)^1,0) | Q27: =IF(21>=Inputs!$D$56,Inputs!$C$56/12*3*(1+Inputs!$B$74)^1,0) | R27: =IF(24>=Inputs!$D$56,Inputs!$C$56/12*3*(1+Inputs!$B$74)^1,0) | S27: =IF(27>=Inputs!$D$56,Inputs!$C$56/12*3*(1+Inputs!$B$74)^2,0) | T27: =IF(30>=Inputs!$D$56,Inputs!$C$56/12*3*(1+Inputs!$B$74)^2,0) | U27: =IF(33>=Inputs!$D$56,Inputs!$C$56/12*3*(1+Inputs!$B$74)^2,0) | V27: =IF(36>=Inputs!$D$56,Inputs!$C$56/12*3*(1+Inputs!$B$74)^2,0)
A28: Intake / Admissions Coordinator - Referral intake | IDG admit coordination | C28: =IF(1>=Inputs!$D$57,Inputs!$C$57/12*1*1,0) | D28: =IF(2>=Inputs!$D$57,Inputs!$C$57/12*1*1,0) | E28: =IF(3>=Inputs!$D$57,Inputs!$C$57/12*1*1,0) | F28: =IF(4>=Inputs!$D$57,Inputs!$C$57/12*1*1,0) | G28: =IF(5>=Inputs!$D$57,Inputs!$C$57/12*1*1,0) | H28: =IF(6>=Inputs!$D$57,Inputs!$C$57/12*1*1,0) | I28: =IF(7>=Inputs!$D$57,Inputs!$C$57/12*1*1,0) | J28: =IF(8>=Inputs!$D$57,Inputs!$C$57/12*1*1,0) | K28: =IF(9>=Inputs!$D$57,Inputs!$C$57/12*1*1,0) | L28: =IF(10>=Inputs!$D$57,Inputs!$C$57/12*1*1,0) | M28: =IF(11>=Inputs!$D$57,Inputs!$C$57/12*1*1,0) | N28: =IF(12>=Inputs!$D$57,Inputs!$C$57/12*1*1,0) | O28: =IF(15>=Inputs!$D$57,Inputs!$C$57/12*3*(1+Inputs!$B$74)^1,0) | P28: =IF(18>=Inputs!$D$57,Inputs!$C$57/12*3*(1+Inputs!$B$74)^1,0) | Q28: =IF(21>=Inputs!$D$57,Inputs!$C$57/12*3*(1+Inputs!$B$74)^1,0) | R28: =IF(24>=Inputs!$D$57,Inputs!$C$57/12*3*(1+Inputs!$B$74)^1,0) | S28: =IF(27>=Inputs!$D$57,Inputs!$C$57/12*3*(1+Inputs!$B$74)^2,0) | T28: =IF(30>=Inputs!$D$57,Inputs!$C$57/12*3*(1+Inputs!$B$74)^2,0) | U28: =IF(33>=Inputs!$D$57,Inputs!$C$57/12*3*(1+Inputs!$B$74)^2,0) | V28: =IF(36>=Inputs!$D$57,Inputs!$C$57/12*3*(1+Inputs!$B$74)^2,0)
A29: Volunteer Coordinator - Medicare CoP requirement | volunteer hours | C29: =IF(1>=Inputs!$D$58,Inputs!$C$58/12*1*1,0) | D29: =IF(2>=Inputs!$D$58,Inputs!$C$58/12*1*1,0) | E29: =IF(3>=Inputs!$D$58,Inputs!$C$58/12*1*1,0) | F29: =IF(4>=Inputs!$D$58,Inputs!$C$58/12*1*1,0) | G29: =IF(5>=Inputs!$D$58,Inputs!$C$58/12*1*1,0) | H29: =IF(6>=Inputs!$D$58,Inputs!$C$58/12*1*1,0) | I29: =IF(7>=Inputs!$D$58,Inputs!$C$58/12*1*1,0) | J29: =IF(8>=Inputs!$D$58,Inputs!$C$58/12*1*1,0) | K29: =IF(9>=Inputs!$D$58,Inputs!$C$58/12*1*1,0) | L29: =IF(10>=Inputs!$D$58,Inputs!$C$58/12*1*1,0) | M29: =IF(11>=Inputs!$D$58,Inputs!$C$58/12*1*1,0) | N29: =IF(12>=Inputs!$D$58,Inputs!$C$58/12*1*1,0) | O29: =IF(15>=Inputs!$D$58,Inputs!$C$58/12*3*(1+Inputs!$B$74)^1,0) | P29: =IF(18>=Inputs!$D$58,Inputs!$C$58/12*3*(1+Inputs!$B$74)^1,0) | Q29: =IF(21>=Inputs!$D$58,Inputs!$C$58/12*3*(1+Inputs!$B$74)^1,0) | R29: =IF(24>=Inputs!$D$58,Inputs!$C$58/12*3*(1+Inputs!$B$74)^1,0) | S29: =IF(27>=Inputs!$D$58,Inputs!$C$58/12*3*(1+Inputs!$B$74)^2,0) | T29: =IF(30>=Inputs!$D$58,Inputs!$C$58/12*3*(1+Inputs!$B$74)^2,0) | U29: =IF(33>=Inputs!$D$58,Inputs!$C$58/12*3*(1+Inputs!$B$74)^2,0) | V29: =IF(36>=Inputs!$D$58,Inputs!$C$58/12*3*(1+Inputs!$B$74)^2,0)
A30: Subtotal - direct-care FT salaries | C30: =C9+C10+C13+C15+C16+C17+C18+C19+C20+C21+C22+C23+C24+C25+C26 | D30: =D9+D10+D13+D15+D16+D17+D18+D19+D20+D21+D22+D23+D24+D25+D26 | E30: =E9+E10+E13+E15+E16+E17+E18+E19+E20+E21+E22+E23+E24+E25+E26 | F30: =F9+F10+F13+F15+F16+F17+F18+F19+F20+F21+F22+F23+F24+F25+F26 | G30: =G9+G10+G13+G15+G16+G17+G18+G19+G20+G21+G22+G23+G24+G25+G26 | H30: =H9+H10+H13+H15+H16+H17+H18+H19+H20+H21+H22+H23+H24+H25+H26 | I30: =I9+I10+I13+I15+I16+I17+I18+I19+I20+I21+I22+I23+I24+I25+I26 | J30: =J9+J10+J13+J15+J16+J17+J18+J19+J20+J21+J22+J23+J24+J25+J26 | ... V30: =V9+V10+V13+V15+V16+V17+V18+V19+V20+V21+V22+V23+V24+V25+V26
A32: PRN / PER-VISIT DIRECT CARE (census-driven)
A33: PRN On-Call LVN (Kendricks-Tuck, Foster) | C33: =C6*Inputs!$C$63*Inputs!$D$63*1 | D33: =D6*Inputs!$C$63*Inputs!$D$63*1 | E33: =E6*Inputs!$C$63*Inputs!$D$63*1 | F33: =F6*Inputs!$C$63*Inputs!$D$63*1 | G33: =G6*Inputs!$C$63*Inputs!$D$63*1 | H33: =H6*Inputs!$C$63*Inputs!$D$63*1 | I33: =I6*Inputs!$C$63*Inputs!$D$63*1 | J33: =J6*Inputs!$C$63*Inputs!$D$63*1 | ... N33: =N6*Inputs!$C$63*Inputs!$D$63*1 | O33: =O6*Inputs!$C$63*Inputs!$D$63*3 | P33: =P6*Inputs!$C$63*Inputs!$D$63*3 | Q33: =Q6*Inputs!$C$63*Inputs!$D$63*3 | R33: =R6*Inputs!$C$63*Inputs!$D$63*3 | S33: =S6*Inputs!$C$63*Inputs!$D$63*3 | T33: =T6*Inputs!$C$63*Inputs!$D$63*3 | U33: =U6*Inputs!$C$63*Inputs!$D$63*3 | V33: =V6*Inputs!$C$63*Inputs!$D$63*3
A34: PRN Chaplain (Ector, Johnson) | C34: =C6*Inputs!$C$64*Inputs!$D$64*1 | D34: =D6*Inputs!$C$64*Inputs!$D$64*1 | E34: =E6*Inputs!$C$64*Inputs!$D$64*1 | F34: =F6*Inputs!$C$64*Inputs!$D$64*1 | G34: =G6*Inputs!$C$64*Inputs!$D$64*1 | H34: =H6*Inputs!$C$64*Inputs!$D$64*1 | I34: =I6*Inputs!$C$64*Inputs!$D$64*1 | J34: =J6*Inputs!$C$64*Inputs!$D$64*1 | ... N34: =N6*Inputs!$C$64*Inputs!$D$64*1 | O34: =O6*Inputs!$C$64*Inputs!$D$64*3 | P34: =P6*Inputs!$C$64*Inputs!$D$64*3 | Q34: =Q6*Inputs!$C$64*Inputs!$D$64*3 | R34: =R6*Inputs!$C$64*Inputs!$D$64*3 | S34: =S6*Inputs!$C$64*Inputs!$D$64*3 | T34: =T6*Inputs!$C$64*Inputs!$D$64*3 | U34: =U6*Inputs!$C$64*Inputs!$D$64*3 | V34: =V6*Inputs!$C$64*Inputs!$D$64*3
A35: PRN Social Worker (Sanders) | C35: =C6*Inputs!$C$65*Inputs!$D$65*1 | D35: =D6*Inputs!$C$65*Inputs!$D$65*1 | E35: =E6*Inputs!$C$65*Inputs!$D$65*1 | F35: =F6*Inputs!$C$65*Inputs!$D$65*1 | G35: =G6*Inputs!$C$65*Inputs!$D$65*1 | H35: =H6*Inputs!$C$65*Inputs!$D$65*1 | I35: =I6*Inputs!$C$65*Inputs!$D$65*1 | J35: =J6*Inputs!$C$65*Inputs!$D$65*1 | ... N35: =N6*Inputs!$C$65*Inputs!$D$65*1 | O35: =O6*Inputs!$C$65*Inputs!$D$65*3 | P35: =P6*Inputs!$C$65*Inputs!$D$65*3 | Q35: =Q6*Inputs!$C$65*Inputs!$D$65*3 | R35: =R6*Inputs!$C$65*Inputs!$D$65*3 | S35: =S6*Inputs!$C$65*Inputs!$D$65*3 | T35: =T6*Inputs!$C$65*Inputs!$D$65*3 | U35: =U6*Inputs!$C$65*Inputs!$D$65*3 | V35: =V6*Inputs!$C$65*Inputs!$D$65*3
A36: PRN Nurse Practitioner (Rogers) | C36: =C6*Inputs!$C$66*Inputs!$D$66*1 | D36: =D6*Inputs!$C$66*Inputs!$D$66*1 | E36: =E6*Inputs!$C$66*Inputs!$D$66*1 | F36: =F6*Inputs!$C$66*Inputs!$D$66*1 | G36: =G6*Inputs!$C$66*Inputs!$D$66*1 | H36: =H6*Inputs!$C$66*Inputs!$D$66*1 | I36: =I6*Inputs!$C$66*Inputs!$D$66*1 | J36: =J6*Inputs!$C$66*Inputs!$D$66*1 | ... N36: =N6*Inputs!$C$66*Inputs!$D$66*1 | O36: =O6*Inputs!$C$66*Inputs!$D$66*3 | P36: =P6*Inputs!$C$66*Inputs!$D$66*3 | Q36: =Q6*Inputs!$C$66*Inputs!$D$66*3 | R36: =R6*Inputs!$C$66*Inputs!$D$66*3 | S36: =S6*Inputs!$C$66*Inputs!$D$66*3 | T36: =T6*Inputs!$C$66*Inputs!$D$66*3 | U36: =U6*Inputs!$C$66*Inputs!$D$66*3 | V36: =V6*Inputs!$C$66*Inputs!$D$66*3
A37: PRN CNA / per-visit (Henson, Mills) | C37: =C6*Inputs!$C$67*Inputs!$D$67*1 | D37: =D6*Inputs!$C$67*Inputs!$D$67*1 | E37: =E6*Inputs!$C$67*Inputs!$D$67*1 | F37: =F6*Inputs!$C$67*Inputs!$D$67*1 | G37: =G6*Inputs!$C$67*Inputs!$D$67*1 | H37: =H6*Inputs!$C$67*Inputs!$D$67*1 | I37: =I6*Inputs!$C$67*Inputs!$D$67*1 | J37: =J6*Inputs!$C$67*Inputs!$D$67*1 | ... N37: =N6*Inputs!$C$67*Inputs!$D$67*1 | O37: =O6*Inputs!$C$67*Inputs!$D$67*3 | P37: =P6*Inputs!$C$67*Inputs!$D$67*3 | Q37: =Q6*Inputs!$C$67*Inputs!$D$67*3 | R37: =R6*Inputs!$C$67*Inputs!$D$67*3 | S37: =S6*Inputs!$C$67*Inputs!$D$67*3 | T37: =T6*Inputs!$C$67*Inputs!$D$67*3 | U37: =U6*Inputs!$C$67*Inputs!$D$67*3 | V37: =V6*Inputs!$C$67*Inputs!$D$67*3
A38: Subtotal - PRN visit wages | C38: =C33+C34+C35+C36+C37 | D38: =D33+D34+D35+D36+D37 | E38: =E33+E34+E35+E36+E37 | F38: =F33+F34+F35+F36+F37 | G38: =G33+G34+G35+G36+G37 | H38: =H33+H34+H35+H36+H37 | I38: =I33+I34+I35+I36+I37 | J38: =J33+J34+J35+J36+J37 | ... V38: =V33+V34+V35+V36+V37
A39: Medical Director 1 + 2 (1099, MD2 conditional) | C39: =Inputs!$B$81*1+IF(1>=Inputs!$B$83,Inputs!$B$82*1,0) | D39: =Inputs!$B$81*1+IF(2>=Inputs!$B$83,Inputs!$B$82*1,0) | E39: =Inputs!$B$81*1+IF(3>=Inputs!$B$83,Inputs!$B$82*1,0) | F39: =Inputs!$B$81*1+IF(4>=Inputs!$B$83,Inputs!$B$82*1,0) | G39: =Inputs!$B$81*1+IF(5>=Inputs!$B$83,Inputs!$B$82*1,0) | H39: =Inputs!$B$81*1+IF(6>=Inputs!$B$83,Inputs!$B$82*1,0) | I39: =Inputs!$B$81*1+IF(7>=Inputs!$B$83,Inputs!$B$82*1,0) | J39: =Inputs!$B$81*1+IF(8>=Inputs!$B$83,Inputs!$B$82*1,0) | K39: =Inputs!$B$81*1+IF(9>=Inputs!$B$83,Inputs!$B$82*1,0) | L39: =Inputs!$B$81*1+IF(10>=Inputs!$B$83,Inputs!$B$82*1,0) | M39: =Inputs!$B$81*1+IF(11>=Inputs!$B$83,Inputs!$B$82*1,0) | N39: =Inputs!$B$81*1+IF(12>=Inputs!$B$83,Inputs!$B$82*1,0) | O39: =Inputs!$B$81*3+IF(15>=Inputs!$B$83,Inputs!$B$82*3,0) | P39: =Inputs!$B$81*3+IF(18>=Inputs!$B$83,Inputs!$B$82*3,0) | Q39: =Inputs!$B$81*3+IF(21>=Inputs!$B$83,Inputs!$B$82*3,0) | R39: =Inputs!$B$81*3+IF(24>=Inputs!$B$83,Inputs!$B$82*3,0) | S39: =Inputs!$B$81*3+IF(27>=Inputs!$B$83,Inputs!$B$82*3,0) | T39: =Inputs!$B$81*3+IF(30>=Inputs!$B$83,Inputs!$B$82*3,0) | U39: =Inputs!$B$81*3+IF(33>=Inputs!$B$83,Inputs!$B$82*3,0) | V39: =Inputs!$B$81*3+IF(36>=Inputs!$B$83,Inputs!$B$82*3,0)
A41: INDIRECT LABOR (SG&A overhead)
A42: Subtotal - indirect FT salaries | C42: =C8+C11+C12+C14+C27+C28+C29 | D42: =D8+D11+D12+D14+D27+D28+D29 | E42: =E8+E11+E12+E14+E27+E28+E29 | F42: =F8+F11+F12+F14+F27+F28+F29 | G42: =G8+G11+G12+G14+G27+G28+G29 | H42: =H8+H11+H12+H14+H27+H28+H29 | I42: =I8+I11+I12+I14+I27+I28+I29 | J42: =J8+J11+J12+J14+J27+J28+J29 | ... V42: =V8+V11+V12+V14+V27+V28+V29
A43: Rhonda Smith - Office Mgr (PRN, W-2) | C43: =Inputs!$C$59/12*1*1 | D43: =Inputs!$C$59/12*1*1 | E43: =Inputs!$C$59/12*1*1 | F43: =Inputs!$C$59/12*1*1 | G43: =Inputs!$C$59/12*1*1 | H43: =Inputs!$C$59/12*1*1 | I43: =Inputs!$C$59/12*1*1 | J43: =Inputs!$C$59/12*1*1 | ... N43: =Inputs!$C$59/12*1*1 | O43: =Inputs!$C$59/12*3*(1+Inputs!$B$74)^1 | P43: =Inputs!$C$59/12*3*(1+Inputs!$B$74)^1 | Q43: =Inputs!$C$59/12*3*(1+Inputs!$B$74)^1 | R43: =Inputs!$C$59/12*3*(1+Inputs!$B$74)^1 | S43: =Inputs!$C$59/12*3*(1+Inputs!$B$74)^2 | T43: =Inputs!$C$59/12*3*(1+Inputs!$B$74)^2 | U43: =Inputs!$C$59/12*3*(1+Inputs!$B$74)^2 | V43: =Inputs!$C$59/12*3*(1+Inputs!$B$74)^2
...

Sheet Operating Budget
A1: AZALEA HOSPICE & PALLIATIVE CARE - Tyler, TX
A2: Operating Budget - P&L | Net Rev - COGS = Gross Profit - SG&A = EBITDA - D&A - Interest = Net Income
A4: ($ per period) | C4: YEAR 1 - monthly | O4: YEAR 2 - quarterly | S4: YEAR 3 - quarterly
C5: M1 | D5: M2 | E5: M3 | F5: M4 | G5: M5 | H5: M6 | I5: M7 | J5: M8 | K5: M9 | L5: M10 | M5: M11 | N5: M12 | O5: Y2 Q1 | P5: Y2 Q2 | Q5: Y2 Q3 | R5: Y2 Q4 | S5: Y3 Q1 | T5: Y3 Q2 | U5: Y3 Q3 | V5: Y3 Q4
A6: NET REVENUE | C6: ='Revenue Model'!C17 | D6: ='Revenue Model'!D17 | E6: ='Revenue Model'!E17 | F6: ='Revenue Model'!F17 | G6: ='Revenue Model'!G17 | H6: ='Revenue Model'!H17 | I6: ='Revenue Model'!I17 | J6: ='Revenue Model'!J17 | ... V6: ='Revenue Model'!V17
A8: COST OF SERVICES
A9: Direct-care labor | C9: ='Staffing & Payroll'!C53 | D9: ='Staffing & Payroll'!D53 | E9: ='Staffing & Payroll'!E53 | F9: ='Staffing & Payroll'!F53 | G9: ='Staffing & Payroll'!G53 | H9: ='Staffing & Payroll'!H53 | I9: ='Staffing & Payroll'!I53 | J9: ='Staffing & Payroll'!J53 | ... V9: ='Staffing & Payroll'!V53
A10: Medical supplies | C10: ='Revenue Model'!C12*Inputs!$B$86 | D10: ='Revenue Model'!D12*Inputs!$B$86 | E10: ='Revenue Model'!E12*Inputs!$B$86 | F10: ='Revenue Model'!F12*Inputs!$B$86 | G10: ='Revenue Model'!G12*Inputs!$B$86 | H10: ='Revenue Model'!H12*Inputs!$B$86 | I10: ='Revenue Model'!I12*Inputs!$B$86 | J10: ='Revenue Model'!J12*Inputs!$B$86 | ... V10: ='Revenue Model'!V12*Inputs!$B$86
A11: DME | C11: ='Revenue Model'!C12*Inputs!$B$87 | D11: ='Revenue Model'!D12*Inputs!$B$87 | E11: ='Revenue Model'!E12*Inputs!$B$87 | F11: ='Revenue Model'!F12*Inputs!$B$87 | G11: ='Revenue Model'!G12*Inputs!$B$87 | H11: ='Revenue Model'!H12*Inputs!$B$87 | I11: ='Revenue Model'!I12*Inputs!$B$87 | J11: ='Revenue Model'!J12*Inputs!$B$87 | ... V11: ='Revenue Model'!V12*Inputs!$B$87
A12: Pharmacy | C12: ='Revenue Model'!C12*Inputs!$B$88 | D12: ='Revenue Model'!D12*Inputs!$B$88 | E12: ='Revenue Model'!E12*Inputs!$B$88 | F12: ='Revenue Model'!F12*Inputs!$B$88 | G12: ='Revenue Model'!G12*Inputs!$B$88 | H12: ='Revenue Model'!H12*Inputs!$B$88 | I12: ='Revenue Model'!I12*Inputs!$B$88 | J12: ='Revenue Model'!J12*Inputs!$B$88 | ... V12: ='Revenue Model'!V12*Inputs!$B$88
A13: Patient-related COGS subtotal | C13: =C10+C11+C12 | D13: =D10+D11+D12 | E13: =E10+E11+E12 | F13: =F10+F11+F12 | G13: =G10+G11+G12 | H13: =H10+H11+H12 | I13: =I10+I11+I12 | J13: =J10+J11+J12 | ... V13: =V10+V11+V12
A14: TOTAL COST OF SERVICES | C14: =C9+C13 | D14: =D9+D13 | E14: =E9+E13 | F14: =F9+F13 | G14: =G9+G13 | H14: =H9+H13 | I14: =I9+I13 | J14: =J9+J13 | ... V14: =V9+V13
A15: GROSS PROFIT | C15: =C6-C14 | D15: =D6-D14 | E15: =E6-E14 | F15: =F6-F14 | G15: =G6-G14 | H15: =H6-H14 | I15: =I6-I14 | J15: =J6-J14 | ... V15: =V6-V14
A16: Gross margin % | C16: =IF(C6=0,0,C15/C6) | D16: =IF(D6=0,0,D15/D6) | E16: =IF(E6=0,0,E15/E6) | F16: =IF(F6=0,0,F15/F6) | G16: =IF(G6=0,0,G15/G6) | H16: =IF(H6=0,0,H15/H6) | I16: =IF(I6=0,0,I15/I6) | J16: =IF(J6=0,0,J15/J6) | ... V16: =IF(V6=0,0,V15/V6)
A18: SELLING, GENERAL & ADMINISTRATIVE
A19: Indirect labor | C19: ='Staffing & Payroll'!C54 | D19: ='Staffing & Payroll'!D54 | E19: ='Staffing & Payroll'!E54 | F19: ='Staffing & Payroll'!F54 | G19: ='Staffing & Payroll'!G54 | H19: ='Staffing & Payroll'!H54 | I19: ='Staffing & Payroll'!I54 | J19: ='Staffing & Payroll'!J54 | ... V19: ='Staffing & Payroll'!V54
A20: Fixed G&A (utilities, EMR, billing, rent, mktg...) | C20: =SUM(Inputs!$B$91:$B$103)*1 | D20: =SUM(Inputs!$B$91:$B$103)*1 | E20: =SUM(Inputs!$B$91:$B$103)*1 | F20: =SUM(Inputs!$B$91:$B$103)*1 | G20: =SUM(Inputs!$B$91:$B$103)*1 | H20: =SUM(Inputs!$B$91:$B$103)*1 | I20: =SUM(Inputs!$B$91:$B$103)*1 | J20: =SUM(Inputs!$B$91:$B$103)*1 | ... N20: =SUM(Inputs!$B$91:$B$103)*1 | O20: =SUM(Inputs!$B$91:$B$103)*3 | P20: =SUM(Inputs!$B$91:$B$103)*3 | Q20: =SUM(Inputs!$B$91:$B$103)*3 | R20: =SUM(Inputs!$B$91:$B$103)*3 | S20: =SUM(Inputs!$B$91:$B$103)*3 | T20: =SUM(Inputs!$B$91:$B$103)*3 | U20: =SUM(Inputs!$B$91:$B$103)*3 | V20: =SUM(Inputs!$B$91:$B$103)*3
A21: Outsourced billing fee (1.5% of gross) | C21: ='Revenue Model'!C14*Inputs!$B$106 | D21: ='Revenue Model'!D14*Inputs!$B$106 | E21: ='Revenue Model'!E14*Inputs!$B$106 | F21: ='Revenue Model'!F14*Inputs!$B$106 | G21: ='Revenue Model'!G14*Inputs!$B$106 | H21: ='Revenue Model'!H14*Inputs!$B$106 | I21: ='Revenue Model'!I14*Inputs!$B$106 | J21: ='Revenue Model'!J14*Inputs!$B$106 | ... V21: ='Revenue Model'!V14*Inputs!$B$106
A22: QR payment fee (% of gross) | C22: ='Revenue Model'!C14*Inputs!$B$107 | D22: ='Revenue Model'!D14*Inputs!$B$107 | E22: ='Revenue Model'!E14*Inputs!$B$107 | F22: ='Revenue Model'!F14*Inputs!$B$107 | G22: ='Revenue Model'!G14*Inputs!$B$107 | H22: ='Revenue Model'!H14*Inputs!$B$107 | I22: ='Revenue Model'!I14*Inputs!$B$107 | J22: ='Revenue Model'!J14*Inputs!$B$107 | ... V22: ='Revenue Model'!V14*Inputs!$B$107
A23: TOTAL SG&A | C23: =C19+C20+C21+C22 | D23: =D19+D20+D21+D22 | E23: =E19+E20+E21+E22 | F23: =F19+F20+F21+F22 | G23: =G19+G20+G21+G22 | H23: =H19+H20+H21+H22 | I23: =I19+I20+I21+I22 | J23: =J19+J20+J21+J22 | ... V23: =V19+V20+V21+V22
A24: EBITDA | C24: =C15-C23 | D24: =D15-D23 | E24: =E15-E23 | F24: =F15-F23 | G24: =G15-G23 | H24: =H15-H23 | I24: =I15-I23 | J24: =J15-J23 | ... V24: =V15-V23
A25: EBITDA margin % | C25: =IF(C6=0,0,C24/C6) | D25: =IF(D6=0,0,D24/D6) | E25: =IF(E6=0,0,E24/E6) | F25: =IF(F6=0,0,F24/F6) | G25: =IF(G6=0,0,G24/G6) | H25: =IF(H6=0,0,H24/H6) | I25: =IF(I6=0,0,I24/I6) | J25: =IF(J6=0,0,J24/J6) | ... V25: =IF(V6=0,0,V24/V6)
A27: BELOW EBITDA
A28: Depreciation & amortization | C28: =Inputs!$B$140*1 | D28: =Inputs!$B$140*1 | E28: =Inputs!$B$140*1 | F28: =Inputs!$B$140*1 | G28: =Inputs!$B$140*1 | H28: =Inputs!$B$140*1 | I28: =Inputs!$B$140*1 | J28: =Inputs!$B$140*1 | ... N28: =Inputs!$B$140*1 | O28: =Inputs!$B$140*3 | P28: =Inputs!$B$140*3 | Q28: =Inputs!$B$140*3 | R28: =Inputs!$B$140*3 | S28: =Inputs!$B$140*3 | T28: =Inputs!$B$140*3 | U28: =Inputs!$B$140*3 | V28: =Inputs!$B$140*3
A29: Interest - SBA loan | C29: ='Debt Schedule'!C13 | D29: ='Debt Schedule'!D13 | E29: ='Debt Schedule'!E13 | F29: ='Debt Schedule'!F13 | G29: ='Debt Schedule'!G13 | H29: ='Debt Schedule'!H13 | I29: ='Debt Schedule'!I13 | J29: ='Debt Schedule'!J13 | ... V29: ='Debt Schedule'!V13
A30: Interest - Hickory license note | C30: ='Debt Schedule'!C21 | D30: ='Debt Schedule'!D21 | E30: ='Debt Schedule'!E21 | F30: ='Debt Schedule'!F21 | G30: ='Debt Schedule'!G21 | H30: ='Debt Schedule'!H21 | I30: ='Debt Schedule'!I21 | J30: ='Debt Schedule'!J21 | ... V30: ='Debt Schedule'!V21
A31: Interest - working-capital line | C31: ='Cash Flow & BS'!C16 | D31: ='Cash Flow & BS'!D16 | E31: ='Cash Flow & BS'!E16 | F31: ='Cash Flow & BS'!F16 | G31: ='Cash Flow & BS'!G16 | H31: ='Cash Flow & BS'!H16 | I31: ='Cash Flow & BS'!I16 | J31: ='Cash Flow & BS'!J16 | ... V31: ='Cash Flow & BS'!V16
A32: PRE-TAX INCOME | C32: =C24-C28-C29-C30-C31 | D32: =D24-D28-D29-D30-D31 | E32: =E24-E28-E29-E30-E31 | F32: =F24-F28-F29-F30-F31 | G32: =G24-G28-G29-G30-G31 | H32: =H24-H28-H29-H30-H31 | I32: =I24-I28-I29-I30-I31 | J32: =J24-J28-J29-J30-J31 | ... V32: =V24-V28-V29-V30-V31
A33: TX franchise / margin tax | C33: =IF(C32>0,C6*Inputs!$B$119,0) | D33: =IF(D32>0,D6*Inputs!$B$119,0) | E33: =IF(E32>0,E6*Inputs!$B$119,0) | F33: =IF(F32>0,F6*Inputs!$B$119,0) | G33: =IF(G32>0,G6*Inputs!$B$119,0) | H33: =IF(H32>0,H6*Inputs!$B$119,0) | I33: =IF(I32>0,I6*Inputs!$B$119,0) | J33: =IF(J32>0,J6*Inputs!$B$119,0) | ... V33: =IF(V32>0,V6*Inputs!$B$119,0)
A34: NET INCOME | C34: =C32-C33 | D34: =D32-D33 | E34: =E32-E33 | F34: =F32-F33 | G34: =G32-G33 | H34: =H32-H33 | I34: =I32-I33 | J34: =J32-J33 | ... V34: =V32-V33

Sheet Detailed P&L
A1: Azalea Hospice & Palliative Care - Tyler, TX
A2: Profit and Loss
A3: Year 1 (monthly) | Years 2-3 (annual) | model data, cash basis
B5: M1 | C5: M2 | D5: M3 | E5: M4 | F5: M5 | G5: M6 | H5: M7 | I5: M8 | J5: M9 | K5: M10 | L5: M11 | M5: M12 | N5: Year 2 | O5: Year 3 | P5: TOTAL
A6: Income
A7: Gross Billed Revenue | B7: ='Revenue Model'!C14 | C7: ='Revenue Model'!D14 | D7: ='Revenue Model'!E14 | E7: ='Revenue Model'!F14 | F7: ='Revenue Model'!G14 | G7: ='Revenue Model'!H14 | H7: ='Revenue Model'!I14 | I7: ='Revenue Model'!J14 | ... M7: ='Revenue Model'!N14 | N7: =SUM('Revenue Model'!O14:R14) | O7: =SUM('Revenue Model'!S14:V14) | P7: =SUM(B7:M7)+N7+O7
A8: Less: CDAs Adjustment | B8: =0 | C8: =0 | D8: =0 | E8: =0 | F8: =0 | G8: =0 | H8: =0 | I8: =0 | ... O8: =0 | P8: =SUM(B8:M8)+N8+O8
A9: Less: Net Due Zero (Write-offs) | B9: ='Revenue Model'!C14*Inputs!$B$11 | C9: ='Revenue Model'!D14*Inputs!$B$11 | D9: ='Revenue Model'!E14*Inputs!$B$11 | E9: ='Revenue Model'!F14*Inputs!$B$11 | F9: ='Revenue Model'!G14*Inputs!$B$11 | G9: ='Revenue Model'!H14*Inputs!$B$11 | H9: ='Revenue Model'!I14*Inputs!$B$11 | I9: ='Revenue Model'!J14*Inputs!$B$11 | ... M9: ='Revenue Model'!N14*Inputs!$B$11 | N9: =SUM('Revenue Model'!O14:R14)*Inputs!$B$11 | O9: =SUM('Revenue Model'!S14:V14)*Inputs!$B$11 | P9: =SUM(B9:M9)+N9+O9
A10: Less: Sequestration | B10: ='Revenue Model'!C14*Inputs!$B$10 | C10: ='Revenue Model'!D14*Inputs!$B$10 | D10: ='Revenue Model'!E14*Inputs!$B$10 | E10: ='Revenue Model'!F14*Inputs!$B$10 | F10: ='Revenue Model'!G14*Inputs!$B$10 | G10: ='Revenue Model'!H14*Inputs!$B$10 | H10: ='Revenue Model'!I14*Inputs!$B$10 | I10: ='Revenue Model'!J14*Inputs!$B$10 | ... M10: ='Revenue Model'!N14*Inputs!$B$10 | N10: =SUM('Revenue Model'!O14:R14)*Inputs!$B$10 | O10: =SUM('Revenue Model'!S14:V14)*Inputs!$B$10 | P10: =SUM(B10:M10)+N10+O10
A11: Less: Medication Adjustments | B11: =0 | C11: =0 | D11: =0 | E11: =0 | F11: =0 | G11: =0 | H11: =0 | I11: =0 | ... O11: =0 | P11: =SUM(B11:M11)+N11+O11
A12: Total Income | B12: =B7-B8-B9-B10-B11 | C12: =C7-C8-C9-C10-C11 | D12: =D7-D8-D9-D10-D11 | E12: =E7-E8-E9-E10-E11 | F12: =F7-F8-F9-F10-F11 | G12: =G7-G8-G9-G10-G11 | H12: =H7-H8-H9-H10-H11 | I12: =I7-I8-I9-I10-I11 | ... P12: =P7-P8-P9-P10-P11
A14: Cost of Services
