Workbook

Sheet Comparison
A1: FOUR-TRACK COMPARISON - peak funding need vs capital actually available. All tracks: same census ramp and unit economics; no equity inflows; no revolver.
A3: Track | B3: Peak funding need | C3: vs available | D3: Month-12 cum. cash | E3: Month-24 cum. cash | F3: Regulatory gates
A4: T1 Jason ADS | B4: ='T1 Jason ADS'!B12 | C4: ='T1 Jason ADS'!B12-'Assumptions'!$B$9 | D4: ='T1 Jason ADS'!M11 | E4: ='T1 Jason ADS'!Y11 | F4: Gates: Jason terms unagreed (fee is placeholder); AKS-compliant structure + county add + 855A location filing; no license owned at end.
A5: T2 Refuge | B5: ='T2 Refuge'!B13 | C5: ='T2 Refuge'!B13-'Assumptions'!$B$9 | D5: ='T2 Refuge'!M12 | E5: ='T2 Refuge'!Y12 | F5: Gates: 36-month window to 1/8/2027; Sept reactivation expiry; PPEO on first claim (letter); bank + SBA must both fund.
A6: T3 Avant | B6: ='T3 Avant'!B13 | C6: ='T3 Avant'!B13-'Assumptions'!$B$9 | D6: ='T3 Avant'!M12 | E6: ='T3 Avant'!Y12 | F6: Gates: Palmetto tie-in/CHOW UNRESOLVED (multi-year); Medicare-only; own 36-month/moratorium analysis unverified; license expires 7/8/2027.
A7: T4a Refuge + Jason | B7: ='T4a Refuge+Jason'!B16 | C7: ='T4a Refuge+Jason'!B16-'Assumptions'!$B$9 | D7: ='T4a Refuge+Jason'!M15 | E7: ='T4a Refuge+Jason'!Y15 | F7: Gates: T2 gates + Jason gates; two arrangements run at once.
A8: T4b Avant + Jason | B8: ='T4b Avant+Jason'!B16 | C8: ='T4b Avant+Jason'!B16-'Assumptions'!$B$9 | D8: ='T4b Avant+Jason'!M15 | E8: ='T4b Avant+Jason'!Y15 | F8: Gates: T3 gates + Jason gates; cheapest capital if Avant clears.
A10: Notes: 'vs available' compares to the capital input on Assumptions (~$215K remaining of Jim's $250K). Positive = additional capital required beyond what is committed. Jason fee, Avant clearance month, and PPEO hold lengths are inputs - flex them on the Assumptions tab. Rev 1.00, prepared 7/28/2026.

Sheet Assumptions
A1: ASSUMPTIONS - single source of truth. Yellow cells are inputs; every track tab references here. Unit economics per the Rev 4.10 proforma Control Tower (net/day, cost rates, ADC path).
A3: SHARED CHASSIS (Rev 4.10 unit economics)
A4: Net revenue per patient-day (blended, after sequestration/fees) | B4: 172 | D4: Rev 4.10 Control Tower; Medicaid r&b treated as cash-neutral pass-through
A5: Days per month (billing average) | B5: 30.4
A6: Variable cost per patient-day (clinical labor + benefits + DPC) | B6: 79 | D6: Rev 4.10 Y1: clinical ~$63/pd + direct patient care ~$16/pd
A7: Fixed overhead per month (admin labor, facility, G&A) | B7: 62000 | D7: Rev 4.10 Y1: indirect $49.7K/mo + facility/G&A $12.3K/mo; no owner deferral assumed (conservative)
A8: % collected month +1 (normal, no hold) | B8: 1
A9: Capital actually available (Jim's remaining $65K + $150K) | B9: 215000
A11: ADC RAMP (chassis; editable)
A12: Month | B12: Aug-26 | C12: Sep-26 | D12: Oct-26 | E12: Nov-26 | F12: Dec-26 | G12: Jan-27 | H12: Feb-27 | I12: Mar-27 | J12: Apr-27 | K12: May-27 | L12: Jun-27 | M12: Jul-27 | N12: Aug-27 | O12: Sep-27 | P12: Oct-27 | Q12: Nov-27 | R12: Dec-27 | S12: Jan-28 | T12: Feb-28 | U12: Mar-28 | V12: Apr-28 | W12: May-28 | X12: Jun-28 | Y12: Jul-28
A13: Average daily census (total book) | B13: 9 | C13: 18 | D13: 25 | E13: 28 | F13: 30 | G13: 32 | H13: 34 | I13: 35.5 | J13: 36.5 | K13: 37.5 | L13: 38.5 | M13: 39.5 | N13: 40.4 | O13: 41.3 | P13: 42.2 | Q13: 43.1 | R13: 44 | S13: 45 | T13: 46 | U13: 47 | V13: 48 | W13: 49 | X13: 49.5 | Y13: 50
A15: T1 - JASON ADS
A16: Jason participation fee per month (flat; terms not yet agreed) | B16: 15000 | D16: PLACEHOLDER - AKS-compliant flat FMV fee or employment-mode equivalent
A18: T2 - REFUGE (Rev 4.10 deal terms)
A19: PPEO hold on first claims (months) | B19: 3 | D19: sensitivity: 4
A20: Down payment at closing (M1) | B20: 125000
A21: Seller installment (M2-M5, replaced by bank payoff M2) | B21: 31250
A22: Bank note funds (M2) | B22: 500000
A23: Seller payoff at bank funding (M2, principal + accrued) | B23: 376875 | D23: $375K balance + ~1 month interest at 6%
A24: Bank note payment (M3-M5) | B24: 15211
A25: SBA funds (M6) | B25: 500000
A26: Bank note payoff at SBA funding (M6) | B26: 461676
A27: SBA payment (M7 on) | B27: 6747
A29: T3 - AVANT ($300K, seller-financed; payments start at PPEO clear)
A30: Palmetto tie-in / CHOW clearance month (census can start) | B30: 2 | D30: UNRESOLVED GATE - multi-year Palmetto saga; sensitivity: 4, 6
A31: PPEO hold on first claims (months after census start) | B31: 4 | D31: sensitivity: 3, 6
A32: Pre-clearance monthly burn (office, skeleton team) | B32: 10000
A33: Down payment (paid at PPEO clear, per re-negotiated terms) | B33: 50000
A34: Month-6-after-clear balloon (per May schedule) | B34: 51478.15
A35: Monthly installment (18 months, starts month 7 after clear) | B35: 11646.35
A37: T4 - COMBO (owned-license seed + Jason growth census)
A38: Seed census on owned license (ADC) | B38: 5
A39: Seed carry cost per month (0.5 RN + 0.5 CNA + PRN allocation) | B39: 12000

Sheet T1 Jason ADS
A1: T1 - JASON ALTERNATE DELIVERY SITE: census bills through Jason's established number; collections at normal +1-month lag, NO hold; flat fee to Jason; no license capital.
B3: Aug-26 | C3: Sep-26 | D3: Oct-26 | E3: Nov-26 | F3: Dec-26 | G3: Jan-27 | H3: Feb-27 | I3: Mar-27 | J3: Apr-27 | K3: May-27 | L3: Jun-27 | M3: Jul-27 | N3: Aug-27 | O3: Sep-27 | P3: Oct-27 | Q3: Nov-27 | R3: Dec-27 | S3: Jan-28 | T3: Feb-28 | U3: Mar-28 | V3: Apr-28 | W3: May-28 | X3: Jun-28 | Y3: Jul-28
A4: ADC on this track | B4: =Assumptions!B13 | C4: =Assumptions!C13 | D4: =Assumptions!D13 | E4: =Assumptions!E13 | F4: =Assumptions!F13 | G4: =Assumptions!G13 | H4: =Assumptions!H13 | I4: =Assumptions!I13 | ... Y4: =Assumptions!Y13
A5: Revenue earned (NPR) | B5: =B4*'Assumptions'!$B$4*'Assumptions'!$B$5 | C5: =C4*'Assumptions'!$B$4*'Assumptions'!$B$5 | D5: =D4*'Assumptions'!$B$4*'Assumptions'!$B$5 | E5: =E4*'Assumptions'!$B$4*'Assumptions'!$B$5 | F5: =F4*'Assumptions'!$B$4*'Assumptions'!$B$5 | G5: =G4*'Assumptions'!$B$4*'Assumptions'!$B$5 | H5: =H4*'Assumptions'!$B$4*'Assumptions'!$B$5 | I5: =I4*'Assumptions'!$B$4*'Assumptions'!$B$5 | ... Y5: =Y4*'Assumptions'!$B$4*'Assumptions'!$B$5
A6: Variable costs (clinical + patient care, paid in month) | B6: =-B4*'Assumptions'!$B$6*'Assumptions'!$B$5 | C6: =-C4*'Assumptions'!$B$6*'Assumptions'!$B$5 | D6: =-D4*'Assumptions'!$B$6*'Assumptions'!$B$5 | E6: =-E4*'Assumptions'!$B$6*'Assumptions'!$B$5 | F6: =-F4*'Assumptions'!$B$6*'Assumptions'!$B$5 | G6: =-G4*'Assumptions'!$B$6*'Assumptions'!$B$5 | H6: =-H4*'Assumptions'!$B$6*'Assumptions'!$B$5 | I6: =-I4*'Assumptions'!$B$6*'Assumptions'!$B$5 | ... Y6: =-Y4*'Assumptions'!$B$6*'Assumptions'!$B$5
A7: Collections (+1 month lag) | B7: =0 | C7: =B5*'Assumptions'!$B$8 | D7: =C5*'Assumptions'!$B$8 | E7: =D5*'Assumptions'!$B$8 | F7: =E5*'Assumptions'!$B$8 | G7: =F5*'Assumptions'!$B$8 | H7: =G5*'Assumptions'!$B$8 | I7: =H5*'Assumptions'!$B$8 | J7: =I5*'Assumptions'!$B$8 | ... Y7: =X5*'Assumptions'!$B$8
A8: Fixed overhead | B8: =-'Assumptions'!$B$7 | C8: =-'Assumptions'!$B$7 | D8: =-'Assumptions'!$B$7 | E8: =-'Assumptions'!$B$7 | F8: =-'Assumptions'!$B$7 | G8: =-'Assumptions'!$B$7 | H8: =-'Assumptions'!$B$7 | I8: =-'Assumptions'!$B$7 | ... Y8: =-'Assumptions'!$B$7
A9: Jason participation fee | B9: =-'Assumptions'!$B$16 | C9: =-'Assumptions'!$B$16 | D9: =-'Assumptions'!$B$16 | E9: =-'Assumptions'!$B$16 | F9: =-'Assumptions'!$B$16 | G9: =-'Assumptions'!$B$16 | H9: =-'Assumptions'!$B$16 | I9: =-'Assumptions'!$B$16 | ... Y9: =-'Assumptions'!$B$16
A10: NET CASH FLOW | B10: =B7+B6+B8+B9 | C10: =C7+C6+C8+C9 | D10: =D7+D6+D8+D9 | E10: =E7+E6+E8+E9 | F10: =F7+F6+F8+F9 | G10: =G7+G6+G8+G9 | H10: =H7+H6+H8+H9 | I10: =I7+I6+I8+I9 | ... Y10: =Y7+Y6+Y8+Y9
A11: Cumulative cash (no equity assumed) | B11: =B10 | C11: =B11+C10 | D11: =C11+D10 | E11: =D11+E10 | F11: =E11+F10 | G11: =F11+G10 | H11: =G11+H10 | I11: =H11+I10 | J11: =I11+J10 | ... Y11: =X11+Y10
A12: PEAK FUNDING NEED (max cumulative deficit) | B12: =MAX(0,-MIN($B$11:$Y$11))

Sheet T2 Refuge
A1: T2 - REFUGE (Rev 4.10 deal): own license from M1; PPEO hold on first claims; seller schedule + Sept bank note + Jan SBA refi. No equity inflow modeled.
B3: Aug-26 | C3: Sep-26 | D3: Oct-26 | E3: Nov-26 | F3: Dec-26 | G3: Jan-27 | H3: Feb-27 | I3: Mar-27 | J3: Apr-27 | K3: May-27 | L3: Jun-27 | M3: Jul-27 | N3: Aug-27 | O3: Sep-27 | P3: Oct-27 | Q3: Nov-27 | R3: Dec-27 | S3: Jan-28 | T3: Feb-28 | U3: Mar-28 | V3: Apr-28 | W3: May-28 | X3: Jun-28 | Y3: Jul-28
A4: ADC on this track | B4: =Assumptions!B13 | C4: =Assumptions!C13 | D4: =Assumptions!D13 | E4: =Assumptions!E13 | F4: =Assumptions!F13 | G4: =Assumptions!G13 | H4: =Assumptions!H13 | I4: =Assumptions!I13 | ... Y4: =Assumptions!Y13
A5: Revenue earned (NPR) | B5: =B4*'Assumptions'!$B$4*'Assumptions'!$B$5 | C5: =C4*'Assumptions'!$B$4*'Assumptions'!$B$5 | D5: =D4*'Assumptions'!$B$4*'Assumptions'!$B$5 | E5: =E4*'Assumptions'!$B$4*'Assumptions'!$B$5 | F5: =F4*'Assumptions'!$B$4*'Assumptions'!$B$5 | G5: =G4*'Assumptions'!$B$4*'Assumptions'!$B$5 | H5: =H4*'Assumptions'!$B$4*'Assumptions'!$B$5 | I5: =I4*'Assumptions'!$B$4*'Assumptions'!$B$5 | ... Y5: =Y4*'Assumptions'!$B$4*'Assumptions'!$B$5
A6: Variable costs (clinical + patient care, paid in month) | B6: =-B4*'Assumptions'!$B$6*'Assumptions'!$B$5 | C6: =-C4*'Assumptions'!$B$6*'Assumptions'!$B$5 | D6: =-D4*'Assumptions'!$B$6*'Assumptions'!$B$5 | E6: =-E4*'Assumptions'!$B$6*'Assumptions'!$B$5 | F6: =-F4*'Assumptions'!$B$6*'Assumptions'!$B$5 | G6: =-G4*'Assumptions'!$B$6*'Assumptions'!$B$5 | H6: =-H4*'Assumptions'!$B$6*'Assumptions'!$B$5 | I6: =-I4*'Assumptions'!$B$6*'Assumptions'!$B$5 | ... Y6: =-Y4*'Assumptions'!$B$6*'Assumptions'!$B$5
A7: Collection month for service month (lag + PPEO hold) | B7: =1+1+MAX(0,'Assumptions'!$B$19-0) | C7: =2+1+MAX(0,'Assumptions'!$B$19-1) | D7: =3+1+MAX(0,'Assumptions'!$B$19-2) | E7: =4+1+MAX(0,'Assumptions'!$B$19-3) | F7: =5+1+MAX(0,'Assumptions'!$B$19-4) | G7: =6+1+MAX(0,'Assumptions'!$B$19-5) | H7: =7+1+MAX(0,'Assumptions'!$B$19-6) | I7: =8+1+MAX(0,'Assumptions'!$B$19-7) | J7: =9+1+MAX(0,'Assumptions'!$B$19-8) | K7: =10+1+MAX(0,'Assumptions'!$B$19-9) | L7: =11+1+MAX(0,'Assumptions'!$B$19-10) | M7: =12+1+MAX(0,'Assumptions'!$B$19-11) | N7: =13+1+MAX(0,'Assumptions'!$B$19-12) | O7: =14+1+MAX(0,'Assumptions'!$B$19-13) | P7: =15+1+MAX(0,'Assumptions'!$B$19-14) | Q7: =16+1+MAX(0,'Assumptions'!$B$19-15) | R7: =17+1+MAX(0,'Assumptions'!$B$19-16) | S7: =18+1+MAX(0,'Assumptions'!$B$19-17) | T7: =19+1+MAX(0,'Assumptions'!$B$19-18) | U7: =20+1+MAX(0,'Assumptions'!$B$19-19) | V7: =21+1+MAX(0,'Assumptions'!$B$19-20) | W7: =22+1+MAX(0,'Assumptions'!$B$19-21) | X7: =23+1+MAX(0,'Assumptions'!$B$19-22) | Y7: =24+1+MAX(0,'Assumptions'!$B$19-23)
A8: Collections (held claims release together) | B8: =SUMPRODUCT(($B$7:$Y$7=1)*$B$5:$Y$5) | C8: =SUMPRODUCT(($B$7:$Y$7=2)*$B$5:$Y$5) | D8: =SUMPRODUCT(($B$7:$Y$7=3)*$B$5:$Y$5) | E8: =SUMPRODUCT(($B$7:$Y$7=4)*$B$5:$Y$5) | F8: =SUMPRODUCT(($B$7:$Y$7=5)*$B$5:$Y$5) | G8: =SUMPRODUCT(($B$7:$Y$7=6)*$B$5:$Y$5) | H8: =SUMPRODUCT(($B$7:$Y$7=7)*$B$5:$Y$5) | I8: =SUMPRODUCT(($B$7:$Y$7=8)*$B$5:$Y$5) | J8: =SUMPRODUCT(($B$7:$Y$7=9)*$B$5:$Y$5) | K8: =SUMPRODUCT(($B$7:$Y$7=10)*$B$5:$Y$5) | L8: =SUMPRODUCT(($B$7:$Y$7=11)*$B$5:$Y$5) | M8: =SUMPRODUCT(($B$7:$Y$7=12)*$B$5:$Y$5) | N8: =SUMPRODUCT(($B$7:$Y$7=13)*$B$5:$Y$5) | O8: =SUMPRODUCT(($B$7:$Y$7=14)*$B$5:$Y$5) | P8: =SUMPRODUCT(($B$7:$Y$7=15)*$B$5:$Y$5) | Q8: =SUMPRODUCT(($B$7:$Y$7=16)*$B$5:$Y$5) | R8: =SUMPRODUCT(($B$7:$Y$7=17)*$B$5:$Y$5) | S8: =SUMPRODUCT(($B$7:$Y$7=18)*$B$5:$Y$5) | T8: =SUMPRODUCT(($B$7:$Y$7=19)*$B$5:$Y$5) | U8: =SUMPRODUCT(($B$7:$Y$7=20)*$B$5:$Y$5) | V8: =SUMPRODUCT(($B$7:$Y$7=21)*$B$5:$Y$5) | W8: =SUMPRODUCT(($B$7:$Y$7=22)*$B$5:$Y$5) | X8: =SUMPRODUCT(($B$7:$Y$7=23)*$B$5:$Y$5) | Y8: =SUMPRODUCT(($B$7:$Y$7=24)*$B$5:$Y$5)
A9: Fixed overhead | B9: =-'Assumptions'!$B$7 | C9: =-'Assumptions'!$B$7 | D9: =-'Assumptions'!$B$7 | E9: =-'Assumptions'!$B$7 | F9: =-'Assumptions'!$B$7 | G9: =-'Assumptions'!$B$7 | H9: =-'Assumptions'!$B$7 | I9: =-'Assumptions'!$B$7 | ... Y9: =-'Assumptions'!$B$7
A10: License & financing flows (Rev 4.10 Path A) | B10: =-IF(1=1,'Assumptions'!$B$20,0)+IF(1=2,'Assumptions'!$B$22-'Assumptions'!$B$23,0)-IF(AND(1>=3,1<=5),'Assumptions'!$B$24,0)+IF(1=6,'Assumptions'!$B$25-'Assumptions'!$B$26,0)-IF(1>=7,'Assumptions'!$B$27,0) | C10: =-IF(2=1,'Assumptions'!$B$20,0)+IF(2=2,'Assumptions'!$B$22-'Assumptions'!$B$23,0)-IF(AND(2>=3,2<=5),'Assumptions'!$B$24,0)+IF(2=6,'Assumptions'!$B$25-'Assumptions'!$B$26,0)-IF(2>=7,'Assumptions'!$B$27,0) | D10: =-IF(3=1,'Assumptions'!$B$20,0)+IF(3=2,'Assumptions'!$B$22-'Assumptions'!$B$23,0)-IF(AND(3>=3,3<=5),'Assumptions'!$B$24,0)+IF(3=6,'Assumptions'!$B$25-'Assumptions'!$B$26,0)-IF(3>=7,'Assumptions'!$B$27,0) | E10: =-IF(4=1,'Assumptions'!$B$20,0)+IF(4=2,'Assumptions'!$B$22-'Assumptions'!$B$23,0)-IF(AND(4>=3,4<=5),'Assumptions'!$B$24,0)+IF(4=6,'Assumptions'!$B$25-'Assumptions'!$B$26,0)-IF(4>=7,'Assumptions'!$B$27,0) | F10: =-IF(5=1,'Assumptions'!$B$20,0)+IF(5=2,'Assumptions'!$B$22-'Assumptions'!$B$23,0)-IF(AND(5>=3,5<=5),'Assumptions'!$B$24,0)+IF(5=6,'Assumptions'!$B$25-'Assumptions'!$B$26,0)-IF(5>=7,'Assumptions'!$B$27,0) | G10: =-IF(6=1,'Assumptions'!$B$20,0)+IF(6=2,'Assumptions'!$B$22-'Assumptions'!$B$23,0)-IF(AND(6>=3,6<=5),'Assumptions'!$B$24,0)+IF(6=6,'Assumptions'!$B$25-'Assumptions'!$B$26,0)-IF(6>=7,'Assumptions'!$B$27,0) | H10: =-IF(7=1,'Assumptions'!$B$20,0)+IF(7=2,'Assumptions'!$B$22-'Assumptions'!$B$23,0)-IF(AND(7>=3,7<=5),'Assumptions'!$B$24,0)+IF(7=6,'Assumptions'!$B$25-'Assumptions'!$B$26,0)-IF(7>=7,'Assumptions'!$B$27,0) | I10: =-IF(8=1,'Assumptions'!$B$20,0)+IF(8=2,'Assumptions'!$B$22-'Assumptions'!$B$23,0)-IF(AND(8>=3,8<=5),'Assumptions'!$B$24,0)+IF(8=6,'Assumptions'!$B$25-'Assumptions'!$B$26,0)-IF(8>=7,'Assumptions'!$B$27,0) | J10: =-IF(9=1,'Assumptions'!$B$20,0)+IF(9=2,'Assumptions'!$B$22-'Assumptions'!$B$23,0)-IF(AND(9>=3,9<=5),'Assumptions'!$B$24,0)+IF(9=6,'Assumptions'!$B$25-'Assumptions'!$B$26,0)-IF(9>=7,'Assumptions'!$B$27,0) | K10: =-IF(10=1,'Assumptions'!$B$20,0)+IF(10=2,'Assumptions'!$B$22-'Assumptions'!$B$23,0)-IF(AND(10>=3,10<=5),'Assumptions'!$B$24,0)+IF(10=6,'Assumptions'!$B$25-'Assumptions'!$B$26,0)-IF(10>=7,'Assumptions'!$B$27,0) | L10: =-IF(11=1,'Assumptions'!$B$20,0)+IF(11=2,'Assumptions'!$B$22-'Assumptions'!$B$23,0)-IF(AND(11>=3,11<=5),'Assumptions'!$B$24,0)+IF(11=6,'Assumptions'!$B$25-'Assumptions'!$B$26,0)-IF(11>=7,'Assumptions'!$B$27,0) | M10: =-IF(12=1,'Assumptions'!$B$20,0)+IF(12=2,'Assumptions'!$B$22-'Assumptions'!$B$23,0)-IF(AND(12>=3,12<=5),'Assumptions'!$B$24,0)+IF(12=6,'Assumptions'!$B$25-'Assumptions'!$B$26,0)-IF(12>=7,'Assumptions'!$B$27,0) | N10: =-IF(13=1,'Assumptions'!$B$20,0)+IF(13=2,'Assumptions'!$B$22-'Assumptions'!$B$23,0)-IF(AND(13>=3,13<=5),'Assumptions'!$B$24,0)+IF(13=6,'Assumptions'!$B$25-'Assumptions'!$B$26,0)-IF(13>=7,'Assumptions'!$B$27,0) | O10: =-IF(14=1,'Assumptions'!$B$20,0)+IF(14=2,'Assumptions'!$B$22-'Assumptions'!$B$23,0)-IF(AND(14>=3,14<=5),'Assumptions'!$B$24,0)+IF(14=6,'Assumptions'!$B$25-'Assumptions'!$B$26,0)-IF(14>=7,'Assumptions'!$B$27,0) | P10: =-IF(15=1,'Assumptions'!$B$20,0)+IF(15=2,'Assumptions'!$B$22-'Assumptions'!$B$23,0)-IF(AND(15>=3,15<=5),'Assumptions'!$B$24,0)+IF(15=6,'Assumptions'!$B$25-'Assumptions'!$B$26,0)-IF(15>=7,'Assumptions'!$B$27,0) | Q10: =-IF(16=1,'Assumptions'!$B$20,0)+IF(16=2,'Assumptions'!$B$22-'Assumptions'!$B$23,0)-IF(AND(16>=3,16<=5),'Assumptions'!$B$24,0)+IF(16=6,'Assumptions'!$B$25-'Assumptions'!$B$26,0)-IF(16>=7,'Assumptions'!$B$27,0) | R10: =-IF(17=1,'Assumptions'!$B$20,0)+IF(17=2,'Assumptions'!$B$22-'Assumptions'!$B$23,0)-IF(AND(17>=3,17<=5),'Assumptions'!$B$24,0)+IF(17=6,'Assumptions'!$B$25-'Assumptions'!$B$26,0)-IF(17>=7,'Assumptions'!$B$27,0) | S10: =-IF(18=1,'Assumptions'!$B$20,0)+IF(18=2,'Assumptions'!$B$22-'Assumptions'!$B$23,0)-IF(AND(18>=3,18<=5),'Assumptions'!$B$24,0)+IF(18=6,'Assumptions'!$B$25-'Assumptions'!$B$26,0)-IF(18>=7,'Assumptions'!$B$27,0) | T10: =-IF(19=1,'Assumptions'!$B$20,0)+IF(19=2,'Assumptions'!$B$22-'Assumptions'!$B$23,0)-IF(AND(19>=3,19<=5),'Assumptions'!$B$24,0)+IF(19=6,'Assumptions'!$B$25-'Assumptions'!$B$26,0)-IF(19>=7,'Assumptions'!$B$27,0) | U10: =-IF(20=1,'Assumptions'!$B$20,0)+IF(20=2,'Assumptions'!$B$22-'Assumptions'!$B$23,0)-IF(AND(20>=3,20<=5),'Assumptions'!$B$24,0)+IF(20=6,'Assumptions'!$B$25-'Assumptions'!$B$26,0)-IF(20>=7,'Assumptions'!$B$27,0) | V10: =-IF(21=1,'Assumptions'!$B$20,0)+IF(21=2,'Assumptions'!$B$22-'Assumptions'!$B$23,0)-IF(AND(21>=3,21<=5),'Assumptions'!$B$24,0)+IF(21=6,'Assumptions'!$B$25-'Assumptions'!$B$26,0)-IF(21>=7,'Assumptions'!$B$27,0) | W10: =-IF(22=1,'Assumptions'!$B$20,0)+IF(22=2,'Assumptions'!$B$22-'Assumptions'!$B$23,0)-IF(AND(22>=3,22<=5),'Assumptions'!$B$24,0)+IF(22=6,'Assumptions'!$B$25-'Assumptions'!$B$26,0)-IF(22>=7,'Assumptions'!$B$27,0) | X10: =-IF(23=1,'Assumptions'!$B$20,0)+IF(23=2,'Assumptions'!$B$22-'Assumptions'!$B$23,0)-IF(AND(23>=3,23<=5),'Assumptions'!$B$24,0)+IF(23=6,'Assumptions'!$B$25-'Assumptions'!$B$26,0)-IF(23>=7,'Assumptions'!$B$27,0) | Y10: =-IF(24=1,'Assumptions'!$B$20,0)+IF(24=2,'Assumptions'!$B$22-'Assumptions'!$B$23,0)-IF(AND(24>=3,24<=5),'Assumptions'!$B$24,0)+IF(24=6,'Assumptions'!$B$25-'Assumptions'!$B$26,0)-IF(24>=7,'Assumptions'!$B$27,0)
A11: NET CASH FLOW | B11: =B8+B6+B9+B10 | C11: =C8+C6+C9+C10 | D11: =D8+D6+D9+D10 | E11: =E8+E6+E9+E10 | F11: =F8+F6+F9+F10 | G11: =G8+G6+G9+G10 | H11: =H8+H6+H9+H10 | I11: =I8+I6+I9+I10 | ... Y11: =Y8+Y6+Y9+Y10
A12: Cumulative cash (no equity assumed) | B12: =B11 | C12: =B12+C11 | D12: =C12+D11 | E12: =D12+E11 | F12: =E12+F11 | G12: =F12+G11 | H12: =G12+H11 | I12: =H12+I11 | J12: =I12+J11 | ... Y12: =X12+Y11
A13: PEAK FUNDING NEED (max cumulative deficit) | B13: =MAX(0,-MIN($B$12:$Y$12))

Sheet T3 Avant
A1: T3 - AVANT ($300K seller-financed, Medicare-only): idle until tie-in/CHOW clears, then census starts; PPEO hold on first claims; payments start at PPEO clear (May schedule, time-shifted).
B3: Aug-26 | C3: Sep-26 | D3: Oct-26 | E3: Nov-26 | F3: Dec-26 | G3: Jan-27 | H3: Feb-27 | I3: Mar-27 | J3: Apr-27 | K3: May-27 | L3: Jun-27 | M3: Jul-27 | N3: Aug-27 | O3: Sep-27 | P3: Oct-27 | Q3: Nov-27 | R3: Dec-27 | S3: Jan-28 | T3: Feb-28 | U3: Mar-28 | V3: Apr-28 | W3: May-28 | X3: Jun-28 | Y3: Jul-28
A4: ADC on this track | B4: =IF(1<'Assumptions'!$B$30,0,INDEX(Assumptions!$B$13:$Y$13,1,1-'Assumptions'!$B$30+1)) | C4: =IF(2<'Assumptions'!$B$30,0,INDEX(Assumptions!$B$13:$Y$13,1,2-'Assumptions'!$B$30+1)) | D4: =IF(3<'Assumptions'!$B$30,0,INDEX(Assumptions!$B$13:$Y$13,1,3-'Assumptions'!$B$30+1)) | E4: =IF(4<'Assumptions'!$B$30,0,INDEX(Assumptions!$B$13:$Y$13,1,4-'Assumptions'!$B$30+1)) | F4: =IF(5<'Assumptions'!$B$30,0,INDEX(Assumptions!$B$13:$Y$13,1,5-'Assumptions'!$B$30+1)) | G4: =IF(6<'Assumptions'!$B$30,0,INDEX(Assumptions!$B$13:$Y$13,1,6-'Assumptions'!$B$30+1)) | H4: =IF(7<'Assumptions'!$B$30,0,INDEX(Assumptions!$B$13:$Y$13,1,7-'Assumptions'!$B$30+1)) | I4: =IF(8<'Assumptions'!$B$30,0,INDEX(Assumptions!$B$13:$Y$13,1,8-'Assumptions'!$B$30+1)) | J4: =IF(9<'Assumptions'!$B$30,0,INDEX(Assumptions!$B$13:$Y$13,1,9-'Assumptions'!$B$30+1)) | K4: =IF(10<'Assumptions'!$B$30,0,INDEX(Assumptions!$B$13:$Y$13,1,10-'Assumptions'!$B$30+1)) | L4: =IF(11<'Assumptions'!$B$30,0,INDEX(Assumptions!$B$13:$Y$13,1,11-'Assumptions'!$B$30+1)) | M4: =IF(12<'Assumptions'!$B$30,0,INDEX(Assumptions!$B$13:$Y$13,1,12-'Assumptions'!$B$30+1)) | N4: =IF(13<'Assumptions'!$B$30,0,INDEX(Assumptions!$B$13:$Y$13,1,13-'Assumptions'!$B$30+1)) | O4: =IF(14<'Assumptions'!$B$30,0,INDEX(Assumptions!$B$13:$Y$13,1,14-'Assumptions'!$B$30+1)) | P4: =IF(15<'Assumptions'!$B$30,0,INDEX(Assumptions!$B$13:$Y$13,1,15-'Assumptions'!$B$30+1)) | Q4: =IF(16<'Assumptions'!$B$30,0,INDEX(Assumptions!$B$13:$Y$13,1,16-'Assumptions'!$B$30+1)) | R4: =IF(17<'Assumptions'!$B$30,0,INDEX(Assumptions!$B$13:$Y$13,1,17-'Assumptions'!$B$30+1)) | S4: =IF(18<'Assumptions'!$B$30,0,INDEX(Assumptions!$B$13:$Y$13,1,18-'Assumptions'!$B$30+1)) | T4: =IF(19<'Assumptions'!$B$30,0,INDEX(Assumptions!$B$13:$Y$13,1,19-'Assumptions'!$B$30+1)) | U4: =IF(20<'Assumptions'!$B$30,0,INDEX(Assumptions!$B$13:$Y$13,1,20-'Assumptions'!$B$30+1)) | V4: =IF(21<'Assumptions'!$B$30,0,INDEX(Assumptions!$B$13:$Y$13,1,21-'Assumptions'!$B$30+1)) | W4: =IF(22<'Assumptions'!$B$30,0,INDEX(Assumptions!$B$13:$Y$13,1,22-'Assumptions'!$B$30+1)) | X4: =IF(23<'Assumptions'!$B$30,0,INDEX(Assumptions!$B$13:$Y$13,1,23-'Assumptions'!$B$30+1)) | Y4: =IF(24<'Assumptions'!$B$30,0,INDEX(Assumptions!$B$13:$Y$13,1,24-'Assumptions'!$B$30+1))
A5: Revenue earned (NPR) | B5: =B4*'Assumptions'!$B$4*'Assumptions'!$B$5 | C5: =C4*'Assumptions'!$B$4*'Assumptions'!$B$5 | D5: =D4*'Assumptions'!$B$4*'Assumptions'!$B$5 | E5: =E4*'Assumptions'!$B$4*'Assumptions'!$B$5 | F5: =F4*'Assumptions'!$B$4*'Assumptions'!$B$5 | G5: =G4*'Assumptions'!$B$4*'Assumptions'!$B$5 | H5: =H4*'Assumptions'!$B$4*'Assumptions'!$B$5 | I5: =I4*'Assumptions'!$B$4*'Assumptions'!$B$5 | ... Y5: =Y4*'Assumptions'!$B$4*'Assumptions'!$B$5
A6: Variable costs (clinical + patient care, paid in month) | B6: =-B4*'Assumptions'!$B$6*'Assumptions'!$B$5 | C6: =-C4*'Assumptions'!$B$6*'Assumptions'!$B$5 | D6: =-D4*'Assumptions'!$B$6*'Assumptions'!$B$5 | E6: =-E4*'Assumptions'!$B$6*'Assumptions'!$B$5 | F6: =-F4*'Assumptions'!$B$6*'Assumptions'!$B$5 | G6: =-G4*'Assumptions'!$B$6*'Assumptions'!$B$5 | H6: =-H4*'Assumptions'!$B$6*'Assumptions'!$B$5 | I6: =-I4*'Assumptions'!$B$6*'Assumptions'!$B$5 | ... Y6: =-Y4*'Assumptions'!$B$6*'Assumptions'!$B$5
A7: Collection month for service month (lag + PPEO hold from census start) | B7: =1+1+MAX(0,'Assumptions'!$B$31-(1-'Assumptions'!$B$30)) | C7: =2+1+MAX(0,'Assumptions'!$B$31-(2-'Assumptions'!$B$30)) | D7: =3+1+MAX(0,'Assumptions'!$B$31-(3-'Assumptions'!$B$30)) | E7: =4+1+MAX(0,'Assumptions'!$B$31-(4-'Assumptions'!$B$30)) | F7: =5+1+MAX(0,'Assumptions'!$B$31-(5-'Assumptions'!$B$30)) | G7: =6+1+MAX(0,'Assumptions'!$B$31-(6-'Assumptions'!$B$30)) | H7: =7+1+MAX(0,'Assumptions'!$B$31-(7-'Assumptions'!$B$30)) | I7: =8+1+MAX(0,'Assumptions'!$B$31-(8-'Assumptions'!$B$30)) | J7: =9+1+MAX(0,'Assumptions'!$B$31-(9-'Assumptions'!$B$30)) | K7: =10+1+MAX(0,'Assumptions'!$B$31-(10-'Assumptions'!$B$30)) | L7: =11+1+MAX(0,'Assumptions'!$B$31-(11-'Assumptions'!$B$30)) | M7: =12+1+MAX(0,'Assumptions'!$B$31-(12-'Assumptions'!$B$30)) | N7: =13+1+MAX(0,'Assumptions'!$B$31-(13-'Assumptions'!$B$30)) | O7: =14+1+MAX(0,'Assumptions'!$B$31-(14-'Assumptions'!$B$30)) | P7: =15+1+MAX(0,'Assumptions'!$B$31-(15-'Assumptions'!$B$30)) | Q7: =16+1+MAX(0,'Assumptions'!$B$31-(16-'Assumptions'!$B$30)) | R7: =17+1+MAX(0,'Assumptions'!$B$31-(17-'Assumptions'!$B$30)) | S7: =18+1+MAX(0,'Assumptions'!$B$31-(18-'Assumptions'!$B$30)) | T7: =19+1+MAX(0,'Assumptions'!$B$31-(19-'Assumptions'!$B$30)) | U7: =20+1+MAX(0,'Assumptions'!$B$31-(20-'Assumptions'!$B$30)) | V7: =21+1+MAX(0,'Assumptions'!$B$31-(21-'Assumptions'!$B$30)) | W7: =22+1+MAX(0,'Assumptions'!$B$31-(22-'Assumptions'!$B$30)) | X7: =23+1+MAX(0,'Assumptions'!$B$31-(23-'Assumptions'!$B$30)) | Y7: =24+1+MAX(0,'Assumptions'!$B$31-(24-'Assumptions'!$B$30))
A8: Collections (held claims release together) | B8: =SUMPRODUCT(($B$7:$Y$7=1)*$B$5:$Y$5) | C8: =SUMPRODUCT(($B$7:$Y$7=2)*$B$5:$Y$5) | D8: =SUMPRODUCT(($B$7:$Y$7=3)*$B$5:$Y$5) | E8: =SUMPRODUCT(($B$7:$Y$7=4)*$B$5:$Y$5) | F8: =SUMPRODUCT(($B$7:$Y$7=5)*$B$5:$Y$5) | G8: =SUMPRODUCT(($B$7:$Y$7=6)*$B$5:$Y$5) | H8: =SUMPRODUCT(($B$7:$Y$7=7)*$B$5:$Y$5) | I8: =SUMPRODUCT(($B$7:$Y$7=8)*$B$5:$Y$5) | J8: =SUMPRODUCT(($B$7:$Y$7=9)*$B$5:$Y$5) | K8: =SUMPRODUCT(($B$7:$Y$7=10)*$B$5:$Y$5) | L8: =SUMPRODUCT(($B$7:$Y$7=11)*$B$5:$Y$5) | M8: =SUMPRODUCT(($B$7:$Y$7=12)*$B$5:$Y$5) | N8: =SUMPRODUCT(($B$7:$Y$7=13)*$B$5:$Y$5) | O8: =SUMPRODUCT(($B$7:$Y$7=14)*$B$5:$Y$5) | P8: =SUMPRODUCT(($B$7:$Y$7=15)*$B$5:$Y$5) | Q8: =SUMPRODUCT(($B$7:$Y$7=16)*$B$5:$Y$5) | R8: =SUMPRODUCT(($B$7:$Y$7=17)*$B$5:$Y$5) | S8: =SUMPRODUCT(($B$7:$Y$7=18)*$B$5:$Y$5) | T8: =SUMPRODUCT(($B$7:$Y$7=19)*$B$5:$Y$5) | U8: =SUMPRODUCT(($B$7:$Y$7=20)*$B$5:$Y$5) | V8: =SUMPRODUCT(($B$7:$Y$7=21)*$B$5:$Y$5) | W8: =SUMPRODUCT(($B$7:$Y$7=22)*$B$5:$Y$5) | X8: =SUMPRODUCT(($B$7:$Y$7=23)*$B$5:$Y$5) | Y8: =SUMPRODUCT(($B$7:$Y$7=24)*$B$5:$Y$5)
A9: Overhead (pre-clearance burn, then full fixed) | B9: =-IF(1<'Assumptions'!$B$30,'Assumptions'!$B$32,'Assumptions'!$B$7) | C9: =-IF(2<'Assumptions'!$B$30,'Assumptions'!$B$32,'Assumptions'!$B$7) | D9: =-IF(3<'Assumptions'!$B$30,'Assumptions'!$B$32,'Assumptions'!$B$7) | E9: =-IF(4<'Assumptions'!$B$30,'Assumptions'!$B$32,'Assumptions'!$B$7) | F9: =-IF(5<'Assumptions'!$B$30,'Assumptions'!$B$32,'Assumptions'!$B$7) | G9: =-IF(6<'Assumptions'!$B$30,'Assumptions'!$B$32,'Assumptions'!$B$7) | H9: =-IF(7<'Assumptions'!$B$30,'Assumptions'!$B$32,'Assumptions'!$B$7) | I9: =-IF(8<'Assumptions'!$B$30,'Assumptions'!$B$32,'Assumptions'!$B$7) | J9: =-IF(9<'Assumptions'!$B$30,'Assumptions'!$B$32,'Assumptions'!$B$7) | K9: =-IF(10<'Assumptions'!$B$30,'Assumptions'!$B$32,'Assumptions'!$B$7) | L9: =-IF(11<'Assumptions'!$B$30,'Assumptions'!$B$32,'Assumptions'!$B$7) | M9: =-IF(12<'Assumptions'!$B$30,'Assumptions'!$B$32,'Assumptions'!$B$7) | N9: =-IF(13<'Assumptions'!$B$30,'Assumptions'!$B$32,'Assumptions'!$B$7) | O9: =-IF(14<'Assumptions'!$B$30,'Assumptions'!$B$32,'Assumptions'!$B$7) | P9: =-IF(15<'Assumptions'!$B$30,'Assumptions'!$B$32,'Assumptions'!$B$7) | Q9: =-IF(16<'Assumptions'!$B$30,'Assumptions'!$B$32,'Assumptions'!$B$7) | R9: =-IF(17<'Assumptions'!$B$30,'Assumptions'!$B$32,'Assumptions'!$B$7) | S9: =-IF(18<'Assumptions'!$B$30,'Assumptions'!$B$32,'Assumptions'!$B$7) | T9: =-IF(19<'Assumptions'!$B$30,'Assumptions'!$B$32,'Assumptions'!$B$7) | U9: =-IF(20<'Assumptions'!$B$30,'Assumptions'!$B$32,'Assumptions'!$B$7) | V9: =-IF(21<'Assumptions'!$B$30,'Assumptions'!$B$32,'Assumptions'!$B$7) | W9: =-IF(22<'Assumptions'!$B$30,'Assumptions'!$B$32,'Assumptions'!$B$7) | X9: =-IF(23<'Assumptions'!$B$30,'Assumptions'!$B$32,'Assumptions'!$B$7) | Y9: =-IF(24<'Assumptions'!$B$30,'Assumptions'!$B$32,'Assumptions'!$B$7)
A10: Seller payments (anchor = PPEO clear = clearance + hold) | B10: =-IF(1=('Assumptions'!$B$30+'Assumptions'!$B$31),'Assumptions'!$B$33,0)-IF(1=('Assumptions'!$B$30+'Assumptions'!$B$31)+6,'Assumptions'!$B$34,0)-IF(AND(1>=('Assumptions'!$B$30+'Assumptions'!$B$31)+7,1<=('Assumptions'!$B$30+'Assumptions'!$B$31)+24),'Assumptions'!$B$35,0) | C10: =-IF(2=('Assumptions'!$B$30+'Assumptions'!$B$31),'Assumptions'!$B$33,0)-IF(2=('Assumptions'!$B$30+'Assumptions'!$B$31)+6,'Assumptions'!$B$34,0)-IF(AND(2>=('Assumptions'!$B$30+'Assumptions'!$B$31)+7,2<=('Assumptions'!$B$30+'Assumptions'!$B$31)+24),'Assumptions'!$B$35,0) | D10: =-IF(3=('Assumptions'!$B$30+'Assumptions'!$B$31),'Assumptions'!$B$33,0)-IF(3=('Assumptions'!$B$30+'Assumptions'!$B$31)+6,'Assumptions'!$B$34,0)-IF(AND(3>=('Assumptions'!$B$30+'Assumptions'!$B$31)+7,3<=('Assumptions'!$B$30+'Assumptions'!$B$31)+24),'Assumptions'!$B$35,0) | E10: =-IF(4=('Assumptions'!$B$30+'Assumptions'!$B$31),'Assumptions'!$B$33,0)-IF(4=('Assumptions'!$B$30+'Assumptions'!$B$31)+6,'Assumptions'!$B$34,0)-IF(AND(4>=('Assumptions'!$B$30+'Assumptions'!$B$31)+7,4<=('Assumptions'!$B$30+'Assumptions'!$B$31)+24),'Assumptions'!$B$35,0) | F10: =-IF(5=('Assumptions'!$B$30+'Assumptions'!$B$31),'Assumptions'!$B$33,0)-IF(5=('Assumptions'!$B$30+'Assumptions'!$B$31)+6,'Assumptions'!$B$34,0)-IF(AND(5>=('Assumptions'!$B$30+'Assumptions'!$B$31)+7,5<=('Assumptions'!$B$30+'Assumptions'!$B$31)+24),'Assumptions'!$B$35,0) | G10: =-IF(6=('Assumptions'!$B$30+'Assumptions'!$B$31),'Assumptions'!$B$33,0)-IF(6=('Assumptions'!$B$30+'Assumptions'!$B$31)+6,'Assumptions'!$B$34,0)-IF(AND(6>=('Assumptions'!$B$30+'Assumptions'!$B$31)+7,6<=('Assumptions'!$B$30+'Assumptions'!$B$31)+24),'Assumptions'!$B$35,0) | H10: =-IF(7=('Assumptions'!$B$30+'Assumptions'!$B$31),'Assumptions'!$B$33,0)-IF(7=('Assumptions'!$B$30+'Assumptions'!$B$31)+6,'Assumptions'!$B$34,0)-IF(AND(7>=('Assumptions'!$B$30+'Assumptions'!$B$31)+7,7<=('Assumptions'!$B$30+'Assumptions'!$B$31)+24),'Assumptions'!$B$35,0) | I10: =-IF(8=('Assumptions'!$B$30+'Assumptions'!$B$31),'Assumptions'!$B$33,0)-IF(8=('Assumptions'!$B$30+'Assumptions'!$B$31)+6,'Assumptions'!$B$34,0)-IF(AND(8>=('Assumptions'!$B$30+'Assumptions'!$B$31)+7,8<=('Assumptions'!$B$30+'Assumptions'!$B$31)+24),'Assumptions'!$B$35,0) | J10: =-IF(9=('Assumptions'!$B$30+'Assumptions'!$B$31),'Assumptions'!$B$33,0)-IF(9=('Assumptions'!$B$30+'Assumptions'!$B$31)+6,'Assumptions'!$B$34,0)-IF(AND(9>=('Assumptions'!$B$30+'Assumptions'!$B$31)+7,9<=('Assumptions'!$B$30+'Assumptions'!$B$31)+24),'Assumptions'!$B$35,0) | K10: =-IF(10=('Assumptions'!$B$30+'Assumptions'!$B$31),'Assumptions'!$B$33,0)-IF(10=('Assumptions'!$B$30+'Assumptions'!$B$31)+6,'Assumptions'!$B$34,0)-IF(AND(10>=('Assumptions'!$B$30+'Assumptions'!$B$31)+7,10<=('Assumptions'!$B$30+'Assumptions'!$B$31)+24),'Assumptions'!$B$35,0) | L10: =-IF(11=('Assumptions'!$B$30+'Assumptions'!$B$31),'Assumptions'!$B$33,0)-IF(11=('Assumptions'!$B$30+'Assumptions'!$B$31)+6,'Assumptions'!$B$34,0)-IF(AND(11>=('Assumptions'!$B$30+'Assumptions'!$B$31)+7,11<=('Assumptions'!$B$30+'Assumptions'!$B$31)+24),'Assumptions'!$B$35,0) | M10: =-IF(12=('Assumptions'!$B$30+'Assumptions'!$B$31),'Assumptions'!$B$33,0)-IF(12=('Assumptions'!$B$30+'Assumptions'!$B$31)+6,'Assumptions'!$B$34,0)-IF(AND(12>=('Assumptions'!$B$30+'Assumptions'!$B$31)+7,12<=('Assumptions'!$B$30+'Assumptions'!$B$31)+24),'Assumptions'!$B$35,0) | N10: =-IF(13=('Assumptions'!$B$30+'Assumptions'!$B$31),'Assumptions'!$B$33,0)-IF(13=('Assumptions'!$B$30+'Assumptions'!$B$31)+6,'Assumptions'!$B$34,0)-IF(AND(13>=('Assumptions'!$B$30+'Assumptions'!$B$31)+7,13<=('Assumptions'!$B$30+'Assumptions'!$B$31)+24),'Assumptions'!$B$35,0) | O10: =-IF(14=('Assumptions'!$B$30+'Assumptions'!$B$31),'Assumptions'!$B$33,0)-IF(14=('Assumptions'!$B$30+'Assumptions'!$B$31)+6,'Assumptions'!$B$34,0)-IF(AND(14>=('Assumptions'!$B$30+'Assumptions'!$B$31)+7,14<=('Assumptions'!$B$30+'Assumptions'!$B$31)+24),'Assumptions'!$B$35,0) | P10: =-IF(15=('Assumptions'!$B$30+'Assumptions'!$B$31),'Assumptions'!$B$33,0)-IF(15=('Assumptions'!$B$30+'Assumptions'!$B$31)+6,'Assumptions'!$B$34,0)-IF(AND(15>=('Assumptions'!$B$30+'Assumptions'!$B$31)+7,15<=('Assumptions'!$B$30+'Assumptions'!$B$31)+24),'Assumptions'!$B$35,0) | Q10: =-IF(16=('Assumptions'!$B$30+'Assumptions'!$B$31),'Assumptions'!$B$33,0)-IF(16=('Assumptions'!$B$30+'Assumptions'!$B$31)+6,'Assumptions'!$B$34,0)-IF(AND(16>=('Assumptions'!$B$30+'Assumptions'!$B$31)+7,16<=('Assumptions'!$B$30+'Assumptions'!$B$31)+24),'Assumptions'!$B$35,0) | R10: =-IF(17=('Assumptions'!$B$30+'Assumptions'!$B$31),'Assumptions'!$B$33,0)-IF(17=('Assumptions'!$B$30+'Assumptions'!$B$31)+6,'Assumptions'!$B$34,0)-IF(AND(17>=('Assumptions'!$B$30+'Assumptions'!$B$31)+7,17<=('Assumptions'!$B$30+'Assumptions'!$B$31)+24),'Assumptions'!$B$35,0) | S10: =-IF(18=('Assumptions'!$B$30+'Assumptions'!$B$31),'Assumptions'!$B$33,0)-IF(18=('Assumptions'!$B$30+'Assumptions'!$B$31)+6,'Assumptions'!$B$34,0)-IF(AND(18>=('Assumptions'!$B$30+'Assumptions'!$B$31)+7,18<=('Assumptions'!$B$30+'Assumptions'!$B$31)+24),'Assumptions'!$B$35,0) | T10: =-IF(19=('Assumptions'!$B$30+'Assumptions'!$B$31),'Assumptions'!$B$33,0)-IF(19=('Assumptions'!$B$30+'Assumptions'!$B$31)+6,'Assumptions'!$B$34,0)-IF(AND(19>=('Assumptions'!$B$30+'Assumptions'!$B$31)+7,19<=('Assumptions'!$B$30+'Assumptions'!$B$31)+24),'Assumptions'!$B$35,0) | U10: =-IF(20=('Assumptions'!$B$30+'Assumptions'!$B$31),'Assumptions'!$B$33,0)-IF(20=('Assumptions'!$B$30+'Assumptions'!$B$31)+6,'Assumptions'!$B$34,0)-IF(AND(20>=('Assumptions'!$B$30+'Assumptions'!$B$31)+7,20<=('Assumptions'!$B$30+'Assumptions'!$B$31)+24),'Assumptions'!$B$35,0) | V10: =-IF(21=('Assumptions'!$B$30+'Assumptions'!$B$31),'Assumptions'!$B$33,0)-IF(21=('Assumptions'!$B$30+'Assumptions'!$B$31)+6,'Assumptions'!$B$34,0)-IF(AND(21>=('Assumptions'!$B$30+'Assumptions'!$B$31)+7,21<=('Assumptions'!$B$30+'Assumptions'!$B$31)+24),'Assumptions'!$B$35,0) | W10: =-IF(22=('Assumptions'!$B$30+'Assumptions'!$B$31),'Assumptions'!$B$33,0)-IF(22=('Assumptions'!$B$30+'Assumptions'!$B$31)+6,'Assumptions'!$B$34,0)-IF(AND(22>=('Assumptions'!$B$30+'Assumptions'!$B$31)+7,22<=('Assumptions'!$B$30+'Assumptions'!$B$31)+24),'Assumptions'!$B$35,0) | X10: =-IF(23=('Assumptions'!$B$30+'Assumptions'!$B$31),'Assumptions'!$B$33,0)-IF(23=('Assumptions'!$B$30+'Assumptions'!$B$31)+6,'Assumptions'!$B$34,0)-IF(AND(23>=('Assumptions'!$B$30+'Assumptions'!$B$31)+7,23<=('Assumptions'!$B$30+'Assumptions'!$B$31)+24),'Assumptions'!$B$35,0) | Y10: =-IF(24=('Assumptions'!$B$30+'Assumptions'!$B$31),'Assumptions'!$B$33,0)-IF(24=('Assumptions'!$B$30+'Assumptions'!$B$31)+6,'Assumptions'!$B$34,0)-IF(AND(24>=('Assumptions'!$B$30+'Assumptions'!$B$31)+7,24<=('Assumptions'!$B$30+'Assumptions'!$B$31)+24),'Assumptions'!$B$35,0)
A11: NET CASH FLOW | B11: =B8+B6+B9+B10 | C11: =C8+C6+C9+C10 | D11: =D8+D6+D9+D10 | E11: =E8+E6+E9+E10 | F11: =F8+F6+F9+F10 | G11: =G8+G6+G9+G10 | H11: =H8+H6+H9+H10 | I11: =I8+I6+I9+I10 | ... Y11: =Y8+Y6+Y9+Y10
A12: Cumulative cash (no equity assumed) | B12: =B11 | C12: =B12+C11 | D12: =C12+D11 | E12: =D12+E11 | F12: =E12+F11 | G12: =F12+G11 | H12: =G12+H11 | I12: =H12+I11 | J12: =I12+J11 | ... Y12: =X12+Y11
A13: PEAK FUNDING NEED (max cumulative deficit) | B13: =MAX(0,-MIN($B$12:$Y$12))

Sheet T4a Refuge+Jason
A1: T4a Refuge+Jason - COMBO: 5-patient PPEO seed on the owned license, growth census on Jason's number; admissions shift to the owned license at PPEO clear; Jason fee ends after shift.
B3: Aug-26 | C3: Sep-26 | D3: Oct-26 | E3: Nov-26 | F3: Dec-26 | G3: Jan-27 | H3: Feb-27 | I3: Mar-27 | J3: Apr-27 | K3: May-27 | L3: Jun-27 | M3: Jul-27 | N3: Aug-27 | O3: Sep-27 | P3: Oct-27 | Q3: Nov-27 | R3: Dec-27 | S3: Jan-28 | T3: Feb-28 | U3: Mar-28 | V3: Apr-28 | W3: May-28 | X3: Jun-28 | Y3: Jul-28
A4: Owned-license ADC (seed until clear, then full book) | B4: =IF(1<1,0,IF(1<=(1+'Assumptions'!$B$19),'Assumptions'!$B$38,Assumptions!B13)) | C4: =IF(2<1,0,IF(2<=(1+'Assumptions'!$B$19),'Assumptions'!$B$38,Assumptions!C13)) | D4: =IF(3<1,0,IF(3<=(1+'Assumptions'!$B$19),'Assumptions'!$B$38,Assumptions!D13)) | E4: =IF(4<1,0,IF(4<=(1+'Assumptions'!$B$19),'Assumptions'!$B$38,Assumptions!E13)) | F4: =IF(5<1,0,IF(5<=(1+'Assumptions'!$B$19),'Assumptions'!$B$38,Assumptions!F13)) | G4: =IF(6<1,0,IF(6<=(1+'Assumptions'!$B$19),'Assumptions'!$B$38,Assumptions!G13)) | H4: =IF(7<1,0,IF(7<=(1+'Assumptions'!$B$19),'Assumptions'!$B$38,Assumptions!H13)) | I4: =IF(8<1,0,IF(8<=(1+'Assumptions'!$B$19),'Assumptions'!$B$38,Assumptions!I13)) | J4: =IF(9<1,0,IF(9<=(1+'Assumptions'!$B$19),'Assumptions'!$B$38,Assumptions!J13)) | K4: =IF(10<1,0,IF(10<=(1+'Assumptions'!$B$19),'Assumptions'!$B$38,Assumptions!K13)) | L4: =IF(11<1,0,IF(11<=(1+'Assumptions'!$B$19),'Assumptions'!$B$38,Assumptions!L13)) | M4: =IF(12<1,0,IF(12<=(1+'Assumptions'!$B$19),'Assumptions'!$B$38,Assumptions!M13)) | N4: =IF(13<1,0,IF(13<=(1+'Assumptions'!$B$19),'Assumptions'!$B$38,Assumptions!N13)) | O4: =IF(14<1,0,IF(14<=(1+'Assumptions'!$B$19),'Assumptions'!$B$38,Assumptions!O13)) | P4: =IF(15<1,0,IF(15<=(1+'Assumptions'!$B$19),'Assumptions'!$B$38,Assumptions!P13)) | Q4: =IF(16<1,0,IF(16<=(1+'Assumptions'!$B$19),'Assumptions'!$B$38,Assumptions!Q13)) | R4: =IF(17<1,0,IF(17<=(1+'Assumptions'!$B$19),'Assumptions'!$B$38,Assumptions!R13)) | S4: =IF(18<1,0,IF(18<=(1+'Assumptions'!$B$19),'Assumptions'!$B$38,Assumptions!S13)) | T4: =IF(19<1,0,IF(19<=(1+'Assumptions'!$B$19),'Assumptions'!$B$38,Assumptions!T13)) | U4: =IF(20<1,0,IF(20<=(1+'Assumptions'!$B$19),'Assumptions'!$B$38,Assumptions!U13)) | V4: =IF(21<1,0,IF(21<=(1+'Assumptions'!$B$19),'Assumptions'!$B$38,Assumptions!V13)) | W4: =IF(22<1,0,IF(22<=(1+'Assumptions'!$B$19),'Assumptions'!$B$38,Assumptions!W13)) | X4: =IF(23<1,0,IF(23<=(1+'Assumptions'!$B$19),'Assumptions'!$B$38,Assumptions!X13)) | Y4: =IF(24<1,0,IF(24<=(1+'Assumptions'!$B$19),'Assumptions'!$B$38,Assumptions!Y13))
A5: Jason ADC (total book minus owned) | B5: =MAX(0,Assumptions!B13-B4) | C5: =MAX(0,Assumptions!C13-C4) | D5: =MAX(0,Assumptions!D13-D4) | E5: =MAX(0,Assumptions!E13-E4) | F5: =MAX(0,Assumptions!F13-F4) | G5: =MAX(0,Assumptions!G13-G4) | H5: =MAX(0,Assumptions!H13-H4) | I5: =MAX(0,Assumptions!I13-I4) | ... Y5: =MAX(0,Assumptions!Y13-Y4)
A6: Revenue earned - owned license | B6: =B4*'Assumptions'!$B$4*'Assumptions'!$B$5 | C6: =C4*'Assumptions'!$B$4*'Assumptions'!$B$5 | D6: =D4*'Assumptions'!$B$4*'Assumptions'!$B$5 | E6: =E4*'Assumptions'!$B$4*'Assumptions'!$B$5 | F6: =F4*'Assumptions'!$B$4*'Assumptions'!$B$5 | G6: =G4*'Assumptions'!$B$4*'Assumptions'!$B$5 | H6: =H4*'Assumptions'!$B$4*'Assumptions'!$B$5 | I6: =I4*'Assumptions'!$B$4*'Assumptions'!$B$5 | ... Y6: =Y4*'Assumptions'!$B$4*'Assumptions'!$B$5
A7: Collection month - owned (lag + hold from start) | B7: =MAX(1+1,(1+'Assumptions'!$B$19)+1) | C7: =MAX(2+1,(1+'Assumptions'!$B$19)+1) | D7: =MAX(3+1,(1+'Assumptions'!$B$19)+1) | E7: =MAX(4+1,(1+'Assumptions'!$B$19)+1) | F7: =MAX(5+1,(1+'Assumptions'!$B$19)+1) | G7: =MAX(6+1,(1+'Assumptions'!$B$19)+1) | H7: =MAX(7+1,(1+'Assumptions'!$B$19)+1) | I7: =MAX(8+1,(1+'Assumptions'!$B$19)+1) | J7: =MAX(9+1,(1+'Assumptions'!$B$19)+1) | K7: =MAX(10+1,(1+'Assumptions'!$B$19)+1) | L7: =MAX(11+1,(1+'Assumptions'!$B$19)+1) | M7: =MAX(12+1,(1+'Assumptions'!$B$19)+1) | N7: =MAX(13+1,(1+'Assumptions'!$B$19)+1) | O7: =MAX(14+1,(1+'Assumptions'!$B$19)+1) | P7: =MAX(15+1,(1+'Assumptions'!$B$19)+1) | Q7: =MAX(16+1,(1+'Assumptions'!$B$19)+1) | R7: =MAX(17+1,(1+'Assumptions'!$B$19)+1) | S7: =MAX(18+1,(1+'Assumptions'!$B$19)+1) | T7: =MAX(19+1,(1+'Assumptions'!$B$19)+1) | U7: =MAX(20+1,(1+'Assumptions'!$B$19)+1) | V7: =MAX(21+1,(1+'Assumptions'!$B$19)+1) | W7: =MAX(22+1,(1+'Assumptions'!$B$19)+1) | X7: =MAX(23+1,(1+'Assumptions'!$B$19)+1) | Y7: =MAX(24+1,(1+'Assumptions'!$B$19)+1)
A8: Collections - owned license | B8: =SUMPRODUCT(($B$7:$Y$7=1)*$B$6:$Y$6) | C8: =SUMPRODUCT(($B$7:$Y$7=2)*$B$6:$Y$6) | D8: =SUMPRODUCT(($B$7:$Y$7=3)*$B$6:$Y$6) | E8: =SUMPRODUCT(($B$7:$Y$7=4)*$B$6:$Y$6) | F8: =SUMPRODUCT(($B$7:$Y$7=5)*$B$6:$Y$6) | G8: =SUMPRODUCT(($B$7:$Y$7=6)*$B$6:$Y$6) | H8: =SUMPRODUCT(($B$7:$Y$7=7)*$B$6:$Y$6) | I8: =SUMPRODUCT(($B$7:$Y$7=8)*$B$6:$Y$6) | J8: =SUMPRODUCT(($B$7:$Y$7=9)*$B$6:$Y$6) | K8: =SUMPRODUCT(($B$7:$Y$7=10)*$B$6:$Y$6) | L8: =SUMPRODUCT(($B$7:$Y$7=11)*$B$6:$Y$6) | M8: =SUMPRODUCT(($B$7:$Y$7=12)*$B$6:$Y$6) | N8: =SUMPRODUCT(($B$7:$Y$7=13)*$B$6:$Y$6) | O8: =SUMPRODUCT(($B$7:$Y$7=14)*$B$6:$Y$6) | P8: =SUMPRODUCT(($B$7:$Y$7=15)*$B$6:$Y$6) | Q8: =SUMPRODUCT(($B$7:$Y$7=16)*$B$6:$Y$6) | R8: =SUMPRODUCT(($B$7:$Y$7=17)*$B$6:$Y$6) | S8: =SUMPRODUCT(($B$7:$Y$7=18)*$B$6:$Y$6) | T8: =SUMPRODUCT(($B$7:$Y$7=19)*$B$6:$Y$6) | U8: =SUMPRODUCT(($B$7:$Y$7=20)*$B$6:$Y$6) | V8: =SUMPRODUCT(($B$7:$Y$7=21)*$B$6:$Y$6) | W8: =SUMPRODUCT(($B$7:$Y$7=22)*$B$6:$Y$6) | X8: =SUMPRODUCT(($B$7:$Y$7=23)*$B$6:$Y$6) | Y8: =SUMPRODUCT(($B$7:$Y$7=24)*$B$6:$Y$6)
A9: Collections - Jason census (+1 lag, no hold) | B9: =0 | C9: =B5*'Assumptions'!$B$4*'Assumptions'!$B$5*'Assumptions'!$B$8 | D9: =C5*'Assumptions'!$B$4*'Assumptions'!$B$5*'Assumptions'!$B$8 | E9: =D5*'Assumptions'!$B$4*'Assumptions'!$B$5*'Assumptions'!$B$8 | F9: =E5*'Assumptions'!$B$4*'Assumptions'!$B$5*'Assumptions'!$B$8 | G9: =F5*'Assumptions'!$B$4*'Assumptions'!$B$5*'Assumptions'!$B$8 | H9: =G5*'Assumptions'!$B$4*'Assumptions'!$B$5*'Assumptions'!$B$8 | I9: =H5*'Assumptions'!$B$4*'Assumptions'!$B$5*'Assumptions'!$B$8 | J9: =I5*'Assumptions'!$B$4*'Assumptions'!$B$5*'Assumptions'!$B$8 | ... Y9: =X5*'Assumptions'!$B$4*'Assumptions'!$B$5*'Assumptions'!$B$8
A10: Variable costs (whole book) | B10: =-((B4+B5)*'Assumptions'!$B$6*'Assumptions'!$B$5) | C10: =-((C4+C5)*'Assumptions'!$B$6*'Assumptions'!$B$5) | D10: =-((D4+D5)*'Assumptions'!$B$6*'Assumptions'!$B$5) | E10: =-((E4+E5)*'Assumptions'!$B$6*'Assumptions'!$B$5) | F10: =-((F4+F5)*'Assumptions'!$B$6*'Assumptions'!$B$5) | G10: =-((G4+G5)*'Assumptions'!$B$6*'Assumptions'!$B$5) | H10: =-((H4+H5)*'Assumptions'!$B$6*'Assumptions'!$B$5) | I10: =-((I4+I5)*'Assumptions'!$B$6*'Assumptions'!$B$5) | ... Y10: =-((Y4+Y5)*'Assumptions'!$B$6*'Assumptions'!$B$5)
A11: Fixed overhead + seed carry | B11: =-('Assumptions'!$B$7+IF(AND(1>=1,1<=(1+'Assumptions'!$B$19)),'Assumptions'!$B$39,0)) | C11: =-('Assumptions'!$B$7+IF(AND(2>=1,2<=(1+'Assumptions'!$B$19)),'Assumptions'!$B$39,0)) | D11: =-('Assumptions'!$B$7+IF(AND(3>=1,3<=(1+'Assumptions'!$B$19)),'Assumptions'!$B$39,0)) | E11: =-('Assumptions'!$B$7+IF(AND(4>=1,4<=(1+'Assumptions'!$B$19)),'Assumptions'!$B$39,0)) | F11: =-('Assumptions'!$B$7+IF(AND(5>=1,5<=(1+'Assumptions'!$B$19)),'Assumptions'!$B$39,0)) | G11: =-('Assumptions'!$B$7+IF(AND(6>=1,6<=(1+'Assumptions'!$B$19)),'Assumptions'!$B$39,0)) | H11: =-('Assumptions'!$B$7+IF(AND(7>=1,7<=(1+'Assumptions'!$B$19)),'Assumptions'!$B$39,0)) | I11: =-('Assumptions'!$B$7+IF(AND(8>=1,8<=(1+'Assumptions'!$B$19)),'Assumptions'!$B$39,0)) | J11: =-('Assumptions'!$B$7+IF(AND(9>=1,9<=(1+'Assumptions'!$B$19)),'Assumptions'!$B$39,0)) | K11: =-('Assumptions'!$B$7+IF(AND(10>=1,10<=(1+'Assumptions'!$B$19)),'Assumptions'!$B$39,0)) | L11: =-('Assumptions'!$B$7+IF(AND(11>=1,11<=(1+'Assumptions'!$B$19)),'Assumptions'!$B$39,0)) | M11: =-('Assumptions'!$B$7+IF(AND(12>=1,12<=(1+'Assumptions'!$B$19)),'Assumptions'!$B$39,0)) | N11: =-('Assumptions'!$B$7+IF(AND(13>=1,13<=(1+'Assumptions'!$B$19)),'Assumptions'!$B$39,0)) | O11: =-('Assumptions'!$B$7+IF(AND(14>=1,14<=(1+'Assumptions'!$B$19)),'Assumptions'!$B$39,0)) | P11: =-('Assumptions'!$B$7+IF(AND(15>=1,15<=(1+'Assumptions'!$B$19)),'Assumptions'!$B$39,0)) | Q11: =-('Assumptions'!$B$7+IF(AND(16>=1,16<=(1+'Assumptions'!$B$19)),'Assumptions'!$B$39,0)) | R11: =-('Assumptions'!$B$7+IF(AND(17>=1,17<=(1+'Assumptions'!$B$19)),'Assumptions'!$B$39,0)) | S11: =-('Assumptions'!$B$7+IF(AND(18>=1,18<=(1+'Assumptions'!$B$19)),'Assumptions'!$B$39,0)) | T11: =-('Assumptions'!$B$7+IF(AND(19>=1,19<=(1+'Assumptions'!$B$19)),'Assumptions'!$B$39,0)) | U11: =-('Assumptions'!$B$7+IF(AND(20>=1,20<=(1+'Assumptions'!$B$19)),'Assumptions'!$B$39,0)) | V11: =-('Assumptions'!$B$7+IF(AND(21>=1,21<=(1+'Assumptions'!$B$19)),'Assumptions'!$B$39,0)) | W11: =-('Assumptions'!$B$7+IF(AND(22>=1,22<=(1+'Assumptions'!$B$19)),'Assumptions'!$B$39,0)) | X11: =-('Assumptions'!$B$7+IF(AND(23>=1,23<=(1+'Assumptions'!$B$19)),'Assumptions'!$B$39,0)) | Y11: =-('Assumptions'!$B$7+IF(AND(24>=1,24<=(1+'Assumptions'!$B$19)),'Assumptions'!$B$39,0))
A12: Jason fee (while Jason census active) | B12: =-IF(B5>0,'Assumptions'!$B$16,0) | C12: =-IF(C5>0,'Assumptions'!$B$16,0) | D12: =-IF(D5>0,'Assumptions'!$B$16,0) | E12: =-IF(E5>0,'Assumptions'!$B$16,0) | F12: =-IF(F5>0,'Assumptions'!$B$16,0) | G12: =-IF(G5>0,'Assumptions'!$B$16,0) | H12: =-IF(H5>0,'Assumptions'!$B$16,0) | I12: =-IF(I5>0,'Assumptions'!$B$16,0) | ... Y12: =-IF(Y5>0,'Assumptions'!$B$16,0)
A13: Owned-license payments | B13: =-IF(1=1,'Assumptions'!$B$20,0)+IF(1=2,'Assumptions'!$B$22-'Assumptions'!$B$23,0)-IF(AND(1>=3,1<=5),'Assumptions'!$B$24,0)+IF(1=6,'Assumptions'!$B$25-'Assumptions'!$B$26,0)-IF(1>=7,'Assumptions'!$B$27,0) | C13: =-IF(2=1,'Assumptions'!$B$20,0)+IF(2=2,'Assumptions'!$B$22-'Assumptions'!$B$23,0)-IF(AND(2>=3,2<=5),'Assumptions'!$B$24,0)+IF(2=6,'Assumptions'!$B$25-'Assumptions'!$B$26,0)-IF(2>=7,'Assumptions'!$B$27,0) | D13: =-IF(3=1,'Assumptions'!$B$20,0)+IF(3=2,'Assumptions'!$B$22-'Assumptions'!$B$23,0)-IF(AND(3>=3,3<=5),'Assumptions'!$B$24,0)+IF(3=6,'Assumptions'!$B$25-'Assumptions'!$B$26,0)-IF(3>=7,'Assumptions'!$B$27,0) | E13: =-IF(4=1,'Assumptions'!$B$20,0)+IF(4=2,'Assumptions'!$B$22-'Assumptions'!$B$23,0)-IF(AND(4>=3,4<=5),'Assumptions'!$B$24,0)+IF(4=6,'Assumptions'!$B$25-'Assumptions'!$B$26,0)-IF(4>=7,'Assumptions'!$B$27,0) | F13: =-IF(5=1,'Assumptions'!$B$20,0)+IF(5=2,'Assumptions'!$B$22-'Assumptions'!$B$23,0)-IF(AND(5>=3,5<=5),'Assumptions'!$B$24,0)+IF(5=6,'Assumptions'!$B$25-'Assumptions'!$B$26,0)-IF(5>=7,'Assumptions'!$B$27,0) | G13: =-IF(6=1,'Assumptions'!$B$20,0)+IF(6=2,'Assumptions'!$B$22-'Assumptions'!$B$23,0)-IF(AND(6>=3,6<=5),'Assumptions'!$B$24,0)+IF(6=6,'Assumptions'!$B$25-'Assumptions'!$B$26,0)-IF(6>=7,'Assumptions'!$B$27,0) | H13: =-IF(7=1,'Assumptions'!$B$20,0)+IF(7=2,'Assumptions'!$B$22-'Assumptions'!$B$23,0)-IF(AND(7>=3,7<=5),'Assumptions'!$B$24,0)+IF(7=6,'Assumptions'!$B$25-'Assumptions'!$B$26,0)-IF(7>=7,'Assumptions'!$B$27,0) | I13: =-IF(8=1,'Assumptions'!$B$20,0)+IF(8=2,'Assumptions'!$B$22-'Assumptions'!$B$23,0)-IF(AND(8>=3,8<=5),'Assumptions'!$B$24,0)+IF(8=6,'Assumptions'!$B$25-'Assumptions'!$B$26,0)-IF(8>=7,'Assumptions'!$B$27,0) | J13: =-IF(9=1,'Assumptions'!$B$20,0)+IF(9=2,'Assumptions'!$B$22-'Assumptions'!$B$23,0)-IF(AND(9>=3,9<=5),'Assumptions'!$B$24,0)+IF(9=6,'Assumptions'!$B$25-'Assumptions'!$B$26,0)-IF(9>=7,'Assumptions'!$B$27,0) | K13: =-IF(10=1,'Assumptions'!$B$20,0)+IF(10=2,'Assumptions'!$B$22-'Assumptions'!$B$23,0)-IF(AND(10>=3,10<=5),'Assumptions'!$B$24,0)+IF(10=6,'Assumptions'!$B$25-'Assumptions'!$B$26,0)-IF(10>=7,'Assumptions'!$B$27,0) | L13: =-IF(11=1,'Assumptions'!$B$20,0)+IF(11=2,'Assumptions'!$B$22-'Assumptions'!$B$23,0)-IF(AND(11>=3,11<=5),'Assumptions'!$B$24,0)+IF(11=6,'Assumptions'!$B$25-'Assumptions'!$B$26,0)-IF(11>=7,'Assumptions'!$B$27,0) | M13: =-IF(12=1,'Assumptions'!$B$20,0)+IF(12=2,'Assumptions'!$B$22-'Assumptions'!$B$23,0)-IF(AND(12>=3,12<=5),'Assumptions'!$B$24,0)+IF(12=6,'Assumptions'!$B$25-'Assumptions'!$B$26,0)-IF(12>=7,'Assumptions'!$B$27,0) | N13: =-IF(13=1,'Assumptions'!$B$20,0)+IF(13=2,'Assumptions'!$B$22-'Assumptions'!$B$23,0)-IF(AND(13>=3,13<=5),'Assumptions'!$B$24,0)+IF(13=6,'Assumptions'!$B$25-'Assumptions'!$B$26,0)-IF(13>=7,'Assumptions'!$B$27,0) | O13: =-IF(14=1,'Assumptions'!$B$20,0)+IF(14=2,'Assumptions'!$B$22-'Assumptions'!$B$23,0)-IF(AND(14>=3,14<=5),'Assumptions'!$B$24,0)+IF(14=6,'Assumptions'!$B$25-'Assumptions'!$B$26,0)-IF(14>=7,'Assumptions'!$B$27,0) | P13: =-IF(15=1,'Assumptions'!$B$20,0)+IF(15=2,'Assumptions'!$B$22-'Assumptions'!$B$23,0)-IF(AND(15>=3,15<=5),'Assumptions'!$B$24,0)+IF(15=6,'Assumptions'!$B$25-'Assumptions'!$B$26,0)-IF(15>=7,'Assumptions'!$B$27,0) | Q13: =-IF(16=1,'Assumptions'!$B$20,0)+IF(16=2,'Assumptions'!$B$22-'Assumptions'!$B$23,0)-IF(AND(16>=3,16<=5),'Assumptions'!$B$24,0)+IF(16=6,'Assumptions'!$B$25-'Assumptions'!$B$26,0)-IF(16>=7,'Assumptions'!$B$27,0) | R13: =-IF(17=1,'Assumptions'!$B$20,0)+IF(17=2,'Assumptions'!$B$22-'Assumptions'!$B$23,0)-IF(AND(17>=3,17<=5),'Assumptions'!$B$24,0)+IF(17=6,'Assumptions'!$B$25-'Assumptions'!$B$26,0)-IF(17>=7,'Assumptions'!$B$27,0) | S13: =-IF(18=1,'Assumptions'!$B$20,0)+IF(18=2,'Assumptions'!$B$22-'Assumptions'!$B$23,0)-IF(AND(18>=3,18<=5),'Assumptions'!$B$24,0)+IF(18=6,'Assumptions'!$B$25-'Assumptions'!$B$26,0)-IF(18>=7,'Assumptions'!$B$27,0) | T13: =-IF(19=1,'Assumptions'!$B$20,0)+IF(19=2,'Assumptions'!$B$22-'Assumptions'!$B$23,0)-IF(AND(19>=3,19<=5),'Assumptions'!$B$24,0)+IF(19=6,'Assumptions'!$B$25-'Assumptions'!$B$26,0)-IF(19>=7,'Assumptions'!$B$27,0) | U13: =-IF(20=1,'Assumptions'!$B$20,0)+IF(20=2,'Assumptions'!$B$22-'Assumptions'!$B$23,0)-IF(AND(20>=3,20<=5),'Assumptions'!$B$24,0)+IF(20=6,'Assumptions'!$B$25-'Assumptions'!$B$26,0)-IF(20>=7,'Assumptions'!$B$27,0) | V13: =-IF(21=1,'Assumptions'!$B$20,0)+IF(21=2,'Assumptions'!$B$22-'Assumptions'!$B$23,0)-IF(AND(21>=3,21<=5),'Assumptions'!$B$24,0)+IF(21=6,'Assumptions'!$B$25-'Assumptions'!$B$26,0)-IF(21>=7,'Assumptions'!$B$27,0) | W13: =-IF(22=1,'Assumptions'!$B$20,0)+IF(22=2,'Assumptions'!$B$22-'Assumptions'!$B$23,0)-IF(AND(22>=3,22<=5),'Assumptions'!$B$24,0)+IF(22=6,'Assumptions'!$B$25-'Assumptions'!$B$26,0)-IF(22>=7,'Assumptions'!$B$27,0) | X13: =-IF(23=1,'Assumptions'!$B$20,0)+IF(23=2,'Assumptions'!$B$22-'Assumptions'!$B$23,0)-IF(AND(23>=3,23<=5),'Assumptions'!$B$24,0)+IF(23=6,'Assumptions'!$B$25-'Assumptions'!$B$26,0)-IF(23>=7,'Assumptions'!$B$27,0) | Y13: =-IF(24=1,'Assumptions'!$B$20,0)+IF(24=2,'Assumptions'!$B$22-'Assumptions'!$B$23,0)-IF(AND(24>=3,24<=5),'Assumptions'!$B$24,0)+IF(24=6,'Assumptions'!$B$25-'Assumptions'!$B$26,0)-IF(24>=7,'Assumptions'!$B$27,0)
A14: NET CASH FLOW | B14: =B8+B9+B10+B11+B12+B13 | C14: =C8+C9+C10+C11+C12+C13 | D14: =D8+D9+D10+D11+D12+D13 | E14: =E8+E9+E10+E11+E12+E13 | F14: =F8+F9+F10+F11+F12+F13 | G14: =G8+G9+G10+G11+G12+G13 | H14: =H8+H9+H10+H11+H12+H13 | I14: =I8+I9+I10+I11+I12+I13 | ... Y14: =Y8+Y9+Y10+Y11+Y12+Y13
A15: Cumulative cash (no equity assumed) | B15: =B14 | C15: =B15+C14 | D15: =C15+D14 | E15: =D15+E14 | F15: =E15+F14 | G15: =F15+G14 | H15: =G15+H14 | I15: =H15+I14 | J15: =I15+J14 | ... Y15: =X15+Y14
A16: PEAK FUNDING NEED (max cumulative deficit) | B16: =MAX(0,-MIN($B$15:$Y$15))

Sheet T4b Avant+Jason
A1: T4b Avant+Jason - COMBO: 5-patient PPEO seed on the owned license, growth census on Jason's number; admissions shift to the owned license at PPEO clear; Jason fee ends after shift.
B3: Aug-26 | C3: Sep-26 | D3: Oct-26 | E3: Nov-26 | F3: Dec-26 | G3: Jan-27 | H3: Feb-27 | I3: Mar-27 | J3: Apr-27 | K3: May-27 | L3: Jun-27 | M3: Jul-27 | N3: Aug-27 | O3: Sep-27 | P3: Oct-27 | Q3: Nov-27 | R3: Dec-27 | S3: Jan-28 | T3: Feb-28 | U3: Mar-28 | V3: Apr-28 | W3: May-28 | X3: Jun-28 | Y3: Jul-28
A4: Owned-license ADC (seed until clear, then full book) | B4: =IF(1<'Assumptions'!$B$30,0,IF(1<=('Assumptions'!$B$30+'Assumptions'!$B$31),'Assumptions'!$B$38,Assumptions!B13)) | C4: =IF(2<'Assumptions'!$B$30,0,IF(2<=('Assumptions'!$B$30+'Assumptions'!$B$31),'Assumptions'!$B$38,Assumptions!C13)) | D4: =IF(3<'Assumptions'!$B$30,0,IF(3<=('Assumptions'!$B$30+'Assumptions'!$B$31),'Assumptions'!$B$38,Assumptions!D13)) | E4: =IF(4<'Assumptions'!$B$30,0,IF(4<=('Assumptions'!$B$30+'Assumptions'!$B$31),'Assumptions'!$B$38,Assumptions!E13)) | F4: =IF(5<'Assumptions'!$B$30,0,IF(5<=('Assumptions'!$B$30+'Assumptions'!$B$31),'Assumptions'!$B$38,Assumptions!F13)) | G4: =IF(6<'Assumptions'!$B$30,0,IF(6<=('Assumptions'!$B$30+'Assumptions'!$B$31),'Assumptions'!$B$38,Assumptions!G13)) | H4: =IF(7<'Assumptions'!$B$30,0,IF(7<=('Assumptions'!$B$30+'Assumptions'!$B$31),'Assumptions'!$B$38,Assumptions!H13)) | I4: =IF(8<'Assumptions'!$B$30,0,IF(8<=('Assumptions'!$B$30+'Assumptions'!$B$31),'Assumptions'!$B$38,Assumptions!I13)) | J4: =IF(9<'Assumptions'!$B$30,0,IF(9<=('Assumptions'!$B$30+'Assumptions'!$B$31),'Assumptions'!$B$38,Assumptions!J13)) | K4: =IF(10<'Assumptions'!$B$30,0,IF(10<=('Assumptions'!$B$30+'Assumptions'!$B$31),'Assumptions'!$B$38,Assumptions!K13)) | L4: =IF(11<'Assumptions'!$B$30,0,IF(11<=('Assumptions'!$B$30+'Assumptions'!$B$31),'Assumptions'!$B$38,Assumptions!L13)) | M4: =IF(12<'Assumptions'!$B$30,0,IF(12<=('Assumptions'!$B$30+'Assumptions'!$B$31),'Assumptions'!$B$38,Assumptions!M13)) | N4: =IF(13<'Assumptions'!$B$30,0,IF(13<=('Assumptions'!$B$30+'Assumptions'!$B$31),'Assumptions'!$B$38,Assumptions!N13)) | O4: =IF(14<'Assumptions'!$B$30,0,IF(14<=('Assumptions'!$B$30+'Assumptions'!$B$31),'Assumptions'!$B$38,Assumptions!O13)) | P4: =IF(15<'Assumptions'!$B$30,0,IF(15<=('Assumptions'!$B$30+'Assumptions'!$B$31),'Assumptions'!$B$38,Assumptions!P13)) | Q4: =IF(16<'Assumptions'!$B$30,0,IF(16<=('Assumptions'!$B$30+'Assumptions'!$B$31),'Assumptions'!$B$38,Assumptions!Q13)) | R4: =IF(17<'Assumptions'!$B$30,0,IF(17<=('Assumptions'!$B$30+'Assumptions'!$B$31),'Assumptions'!$B$38,Assumptions!R13)) | S4: =IF(18<'Assumptions'!$B$30,0,IF(18<=('Assumptions'!$B$30+'Assumptions'!$B$31),'Assumptions'!$B$38,Assumptions!S13)) | T4: =IF(19<'Assumptions'!$B$30,0,IF(19<=('Assumptions'!$B$30+'Assumptions'!$B$31),'Assumptions'!$B$38,Assumptions!T13)) | U4: =IF(20<'Assumptions'!$B$30,0,IF(20<=('Assumptions'!$B$30+'Assumptions'!$B$31),'Assumptions'!$B$38,Assumptions!U13)) | V4: =IF(21<'Assumptions'!$B$30,0,IF(21<=('Assumptions'!$B$30+'Assumptions'!$B$31),'Assumptions'!$B$38,Assumptions!V13)) | W4: =IF(22<'Assumptions'!$B$30,0,IF(22<=('Assumptions'!$B$30+'Assumptions'!$B$31),'Assumptions'!$B$38,Assumptions!W13)) | X4: =IF(23<'Assumptions'!$B$30,0,IF(23<=('Assumptions'!$B$30+'Assumptions'!$B$31),'Assumptions'!$B$38,Assumptions!X13)) | Y4: =IF(24<'Assumptions'!$B$30,0,IF(24<=('Assumptions'!$B$30+'Assumptions'!$B$31),'Assumptions'!$B$38,Assumptions!Y13))
A5: Jason ADC (total book minus owned) | B5: =MAX(0,Assumptions!B13-B4) | C5: =MAX(0,Assumptions!C13-C4) | D5: =MAX(0,Assumptions!D13-D4) | E5: =MAX(0,Assumptions!E13-E4) | F5: =MAX(0,Assumptions!F13-F4) | G5: =MAX(0,Assumptions!G13-G4) | H5: =MAX(0,Assumptions!H13-H4) | I5: =MAX(0,Assumptions!I13-I4) | ... Y5: =MAX(0,Assumptions!Y13-Y4)
A6: Revenue earned - owned license | B6: =B4*'Assumptions'!$B$4*'Assumptions'!$B$5 | C6: =C4*'Assumptions'!$B$4*'Assumptions'!$B$5 | D6: =D4*'Assumptions'!$B$4*'Assumptions'!$B$5 | E6: =E4*'Assumptions'!$B$4*'Assumptions'!$B$5 | F6: =F4*'Assumptions'!$B$4*'Assumptions'!$B$5 | G6: =G4*'Assumptions'!$B$4*'Assumptions'!$B$5 | H6: =H4*'Assumptions'!$B$4*'Assumptions'!$B$5 | I6: =I4*'Assumptions'!$B$4*'Assumptions'!$B$5 | ... Y6: =Y4*'Assumptions'!$B$4*'Assumptions'!$B$5
A7: Collection month - owned (lag + hold from start) | B7: =MAX(1+1,('Assumptions'!$B$30+'Assumptions'!$B$31)+1) | C7: =MAX(2+1,('Assumptions'!$B$30+'Assumptions'!$B$31)+1) | D7: =MAX(3+1,('Assumptions'!$B$30+'Assumptions'!$B$31)+1) | E7: =MAX(4+1,('Assumptions'!$B$30+'Assumptions'!$B$31)+1) | F7: =MAX(5+1,('Assumptions'!$B$30+'Assumptions'!$B$31)+1) | G7: =MAX(6+1,('Assumptions'!$B$30+'Assumptions'!$B$31)+1) | H7: =MAX(7+1,('Assumptions'!$B$30+'Assumptions'!$B$31)+1) | I7: =MAX(8+1,('Assumptions'!$B$30+'Assumptions'!$B$31)+1) | J7: =MAX(9+1,('Assumptions'!$B$30+'Assumptions'!$B$31)+1) | K7: =MAX(10+1,('Assumptions'!$B$30+'Assumptions'!$B$31)+1) | L7: =MAX(11+1,('Assumptions'!$B$30+'Assumptions'!$B$31)+1) | M7: =MAX(12+1,('Assumptions'!$B$30+'Assumptions'!$B$31)+1) | N7: =MAX(13+1,('Assumptions'!$B$30+'Assumptions'!$B$31)+1) | O7: =MAX(14+1,('Assumptions'!$B$30+'Assumptions'!$B$31)+1) | P7: =MAX(15+1,('Assumptions'!$B$30+'Assumptions'!$B$31)+1) | Q7: =MAX(16+1,('Assumptions'!$B$30+'Assumptions'!$B$31)+1) | R7: =MAX(17+1,('Assumptions'!$B$30+'Assumptions'!$B$31)+1) | S7: =MAX(18+1,('Assumptions'!$B$30+'Assumptions'!$B$31)+1) | T7: =MAX(19+1,('Assumptions'!$B$30+'Assumptions'!$B$31)+1) | U7: =MAX(20+1,('Assumptions'!$B$30+'Assumptions'!$B$31)+1) | V7: =MAX(21+1,('Assumptions'!$B$30+'Assumptions'!$B$31)+1) | W7: =MAX(22+1,('Assumptions'!$B$30+'Assumptions'!$B$31)+1) | X7: =MAX(23+1,('Assumptions'!$B$30+'Assumptions'!$B$31)+1) | Y7: =MAX(24+1,('Assumptions'!$B$30+'Assumptions'!$B$31)+1)
A8: Collections - owned license | B8: =SUMPRODUCT(($B$7:$Y$7=1)*$B$6:$Y$6) | C8: =SUMPRODUCT(($B$7:$Y$7=2)*$B$6:$Y$6) | D8: =SUMPRODUCT(($B$7:$Y$7=3)*$B$6:$Y$6) | E8: =SUMPRODUCT(($B$7:$Y$7=4)*$B$6:$Y$6) | F8: =SUMPRODUCT(($B$7:$Y$7=5)*$B$6:$Y$6) | G8: =SUMPRODUCT(($B$7:$Y$7=6)*$B$6:$Y$6) | H8: =SUMPRODUCT(($B$7:$Y$7=7)*$B$6:$Y$6) | I8: =SUMPRODUCT(($B$7:$Y$7=8)*$B$6:$Y$6) | J8: =SUMPRODUCT(($B$7:$Y$7=9)*$B$6:$Y$6) | K8: =SUMPRODUCT(($B$7:$Y$7=10)*$B$6:$Y$6) | L8: =SUMPRODUCT(($B$7:$Y$7=11)*$B$6:$Y$6) | M8: =SUMPRODUCT(($B$7:$Y$7=12)*$B$6:$Y$6) | N8: =SUMPRODUCT(($B$7:$Y$7=13)*$B$6:$Y$6) | O8: =SUMPRODUCT(($B$7:$Y$7=14)*$B$6:$Y$6) | P8: =SUMPRODUCT(($B$7:$Y$7=15)*$B$6:$Y$6) | Q8: =SUMPRODUCT(($B$7:$Y$7=16)*$B$6:$Y$6) | R8: =SUMPRODUCT(($B$7:$Y$7=17)*$B$6:$Y$6) | S8: =SUMPRODUCT(($B$7:$Y$7=18)*$B$6:$Y$6) | T8: =SUMPRODUCT(($B$7:$Y$7=19)*$B$6:$Y$6) | U8: =SUMPRODUCT(($B$7:$Y$7=20)*$B$6:$Y$6) | V8: =SUMPRODUCT(($B$7:$Y$7=21)*$B$6:$Y$6) | W8: =SUMPRODUCT(($B$7:$Y$7=22)*$B$6:$Y$6) | X8: =SUMPRODUCT(($B$7:$Y$7=23)*$B$6:$Y$6) | Y8: =SUMPRODUCT(($B$7:$Y$7=24)*$B$6:$Y$6)
A9: Collections - Jason census (+1 lag, no hold) | B9: =0 | C9: =B5*'Assumptions'!$B$4*'Assumptions'!$B$5*'Assumptions'!$B$8 | D9: =C5*'Assumptions'!$B$4*'Assumptions'!$B$5*'Assumptions'!$B$8 | E9: =D5*'Assumptions'!$B$4*'Assumptions'!$B$5*'Assumptions'!$B$8 | F9: =E5*'Assumptions'!$B$4*'Assumptions'!$B$5*'Assumptions'!$B$8 | G9: =F5*'Assumptions'!$B$4*'Assumptions'!$B$5*'Assumptions'!$B$8 | H9: =G5*'Assumptions'!$B$4*'Assumptions'!$B$5*'Assumptions'!$B$8 | I9: =H5*'Assumptions'!$B$4*'Assumptions'!$B$5*'Assumptions'!$B$8 | J9: =I5*'Assumptions'!$B$4*'Assumptions'!$B$5*'Assumptions'!$B$8 | ... Y9: =X5*'Assumptions'!$B$4*'Assumptions'!$B$5*'Assumptions'!$B$8
A10: Variable costs (whole book) | B10: =-((B4+B5)*'Assumptions'!$B$6*'Assumptions'!$B$5) | C10: =-((C4+C5)*'Assumptions'!$B$6*'Assumptions'!$B$5) | D10: =-((D4+D5)*'Assumptions'!$B$6*'Assumptions'!$B$5) | E10: =-((E4+E5)*'Assumptions'!$B$6*'Assumptions'!$B$5) | F10: =-((F4+F5)*'Assumptions'!$B$6*'Assumptions'!$B$5) | G10: =-((G4+G5)*'Assumptions'!$B$6*'Assumptions'!$B$5) | H10: =-((H4+H5)*'Assumptions'!$B$6*'Assumptions'!$B$5) | I10: =-((I4+I5)*'Assumptions'!$B$6*'Assumptions'!$B$5) | ... Y10: =-((Y4+Y5)*'Assumptions'!$B$6*'Assumptions'!$B$5)
A11: Fixed overhead + seed carry | B11: =-('Assumptions'!$B$7+IF(AND(1>='Assumptions'!$B$30,1<=('Assumptions'!$B$30+'Assumptions'!$B$31)),'Assumptions'!$B$39,0)) | C11: =-('Assumptions'!$B$7+IF(AND(2>='Assumptions'!$B$30,2<=('Assumptions'!$B$30+'Assumptions'!$B$31)),'Assumptions'!$B$39,0)) | D11: =-('Assumptions'!$B$7+IF(AND(3>='Assumptions'!$B$30,3<=('Assumptions'!$B$30+'Assumptions'!$B$31)),'Assumptions'!$B$39,0)) | E11: =-('Assumptions'!$B$7+IF(AND(4>='Assumptions'!$B$30,4<=('Assumptions'!$B$30+'Assumptions'!$B$31)),'Assumptions'!$B$39,0)) | F11: =-('Assumptions'!$B$7+IF(AND(5>='Assumptions'!$B$30,5<=('Assumptions'!$B$30+'Assumptions'!$B$31)),'Assumptions'!$B$39,0)) | G11: =-('Assumptions'!$B$7+IF(AND(6>='Assumptions'!$B$30,6<=('Assumptions'!$B$30+'Assumptions'!$B$31)),'Assumptions'!$B$39,0)) | H11: =-('Assumptions'!$B$7+IF(AND(7>='Assumptions'!$B$30,7<=('Assumptions'!$B$30+'Assumptions'!$B$31)),'Assumptions'!$B$39,0)) | I11: =-('Assumptions'!$B$7+IF(AND(8>='Assumptions'!$B$30,8<=('Assumptions'!$B$30+'Assumptions'!$B$31)),'Assumptions'!$B$39,0)) | J11: =-('Assumptions'!$B$7+IF(AND(9>='Assumptions'!$B$30,9<=('Assumptions'!$B$30+'Assumptions'!$B$31)),'Assumptions'!$B$39,0)) | K11: =-('Assumptions'!$B$7+IF(AND(10>='Assumptions'!$B$30,10<=('Assumptions'!$B$30+'Assumptions'!$B$31)),'Assumptions'!$B$39,0)) | L11: =-('Assumptions'!$B$7+IF(AND(11>='Assumptions'!$B$30,11<=('Assumptions'!$B$30+'Assumptions'!$B$31)),'Assumptions'!$B$39,0)) | M11: =-('Assumptions'!$B$7+IF(AND(12>='Assumptions'!$B$30,12<=('Assumptions'!$B$30+'Assumptions'!$B$31)),'Assumptions'!$B$39,0)) | N11: =-('Assumptions'!$B$7+IF(AND(13>='Assumptions'!$B$30,13<=('Assumptions'!$B$30+'Assumptions'!$B$31)),'Assumptions'!$B$39,0)) | O11: =-('Assumptions'!$B$7+IF(AND(14>='Assumptions'!$B$30,14<=('Assumptions'!$B$30+'Assumptions'!$B$31)),'Assumptions'!$B$39,0)) | P11: =-('Assumptions'!$B$7+IF(AND(15>='Assumptions'!$B$30,15<=('Assumptions'!$B$30+'Assumptions'!$B$31)),'Assumptions'!$B$39,0)) | Q11: =-('Assumptions'!$B$7+IF(AND(16>='Assumptions'!$B$30,16<=('Assumptions'!$B$30+'Assumptions'!$B$31)),'Assumptions'!$B$39,0)) | R11: =-('Assumptions'!$B$7+IF(AND(17>='Assumptions'!$B$30,17<=('Assumptions'!$B$30+'Assumptions'!$B$31)),'Assumptions'!$B$39,0)) | S11: =-('Assumptions'!$B$7+IF(AND(18>='Assumptions'!$B$30,18<=('Assumptions'!$B$30+'Assumptions'!$B$31)),'Assumptions'!$B$39,0)) | T11: =-('Assumptions'!$B$7+IF(AND(19>='Assumptions'!$B$30,19<=('Assumptions'!$B$30+'Assumptions'!$B$31)),'Assumptions'!$B$39,0)) | U11: =-('Assumptions'!$B$7+IF(AND(20>='Assumptions'!$B$30,20<=('Assumptions'!$B$30+'Assumptions'!$B$31)),'Assumptions'!$B$39,0)) | V11: =-('Assumptions'!$B$7+IF(AND(21>='Assumptions'!$B$30,21<=('Assumptions'!$B$30+'Assumptions'!$B$31)),'Assumptions'!$B$39,0)) | W11: =-('Assumptions'!$B$7+IF(AND(22>='Assumptions'!$B$30,22<=('Assumptions'!$B$30+'Assumptions'!$B$31)),'Assumptions'!$B$39,0)) | X11: =-('Assumptions'!$B$7+IF(AND(23>='Assumptions'!$B$30,23<=('Assumptions'!$B$30+'Assumptions'!$B$31)),'Assumptions'!$B$39,0)) | Y11: =-('Assumptions'!$B$7+IF(AND(24>='Assumptions'!$B$30,24<=('Assumptions'!$B$30+'Assumptions'!$B$31)),'Assumptions'!$B$39,0))
