Workbook

Sheet Control Tower
A1: AZALEA HOSPICE - REFUGE OPERATING MODEL
A2: CONTROL TOWER - every number in the model flows from this tab. Yellow = input; everything else is formulas.
A4: COMPANY & DEAL (current Refuge structure)
A5: Starting capital on deposit (equity) | B5: 250000 | D5: Jim Bullard $195K + owner $55K
A6: Pre-opening / startup spend from capital | B6: 0 | D6: 0 = funded elsewhere
A7: Refuge license purchase price (100% membership CHOW) | B7: 500000 | D7: Acct 1980 intangible
A8: Down payment at closing (Month 1) | B8: 125000
A9: Seller monthly payment | B9: 25000
A10: First seller payment month | B10: 3 | D10: 3 = September
A11: Last seller payment month | B11: 6 | D11: 6 = December
A12: Seller note simple interest (APR) | B12: 0.06
A13: Balloon month (36-month rule / January) | B13: 7
A14: Balloon refinance rate (APR) | B14: 0.09 | D14: funds the Jan balloon when full-refi toggle is OFF
A15: Balloon refinance term (months) | B15: 120
A16: FULL-REFI TOGGLE (1 = $500K/6%/36 note - BASE CASE) | B16: 1 | D16: base: sellers paid off Sept; company services $15,211/mo x36
A17: Full-refi funding month | B17: 3 | D17: 3 = September
A18: Full-refi amount | B18: 500000
A19: Full-refi rate (APR) | B19: 0.06
A20: Full-refi term (months) | B20: 36
A21: SBA TOGGLE (1 = SBA 7(a) funds) | B21: 0
A22: SBA funding month | B22: 3
A23: SBA amount | B23: 450000
A24: SBA rate (APR) | B24: 0.105
A25: SBA term (months) | B25: 180
A26: License intangible amortization (yrs, Acct 7200) | B26: 15
A27: CHOW / go-live month (amortization starts) | B27: 1
A28: CENSUS (admissions row lives on Census Waterfall - blue)
A29: Days per month (model uniform) | B29: 30.4
A30: Average length of stay (days) | B30: 82 | D30: drives discharges = BOM x days/ALOS
A31: Deaths as share of discharges | B31: 0.55
A32: SCENARIO CASES (1 = Base, 2 = Downside, 3 = Upside; active values are formulas)
A33: ACTIVE CASE | B33: 1 | D33: flip 1/2/3 - drives capture, payroll adj, CHOW hold
A34: Case matrix: | B34: Base | C34: Downside | D34: Upside
A35: Census capture | B35: 1 | C35: 0.85 | D35: 1.1
A36: Payroll adjustment | B36: 0 | C36: 0.1 | D36: 0
A37: CHOW hold (months) | B37: 1 | C37: 2 | D37: 0
A38: ACTIVE census capture (formula) | B38: =CHOOSE('Control Tower'!$B$33,'Control Tower'!$B$35,'Control Tower'!$C$35,'Control Tower'!$D$35)
A39: ACTIVE payroll adjustment (formula) | B39: =CHOOSE('Control Tower'!$B$33,'Control Tower'!$B$36,'Control Tower'!$C$36,'Control Tower'!$D$36)
A40: ACTIVE CHOW hold (formula) | B40: =CHOOSE('Control Tower'!$B$33,'Control Tower'!$B$37,'Control Tower'!$C$37,'Control Tower'!$D$37)
A41: REVENUE - CMS FY2026 SMITH COUNTY (Acct 3000/3010)
...

Sheet Census Waterfall
A1: AZALEA HOSPICE - REFUGE OPERATING MODEL
A2: CENSUS WATERFALL - admissions are the operating lever (blue). Discharges follow ALOS. 36 months.
A4: Month # | C4: 1 | D4: 2 | E4: 3 | F4: 4 | G4: 5 | H4: 6 | I4: 7 | J4: 8 | K4: 9 | L4: 10 | M4: 11 | N4: 12 | O4: 13 | P4: 14 | Q4: 15 | R4: 16 | S4: 17 | T4: 18 | U4: 19 | V4: 20 | W4: 21 | X4: 22 | Y4: 23 | Z4: 24 | AA4: 25 | AB4: 26 | AC4: 27 | AD4: 28 | AE4: 29 | AF4: 30 | AG4: 31 | AH4: 32 | AI4: 33 | AJ4: 34 | AK4: 35 | AL4: 36
C5: Jul-26 | D5: Aug-26 | E5: Sep-26 | F5: Oct-26 | G5: Nov-26 | H5: Dec-26 | I5: Jan-27 | J5: Feb-27 | K5: Mar-27 | L5: Apr-27 | M5: May-27 | N5: Jun-27 | O5: Jul-27 | P5: Aug-27 | Q5: Sep-27 | R5: Oct-27 | S5: Nov-27 | T5: Dec-27 | U5: Jan-28 | V5: Feb-28 | W5: Mar-28 | X5: Apr-28 | Y5: May-28 | Z5: Jun-28 | AA5: Jul-28 | AB5: Aug-28 | AC5: Sep-28 | AD5: Oct-28 | AE5: Nov-28 | AF5: Dec-28 | AG5: Jan-29 | AH5: Feb-29 | AI5: Mar-29 | AJ5: Apr-29 | AK5: May-29 | AL5: Jun-29
A6: Beginning-of-month census (BOM) | C6: =0 | D6: =C9 | E6: =D9 | F6: =E9 | G6: =F9 | H6: =G9 | I6: =H9 | J6: =I9 | K6: =J9 | ... AL6: =AK9
A7: + New admissions [INPUT - 7/6 plan default] | C7: 20 | D7: 11.41 | E7: 11.4 | F7: 12.32 | G7: 13.25 | H7: 14.18 | I7: 13.6 | J7: 13.98 | K7: 14.35 | L7: 14.72 | M7: 15.09 | N7: 15.46 | O7: 15.66 | P7: 15.98 | Q7: 16.28 | R7: 16.59 | S7: 16.9 | T7: 17.21 | U7: 17.51 | V7: 17.83 | W7: 18.13 | X7: 18.44 | Y7: 18.76 | Z7: 19.06 | AA7: 19.04 | AB7: 19.22 | AC7: 19.41 | AD7: 19.59 | AE7: 19.78 | AF7: 19.96 | AG7: 20.15 | AH7: 20.33 | AI7: 20.52 | AJ7: 20.7 | AK7: 20.89 | AL7: 21.08
A8: - Discharges (deaths + revocations) = BOM x days/ALOS | C8: =C6*'Control Tower'!$B$29/'Control Tower'!$B$30 | D8: =D6*'Control Tower'!$B$29/'Control Tower'!$B$30 | E8: =E6*'Control Tower'!$B$29/'Control Tower'!$B$30 | F8: =F6*'Control Tower'!$B$29/'Control Tower'!$B$30 | G8: =G6*'Control Tower'!$B$29/'Control Tower'!$B$30 | H8: =H6*'Control Tower'!$B$29/'Control Tower'!$B$30 | I8: =I6*'Control Tower'!$B$29/'Control Tower'!$B$30 | J8: =J6*'Control Tower'!$B$29/'Control Tower'!$B$30 | ... AL8: =AL6*'Control Tower'!$B$29/'Control Tower'!$B$30
A9: End-of-month census (EOM) | C9: =C6+C7-C8 | D9: =D6+D7-D8 | E9: =E6+E7-E8 | F9: =F6+F7-F8 | G9: =G6+G7-G8 | H9: =H6+H7-H8 | I9: =I6+I7-I8 | J9: =J6+J7-J8 | ... AL9: =AL6+AL7-AL8
A10: of which deaths (bereavement trigger) | C10: =C8*'Control Tower'!$B$31 | D10: =D8*'Control Tower'!$B$31 | E10: =E8*'Control Tower'!$B$31 | F10: =F8*'Control Tower'!$B$31 | G10: =G8*'Control Tower'!$B$31 | H10: =H8*'Control Tower'!$B$31 | I10: =I8*'Control Tower'!$B$31 | J10: =J8*'Control Tower'!$B$31 | ... AL10: =AL8*'Control Tower'!$B$31
A11: ADC = (BOM + EOM)/2 x capture | C11: =(C6+C9)/2*'Control Tower'!$B$38 | D11: =(D6+D9)/2*'Control Tower'!$B$38 | E11: =(E6+E9)/2*'Control Tower'!$B$38 | F11: =(F6+F9)/2*'Control Tower'!$B$38 | G11: =(G6+G9)/2*'Control Tower'!$B$38 | H11: =(H6+H9)/2*'Control Tower'!$B$38 | I11: =(I6+I9)/2*'Control Tower'!$B$38 | J11: =(J6+J9)/2*'Control Tower'!$B$38 | ... AL11: =(AL6+AL9)/2*'Control Tower'!$B$38
A12: Patient days (ADC x days/month) | C12: =C11*'Control Tower'!$B$29 | D12: =D11*'Control Tower'!$B$29 | E12: =E11*'Control Tower'!$B$29 | F12: =F11*'Control Tower'!$B$29 | G12: =G11*'Control Tower'!$B$29 | H12: =H11*'Control Tower'!$B$29 | I12: =I11*'Control Tower'!$B$29 | J12: =J11*'Control Tower'!$B$29 | ... AL12: =AL11*'Control Tower'!$B$29
A13: Monthly discharge rate (of BOM) | C13: =IF(C6=0,0,C8/C6) | D13: =IF(D6=0,0,D8/D6) | E13: =IF(E6=0,0,E8/E6) | F13: =IF(F6=0,0,F8/F6) | G13: =IF(G6=0,0,G8/G6) | H13: =IF(H6=0,0,H8/H6) | I13: =IF(I6=0,0,I8/I6) | J13: =IF(J6=0,0,J8/J6) | ... AL13: =IF(AL6=0,0,AL8/AL6)

Sheet Revenue Model
A1: AZALEA HOSPICE - REFUGE OPERATING MODEL
A2: REVENUE - patient days x CMS rates (high/low split), less billing fee -> NET PATIENT REVENUE (accrual).
A4: Month # | C4: 1 | D4: 2 | E4: 3 | F4: 4 | G4: 5 | H4: 6 | I4: 7 | J4: 8 | K4: 9 | L4: 10 | M4: 11 | N4: 12 | O4: 13 | P4: 14 | Q4: 15 | R4: 16 | S4: 17 | T4: 18 | U4: 19 | V4: 20 | W4: 21 | X4: 22 | Y4: 23 | Z4: 24 | AA4: 25 | AB4: 26 | AC4: 27 | AD4: 28 | AE4: 29 | AF4: 30 | AG4: 31 | AH4: 32 | AI4: 33 | AJ4: 34 | AK4: 35 | AL4: 36
C5: Jul-26 | D5: Aug-26 | E5: Sep-26 | F5: Oct-26 | G5: Nov-26 | H5: Dec-26 | I5: Jan-27 | J5: Feb-27 | K5: Mar-27 | L5: Apr-27 | M5: May-27 | N5: Jun-27 | O5: Jul-27 | P5: Aug-27 | Q5: Sep-27 | R5: Oct-27 | S5: Nov-27 | T5: Dec-27 | U5: Jan-28 | V5: Feb-28 | W5: Mar-28 | X5: Apr-28 | Y5: May-28 | Z5: Jun-28 | AA5: Jul-28 | AB5: Aug-28 | AC5: Sep-28 | AD5: Oct-28 | AE5: Nov-28 | AF5: Dec-28 | AG5: Jan-29 | AH5: Feb-29 | AI5: Mar-29 | AJ5: Apr-29 | AK5: May-29 | AL5: Jun-29
A6: Medicare RHC HIGH (days 1-60, 3000-R-6-0) | C6: ='Census Waterfall'!C12*'Control Tower'!$B$45*'Control Tower'!$B$46*'Control Tower'!$B$42*(1+'Control Tower'!$B$48)^0 | D6: ='Census Waterfall'!D12*'Control Tower'!$B$45*'Control Tower'!$B$46*'Control Tower'!$B$42*(1+'Control Tower'!$B$48)^0 | E6: ='Census Waterfall'!E12*'Control Tower'!$B$45*'Control Tower'!$B$46*'Control Tower'!$B$42*(1+'Control Tower'!$B$48)^0 | F6: ='Census Waterfall'!F12*'Control Tower'!$B$45*'Control Tower'!$B$46*'Control Tower'!$B$42*(1+'Control Tower'!$B$48)^0 | G6: ='Census Waterfall'!G12*'Control Tower'!$B$45*'Control Tower'!$B$46*'Control Tower'!$B$42*(1+'Control Tower'!$B$48)^0 | H6: ='Census Waterfall'!H12*'Control Tower'!$B$45*'Control Tower'!$B$46*'Control Tower'!$B$42*(1+'Control Tower'!$B$48)^0 | I6: ='Census Waterfall'!I12*'Control Tower'!$B$45*'Control Tower'!$B$46*'Control Tower'!$B$42*(1+'Control Tower'!$B$48)^0 | J6: ='Census Waterfall'!J12*'Control Tower'!$B$45*'Control Tower'!$B$46*'Control Tower'!$B$42*(1+'Control Tower'!$B$48)^0 | ... N6: ='Census Waterfall'!N12*'Control Tower'!$B$45*'Control Tower'!$B$46*'Control Tower'!$B$42*(1+'Control Tower'!$B$48)^0 | O6: ='Census Waterfall'!O12*'Control Tower'!$B$45*'Control Tower'!$B$46*'Control Tower'!$B$42*(1+'Control Tower'!$B$48)^1 | P6: ='Census Waterfall'!P12*'Control Tower'!$B$45*'Control Tower'!$B$46*'Control Tower'!$B$42*(1+'Control Tower'!$B$48)^1 | Q6: ='Census Waterfall'!Q12*'Control Tower'!$B$45*'Control Tower'!$B$46*'Control Tower'!$B$42*(1+'Control Tower'!$B$48)^1 | R6: ='Census Waterfall'!R12*'Control Tower'!$B$45*'Control Tower'!$B$46*'Control Tower'!$B$42*(1+'Control Tower'!$B$48)^1 | S6: ='Census Waterfall'!S12*'Control Tower'!$B$45*'Control Tower'!$B$46*'Control Tower'!$B$42*(1+'Control Tower'!$B$48)^1 | T6: ='Census Waterfall'!T12*'Control Tower'!$B$45*'Control Tower'!$B$46*'Control Tower'!$B$42*(1+'Control Tower'!$B$48)^1 | U6: ='Census Waterfall'!U12*'Control Tower'!$B$45*'Control Tower'!$B$46*'Control Tower'!$B$42*(1+'Control Tower'!$B$48)^1 | V6: ='Census Waterfall'!V12*'Control Tower'!$B$45*'Control Tower'!$B$46*'Control Tower'!$B$42*(1+'Control Tower'!$B$48)^1 | ... Z6: ='Census Waterfall'!Z12*'Control Tower'!$B$45*'Control Tower'!$B$46*'Control Tower'!$B$42*(1+'Control Tower'!$B$48)^1 | AA6: ='Census Waterfall'!AA12*'Control Tower'!$B$45*'Control Tower'!$B$46*'Control Tower'!$B$42*(1+'Control Tower'!$B$48)^2 | AB6: ='Census Waterfall'!AB12*'Control Tower'!$B$45*'Control Tower'!$B$46*'Control Tower'!$B$42*(1+'Control Tower'!$B$48)^2 | AC6: ='Census Waterfall'!AC12*'Control Tower'!$B$45*'Control Tower'!$B$46*'Control Tower'!$B$42*(1+'Control Tower'!$B$48)^2 | AD6: ='Census Waterfall'!AD12*'Control Tower'!$B$45*'Control Tower'!$B$46*'Control Tower'!$B$42*(1+'Control Tower'!$B$48)^2 | AE6: ='Census Waterfall'!AE12*'Control Tower'!$B$45*'Control Tower'!$B$46*'Control Tower'!$B$42*(1+'Control Tower'!$B$48)^2 | AF6: ='Census Waterfall'!AF12*'Control Tower'!$B$45*'Control Tower'!$B$46*'Control Tower'!$B$42*(1+'Control Tower'!$B$48)^2 | AG6: ='Census Waterfall'!AG12*'Control Tower'!$B$45*'Control Tower'!$B$46*'Control Tower'!$B$42*(1+'Control Tower'!$B$48)^2 | AH6: ='Census Waterfall'!AH12*'Control Tower'!$B$45*'Control Tower'!$B$46*'Control Tower'!$B$42*(1+'Control Tower'!$B$48)^2 | ... AL6: ='Census Waterfall'!AL12*'Control Tower'!$B$45*'Control Tower'!$B$46*'Control Tower'!$B$42*(1+'Control Tower'!$B$48)^2
A7: Medicare RHC LOW (days 61+, 3000-R-6-0) | C7: ='Census Waterfall'!C12*'Control Tower'!$B$45*(1-'Control Tower'!$B$46)*'Control Tower'!$B$43*(1+'Control Tower'!$B$48)^0 | D7: ='Census Waterfall'!D12*'Control Tower'!$B$45*(1-'Control Tower'!$B$46)*'Control Tower'!$B$43*(1+'Control Tower'!$B$48)^0 | E7: ='Census Waterfall'!E12*'Control Tower'!$B$45*(1-'Control Tower'!$B$46)*'Control Tower'!$B$43*(1+'Control Tower'!$B$48)^0 | F7: ='Census Waterfall'!F12*'Control Tower'!$B$45*(1-'Control Tower'!$B$46)*'Control Tower'!$B$43*(1+'Control Tower'!$B$48)^0 | G7: ='Census Waterfall'!G12*'Control Tower'!$B$45*(1-'Control Tower'!$B$46)*'Control Tower'!$B$43*(1+'Control Tower'!$B$48)^0 | H7: ='Census Waterfall'!H12*'Control Tower'!$B$45*(1-'Control Tower'!$B$46)*'Control Tower'!$B$43*(1+'Control Tower'!$B$48)^0 | I7: ='Census Waterfall'!I12*'Control Tower'!$B$45*(1-'Control Tower'!$B$46)*'Control Tower'!$B$43*(1+'Control Tower'!$B$48)^0 | J7: ='Census Waterfall'!J12*'Control Tower'!$B$45*(1-'Control Tower'!$B$46)*'Control Tower'!$B$43*(1+'Control Tower'!$B$48)^0 | ... N7: ='Census Waterfall'!N12*'Control Tower'!$B$45*(1-'Control Tower'!$B$46)*'Control Tower'!$B$43*(1+'Control Tower'!$B$48)^0 | O7: ='Census Waterfall'!O12*'Control Tower'!$B$45*(1-'Control Tower'!$B$46)*'Control Tower'!$B$43*(1+'Control Tower'!$B$48)^1 | P7: ='Census Waterfall'!P12*'Control Tower'!$B$45*(1-'Control Tower'!$B$46)*'Control Tower'!$B$43*(1+'Control Tower'!$B$48)^1 | Q7: ='Census Waterfall'!Q12*'Control Tower'!$B$45*(1-'Control Tower'!$B$46)*'Control Tower'!$B$43*(1+'Control Tower'!$B$48)^1 | R7: ='Census Waterfall'!R12*'Control Tower'!$B$45*(1-'Control Tower'!$B$46)*'Control Tower'!$B$43*(1+'Control Tower'!$B$48)^1 | S7: ='Census Waterfall'!S12*'Control Tower'!$B$45*(1-'Control Tower'!$B$46)*'Control Tower'!$B$43*(1+'Control Tower'!$B$48)^1 | T7: ='Census Waterfall'!T12*'Control Tower'!$B$45*(1-'Control Tower'!$B$46)*'Control Tower'!$B$43*(1+'Control Tower'!$B$48)^1 | U7: ='Census Waterfall'!U12*'Control Tower'!$B$45*(1-'Control Tower'!$B$46)*'Control Tower'!$B$43*(1+'Control Tower'!$B$48)^1 | V7: ='Census Waterfall'!V12*'Control Tower'!$B$45*(1-'Control Tower'!$B$46)*'Control Tower'!$B$43*(1+'Control Tower'!$B$48)^1 | ... Z7: ='Census Waterfall'!Z12*'Control Tower'!$B$45*(1-'Control Tower'!$B$46)*'Control Tower'!$B$43*(1+'Control Tower'!$B$48)^1 | AA7: ='Census Waterfall'!AA12*'Control Tower'!$B$45*(1-'Control Tower'!$B$46)*'Control Tower'!$B$43*(1+'Control Tower'!$B$48)^2 | AB7: ='Census Waterfall'!AB12*'Control Tower'!$B$45*(1-'Control Tower'!$B$46)*'Control Tower'!$B$43*(1+'Control Tower'!$B$48)^2 | AC7: ='Census Waterfall'!AC12*'Control Tower'!$B$45*(1-'Control Tower'!$B$46)*'Control Tower'!$B$43*(1+'Control Tower'!$B$48)^2 | AD7: ='Census Waterfall'!AD12*'Control Tower'!$B$45*(1-'Control Tower'!$B$46)*'Control Tower'!$B$43*(1+'Control Tower'!$B$48)^2 | AE7: ='Census Waterfall'!AE12*'Control Tower'!$B$45*(1-'Control Tower'!$B$46)*'Control Tower'!$B$43*(1+'Control Tower'!$B$48)^2 | AF7: ='Census Waterfall'!AF12*'Control Tower'!$B$45*(1-'Control Tower'!$B$46)*'Control Tower'!$B$43*(1+'Control Tower'!$B$48)^2 | AG7: ='Census Waterfall'!AG12*'Control Tower'!$B$45*(1-'Control Tower'!$B$46)*'Control Tower'!$B$43*(1+'Control Tower'!$B$48)^2 | AH7: ='Census Waterfall'!AH12*'Control Tower'!$B$45*(1-'Control Tower'!$B$46)*'Control Tower'!$B$43*(1+'Control Tower'!$B$48)^2 | ... AL7: ='Census Waterfall'!AL12*'Control Tower'!$B$45*(1-'Control Tower'!$B$46)*'Control Tower'!$B$43*(1+'Control Tower'!$B$48)^2
A8: Medicaid RHC (3010-R-6-0) | C8: ='Census Waterfall'!C12*(1-'Control Tower'!$B$45)*'Control Tower'!$B$44*(1+'Control Tower'!$B$48)^0 | D8: ='Census Waterfall'!D12*(1-'Control Tower'!$B$45)*'Control Tower'!$B$44*(1+'Control Tower'!$B$48)^0 | E8: ='Census Waterfall'!E12*(1-'Control Tower'!$B$45)*'Control Tower'!$B$44*(1+'Control Tower'!$B$48)^0 | F8: ='Census Waterfall'!F12*(1-'Control Tower'!$B$45)*'Control Tower'!$B$44*(1+'Control Tower'!$B$48)^0 | G8: ='Census Waterfall'!G12*(1-'Control Tower'!$B$45)*'Control Tower'!$B$44*(1+'Control Tower'!$B$48)^0 | H8: ='Census Waterfall'!H12*(1-'Control Tower'!$B$45)*'Control Tower'!$B$44*(1+'Control Tower'!$B$48)^0 | I8: ='Census Waterfall'!I12*(1-'Control Tower'!$B$45)*'Control Tower'!$B$44*(1+'Control Tower'!$B$48)^0 | J8: ='Census Waterfall'!J12*(1-'Control Tower'!$B$45)*'Control Tower'!$B$44*(1+'Control Tower'!$B$48)^0 | ... N8: ='Census Waterfall'!N12*(1-'Control Tower'!$B$45)*'Control Tower'!$B$44*(1+'Control Tower'!$B$48)^0 | O8: ='Census Waterfall'!O12*(1-'Control Tower'!$B$45)*'Control Tower'!$B$44*(1+'Control Tower'!$B$48)^1 | P8: ='Census Waterfall'!P12*(1-'Control Tower'!$B$45)*'Control Tower'!$B$44*(1+'Control Tower'!$B$48)^1 | Q8: ='Census Waterfall'!Q12*(1-'Control Tower'!$B$45)*'Control Tower'!$B$44*(1+'Control Tower'!$B$48)^1 | R8: ='Census Waterfall'!R12*(1-'Control Tower'!$B$45)*'Control Tower'!$B$44*(1+'Control Tower'!$B$48)^1 | S8: ='Census Waterfall'!S12*(1-'Control Tower'!$B$45)*'Control Tower'!$B$44*(1+'Control Tower'!$B$48)^1 | T8: ='Census Waterfall'!T12*(1-'Control Tower'!$B$45)*'Control Tower'!$B$44*(1+'Control Tower'!$B$48)^1 | U8: ='Census Waterfall'!U12*(1-'Control Tower'!$B$45)*'Control Tower'!$B$44*(1+'Control Tower'!$B$48)^1 | V8: ='Census Waterfall'!V12*(1-'Control Tower'!$B$45)*'Control Tower'!$B$44*(1+'Control Tower'!$B$48)^1 | ... Z8: ='Census Waterfall'!Z12*(1-'Control Tower'!$B$45)*'Control Tower'!$B$44*(1+'Control Tower'!$B$48)^1 | AA8: ='Census Waterfall'!AA12*(1-'Control Tower'!$B$45)*'Control Tower'!$B$44*(1+'Control Tower'!$B$48)^2 | AB8: ='Census Waterfall'!AB12*(1-'Control Tower'!$B$45)*'Control Tower'!$B$44*(1+'Control Tower'!$B$48)^2 | AC8: ='Census Waterfall'!AC12*(1-'Control Tower'!$B$45)*'Control Tower'!$B$44*(1+'Control Tower'!$B$48)^2 | AD8: ='Census Waterfall'!AD12*(1-'Control Tower'!$B$45)*'Control Tower'!$B$44*(1+'Control Tower'!$B$48)^2 | AE8: ='Census Waterfall'!AE12*(1-'Control Tower'!$B$45)*'Control Tower'!$B$44*(1+'Control Tower'!$B$48)^2 | AF8: ='Census Waterfall'!AF12*(1-'Control Tower'!$B$45)*'Control Tower'!$B$44*(1+'Control Tower'!$B$48)^2 | AG8: ='Census Waterfall'!AG12*(1-'Control Tower'!$B$45)*'Control Tower'!$B$44*(1+'Control Tower'!$B$48)^2 | AH8: ='Census Waterfall'!AH12*(1-'Control Tower'!$B$45)*'Control Tower'!$B$44*(1+'Control Tower'!$B$48)^2 | ... AL8: ='Census Waterfall'!AL12*(1-'Control Tower'!$B$45)*'Control Tower'!$B$44*(1+'Control Tower'!$B$48)^2
A9: TOTAL GROSS REVENUE | C9: =C6+C7+C8 | D9: =D6+D7+D8 | E9: =E6+E7+E8 | F9: =F6+F7+F8 | G9: =G6+G7+G8 | H9: =H6+H7+H8 | I9: =I6+I7+I8 | J9: =J6+J7+J8 | ... AL9: =AL6+AL7+AL8
A10: Less: billing company fee (6510-Z) | C10: =-C9*'Control Tower'!$B$47 | D10: =-D9*'Control Tower'!$B$47 | E10: =-E9*'Control Tower'!$B$47 | F10: =-F9*'Control Tower'!$B$47 | G10: =-G9*'Control Tower'!$B$47 | H10: =-H9*'Control Tower'!$B$47 | I10: =-I9*'Control Tower'!$B$47 | J10: =-J9*'Control Tower'!$B$47 | ... AL10: =-AL9*'Control Tower'!$B$47
A11: NET PATIENT REVENUE (accrual) | C11: =C9+C10 | D11: =D9+D10 | E11: =E9+E10 | F11: =F9+F10 | G11: =G9+G10 | H11: =H9+H10 | I11: =I9+I10 | J11: =J9+J10 | ... AL11: =AL9+AL10

Sheet Staffing
A1: AZALEA HOSPICE - REFUGE OPERATING MODEL
A2: STAFFING - FTEs step with census (caseload formulas); PRN 1099 supplement fires when FTE capacity < required visits.
A4: Month # | C4: 1 | D4: 2 | E4: 3 | F4: 4 | G4: 5 | H4: 6 | I4: 7 | J4: 8 | K4: 9 | L4: 10 | M4: 11 | N4: 12 | O4: 13 | P4: 14 | Q4: 15 | R4: 16 | S4: 17 | T4: 18 | U4: 19 | V4: 20 | W4: 21 | X4: 22 | Y4: 23 | Z4: 24 | AA4: 25 | AB4: 26 | AC4: 27 | AD4: 28 | AE4: 29 | AF4: 30 | AG4: 31 | AH4: 32 | AI4: 33 | AJ4: 34 | AK4: 35 | AL4: 36
C5: Jul-26 | D5: Aug-26 | E5: Sep-26 | F5: Oct-26 | G5: Nov-26 | H5: Dec-26 | I5: Jan-27 | J5: Feb-27 | K5: Mar-27 | L5: Apr-27 | M5: May-27 | N5: Jun-27 | O5: Jul-27 | P5: Aug-27 | Q5: Sep-27 | R5: Oct-27 | S5: Nov-27 | T5: Dec-27 | U5: Jan-28 | V5: Feb-28 | W5: Mar-28 | X5: Apr-28 | Y5: May-28 | Z5: Jun-28 | AA5: Jul-28 | AB5: Aug-28 | AC5: Sep-28 | AD5: Oct-28 | AE5: Nov-28 | AF5: Dec-28 | AG5: Jan-29 | AH5: Feb-29 | AI5: Mar-29 | AJ5: Apr-29 | AK5: May-29 | AL5: Jun-29
A6: CLINICAL IDG - EMPLOYED (Acct 4000; FTE = census/caseload in 0.5 steps)
A7: RN Case Manager (4000-0-6-1) - FTE | C7: =ROUNDUP('Census Waterfall'!C11/'Control Tower'!$B$59*2,0)/2 | D7: =ROUNDUP('Census Waterfall'!D11/'Control Tower'!$B$59*2,0)/2 | E7: =ROUNDUP('Census Waterfall'!E11/'Control Tower'!$B$59*2,0)/2 | F7: =ROUNDUP('Census Waterfall'!F11/'Control Tower'!$B$59*2,0)/2 | G7: =ROUNDUP('Census Waterfall'!G11/'Control Tower'!$B$59*2,0)/2 | H7: =ROUNDUP('Census Waterfall'!H11/'Control Tower'!$B$59*2,0)/2 | I7: =ROUNDUP('Census Waterfall'!I11/'Control Tower'!$B$59*2,0)/2 | J7: =ROUNDUP('Census Waterfall'!J11/'Control Tower'!$B$59*2,0)/2 | ... AL7: =ROUNDUP('Census Waterfall'!AL11/'Control Tower'!$B$59*2,0)/2
A8: RN Case Manager (4000-0-6-1) - wages | C8: =C7*'Control Tower'!$B$58/12*(1+'Control Tower'!$B$57)^0*(1+'Control Tower'!$B$39) | D8: =D7*'Control Tower'!$B$58/12*(1+'Control Tower'!$B$57)^0*(1+'Control Tower'!$B$39) | E8: =E7*'Control Tower'!$B$58/12*(1+'Control Tower'!$B$57)^0*(1+'Control Tower'!$B$39) | F8: =F7*'Control Tower'!$B$58/12*(1+'Control Tower'!$B$57)^0*(1+'Control Tower'!$B$39) | G8: =G7*'Control Tower'!$B$58/12*(1+'Control Tower'!$B$57)^0*(1+'Control Tower'!$B$39) | H8: =H7*'Control Tower'!$B$58/12*(1+'Control Tower'!$B$57)^0*(1+'Control Tower'!$B$39) | I8: =I7*'Control Tower'!$B$58/12*(1+'Control Tower'!$B$57)^0*(1+'Control Tower'!$B$39) | J8: =J7*'Control Tower'!$B$58/12*(1+'Control Tower'!$B$57)^0*(1+'Control Tower'!$B$39) | ... N8: =N7*'Control Tower'!$B$58/12*(1+'Control Tower'!$B$57)^0*(1+'Control Tower'!$B$39) | O8: =O7*'Control Tower'!$B$58/12*(1+'Control Tower'!$B$57)^1*(1+'Control Tower'!$B$39) | P8: =P7*'Control Tower'!$B$58/12*(1+'Control Tower'!$B$57)^1*(1+'Control Tower'!$B$39) | Q8: =Q7*'Control Tower'!$B$58/12*(1+'Control Tower'!$B$57)^1*(1+'Control Tower'!$B$39) | R8: =R7*'Control Tower'!$B$58/12*(1+'Control Tower'!$B$57)^1*(1+'Control Tower'!$B$39) | S8: =S7*'Control Tower'!$B$58/12*(1+'Control Tower'!$B$57)^1*(1+'Control Tower'!$B$39) | T8: =T7*'Control Tower'!$B$58/12*(1+'Control Tower'!$B$57)^1*(1+'Control Tower'!$B$39) | U8: =U7*'Control Tower'!$B$58/12*(1+'Control Tower'!$B$57)^1*(1+'Control Tower'!$B$39) | V8: =V7*'Control Tower'!$B$58/12*(1+'Control Tower'!$B$57)^1*(1+'Control Tower'!$B$39) | ... Z8: =Z7*'Control Tower'!$B$58/12*(1+'Control Tower'!$B$57)^1*(1+'Control Tower'!$B$39) | AA8: =AA7*'Control Tower'!$B$58/12*(1+'Control Tower'!$B$57)^2*(1+'Control Tower'!$B$39) | AB8: =AB7*'Control Tower'!$B$58/12*(1+'Control Tower'!$B$57)^2*(1+'Control Tower'!$B$39) | AC8: =AC7*'Control Tower'!$B$58/12*(1+'Control Tower'!$B$57)^2*(1+'Control Tower'!$B$39) | AD8: =AD7*'Control Tower'!$B$58/12*(1+'Control Tower'!$B$57)^2*(1+'Control Tower'!$B$39) | AE8: =AE7*'Control Tower'!$B$58/12*(1+'Control Tower'!$B$57)^2*(1+'Control Tower'!$B$39) | AF8: =AF7*'Control Tower'!$B$58/12*(1+'Control Tower'!$B$57)^2*(1+'Control Tower'!$B$39) | AG8: =AG7*'Control Tower'!$B$58/12*(1+'Control Tower'!$B$57)^2*(1+'Control Tower'!$B$39) | AH8: =AH7*'Control Tower'!$B$58/12*(1+'Control Tower'!$B$57)^2*(1+'Control Tower'!$B$39) | ... AL8: =AL7*'Control Tower'!$B$58/12*(1+'Control Tower'!$B$57)^2*(1+'Control Tower'!$B$39)
A9: RN On-Call / part-time (4000-R-6-3) - FTE | C9: =MAX('Control Tower'!$B$61,ROUNDUP('Census Waterfall'!C11/60*2,0)/2) | D9: =MAX('Control Tower'!$B$61,ROUNDUP('Census Waterfall'!D11/60*2,0)/2) | E9: =MAX('Control Tower'!$B$61,ROUNDUP('Census Waterfall'!E11/60*2,0)/2) | F9: =MAX('Control Tower'!$B$61,ROUNDUP('Census Waterfall'!F11/60*2,0)/2) | G9: =MAX('Control Tower'!$B$61,ROUNDUP('Census Waterfall'!G11/60*2,0)/2) | H9: =MAX('Control Tower'!$B$61,ROUNDUP('Census Waterfall'!H11/60*2,0)/2) | I9: =MAX('Control Tower'!$B$61,ROUNDUP('Census Waterfall'!I11/60*2,0)/2) | J9: =MAX('Control Tower'!$B$61,ROUNDUP('Census Waterfall'!J11/60*2,0)/2) | ... AL9: =MAX('Control Tower'!$B$61,ROUNDUP('Census Waterfall'!AL11/60*2,0)/2)
A10: RN On-Call / part-time (4000-R-6-3) - wages | C10: =C9*'Control Tower'!$B$60/12*(1+'Control Tower'!$B$57)^0*(1+'Control Tower'!$B$39) | D10: =D9*'Control Tower'!$B$60/12*(1+'Control Tower'!$B$57)^0*(1+'Control Tower'!$B$39) | E10: =E9*'Control Tower'!$B$60/12*(1+'Control Tower'!$B$57)^0*(1+'Control Tower'!$B$39) | F10: =F9*'Control Tower'!$B$60/12*(1+'Control Tower'!$B$57)^0*(1+'Control Tower'!$B$39) | G10: =G9*'Control Tower'!$B$60/12*(1+'Control Tower'!$B$57)^0*(1+'Control Tower'!$B$39) | H10: =H9*'Control Tower'!$B$60/12*(1+'Control Tower'!$B$57)^0*(1+'Control Tower'!$B$39) | I10: =I9*'Control Tower'!$B$60/12*(1+'Control Tower'!$B$57)^0*(1+'Control Tower'!$B$39) | J10: =J9*'Control Tower'!$B$60/12*(1+'Control Tower'!$B$57)^0*(1+'Control Tower'!$B$39) | ... N10: =N9*'Control Tower'!$B$60/12*(1+'Control Tower'!$B$57)^0*(1+'Control Tower'!$B$39) | O10: =O9*'Control Tower'!$B$60/12*(1+'Control Tower'!$B$57)^1*(1+'Control Tower'!$B$39) | P10: =P9*'Control Tower'!$B$60/12*(1+'Control Tower'!$B$57)^1*(1+'Control Tower'!$B$39) | Q10: =Q9*'Control Tower'!$B$60/12*(1+'Control Tower'!$B$57)^1*(1+'Control Tower'!$B$39) | R10: =R9*'Control Tower'!$B$60/12*(1+'Control Tower'!$B$57)^1*(1+'Control Tower'!$B$39) | S10: =S9*'Control Tower'!$B$60/12*(1+'Control Tower'!$B$57)^1*(1+'Control Tower'!$B$39) | T10: =T9*'Control Tower'!$B$60/12*(1+'Control Tower'!$B$57)^1*(1+'Control Tower'!$B$39) | U10: =U9*'Control Tower'!$B$60/12*(1+'Control Tower'!$B$57)^1*(1+'Control Tower'!$B$39) | V10: =V9*'Control Tower'!$B$60/12*(1+'Control Tower'!$B$57)^1*(1+'Control Tower'!$B$39) | ... Z10: =Z9*'Control Tower'!$B$60/12*(1+'Control Tower'!$B$57)^1*(1+'Control Tower'!$B$39) | AA10: =AA9*'Control Tower'!$B$60/12*(1+'Control Tower'!$B$57)^2*(1+'Control Tower'!$B$39) | AB10: =AB9*'Control Tower'!$B$60/12*(1+'Control Tower'!$B$57)^2*(1+'Control Tower'!$B$39) | AC10: =AC9*'Control Tower'!$B$60/12*(1+'Control Tower'!$B$57)^2*(1+'Control Tower'!$B$39) | AD10: =AD9*'Control Tower'!$B$60/12*(1+'Control Tower'!$B$57)^2*(1+'Control Tower'!$B$39) | AE10: =AE9*'Control Tower'!$B$60/12*(1+'Control Tower'!$B$57)^2*(1+'Control Tower'!$B$39) | AF10: =AF9*'Control Tower'!$B$60/12*(1+'Control Tower'!$B$57)^2*(1+'Control Tower'!$B$39) | AG10: =AG9*'Control Tower'!$B$60/12*(1+'Control Tower'!$B$57)^2*(1+'Control Tower'!$B$39) | AH10: =AH9*'Control Tower'!$B$60/12*(1+'Control Tower'!$B$57)^2*(1+'Control Tower'!$B$39) | ... AL10: =AL9*'Control Tower'!$B$60/12*(1+'Control Tower'!$B$57)^2*(1+'Control Tower'!$B$39)
A11: Hospice Aide / CNA (4000-R-6-5) - FTE | C11: =ROUNDUP('Census Waterfall'!C11/'Control Tower'!$B$63*2,0)/2 | D11: =ROUNDUP('Census Waterfall'!D11/'Control Tower'!$B$63*2,0)/2 | E11: =ROUNDUP('Census Waterfall'!E11/'Control Tower'!$B$63*2,0)/2 | F11: =ROUNDUP('Census Waterfall'!F11/'Control Tower'!$B$63*2,0)/2 | G11: =ROUNDUP('Census Waterfall'!G11/'Control Tower'!$B$63*2,0)/2 | H11: =ROUNDUP('Census Waterfall'!H11/'Control Tower'!$B$63*2,0)/2 | I11: =ROUNDUP('Census Waterfall'!I11/'Control Tower'!$B$63*2,0)/2 | J11: =ROUNDUP('Census Waterfall'!J11/'Control Tower'!$B$63*2,0)/2 | ... AL11: =ROUNDUP('Census Waterfall'!AL11/'Control Tower'!$B$63*2,0)/2
A12: Hospice Aide / CNA (4000-R-6-5) - wages | C12: =C11*'Control Tower'!$B$62/12*(1+'Control Tower'!$B$57)^0*(1+'Control Tower'!$B$39) | D12: =D11*'Control Tower'!$B$62/12*(1+'Control Tower'!$B$57)^0*(1+'Control Tower'!$B$39) | E12: =E11*'Control Tower'!$B$62/12*(1+'Control Tower'!$B$57)^0*(1+'Control Tower'!$B$39) | F12: =F11*'Control Tower'!$B$62/12*(1+'Control Tower'!$B$57)^0*(1+'Control Tower'!$B$39) | G12: =G11*'Control Tower'!$B$62/12*(1+'Control Tower'!$B$57)^0*(1+'Control Tower'!$B$39) | H12: =H11*'Control Tower'!$B$62/12*(1+'Control Tower'!$B$57)^0*(1+'Control Tower'!$B$39) | I12: =I11*'Control Tower'!$B$62/12*(1+'Control Tower'!$B$57)^0*(1+'Control Tower'!$B$39) | J12: =J11*'Control Tower'!$B$62/12*(1+'Control Tower'!$B$57)^0*(1+'Control Tower'!$B$39) | ... N12: =N11*'Control Tower'!$B$62/12*(1+'Control Tower'!$B$57)^0*(1+'Control Tower'!$B$39) | O12: =O11*'Control Tower'!$B$62/12*(1+'Control Tower'!$B$57)^1*(1+'Control Tower'!$B$39) | P12: =P11*'Control Tower'!$B$62/12*(1+'Control Tower'!$B$57)^1*(1+'Control Tower'!$B$39) | Q12: =Q11*'Control Tower'!$B$62/12*(1+'Control Tower'!$B$57)^1*(1+'Control Tower'!$B$39) | R12: =R11*'Control Tower'!$B$62/12*(1+'Control Tower'!$B$57)^1*(1+'Control Tower'!$B$39) | S12: =S11*'Control Tower'!$B$62/12*(1+'Control Tower'!$B$57)^1*(1+'Control Tower'!$B$39) | T12: =T11*'Control Tower'!$B$62/12*(1+'Control Tower'!$B$57)^1*(1+'Control Tower'!$B$39) | U12: =U11*'Control Tower'!$B$62/12*(1+'Control Tower'!$B$57)^1*(1+'Control Tower'!$B$39) | V12: =V11*'Control Tower'!$B$62/12*(1+'Control Tower'!$B$57)^1*(1+'Control Tower'!$B$39) | ... Z12: =Z11*'Control Tower'!$B$62/12*(1+'Control Tower'!$B$57)^1*(1+'Control Tower'!$B$39) | AA12: =AA11*'Control Tower'!$B$62/12*(1+'Control Tower'!$B$57)^2*(1+'Control Tower'!$B$39) | AB12: =AB11*'Control Tower'!$B$62/12*(1+'Control Tower'!$B$57)^2*(1+'Control Tower'!$B$39) | AC12: =AC11*'Control Tower'!$B$62/12*(1+'Control Tower'!$B$57)^2*(1+'Control Tower'!$B$39) | AD12: =AD11*'Control Tower'!$B$62/12*(1+'Control Tower'!$B$57)^2*(1+'Control Tower'!$B$39) | AE12: =AE11*'Control Tower'!$B$62/12*(1+'Control Tower'!$B$57)^2*(1+'Control Tower'!$B$39) | AF12: =AF11*'Control Tower'!$B$62/12*(1+'Control Tower'!$B$57)^2*(1+'Control Tower'!$B$39) | AG12: =AG11*'Control Tower'!$B$62/12*(1+'Control Tower'!$B$57)^2*(1+'Control Tower'!$B$39) | AH12: =AH11*'Control Tower'!$B$62/12*(1+'Control Tower'!$B$57)^2*(1+'Control Tower'!$B$39) | ... AL12: =AL11*'Control Tower'!$B$62/12*(1+'Control Tower'!$B$57)^2*(1+'Control Tower'!$B$39)
A13: Medical Social Worker (4000-R-6-6) - FTE | C13: =ROUNDUP('Census Waterfall'!C11/'Control Tower'!$B$65*2,0)/2 | D13: =ROUNDUP('Census Waterfall'!D11/'Control Tower'!$B$65*2,0)/2 | E13: =ROUNDUP('Census Waterfall'!E11/'Control Tower'!$B$65*2,0)/2 | F13: =ROUNDUP('Census Waterfall'!F11/'Control Tower'!$B$65*2,0)/2 | G13: =ROUNDUP('Census Waterfall'!G11/'Control Tower'!$B$65*2,0)/2 | H13: =ROUNDUP('Census Waterfall'!H11/'Control Tower'!$B$65*2,0)/2 | I13: =ROUNDUP('Census Waterfall'!I11/'Control Tower'!$B$65*2,0)/2 | J13: =ROUNDUP('Census Waterfall'!J11/'Control Tower'!$B$65*2,0)/2 | ... AL13: =ROUNDUP('Census Waterfall'!AL11/'Control Tower'!$B$65*2,0)/2
A14: Medical Social Worker (4000-R-6-6) - wages | C14: =C13*'Control Tower'!$B$64/12*(1+'Control Tower'!$B$57)^0*(1+'Control Tower'!$B$39) | D14: =D13*'Control Tower'!$B$64/12*(1+'Control Tower'!$B$57)^0*(1+'Control Tower'!$B$39) | E14: =E13*'Control Tower'!$B$64/12*(1+'Control Tower'!$B$57)^0*(1+'Control Tower'!$B$39) | F14: =F13*'Control Tower'!$B$64/12*(1+'Control Tower'!$B$57)^0*(1+'Control Tower'!$B$39) | G14: =G13*'Control Tower'!$B$64/12*(1+'Control Tower'!$B$57)^0*(1+'Control Tower'!$B$39) | H14: =H13*'Control Tower'!$B$64/12*(1+'Control Tower'!$B$57)^0*(1+'Control Tower'!$B$39) | I14: =I13*'Control Tower'!$B$64/12*(1+'Control Tower'!$B$57)^0*(1+'Control Tower'!$B$39) | J14: =J13*'Control Tower'!$B$64/12*(1+'Control Tower'!$B$57)^0*(1+'Control Tower'!$B$39) | ... N14: =N13*'Control Tower'!$B$64/12*(1+'Control Tower'!$B$57)^0*(1+'Control Tower'!$B$39) | O14: =O13*'Control Tower'!$B$64/12*(1+'Control Tower'!$B$57)^1*(1+'Control Tower'!$B$39) | P14: =P13*'Control Tower'!$B$64/12*(1+'Control Tower'!$B$57)^1*(1+'Control Tower'!$B$39) | Q14: =Q13*'Control Tower'!$B$64/12*(1+'Control Tower'!$B$57)^1*(1+'Control Tower'!$B$39) | R14: =R13*'Control Tower'!$B$64/12*(1+'Control Tower'!$B$57)^1*(1+'Control Tower'!$B$39) | S14: =S13*'Control Tower'!$B$64/12*(1+'Control Tower'!$B$57)^1*(1+'Control Tower'!$B$39) | T14: =T13*'Control Tower'!$B$64/12*(1+'Control Tower'!$B$57)^1*(1+'Control Tower'!$B$39) | U14: =U13*'Control Tower'!$B$64/12*(1+'Control Tower'!$B$57)^1*(1+'Control Tower'!$B$39) | V14: =V13*'Control Tower'!$B$64/12*(1+'Control Tower'!$B$57)^1*(1+'Control Tower'!$B$39) | ... Z14: =Z13*'Control Tower'!$B$64/12*(1+'Control Tower'!$B$57)^1*(1+'Control Tower'!$B$39) | AA14: =AA13*'Control Tower'!$B$64/12*(1+'Control Tower'!$B$57)^2*(1+'Control Tower'!$B$39) | AB14: =AB13*'Control Tower'!$B$64/12*(1+'Control Tower'!$B$57)^2*(1+'Control Tower'!$B$39) | AC14: =AC13*'Control Tower'!$B$64/12*(1+'Control Tower'!$B$57)^2*(1+'Control Tower'!$B$39) | AD14: =AD13*'Control Tower'!$B$64/12*(1+'Control Tower'!$B$57)^2*(1+'Control Tower'!$B$39) | AE14: =AE13*'Control Tower'!$B$64/12*(1+'Control Tower'!$B$57)^2*(1+'Control Tower'!$B$39) | AF14: =AF13*'Control Tower'!$B$64/12*(1+'Control Tower'!$B$57)^2*(1+'Control Tower'!$B$39) | AG14: =AG13*'Control Tower'!$B$64/12*(1+'Control Tower'!$B$57)^2*(1+'Control Tower'!$B$39) | AH14: =AH13*'Control Tower'!$B$64/12*(1+'Control Tower'!$B$57)^2*(1+'Control Tower'!$B$39) | ... AL14: =AL13*'Control Tower'!$B$64/12*(1+'Control Tower'!$B$57)^2*(1+'Control Tower'!$B$39)
A15: Employed clinical wages | C15: =C8+C10+C12+C14 | D15: =D8+D10+D12+D14 | E15: =E8+E10+E12+E14 | F15: =F8+F10+F12+F14 | G15: =G8+G10+G12+G14 | H15: =H8+H10+H12+H14 | I15: =I8+I10+I12+I14 | J15: =J8+J10+J12+J14 | ... AL15: =AL8+AL10+AL12+AL14
A16: PRN 1099 SUPPLEMENT (Acct 4025 - no benefits)
A17: PRN RN supplement (4025-0-6-1) | C17: =MAX(0,'Census Waterfall'!C11*'Control Tower'!$B$70-C7*'Control Tower'!$B$71)*'Control Tower'!$B$72*(1+'Control Tower'!$B$39) | D17: =MAX(0,'Census Waterfall'!D11*'Control Tower'!$B$70-D7*'Control Tower'!$B$71)*'Control Tower'!$B$72*(1+'Control Tower'!$B$39) | E17: =MAX(0,'Census Waterfall'!E11*'Control Tower'!$B$70-E7*'Control Tower'!$B$71)*'Control Tower'!$B$72*(1+'Control Tower'!$B$39) | F17: =MAX(0,'Census Waterfall'!F11*'Control Tower'!$B$70-F7*'Control Tower'!$B$71)*'Control Tower'!$B$72*(1+'Control Tower'!$B$39) | G17: =MAX(0,'Census Waterfall'!G11*'Control Tower'!$B$70-G7*'Control Tower'!$B$71)*'Control Tower'!$B$72*(1+'Control Tower'!$B$39) | H17: =MAX(0,'Census Waterfall'!H11*'Control Tower'!$B$70-H7*'Control Tower'!$B$71)*'Control Tower'!$B$72*(1+'Control Tower'!$B$39) | I17: =MAX(0,'Census Waterfall'!I11*'Control Tower'!$B$70-I7*'Control Tower'!$B$71)*'Control Tower'!$B$72*(1+'Control Tower'!$B$39) | J17: =MAX(0,'Census Waterfall'!J11*'Control Tower'!$B$70-J7*'Control Tower'!$B$71)*'Control Tower'!$B$72*(1+'Control Tower'!$B$39) | ... AL17: =MAX(0,'Census Waterfall'!AL11*'Control Tower'!$B$70-AL7*'Control Tower'!$B$71)*'Control Tower'!$B$72*(1+'Control Tower'!$B$39)
A18: PRN Aide supplement (4025-0-6-5) | C18: =MAX(0,'Census Waterfall'!C11*'Control Tower'!$B$73-C11*'Control Tower'!$B$74)*'Control Tower'!$B$75*(1+'Control Tower'!$B$39) | D18: =MAX(0,'Census Waterfall'!D11*'Control Tower'!$B$73-D11*'Control Tower'!$B$74)*'Control Tower'!$B$75*(1+'Control Tower'!$B$39) | E18: =MAX(0,'Census Waterfall'!E11*'Control Tower'!$B$73-E11*'Control Tower'!$B$74)*'Control Tower'!$B$75*(1+'Control Tower'!$B$39) | F18: =MAX(0,'Census Waterfall'!F11*'Control Tower'!$B$73-F11*'Control Tower'!$B$74)*'Control Tower'!$B$75*(1+'Control Tower'!$B$39) | G18: =MAX(0,'Census Waterfall'!G11*'Control Tower'!$B$73-G11*'Control Tower'!$B$74)*'Control Tower'!$B$75*(1+'Control Tower'!$B$39) | H18: =MAX(0,'Census Waterfall'!H11*'Control Tower'!$B$73-H11*'Control Tower'!$B$74)*'Control Tower'!$B$75*(1+'Control Tower'!$B$39) | I18: =MAX(0,'Census Waterfall'!I11*'Control Tower'!$B$73-I11*'Control Tower'!$B$74)*'Control Tower'!$B$75*(1+'Control Tower'!$B$39) | J18: =MAX(0,'Census Waterfall'!J11*'Control Tower'!$B$73-J11*'Control Tower'!$B$74)*'Control Tower'!$B$75*(1+'Control Tower'!$B$39) | ... AL18: =MAX(0,'Census Waterfall'!AL11*'Control Tower'!$B$73-AL11*'Control Tower'!$B$74)*'Control Tower'!$B$75*(1+'Control Tower'!$B$39)
A19: PRN MSW supplement (4025-0-6-6) | C19: =MAX(0,'Census Waterfall'!C11*'Control Tower'!$B$76-C13*'Control Tower'!$B$77)*'Control Tower'!$B$78*(1+'Control Tower'!$B$39) | D19: =MAX(0,'Census Waterfall'!D11*'Control Tower'!$B$76-D13*'Control Tower'!$B$77)*'Control Tower'!$B$78*(1+'Control Tower'!$B$39) | E19: =MAX(0,'Census Waterfall'!E11*'Control Tower'!$B$76-E13*'Control Tower'!$B$77)*'Control Tower'!$B$78*(1+'Control Tower'!$B$39) | F19: =MAX(0,'Census Waterfall'!F11*'Control Tower'!$B$76-F13*'Control Tower'!$B$77)*'Control Tower'!$B$78*(1+'Control Tower'!$B$39) | G19: =MAX(0,'Census Waterfall'!G11*'Control Tower'!$B$76-G13*'Control Tower'!$B$77)*'Control Tower'!$B$78*(1+'Control Tower'!$B$39) | H19: =MAX(0,'Census Waterfall'!H11*'Control Tower'!$B$76-H13*'Control Tower'!$B$77)*'Control Tower'!$B$78*(1+'Control Tower'!$B$39) | I19: =MAX(0,'Census Waterfall'!I11*'Control Tower'!$B$76-I13*'Control Tower'!$B$77)*'Control Tower'!$B$78*(1+'Control Tower'!$B$39) | J19: =MAX(0,'Census Waterfall'!J11*'Control Tower'!$B$76-J13*'Control Tower'!$B$77)*'Control Tower'!$B$78*(1+'Control Tower'!$B$39) | ... AL19: =MAX(0,'Census Waterfall'!AL11*'Control Tower'!$B$76-AL13*'Control Tower'!$B$77)*'Control Tower'!$B$78*(1+'Control Tower'!$B$39)
A20: PRN Chaplain above base (4025-0-6-7) | C20: =MAX(0,'Census Waterfall'!C11*'Control Tower'!$B$79-'Control Tower'!$B$80)*'Control Tower'!$B$81*(1+'Control Tower'!$B$39) | D20: =MAX(0,'Census Waterfall'!D11*'Control Tower'!$B$79-'Control Tower'!$B$80)*'Control Tower'!$B$81*(1+'Control Tower'!$B$39) | E20: =MAX(0,'Census Waterfall'!E11*'Control Tower'!$B$79-'Control Tower'!$B$80)*'Control Tower'!$B$81*(1+'Control Tower'!$B$39) | F20: =MAX(0,'Census Waterfall'!F11*'Control Tower'!$B$79-'Control Tower'!$B$80)*'Control Tower'!$B$81*(1+'Control Tower'!$B$39) | G20: =MAX(0,'Census Waterfall'!G11*'Control Tower'!$B$79-'Control Tower'!$B$80)*'Control Tower'!$B$81*(1+'Control Tower'!$B$39) | H20: =MAX(0,'Census Waterfall'!H11*'Control Tower'!$B$79-'Control Tower'!$B$80)*'Control Tower'!$B$81*(1+'Control Tower'!$B$39) | I20: =MAX(0,'Census Waterfall'!I11*'Control Tower'!$B$79-'Control Tower'!$B$80)*'Control Tower'!$B$81*(1+'Control Tower'!$B$39) | J20: =MAX(0,'Census Waterfall'!J11*'Control Tower'!$B$79-'Control Tower'!$B$80)*'Control Tower'!$B$81*(1+'Control Tower'!$B$39) | ... AL20: =MAX(0,'Census Waterfall'!AL11*'Control Tower'!$B$79-'Control Tower'!$B$80)*'Control Tower'!$B$81*(1+'Control Tower'!$B$39)
A21: Total PRN supplement | C21: =C17+C18+C19+C20 | D21: =D17+D18+D19+D20 | E21: =E17+E18+E19+E20 | F21: =F17+F18+F19+F20 | G21: =G17+G18+G19+G20 | H21: =H17+H18+H19+H20 | I21: =I17+I18+I19+I20 | J21: =J17+J18+J19+J20 | ... AL21: =AL17+AL18+AL19+AL20
A22: CONTRACT & INDIRECT (leadership per Control Tower start months)
A23: Chaplain base contract (4020-0-6-7) | C23: ='Control Tower'!$B$66*(1+'Control Tower'!$B$57)^0 | D23: ='Control Tower'!$B$66*(1+'Control Tower'!$B$57)^0 | E23: ='Control Tower'!$B$66*(1+'Control Tower'!$B$57)^0 | F23: ='Control Tower'!$B$66*(1+'Control Tower'!$B$57)^0 | G23: ='Control Tower'!$B$66*(1+'Control Tower'!$B$57)^0 | H23: ='Control Tower'!$B$66*(1+'Control Tower'!$B$57)^0 | I23: ='Control Tower'!$B$66*(1+'Control Tower'!$B$57)^0 | J23: ='Control Tower'!$B$66*(1+'Control Tower'!$B$57)^0 | ... N23: ='Control Tower'!$B$66*(1+'Control Tower'!$B$57)^0 | O23: ='Control Tower'!$B$66*(1+'Control Tower'!$B$57)^1 | P23: ='Control Tower'!$B$66*(1+'Control Tower'!$B$57)^1 | Q23: ='Control Tower'!$B$66*(1+'Control Tower'!$B$57)^1 | R23: ='Control Tower'!$B$66*(1+'Control Tower'!$B$57)^1 | S23: ='Control Tower'!$B$66*(1+'Control Tower'!$B$57)^1 | T23: ='Control Tower'!$B$66*(1+'Control Tower'!$B$57)^1 | U23: ='Control Tower'!$B$66*(1+'Control Tower'!$B$57)^1 | V23: ='Control Tower'!$B$66*(1+'Control Tower'!$B$57)^1 | ... Z23: ='Control Tower'!$B$66*(1+'Control Tower'!$B$57)^1 | AA23: ='Control Tower'!$B$66*(1+'Control Tower'!$B$57)^2 | AB23: ='Control Tower'!$B$66*(1+'Control Tower'!$B$57)^2 | AC23: ='Control Tower'!$B$66*(1+'Control Tower'!$B$57)^2 | AD23: ='Control Tower'!$B$66*(1+'Control Tower'!$B$57)^2 | AE23: ='Control Tower'!$B$66*(1+'Control Tower'!$B$57)^2 | AF23: ='Control Tower'!$B$66*(1+'Control Tower'!$B$57)^2 | AG23: ='Control Tower'!$B$66*(1+'Control Tower'!$B$57)^2 | AH23: ='Control Tower'!$B$66*(1+'Control Tower'!$B$57)^2 | ... AL23: ='Control Tower'!$B$66*(1+'Control Tower'!$B$57)^2
A24: Medical director (4020-0-6-M) | C24: =IF(1>='Control Tower'!$B$68,'Control Tower'!$B$67*(1+'Control Tower'!$B$57)^0,0) | D24: =IF(2>='Control Tower'!$B$68,'Control Tower'!$B$67*(1+'Control Tower'!$B$57)^0,0) | E24: =IF(3>='Control Tower'!$B$68,'Control Tower'!$B$67*(1+'Control Tower'!$B$57)^0,0) | F24: =IF(4>='Control Tower'!$B$68,'Control Tower'!$B$67*(1+'Control Tower'!$B$57)^0,0) | G24: =IF(5>='Control Tower'!$B$68,'Control Tower'!$B$67*(1+'Control Tower'!$B$57)^0,0) | H24: =IF(6>='Control Tower'!$B$68,'Control Tower'!$B$67*(1+'Control Tower'!$B$57)^0,0) | I24: =IF(7>='Control Tower'!$B$68,'Control Tower'!$B$67*(1+'Control Tower'!$B$57)^0,0) | J24: =IF(8>='Control Tower'!$B$68,'Control Tower'!$B$67*(1+'Control Tower'!$B$57)^0,0) | K24: =IF(9>='Control Tower'!$B$68,'Control Tower'!$B$67*(1+'Control Tower'!$B$57)^0,0) | L24: =IF(10>='Control Tower'!$B$68,'Control Tower'!$B$67*(1+'Control Tower'!$B$57)^0,0) | M24: =IF(11>='Control Tower'!$B$68,'Control Tower'!$B$67*(1+'Control Tower'!$B$57)^0,0) | N24: =IF(12>='Control Tower'!$B$68,'Control Tower'!$B$67*(1+'Control Tower'!$B$57)^0,0) | O24: =IF(13>='Control Tower'!$B$68,'Control Tower'!$B$67*(1+'Control Tower'!$B$57)^1,0) | P24: =IF(14>='Control Tower'!$B$68,'Control Tower'!$B$67*(1+'Control Tower'!$B$57)^1,0) | Q24: =IF(15>='Control Tower'!$B$68,'Control Tower'!$B$67*(1+'Control Tower'!$B$57)^1,0) | R24: =IF(16>='Control Tower'!$B$68,'Control Tower'!$B$67*(1+'Control Tower'!$B$57)^1,0) | S24: =IF(17>='Control Tower'!$B$68,'Control Tower'!$B$67*(1+'Control Tower'!$B$57)^1,0) | T24: =IF(18>='Control Tower'!$B$68,'Control Tower'!$B$67*(1+'Control Tower'!$B$57)^1,0) | U24: =IF(19>='Control Tower'!$B$68,'Control Tower'!$B$67*(1+'Control Tower'!$B$57)^1,0) | V24: =IF(20>='Control Tower'!$B$68,'Control Tower'!$B$67*(1+'Control Tower'!$B$57)^1,0) | W24: =IF(21>='Control Tower'!$B$68,'Control Tower'!$B$67*(1+'Control Tower'!$B$57)^1,0) | X24: =IF(22>='Control Tower'!$B$68,'Control Tower'!$B$67*(1+'Control Tower'!$B$57)^1,0) | Y24: =IF(23>='Control Tower'!$B$68,'Control Tower'!$B$67*(1+'Control Tower'!$B$57)^1,0) | Z24: =IF(24>='Control Tower'!$B$68,'Control Tower'!$B$67*(1+'Control Tower'!$B$57)^1,0) | AA24: =IF(25>='Control Tower'!$B$68,'Control Tower'!$B$67*(1+'Control Tower'!$B$57)^2,0) | AB24: =IF(26>='Control Tower'!$B$68,'Control Tower'!$B$67*(1+'Control Tower'!$B$57)^2,0) | AC24: =IF(27>='Control Tower'!$B$68,'Control Tower'!$B$67*(1+'Control Tower'!$B$57)^2,0) | AD24: =IF(28>='Control Tower'!$B$68,'Control Tower'!$B$67*(1+'Control Tower'!$B$57)^2,0) | AE24: =IF(29>='Control Tower'!$B$68,'Control Tower'!$B$67*(1+'Control Tower'!$B$57)^2,0) | AF24: =IF(30>='Control Tower'!$B$68,'Control Tower'!$B$67*(1+'Control Tower'!$B$57)^2,0) | AG24: =IF(31>='Control Tower'!$B$68,'Control Tower'!$B$67*(1+'Control Tower'!$B$57)^2,0) | AH24: =IF(32>='Control Tower'!$B$68,'Control Tower'!$B$67*(1+'Control Tower'!$B$57)^2,0) | AI24: =IF(33>='Control Tower'!$B$68,'Control Tower'!$B$67*(1+'Control Tower'!$B$57)^2,0) | AJ24: =IF(34>='Control Tower'!$B$68,'Control Tower'!$B$67*(1+'Control Tower'!$B$57)^2,0) | AK24: =IF(35>='Control Tower'!$B$68,'Control Tower'!$B$67*(1+'Control Tower'!$B$57)^2,0) | AL24: =IF(36>='Control Tower'!$B$68,'Control Tower'!$B$67*(1+'Control Tower'!$B$57)^2,0)
A25: Silas Shelton - Executive Director (4000-0-A-0) | C25: =IF(1>='Control Tower'!$B$84,'Control Tower'!$B$83/12*(1+'Control Tower'!$B$57)^0*(1+'Control Tower'!$B$39),0) | D25: =IF(2>='Control Tower'!$B$84,'Control Tower'!$B$83/12*(1+'Control Tower'!$B$57)^0*(1+'Control Tower'!$B$39),0) | E25: =IF(3>='Control Tower'!$B$84,'Control Tower'!$B$83/12*(1+'Control Tower'!$B$57)^0*(1+'Control Tower'!$B$39),0) | F25: =IF(4>='Control Tower'!$B$84,'Control Tower'!$B$83/12*(1+'Control Tower'!$B$57)^0*(1+'Control Tower'!$B$39),0) | G25: =IF(5>='Control Tower'!$B$84,'Control Tower'!$B$83/12*(1+'Control Tower'!$B$57)^0*(1+'Control Tower'!$B$39),0) | H25: =IF(6>='Control Tower'!$B$84,'Control Tower'!$B$83/12*(1+'Control Tower'!$B$57)^0*(1+'Control Tower'!$B$39),0) | I25: =IF(7>='Control Tower'!$B$84,'Control Tower'!$B$83/12*(1+'Control Tower'!$B$57)^0*(1+'Control Tower'!$B$39),0) | J25: =IF(8>='Control Tower'!$B$84,'Control Tower'!$B$83/12*(1+'Control Tower'!$B$57)^0*(1+'Control Tower'!$B$39),0) | K25: =IF(9>='Control Tower'!$B$84,'Control Tower'!$B$83/12*(1+'Control Tower'!$B$57)^0*(1+'Control Tower'!$B$39),0) | L25: =IF(10>='Control Tower'!$B$84,'Control Tower'!$B$83/12*(1+'Control Tower'!$B$57)^0*(1+'Control Tower'!$B$39),0) | M25: =IF(11>='Control Tower'!$B$84,'Control Tower'!$B$83/12*(1+'Control Tower'!$B$57)^0*(1+'Control Tower'!$B$39),0) | N25: =IF(12>='Control Tower'!$B$84,'Control Tower'!$B$83/12*(1+'Control Tower'!$B$57)^0*(1+'Control Tower'!$B$39),0) | O25: =IF(13>='Control Tower'!$B$84,'Control Tower'!$B$83/12*(1+'Control Tower'!$B$57)^1*(1+'Control Tower'!$B$39),0) | P25: =IF(14>='Control Tower'!$B$84,'Control Tower'!$B$83/12*(1+'Control Tower'!$B$57)^1*(1+'Control Tower'!$B$39),0) | Q25: =IF(15>='Control Tower'!$B$84,'Control Tower'!$B$83/12*(1+'Control Tower'!$B$57)^1*(1+'Control Tower'!$B$39),0) | R25: =IF(16>='Control Tower'!$B$84,'Control Tower'!$B$83/12*(1+'Control Tower'!$B$57)^1*(1+'Control Tower'!$B$39),0) | S25: =IF(17>='Control Tower'!$B$84,'Control Tower'!$B$83/12*(1+'Control Tower'!$B$57)^1*(1+'Control Tower'!$B$39),0) | T25: =IF(18>='Control Tower'!$B$84,'Control Tower'!$B$83/12*(1+'Control Tower'!$B$57)^1*(1+'Control Tower'!$B$39),0) | U25: =IF(19>='Control Tower'!$B$84,'Control Tower'!$B$83/12*(1+'Control Tower'!$B$57)^1*(1+'Control Tower'!$B$39),0) | V25: =IF(20>='Control Tower'!$B$84,'Control Tower'!$B$83/12*(1+'Control Tower'!$B$57)^1*(1+'Control Tower'!$B$39),0) | W25: =IF(21>='Control Tower'!$B$84,'Control Tower'!$B$83/12*(1+'Control Tower'!$B$57)^1*(1+'Control Tower'!$B$39),0) | X25: =IF(22>='Control Tower'!$B$84,'Control Tower'!$B$83/12*(1+'Control Tower'!$B$57)^1*(1+'Control Tower'!$B$39),0) | Y25: =IF(23>='Control Tower'!$B$84,'Control Tower'!$B$83/12*(1+'Control Tower'!$B$57)^1*(1+'Control Tower'!$B$39),0) | Z25: =IF(24>='Control Tower'!$B$84,'Control Tower'!$B$83/12*(1+'Control Tower'!$B$57)^1*(1+'Control Tower'!$B$39),0) | AA25: =IF(25>='Control Tower'!$B$84,'Control Tower'!$B$83/12*(1+'Control Tower'!$B$57)^2*(1+'Control Tower'!$B$39),0) | AB25: =IF(26>='Control Tower'!$B$84,'Control Tower'!$B$83/12*(1+'Control Tower'!$B$57)^2*(1+'Control Tower'!$B$39),0) | AC25: =IF(27>='Control Tower'!$B$84,'Control Tower'!$B$83/12*(1+'Control Tower'!$B$57)^2*(1+'Control Tower'!$B$39),0) | AD25: =IF(28>='Control Tower'!$B$84,'Control Tower'!$B$83/12*(1+'Control Tower'!$B$57)^2*(1+'Control Tower'!$B$39),0) | AE25: =IF(29>='Control Tower'!$B$84,'Control Tower'!$B$83/12*(1+'Control Tower'!$B$57)^2*(1+'Control Tower'!$B$39),0) | AF25: =IF(30>='Control Tower'!$B$84,'Control Tower'!$B$83/12*(1+'Control Tower'!$B$57)^2*(1+'Control Tower'!$B$39),0) | AG25: =IF(31>='Control Tower'!$B$84,'Control Tower'!$B$83/12*(1+'Control Tower'!$B$57)^2*(1+'Control Tower'!$B$39),0) | AH25: =IF(32>='Control Tower'!$B$84,'Control Tower'!$B$83/12*(1+'Control Tower'!$B$57)^2*(1+'Control Tower'!$B$39),0) | AI25: =IF(33>='Control Tower'!$B$84,'Control Tower'!$B$83/12*(1+'Control Tower'!$B$57)^2*(1+'Control Tower'!$B$39),0) | AJ25: =IF(34>='Control Tower'!$B$84,'Control Tower'!$B$83/12*(1+'Control Tower'!$B$57)^2*(1+'Control Tower'!$B$39),0) | AK25: =IF(35>='Control Tower'!$B$84,'Control Tower'!$B$83/12*(1+'Control Tower'!$B$57)^2*(1+'Control Tower'!$B$39),0) | AL25: =IF(36>='Control Tower'!$B$84,'Control Tower'!$B$83/12*(1+'Control Tower'!$B$57)^2*(1+'Control Tower'!$B$39),0)
A26: Dana Davenport - Director of Nursing (4000-0-C-0) | C26: =IF(1>='Control Tower'!$B$86,'Control Tower'!$B$85/12*(1+'Control Tower'!$B$57)^0*(1+'Control Tower'!$B$39),0) | D26: =IF(2>='Control Tower'!$B$86,'Control Tower'!$B$85/12*(1+'Control Tower'!$B$57)^0*(1+'Control Tower'!$B$39),0) | E26: =IF(3>='Control Tower'!$B$86,'Control Tower'!$B$85/12*(1+'Control Tower'!$B$57)^0*(1+'Control Tower'!$B$39),0) | F26: =IF(4>='Control Tower'!$B$86,'Control Tower'!$B$85/12*(1+'Control Tower'!$B$57)^0*(1+'Control Tower'!$B$39),0) | G26: =IF(5>='Control Tower'!$B$86,'Control Tower'!$B$85/12*(1+'Control Tower'!$B$57)^0*(1+'Control Tower'!$B$39),0) | H26: =IF(6>='Control Tower'!$B$86,'Control Tower'!$B$85/12*(1+'Control Tower'!$B$57)^0*(1+'Control Tower'!$B$39),0) | I26: =IF(7>='Control Tower'!$B$86,'Control Tower'!$B$85/12*(1+'Control Tower'!$B$57)^0*(1+'Control Tower'!$B$39),0) | J26: =IF(8>='Control Tower'!$B$86,'Control Tower'!$B$85/12*(1+'Control Tower'!$B$57)^0*(1+'Control Tower'!$B$39),0) | K26: =IF(9>='Control Tower'!$B$86,'Control Tower'!$B$85/12*(1+'Control Tower'!$B$57)^0*(1+'Control Tower'!$B$39),0) | L26: =IF(10>='Control Tower'!$B$86,'Control Tower'!$B$85/12*(1+'Control Tower'!$B$57)^0*(1+'Control Tower'!$B$39),0) | M26: =IF(11>='Control Tower'!$B$86,'Control Tower'!$B$85/12*(1+'Control Tower'!$B$57)^0*(1+'Control Tower'!$B$39),0) | N26: =IF(12>='Control Tower'!$B$86,'Control Tower'!$B$85/12*(1+'Control Tower'!$B$57)^0*(1+'Control Tower'!$B$39),0) | O26: =IF(13>='Control Tower'!$B$86,'Control Tower'!$B$85/12*(1+'Control Tower'!$B$57)^1*(1+'Control Tower'!$B$39),0) | P26: =IF(14>='Control Tower'!$B$86,'Control Tower'!$B$85/12*(1+'Control Tower'!$B$57)^1*(1+'Control Tower'!$B$39),0) | Q26: =IF(15>='Control Tower'!$B$86,'Control Tower'!$B$85/12*(1+'Control Tower'!$B$57)^1*(1+'Control Tower'!$B$39),0) | R26: =IF(16>='Control Tower'!$B$86,'Control Tower'!$B$85/12*(1+'Control Tower'!$B$57)^1*(1+'Control Tower'!$B$39),0) | S26: =IF(17>='Control Tower'!$B$86,'Control Tower'!$B$85/12*(1+'Control Tower'!$B$57)^1*(1+'Control Tower'!$B$39),0) | T26: =IF(18>='Control Tower'!$B$86,'Control Tower'!$B$85/12*(1+'Control Tower'!$B$57)^1*(1+'Control Tower'!$B$39),0) | U26: =IF(19>='Control Tower'!$B$86,'Control Tower'!$B$85/12*(1+'Control Tower'!$B$57)^1*(1+'Control Tower'!$B$39),0) | V26: =IF(20>='Control Tower'!$B$86,'Control Tower'!$B$85/12*(1+'Control Tower'!$B$57)^1*(1+'Control Tower'!$B$39),0) | W26: =IF(21>='Control Tower'!$B$86,'Control Tower'!$B$85/12*(1+'Control Tower'!$B$57)^1*(1+'Control Tower'!$B$39),0) | X26: =IF(22>='Control Tower'!$B$86,'Control Tower'!$B$85/12*(1+'Control Tower'!$B$57)^1*(1+'Control Tower'!$B$39),0) | Y26: =IF(23>='Control Tower'!$B$86,'Control Tower'!$B$85/12*(1+'Control Tower'!$B$57)^1*(1+'Control Tower'!$B$39),0) | Z26: =IF(24>='Control Tower'!$B$86,'Control Tower'!$B$85/12*(1+'Control Tower'!$B$57)^1*(1+'Control Tower'!$B$39),0) | AA26: =IF(25>='Control Tower'!$B$86,'Control Tower'!$B$85/12*(1+'Control Tower'!$B$57)^2*(1+'Control Tower'!$B$39),0) | AB26: =IF(26>='Control Tower'!$B$86,'Control Tower'!$B$85/12*(1+'Control Tower'!$B$57)^2*(1+'Control Tower'!$B$39),0) | AC26: =IF(27>='Control Tower'!$B$86,'Control Tower'!$B$85/12*(1+'Control Tower'!$B$57)^2*(1+'Control Tower'!$B$39),0) | AD26: =IF(28>='Control Tower'!$B$86,'Control Tower'!$B$85/12*(1+'Control Tower'!$B$57)^2*(1+'Control Tower'!$B$39),0) | AE26: =IF(29>='Control Tower'!$B$86,'Control Tower'!$B$85/12*(1+'Control Tower'!$B$57)^2*(1+'Control Tower'!$B$39),0) | AF26: =IF(30>='Control Tower'!$B$86,'Control Tower'!$B$85/12*(1+'Control Tower'!$B$57)^2*(1+'Control Tower'!$B$39),0) | AG26: =IF(31>='Control Tower'!$B$86,'Control Tower'!$B$85/12*(1+'Control Tower'!$B$57)^2*(1+'Control Tower'!$B$39),0) | AH26: =IF(32>='Control Tower'!$B$86,'Control Tower'!$B$85/12*(1+'Control Tower'!$B$57)^2*(1+'Control Tower'!$B$39),0) | AI26: =IF(33>='Control Tower'!$B$86,'Control Tower'!$B$85/12*(1+'Control Tower'!$B$57)^2*(1+'Control Tower'!$B$39),0) | AJ26: =IF(34>='Control Tower'!$B$86,'Control Tower'!$B$85/12*(1+'Control Tower'!$B$57)^2*(1+'Control Tower'!$B$39),0) | AK26: =IF(35>='Control Tower'!$B$86,'Control Tower'!$B$85/12*(1+'Control Tower'!$B$57)^2*(1+'Control Tower'!$B$39),0) | AL26: =IF(36>='Control Tower'!$B$86,'Control Tower'!$B$85/12*(1+'Control Tower'!$B$57)^2*(1+'Control Tower'!$B$39),0)
A27: Brad Woodard - Director of Sales (4000-0-M-0) | C27: =IF(1>='Control Tower'!$B$88,'Control Tower'!$B$87/12*(1+'Control Tower'!$B$57)^0*(1+'Control Tower'!$B$39),0) | D27: =IF(2>='Control Tower'!$B$88,'Control Tower'!$B$87/12*(1+'Control Tower'!$B$57)^0*(1+'Control Tower'!$B$39),0) | E27: =IF(3>='Control Tower'!$B$88,'Control Tower'!$B$87/12*(1+'Control Tower'!$B$57)^0*(1+'Control Tower'!$B$39),0) | F27: =IF(4>='Control Tower'!$B$88,'Control Tower'!$B$87/12*(1+'Control Tower'!$B$57)^0*(1+'Control Tower'!$B$39),0) | G27: =IF(5>='Control Tower'!$B$88,'Control Tower'!$B$87/12*(1+'Control Tower'!$B$57)^0*(1+'Control Tower'!$B$39),0) | H27: =IF(6>='Control Tower'!$B$88,'Control Tower'!$B$87/12*(1+'Control Tower'!$B$57)^0*(1+'Control Tower'!$B$39),0) | I27: =IF(7>='Control Tower'!$B$88,'Control Tower'!$B$87/12*(1+'Control Tower'!$B$57)^0*(1+'Control Tower'!$B$39),0) | J27: =IF(8>='Control Tower'!$B$88,'Control Tower'!$B$87/12*(1+'Control Tower'!$B$57)^0*(1+'Control Tower'!$B$39),0) | K27: =IF(9>='Control Tower'!$B$88,'Control Tower'!$B$87/12*(1+'Control Tower'!$B$57)^0*(1+'Control Tower'!$B$39),0) | L27: =IF(10>='Control Tower'!$B$88,'Control Tower'!$B$87/12*(1+'Control Tower'!$B$57)^0*(1+'Control Tower'!$B$39),0) | M27: =IF(11>='Control Tower'!$B$88,'Control Tower'!$B$87/12*(1+'Control Tower'!$B$57)^0*(1+'Control Tower'!$B$39),0) | N27: =IF(12>='Control Tower'!$B$88,'Control Tower'!$B$87/12*(1+'Control Tower'!$B$57)^0*(1+'Control Tower'!$B$39),0) | O27: =IF(13>='Control Tower'!$B$88,'Control Tower'!$B$87/12*(1+'Control Tower'!$B$57)^1*(1+'Control Tower'!$B$39),0) | P27: =IF(14>='Control Tower'!$B$88,'Control Tower'!$B$87/12*(1+'Control Tower'!$B$57)^1*(1+'Control Tower'!$B$39),0) | Q27: =IF(15>='Control Tower'!$B$88,'Control Tower'!$B$87/12*(1+'Control Tower'!$B$57)^1*(1+'Control Tower'!$B$39),0) | R27: =IF(16>='Control Tower'!$B$88,'Control Tower'!$B$87/12*(1+'Control Tower'!$B$57)^1*(1+'Control Tower'!$B$39),0) | S27: =IF(17>='Control Tower'!$B$88,'Control Tower'!$B$87/12*(1+'Control Tower'!$B$57)^1*(1+'Control Tower'!$B$39),0) | T27: =IF(18>='Control Tower'!$B$88,'Control Tower'!$B$87/12*(1+'Control Tower'!$B$57)^1*(1+'Control Tower'!$B$39),0) | U27: =IF(19>='Control Tower'!$B$88,'Control Tower'!$B$87/12*(1+'Control Tower'!$B$57)^1*(1+'Control Tower'!$B$39),0) | V27: =IF(20>='Control Tower'!$B$88,'Control Tower'!$B$87/12*(1+'Control Tower'!$B$57)^1*(1+'Control Tower'!$B$39),0) | W27: =IF(21>='Control Tower'!$B$88,'Control Tower'!$B$87/12*(1+'Control Tower'!$B$57)^1*(1+'Control Tower'!$B$39),0) | X27: =IF(22>='Control Tower'!$B$88,'Control Tower'!$B$87/12*(1+'Control Tower'!$B$57)^1*(1+'Control Tower'!$B$39),0) | Y27: =IF(23>='Control Tower'!$B$88,'Control Tower'!$B$87/12*(1+'Control Tower'!$B$57)^1*(1+'Control Tower'!$B$39),0) | Z27: =IF(24>='Control Tower'!$B$88,'Control Tower'!$B$87/12*(1+'Control Tower'!$B$57)^1*(1+'Control Tower'!$B$39),0) | AA27: =IF(25>='Control Tower'!$B$88,'Control Tower'!$B$87/12*(1+'Control Tower'!$B$57)^2*(1+'Control Tower'!$B$39),0) | AB27: =IF(26>='Control Tower'!$B$88,'Control Tower'!$B$87/12*(1+'Control Tower'!$B$57)^2*(1+'Control Tower'!$B$39),0) | AC27: =IF(27>='Control Tower'!$B$88,'Control Tower'!$B$87/12*(1+'Control Tower'!$B$57)^2*(1+'Control Tower'!$B$39),0) | AD27: =IF(28>='Control Tower'!$B$88,'Control Tower'!$B$87/12*(1+'Control Tower'!$B$57)^2*(1+'Control Tower'!$B$39),0) | AE27: =IF(29>='Control Tower'!$B$88,'Control Tower'!$B$87/12*(1+'Control Tower'!$B$57)^2*(1+'Control Tower'!$B$39),0) | AF27: =IF(30>='Control Tower'!$B$88,'Control Tower'!$B$87/12*(1+'Control Tower'!$B$57)^2*(1+'Control Tower'!$B$39),0) | AG27: =IF(31>='Control Tower'!$B$88,'Control Tower'!$B$87/12*(1+'Control Tower'!$B$57)^2*(1+'Control Tower'!$B$39),0) | AH27: =IF(32>='Control Tower'!$B$88,'Control Tower'!$B$87/12*(1+'Control Tower'!$B$57)^2*(1+'Control Tower'!$B$39),0) | AI27: =IF(33>='Control Tower'!$B$88,'Control Tower'!$B$87/12*(1+'Control Tower'!$B$57)^2*(1+'Control Tower'!$B$39),0) | AJ27: =IF(34>='Control Tower'!$B$88,'Control Tower'!$B$87/12*(1+'Control Tower'!$B$57)^2*(1+'Control Tower'!$B$39),0) | AK27: =IF(35>='Control Tower'!$B$88,'Control Tower'!$B$87/12*(1+'Control Tower'!$B$57)^2*(1+'Control Tower'!$B$39),0) | AL27: =IF(36>='Control Tower'!$B$88,'Control Tower'!$B$87/12*(1+'Control Tower'!$B$57)^2*(1+'Control Tower'!$B$39),0)
A28: Rhonda Smith - ADON / Intake (4000-0-I-1) | C28: =IF(1>='Control Tower'!$B$90,'Control Tower'!$B$89/12*(1+'Control Tower'!$B$57)^0*(1+'Control Tower'!$B$39),0) | D28: =IF(2>='Control Tower'!$B$90,'Control Tower'!$B$89/12*(1+'Control Tower'!$B$57)^0*(1+'Control Tower'!$B$39),0) | E28: =IF(3>='Control Tower'!$B$90,'Control Tower'!$B$89/12*(1+'Control Tower'!$B$57)^0*(1+'Control Tower'!$B$39),0) | F28: =IF(4>='Control Tower'!$B$90,'Control Tower'!$B$89/12*(1+'Control Tower'!$B$57)^0*(1+'Control Tower'!$B$39),0) | G28: =IF(5>='Control Tower'!$B$90,'Control Tower'!$B$89/12*(1+'Control Tower'!$B$57)^0*(1+'Control Tower'!$B$39),0) | H28: =IF(6>='Control Tower'!$B$90,'Control Tower'!$B$89/12*(1+'Control Tower'!$B$57)^0*(1+'Control Tower'!$B$39),0) | I28: =IF(7>='Control Tower'!$B$90,'Control Tower'!$B$89/12*(1+'Control Tower'!$B$57)^0*(1+'Control Tower'!$B$39),0) | J28: =IF(8>='Control Tower'!$B$90,'Control Tower'!$B$89/12*(1+'Control Tower'!$B$57)^0*(1+'Control Tower'!$B$39),0) | K28: =IF(9>='Control Tower'!$B$90,'Control Tower'!$B$89/12*(1+'Control Tower'!$B$57)^0*(1+'Control Tower'!$B$39),0) | L28: =IF(10>='Control Tower'!$B$90,'Control Tower'!$B$89/12*(1+'Control Tower'!$B$57)^0*(1+'Control Tower'!$B$39),0) | M28: =IF(11>='Control Tower'!$B$90,'Control Tower'!$B$89/12*(1+'Control Tower'!$B$57)^0*(1+'Control Tower'!$B$39),0) | N28: =IF(12>='Control Tower'!$B$90,'Control Tower'!$B$89/12*(1+'Control Tower'!$B$57)^0*(1+'Control Tower'!$B$39),0) | O28: =IF(13>='Control Tower'!$B$90,'Control Tower'!$B$89/12*(1+'Control Tower'!$B$57)^1*(1+'Control Tower'!$B$39),0) | P28: =IF(14>='Control Tower'!$B$90,'Control Tower'!$B$89/12*(1+'Control Tower'!$B$57)^1*(1+'Control Tower'!$B$39),0) | Q28: =IF(15>='Control Tower'!$B$90,'Control Tower'!$B$89/12*(1+'Control Tower'!$B$57)^1*(1+'Control Tower'!$B$39),0) | R28: =IF(16>='Control Tower'!$B$90,'Control Tower'!$B$89/12*(1+'Control Tower'!$B$57)^1*(1+'Control Tower'!$B$39),0) | S28: =IF(17>='Control Tower'!$B$90,'Control Tower'!$B$89/12*(1+'Control Tower'!$B$57)^1*(1+'Control Tower'!$B$39),0) | T28: =IF(18>='Control Tower'!$B$90,'Control Tower'!$B$89/12*(1+'Control Tower'!$B$57)^1*(1+'Control Tower'!$B$39),0) | U28: =IF(19>='Control Tower'!$B$90,'Control Tower'!$B$89/12*(1+'Control Tower'!$B$57)^1*(1+'Control Tower'!$B$39),0) | V28: =IF(20>='Control Tower'!$B$90,'Control Tower'!$B$89/12*(1+'Control Tower'!$B$57)^1*(1+'Control Tower'!$B$39),0) | W28: =IF(21>='Control Tower'!$B$90,'Control Tower'!$B$89/12*(1+'Control Tower'!$B$57)^1*(1+'Control Tower'!$B$39),0) | X28: =IF(22>='Control Tower'!$B$90,'Control Tower'!$B$89/12*(1+'Control Tower'!$B$57)^1*(1+'Control Tower'!$B$39),0) | Y28: =IF(23>='Control Tower'!$B$90,'Control Tower'!$B$89/12*(1+'Control Tower'!$B$57)^1*(1+'Control Tower'!$B$39),0) | Z28: =IF(24>='Control Tower'!$B$90,'Control Tower'!$B$89/12*(1+'Control Tower'!$B$57)^1*(1+'Control Tower'!$B$39),0) | AA28: =IF(25>='Control Tower'!$B$90,'Control Tower'!$B$89/12*(1+'Control Tower'!$B$57)^2*(1+'Control Tower'!$B$39),0) | AB28: =IF(26>='Control Tower'!$B$90,'Control Tower'!$B$89/12*(1+'Control Tower'!$B$57)^2*(1+'Control Tower'!$B$39),0) | AC28: =IF(27>='Control Tower'!$B$90,'Control Tower'!$B$89/12*(1+'Control Tower'!$B$57)^2*(1+'Control Tower'!$B$39),0) | AD28: =IF(28>='Control Tower'!$B$90,'Control Tower'!$B$89/12*(1+'Control Tower'!$B$57)^2*(1+'Control Tower'!$B$39),0) | AE28: =IF(29>='Control Tower'!$B$90,'Control Tower'!$B$89/12*(1+'Control Tower'!$B$57)^2*(1+'Control Tower'!$B$39),0) | AF28: =IF(30>='Control Tower'!$B$90,'Control Tower'!$B$89/12*(1+'Control Tower'!$B$57)^2*(1+'Control Tower'!$B$39),0) | AG28: =IF(31>='Control Tower'!$B$90,'Control Tower'!$B$89/12*(1+'Control Tower'!$B$57)^2*(1+'Control Tower'!$B$39),0) | AH28: =IF(32>='Control Tower'!$B$90,'Control Tower'!$B$89/12*(1+'Control Tower'!$B$57)^2*(1+'Control Tower'!$B$39),0) | AI28: =IF(33>='Control Tower'!$B$90,'Control Tower'!$B$89/12*(1+'Control Tower'!$B$57)^2*(1+'Control Tower'!$B$39),0) | AJ28: =IF(34>='Control Tower'!$B$90,'Control Tower'!$B$89/12*(1+'Control Tower'!$B$57)^2*(1+'Control Tower'!$B$39),0) | AK28: =IF(35>='Control Tower'!$B$90,'Control Tower'!$B$89/12*(1+'Control Tower'!$B$57)^2*(1+'Control Tower'!$B$39),0) | AL28: =IF(36>='Control Tower'!$B$90,'Control Tower'!$B$89/12*(1+'Control Tower'!$B$57)^2*(1+'Control Tower'!$B$39),0)
