Workbook

Sheet Assumptions
A1: AZALEA HOSPICE - REFUGE OPERATING MODEL
A2: Assumptions - ALL editable cells are yellow/blue. Everything downstream is formulas.
A4: A. RATES & PAYER MIX
A5: Medicare blended NET rate ($/patient-day) | B5: 181
A6: Medicaid blended NET rate ($/patient-day) | B6: 155
A7: Medicare share of patient days | B7: 0.95
A8: Rate escalation (annual, yrs 2-3) | B8: 0.025
A9: Average days per month | B9: 30.4
A11: B. CENSUS ENGINE (admissions are the operating lever - edit rows on Census tab)
A12: Average length of stay (days) | B12: 82
A13: Deaths as share of separations | B13: 0.55
A14: SCENARIO: census capture (1.00 = plan) | B14: 1
A16: C. BILLING & COLLECTIONS
A17: Days lost per late NOE (per affected admit) | B17: 5
A18: Late-NOE rate (share of admits) | B18: 0.02
A19: CHOW payment hold (months; 0/1/2) | B19: 1 | D19: MAC hold on first claims after ownership change
A20: Base collection lag (months) | B20: 1
A22: D. PAYROLL & BENEFITS (per-employee register on Payroll tab)
A23: Payroll burden (taxes/WC) on W-2 + PRN | B23: 0.1827
A24: Health insurance ($/covered head/mo) | B24: 550
A25: Health waiting period (months) | B25: 3
A26: SCENARIO: payroll adjustment (+/- %) | B26: 0
A27: Salary escalation (annual, yrs 2-3) | B27: 0.03
A28: Owner salary deferral % (0 = off; 0.40 = lever on) | B28: 0
A29: Deferral window ends (month #) | B29: 6
A30: Medical director ($/mo, contracted) | B30: 4000
A31: 2nd medical director ($/mo) | B31: 5000
A32: 2nd med director start month | B32: 18
A33: Bookkeeping/admin support (annual) | B33: 34000
A35: E. PRN PER-VISIT ROSTER (census-driven)
A36: Role | B36: Visits/pt/mo | C36: $/visit
A37: PRN On-Call LVN (Kendricks-Tuck, Foster) | B37: 0.6 | C37: 100
A38: PRN Chaplain (Ector, Johnson) | B38: 0.75 | C38: 75
A39: PRN Social Worker (Sanders) | B39: 1 | C39: 75
A40: PRN Nurse Practitioner (Rogers) | B40: 0.15 | C40: 200
A41: PRN CNA / per-visit (Henson, Mills) | B41: 0.5 | C41: 21
A43: F. PATIENT COSTS & NEW (BLIND-SPOT) LINES
A44: Patient costs $/patient-day (pharmacy+supplies+DME) | B44: 8.99 | D44: paid net-30 (following month)
A45: Mileage $/ADC/month | B45: 136.36 | D45: ~$3,000/mo at 22 ADC; paid following month
A46: Billing + QR fees (% of net revenue) | B46: 0.023
...

Sheet Census
A1: AZALEA HOSPICE - REFUGE OPERATING MODEL
A2: Census engine - admissions are BLUE inputs; flows follow ALOS. Weekly (13) then monthly (36).
A4: WEEKLY - first 13 weeks (Jul-Sep 2026)
C5: W1 | D5: W2 | E5: W3 | F5: W4 | G5: W5 | H5: W6 | I5: W7 | J5: W8 | K5: W9 | L5: W10 | M5: W11 | N5: W12 | O5: W13
A6: Admissions (per week) [INPUT] | C6: 12 | D6: 8.02 | E6: 5.62 | F6: 4.26 | G6: 2.76 | H6: 2.61 | I6: 2.65 | J6: 2.68 | K6: 2.61 | L6: 3.04 | M6: 3 | N6: 3.05 | O6: 3.1
A7: Separations (census x 7/ALOS) | C7: =0*7/'Assumptions'!$B$12 | D7: =C9*7/'Assumptions'!$B$12 | E7: =D9*7/'Assumptions'!$B$12 | F7: =E9*7/'Assumptions'!$B$12 | G7: =F9*7/'Assumptions'!$B$12 | H7: =G9*7/'Assumptions'!$B$12 | I7: =H9*7/'Assumptions'!$B$12 | J7: =I9*7/'Assumptions'!$B$12 | K7: =J9*7/'Assumptions'!$B$12 | ... O7: =N9*7/'Assumptions'!$B$12
A8: of which deaths | C8: =C7*'Assumptions'!$B$13 | D8: =D7*'Assumptions'!$B$13 | E8: =E7*'Assumptions'!$B$13 | F8: =F7*'Assumptions'!$B$13 | G8: =G7*'Assumptions'!$B$13 | H8: =H7*'Assumptions'!$B$13 | I8: =I7*'Assumptions'!$B$13 | J8: =J7*'Assumptions'!$B$13 | ... O8: =O7*'Assumptions'!$B$13
A9: End-of-week census | C9: =0+C6-C7 | D9: =C9+D6-D7 | E9: =D9+E6-E7 | F9: =E9+F6-F7 | G9: =F9+G6-G7 | H9: =G9+H6-H7 | I9: =H9+I6-I7 | J9: =I9+J6-J7 | K9: =J9+K6-K7 | ... O9: =N9+O6-O7
A10: Average census (week) | C10: =(0+C9)/2*'Assumptions'!$B$14 | D10: =(C9+D9)/2*'Assumptions'!$B$14 | E10: =(D9+E9)/2*'Assumptions'!$B$14 | F10: =(E9+F9)/2*'Assumptions'!$B$14 | G10: =(F9+G9)/2*'Assumptions'!$B$14 | H10: =(G9+H9)/2*'Assumptions'!$B$14 | I10: =(H9+I9)/2*'Assumptions'!$B$14 | J10: =(I9+J9)/2*'Assumptions'!$B$14 | K10: =(J9+K9)/2*'Assumptions'!$B$14 | ... O10: =(N9+O9)/2*'Assumptions'!$B$14
A11: Patient days (week) | C11: =C10*7 | D11: =D10*7 | E11: =E10*7 | F11: =F10*7 | G11: =G10*7 | H11: =H10*7 | I11: =I10*7 | J11: =J10*7 | ... O11: =O10*7
A13: MONTHLY - 36 months (M1-M3 tie to the weekly engine)
A14: Month # | C14: 1 | D14: 2 | E14: 3 | F14: 4 | G14: 5 | H14: 6 | I14: 7 | J14: 8 | K14: 9 | L14: 10 | M14: 11 | N14: 12 | O14: 13 | P14: 14 | Q14: 15 | R14: 16 | S14: 17 | T14: 18 | U14: 19 | V14: 20 | W14: 21 | X14: 22 | Y14: 23 | Z14: 24 | AA14: 25 | AB14: 26 | AC14: 27 | AD14: 28 | AE14: 29 | AF14: 30 | AG14: 31 | AH14: 32 | AI14: 33 | AJ14: 34 | AK14: 35 | AL14: 36
C15: Jul-26 | D15: Aug-26 | E15: Sep-26 | F15: Oct-26 | G15: Nov-26 | H15: Dec-26 | I15: Jan-27 | J15: Feb-27 | K15: Mar-27 | L15: Apr-27 | M15: May-27 | N15: Jun-27 | O15: Jul-27 | P15: Aug-27 | Q15: Sep-27 | R15: Oct-27 | S15: Nov-27 | T15: Dec-27 | U15: Jan-28 | V15: Feb-28 | W15: Mar-28 | X15: Apr-28 | Y15: May-28 | Z15: Jun-28 | AA15: Jul-28 | AB15: Aug-28 | AC15: Sep-28 | AD15: Oct-28 | AE15: Nov-28 | AF15: Dec-28 | AG15: Jan-29 | AH15: Feb-29 | AI15: Mar-29 | AJ15: Apr-29 | AK15: May-29 | AL15: Jun-29
A16: Admissions (per month) [INPUT M4+] | C16: =SUM(C6:F6) | D16: =SUM(G6:K6) | E16: =SUM(L6:O6) | F16: 13.58 | G16: 13.31 | H16: 13.79 | I16: 13.78 | J16: 14.17 | K16: 14.41 | L16: 14.7 | M16: 15.1 | N16: 15.33 | O16: 15.63 | P16: 16.03 | Q16: 16.26 | R16: 16.56 | S16: 16.95 | T16: 17.19 | U16: 17.48 | V16: 17.88 | W16: 18.11 | X16: 18.41 | Y16: 18.81 | Z16: 19.04 | AA16: 19.04 | AB16: 19.22 | AC16: 19.41 | AD16: 19.59 | AE16: 19.78 | AF16: 19.96 | AG16: 20.15 | AH16: 20.33 | AI16: 20.52 | AJ16: 20.7 | AK16: 20.89 | AL16: 21.08
A17: Separations | C17: =SUM(C7:F7) | D17: =SUM(G7:K7) | E17: =SUM(L7:O7) | F17: =E19*'Assumptions'!$B$9/'Assumptions'!$B$12 | G17: =F19*'Assumptions'!$B$9/'Assumptions'!$B$12 | H17: =G19*'Assumptions'!$B$9/'Assumptions'!$B$12 | I17: =H19*'Assumptions'!$B$9/'Assumptions'!$B$12 | J17: =I19*'Assumptions'!$B$9/'Assumptions'!$B$12 | K17: =J19*'Assumptions'!$B$9/'Assumptions'!$B$12 | L17: =K19*'Assumptions'!$B$9/'Assumptions'!$B$12 | M17: =L19*'Assumptions'!$B$9/'Assumptions'!$B$12 | ... AL17: =AK19*'Assumptions'!$B$9/'Assumptions'!$B$12
A18: of which deaths | C18: =C17*'Assumptions'!$B$13 | D18: =D17*'Assumptions'!$B$13 | E18: =E17*'Assumptions'!$B$13 | F18: =F17*'Assumptions'!$B$13 | G18: =G17*'Assumptions'!$B$13 | H18: =H17*'Assumptions'!$B$13 | I18: =I17*'Assumptions'!$B$13 | J18: =J17*'Assumptions'!$B$13 | ... AL18: =AL17*'Assumptions'!$B$13
A19: End-of-month census | C19: =F9 | D19: =K9 | E19: =O9 | F19: =E19+F16-F17 | G19: =F19+G16-G17 | H19: =G19+H16-H17 | I19: =H19+I16-I17 | J19: =I19+J16-J17 | K19: =J19+K16-K17 | L19: =K19+L16-L17 | M19: =L19+M16-M17 | ... AL19: =AK19+AL16-AL17
A20: ADC (avg daily census, x capture) | C20: =AVERAGE(C9:F9)*'Assumptions'!$B$14 | D20: =AVERAGE(G9:K9)*'Assumptions'!$B$14 | E20: =AVERAGE(L9:O9)*'Assumptions'!$B$14 | F20: =(E19+F19)/2*'Assumptions'!$B$14 | G20: =(F19+G19)/2*'Assumptions'!$B$14 | H20: =(G19+H19)/2*'Assumptions'!$B$14 | I20: =(H19+I19)/2*'Assumptions'!$B$14 | J20: =(I19+J19)/2*'Assumptions'!$B$14 | K20: =(J19+K19)/2*'Assumptions'!$B$14 | L20: =(K19+L19)/2*'Assumptions'!$B$14 | M20: =(L19+M19)/2*'Assumptions'!$B$14 | ... AL20: =(AK19+AL19)/2*'Assumptions'!$B$14
A21: Patient days (month) | C21: =C20*'Assumptions'!$B$9 | D21: =D20*'Assumptions'!$B$9 | E21: =E20*'Assumptions'!$B$9 | F21: =F20*'Assumptions'!$B$9 | G21: =G20*'Assumptions'!$B$9 | H21: =H20*'Assumptions'!$B$9 | I21: =I20*'Assumptions'!$B$9 | J21: =J20*'Assumptions'!$B$9 | ... AL21: =AL20*'Assumptions'!$B$9

Sheet Collections
A1: AZALEA HOSPICE - REFUGE OPERATING MODEL
A2: Revenue earned -> cash collected. NOE losses, sequential claims, CHOW payment hold on first claims.
A4: Month # | C4: 1 | D4: 2 | E4: 3 | F4: 4 | G4: 5 | H4: 6 | I4: 7 | J4: 8 | K4: 9 | L4: 10 | M4: 11 | N4: 12 | O4: 13 | P4: 14 | Q4: 15 | R4: 16 | S4: 17 | T4: 18 | U4: 19 | V4: 20 | W4: 21 | X4: 22 | Y4: 23 | Z4: 24 | AA4: 25 | AB4: 26 | AC4: 27 | AD4: 28 | AE4: 29 | AF4: 30 | AG4: 31 | AH4: 32 | AI4: 33 | AJ4: 34 | AK4: 35 | AL4: 36
C5: Jul-26 | D5: Aug-26 | E5: Sep-26 | F5: Oct-26 | G5: Nov-26 | H5: Dec-26 | I5: Jan-27 | J5: Feb-27 | K5: Mar-27 | L5: Apr-27 | M5: May-27 | N5: Jun-27 | O5: Jul-27 | P5: Aug-27 | Q5: Sep-27 | R5: Oct-27 | S5: Nov-27 | T5: Dec-27 | U5: Jan-28 | V5: Feb-28 | W5: Mar-28 | X5: Apr-28 | Y5: May-28 | Z5: Jun-28 | AA5: Jul-28 | AB5: Aug-28 | AC5: Sep-28 | AD5: Oct-28 | AE5: Nov-28 | AF5: Dec-28 | AG5: Jan-29 | AH5: Feb-29 | AI5: Mar-29 | AJ5: Apr-29 | AK5: May-29 | AL5: Jun-29
A6: Blended net rate ($/PD, escalated) | C6: =('Assumptions'!$B$7*'Assumptions'!$B$5+(1-'Assumptions'!$B$7)*'Assumptions'!$B$6)*(1+'Assumptions'!$B$8)^0 | D6: =('Assumptions'!$B$7*'Assumptions'!$B$5+(1-'Assumptions'!$B$7)*'Assumptions'!$B$6)*(1+'Assumptions'!$B$8)^0 | E6: =('Assumptions'!$B$7*'Assumptions'!$B$5+(1-'Assumptions'!$B$7)*'Assumptions'!$B$6)*(1+'Assumptions'!$B$8)^0 | F6: =('Assumptions'!$B$7*'Assumptions'!$B$5+(1-'Assumptions'!$B$7)*'Assumptions'!$B$6)*(1+'Assumptions'!$B$8)^0 | G6: =('Assumptions'!$B$7*'Assumptions'!$B$5+(1-'Assumptions'!$B$7)*'Assumptions'!$B$6)*(1+'Assumptions'!$B$8)^0 | H6: =('Assumptions'!$B$7*'Assumptions'!$B$5+(1-'Assumptions'!$B$7)*'Assumptions'!$B$6)*(1+'Assumptions'!$B$8)^0 | I6: =('Assumptions'!$B$7*'Assumptions'!$B$5+(1-'Assumptions'!$B$7)*'Assumptions'!$B$6)*(1+'Assumptions'!$B$8)^0 | J6: =('Assumptions'!$B$7*'Assumptions'!$B$5+(1-'Assumptions'!$B$7)*'Assumptions'!$B$6)*(1+'Assumptions'!$B$8)^0 | ... N6: =('Assumptions'!$B$7*'Assumptions'!$B$5+(1-'Assumptions'!$B$7)*'Assumptions'!$B$6)*(1+'Assumptions'!$B$8)^0 | O6: =('Assumptions'!$B$7*'Assumptions'!$B$5+(1-'Assumptions'!$B$7)*'Assumptions'!$B$6)*(1+'Assumptions'!$B$8)^1 | P6: =('Assumptions'!$B$7*'Assumptions'!$B$5+(1-'Assumptions'!$B$7)*'Assumptions'!$B$6)*(1+'Assumptions'!$B$8)^1 | Q6: =('Assumptions'!$B$7*'Assumptions'!$B$5+(1-'Assumptions'!$B$7)*'Assumptions'!$B$6)*(1+'Assumptions'!$B$8)^1 | R6: =('Assumptions'!$B$7*'Assumptions'!$B$5+(1-'Assumptions'!$B$7)*'Assumptions'!$B$6)*(1+'Assumptions'!$B$8)^1 | S6: =('Assumptions'!$B$7*'Assumptions'!$B$5+(1-'Assumptions'!$B$7)*'Assumptions'!$B$6)*(1+'Assumptions'!$B$8)^1 | T6: =('Assumptions'!$B$7*'Assumptions'!$B$5+(1-'Assumptions'!$B$7)*'Assumptions'!$B$6)*(1+'Assumptions'!$B$8)^1 | U6: =('Assumptions'!$B$7*'Assumptions'!$B$5+(1-'Assumptions'!$B$7)*'Assumptions'!$B$6)*(1+'Assumptions'!$B$8)^1 | V6: =('Assumptions'!$B$7*'Assumptions'!$B$5+(1-'Assumptions'!$B$7)*'Assumptions'!$B$6)*(1+'Assumptions'!$B$8)^1 | ... Z6: =('Assumptions'!$B$7*'Assumptions'!$B$5+(1-'Assumptions'!$B$7)*'Assumptions'!$B$6)*(1+'Assumptions'!$B$8)^1 | AA6: =('Assumptions'!$B$7*'Assumptions'!$B$5+(1-'Assumptions'!$B$7)*'Assumptions'!$B$6)*(1+'Assumptions'!$B$8)^2 | AB6: =('Assumptions'!$B$7*'Assumptions'!$B$5+(1-'Assumptions'!$B$7)*'Assumptions'!$B$6)*(1+'Assumptions'!$B$8)^2 | AC6: =('Assumptions'!$B$7*'Assumptions'!$B$5+(1-'Assumptions'!$B$7)*'Assumptions'!$B$6)*(1+'Assumptions'!$B$8)^2 | AD6: =('Assumptions'!$B$7*'Assumptions'!$B$5+(1-'Assumptions'!$B$7)*'Assumptions'!$B$6)*(1+'Assumptions'!$B$8)^2 | AE6: =('Assumptions'!$B$7*'Assumptions'!$B$5+(1-'Assumptions'!$B$7)*'Assumptions'!$B$6)*(1+'Assumptions'!$B$8)^2 | AF6: =('Assumptions'!$B$7*'Assumptions'!$B$5+(1-'Assumptions'!$B$7)*'Assumptions'!$B$6)*(1+'Assumptions'!$B$8)^2 | AG6: =('Assumptions'!$B$7*'Assumptions'!$B$5+(1-'Assumptions'!$B$7)*'Assumptions'!$B$6)*(1+'Assumptions'!$B$8)^2 | AH6: =('Assumptions'!$B$7*'Assumptions'!$B$5+(1-'Assumptions'!$B$7)*'Assumptions'!$B$6)*(1+'Assumptions'!$B$8)^2 | ... AL6: =('Assumptions'!$B$7*'Assumptions'!$B$5+(1-'Assumptions'!$B$7)*'Assumptions'!$B$6)*(1+'Assumptions'!$B$8)^2
A7: Revenue earned (PD x rate) | C7: =Census!C21*C6 | D7: =Census!D21*D6 | E7: =Census!E21*E6 | F7: =Census!F21*F6 | G7: =Census!G21*G6 | H7: =Census!H21*H6 | I7: =Census!I21*I6 | J7: =Census!J21*J6 | ... AL7: =Census!AL21*AL6
A8: less: NOE losses (late notices) | C8: =-Census!C16*'Assumptions'!$B$18*'Assumptions'!$B$17*C6 | D8: =-Census!D16*'Assumptions'!$B$18*'Assumptions'!$B$17*D6 | E8: =-Census!E16*'Assumptions'!$B$18*'Assumptions'!$B$17*E6 | F8: =-Census!F16*'Assumptions'!$B$18*'Assumptions'!$B$17*F6 | G8: =-Census!G16*'Assumptions'!$B$18*'Assumptions'!$B$17*G6 | H8: =-Census!H16*'Assumptions'!$B$18*'Assumptions'!$B$17*H6 | I8: =-Census!I16*'Assumptions'!$B$18*'Assumptions'!$B$17*I6 | J8: =-Census!J16*'Assumptions'!$B$18*'Assumptions'!$B$17*J6 | ... AL8: =-Census!AL16*'Assumptions'!$B$18*'Assumptions'!$B$17*AL6
A9: NET REVENUE (billable) | C9: =C7+C8 | D9: =D7+D8 | E9: =E7+E8 | F9: =F7+F8 | G9: =G7+G8 | H9: =H7+H8 | I9: =I7+I8 | J9: =J7+J8 | ... AL9: =AL7+AL8
A10: Collection month (svc mo + lag + hold on first claims) | C10: =1+'Assumptions'!$B$20+MAX(0,'Assumptions'!$B$19-0) | D10: =2+'Assumptions'!$B$20+MAX(0,'Assumptions'!$B$19-1) | E10: =3+'Assumptions'!$B$20+MAX(0,'Assumptions'!$B$19-2) | F10: =4+'Assumptions'!$B$20+MAX(0,'Assumptions'!$B$19-3) | G10: =5+'Assumptions'!$B$20+MAX(0,'Assumptions'!$B$19-4) | H10: =6+'Assumptions'!$B$20+MAX(0,'Assumptions'!$B$19-5) | I10: =7+'Assumptions'!$B$20+MAX(0,'Assumptions'!$B$19-6) | J10: =8+'Assumptions'!$B$20+MAX(0,'Assumptions'!$B$19-7) | K10: =9+'Assumptions'!$B$20+MAX(0,'Assumptions'!$B$19-8) | L10: =10+'Assumptions'!$B$20+MAX(0,'Assumptions'!$B$19-9) | M10: =11+'Assumptions'!$B$20+MAX(0,'Assumptions'!$B$19-10) | N10: =12+'Assumptions'!$B$20+MAX(0,'Assumptions'!$B$19-11) | O10: =13+'Assumptions'!$B$20+MAX(0,'Assumptions'!$B$19-12) | P10: =14+'Assumptions'!$B$20+MAX(0,'Assumptions'!$B$19-13) | Q10: =15+'Assumptions'!$B$20+MAX(0,'Assumptions'!$B$19-14) | R10: =16+'Assumptions'!$B$20+MAX(0,'Assumptions'!$B$19-15) | S10: =17+'Assumptions'!$B$20+MAX(0,'Assumptions'!$B$19-16) | T10: =18+'Assumptions'!$B$20+MAX(0,'Assumptions'!$B$19-17) | U10: =19+'Assumptions'!$B$20+MAX(0,'Assumptions'!$B$19-18) | V10: =20+'Assumptions'!$B$20+MAX(0,'Assumptions'!$B$19-19) | W10: =21+'Assumptions'!$B$20+MAX(0,'Assumptions'!$B$19-20) | X10: =22+'Assumptions'!$B$20+MAX(0,'Assumptions'!$B$19-21) | Y10: =23+'Assumptions'!$B$20+MAX(0,'Assumptions'!$B$19-22) | Z10: =24+'Assumptions'!$B$20+MAX(0,'Assumptions'!$B$19-23) | AA10: =25+'Assumptions'!$B$20+MAX(0,'Assumptions'!$B$19-24) | AB10: =26+'Assumptions'!$B$20+MAX(0,'Assumptions'!$B$19-25) | AC10: =27+'Assumptions'!$B$20+MAX(0,'Assumptions'!$B$19-26) | AD10: =28+'Assumptions'!$B$20+MAX(0,'Assumptions'!$B$19-27) | AE10: =29+'Assumptions'!$B$20+MAX(0,'Assumptions'!$B$19-28) | AF10: =30+'Assumptions'!$B$20+MAX(0,'Assumptions'!$B$19-29) | AG10: =31+'Assumptions'!$B$20+MAX(0,'Assumptions'!$B$19-30) | AH10: =32+'Assumptions'!$B$20+MAX(0,'Assumptions'!$B$19-31) | AI10: =33+'Assumptions'!$B$20+MAX(0,'Assumptions'!$B$19-32) | AJ10: =34+'Assumptions'!$B$20+MAX(0,'Assumptions'!$B$19-33) | AK10: =35+'Assumptions'!$B$20+MAX(0,'Assumptions'!$B$19-34) | AL10: =36+'Assumptions'!$B$20+MAX(0,'Assumptions'!$B$19-35)
A11: CASH COLLECTED | C11: =SUMPRODUCT(($C$10:$AL$10=1)*$C$9:$AL$9) | D11: =SUMPRODUCT(($C$10:$AL$10=2)*$C$9:$AL$9) | E11: =SUMPRODUCT(($C$10:$AL$10=3)*$C$9:$AL$9) | F11: =SUMPRODUCT(($C$10:$AL$10=4)*$C$9:$AL$9) | G11: =SUMPRODUCT(($C$10:$AL$10=5)*$C$9:$AL$9) | H11: =SUMPRODUCT(($C$10:$AL$10=6)*$C$9:$AL$9) | I11: =SUMPRODUCT(($C$10:$AL$10=7)*$C$9:$AL$9) | J11: =SUMPRODUCT(($C$10:$AL$10=8)*$C$9:$AL$9) | K11: =SUMPRODUCT(($C$10:$AL$10=9)*$C$9:$AL$9) | L11: =SUMPRODUCT(($C$10:$AL$10=10)*$C$9:$AL$9) | M11: =SUMPRODUCT(($C$10:$AL$10=11)*$C$9:$AL$9) | N11: =SUMPRODUCT(($C$10:$AL$10=12)*$C$9:$AL$9) | O11: =SUMPRODUCT(($C$10:$AL$10=13)*$C$9:$AL$9) | P11: =SUMPRODUCT(($C$10:$AL$10=14)*$C$9:$AL$9) | Q11: =SUMPRODUCT(($C$10:$AL$10=15)*$C$9:$AL$9) | R11: =SUMPRODUCT(($C$10:$AL$10=16)*$C$9:$AL$9) | S11: =SUMPRODUCT(($C$10:$AL$10=17)*$C$9:$AL$9) | T11: =SUMPRODUCT(($C$10:$AL$10=18)*$C$9:$AL$9) | U11: =SUMPRODUCT(($C$10:$AL$10=19)*$C$9:$AL$9) | V11: =SUMPRODUCT(($C$10:$AL$10=20)*$C$9:$AL$9) | W11: =SUMPRODUCT(($C$10:$AL$10=21)*$C$9:$AL$9) | X11: =SUMPRODUCT(($C$10:$AL$10=22)*$C$9:$AL$9) | Y11: =SUMPRODUCT(($C$10:$AL$10=23)*$C$9:$AL$9) | Z11: =SUMPRODUCT(($C$10:$AL$10=24)*$C$9:$AL$9) | AA11: =SUMPRODUCT(($C$10:$AL$10=25)*$C$9:$AL$9) | AB11: =SUMPRODUCT(($C$10:$AL$10=26)*$C$9:$AL$9) | AC11: =SUMPRODUCT(($C$10:$AL$10=27)*$C$9:$AL$9) | AD11: =SUMPRODUCT(($C$10:$AL$10=28)*$C$9:$AL$9) | AE11: =SUMPRODUCT(($C$10:$AL$10=29)*$C$9:$AL$9) | AF11: =SUMPRODUCT(($C$10:$AL$10=30)*$C$9:$AL$9) | AG11: =SUMPRODUCT(($C$10:$AL$10=31)*$C$9:$AL$9) | AH11: =SUMPRODUCT(($C$10:$AL$10=32)*$C$9:$AL$9) | AI11: =SUMPRODUCT(($C$10:$AL$10=33)*$C$9:$AL$9) | AJ11: =SUMPRODUCT(($C$10:$AL$10=34)*$C$9:$AL$9) | AK11: =SUMPRODUCT(($C$10:$AL$10=35)*$C$9:$AL$9) | AL11: =SUMPRODUCT(($C$10:$AL$10=36)*$C$9:$AL$9)
A12: AR balance (earned not yet collected) | C12: =SUM($C$9:C9)-SUM($C$11:C11) | D12: =SUM($C$9:D9)-SUM($C$11:D11) | E12: =SUM($C$9:E9)-SUM($C$11:E11) | F12: =SUM($C$9:F9)-SUM($C$11:F11) | G12: =SUM($C$9:G9)-SUM($C$11:G11) | H12: =SUM($C$9:H9)-SUM($C$11:H11) | I12: =SUM($C$9:I9)-SUM($C$11:I11) | J12: =SUM($C$9:J9)-SUM($C$11:J11) | ... AL12: =SUM($C$9:AL9)-SUM($C$11:AL11)
A14: WEEKLY RECEIPTS (13 weeks; month receipts spread across its weeks)
C15: W1 | D15: W2 | E15: W3 | F15: W4 | G15: W5 | H15: W6 | I15: W7 | J15: W8 | K15: W9 | L15: W10 | M15: W11 | N15: W12 | O15: W13
A16: Cash received (week) | C16: =C11/4 | D16: =C11/4 | E16: =C11/4 | F16: =C11/4 | G16: =D11/5 | H16: =D11/5 | I16: =D11/5 | J16: =D11/5 | K16: =D11/5 | L16: =E11/4 | M16: =E11/4 | N16: =E11/4 | O16: =E11/4

Sheet Payroll
A1: AZALEA HOSPICE - REFUGE OPERATING MODEL
A2: Per-employee register (blue inputs) -> monthly cost matrix -> summary rows. Semi-monthly cash timing on Weekly Cash tab.
A4: REGISTER (I..AT = monthly gross cost incl. scenario adj, deferral, escalation)
A5: Employee / role | B5: Salary | C5: Hire mo | D5: Direct? | E5: Hlth wait | F5: Defer % | G5: Defer end | I5: M1 | J5: M2 | K5: M3 | L5: M4 | M5: M5 | N5: M6 | O5: M7 | P5: M8 | Q5: M9 | R5: M10 | S5: M11 | T5: M12 | U5: M13 | V5: M14 | W5: M15 | X5: M16 | Y5: M17 | Z5: M18 | AA5: M19 | AB5: M20 | AC5: M21 | AD5: M22 | AE5: M23 | AF5: M24 | AG5: M25 | AH5: M26 | AI5: M27 | AJ5: M28 | AK5: M29 | AL5: M30 | AM5: M31 | AN5: M32 | AO5: M33 | AP5: M34 | AQ5: M35 | AR5: M36
A6: Brad Woodard - Administrator / Director | B6: 120000 | C6: 1 | D6: I | E6: 3 | F6: =IF(1,'Assumptions'!$B$28,0) | G6: ='Assumptions'!$B$29 | I6: =IF(1>=$C6,$B6/12*(1+'Assumptions'!$B$26)*(1+'Assumptions'!$B$27)^0*(1-IF(1<=$G6,$F6,0)),0) | J6: =IF(2>=$C6,$B6/12*(1+'Assumptions'!$B$26)*(1+'Assumptions'!$B$27)^0*(1-IF(2<=$G6,$F6,0)),0) | K6: =IF(3>=$C6,$B6/12*(1+'Assumptions'!$B$26)*(1+'Assumptions'!$B$27)^0*(1-IF(3<=$G6,$F6,0)),0) | L6: =IF(4>=$C6,$B6/12*(1+'Assumptions'!$B$26)*(1+'Assumptions'!$B$27)^0*(1-IF(4<=$G6,$F6,0)),0) | M6: =IF(5>=$C6,$B6/12*(1+'Assumptions'!$B$26)*(1+'Assumptions'!$B$27)^0*(1-IF(5<=$G6,$F6,0)),0) | N6: =IF(6>=$C6,$B6/12*(1+'Assumptions'!$B$26)*(1+'Assumptions'!$B$27)^0*(1-IF(6<=$G6,$F6,0)),0) | O6: =IF(7>=$C6,$B6/12*(1+'Assumptions'!$B$26)*(1+'Assumptions'!$B$27)^0*(1-IF(7<=$G6,$F6,0)),0) | P6: =IF(8>=$C6,$B6/12*(1+'Assumptions'!$B$26)*(1+'Assumptions'!$B$27)^0*(1-IF(8<=$G6,$F6,0)),0) | Q6: =IF(9>=$C6,$B6/12*(1+'Assumptions'!$B$26)*(1+'Assumptions'!$B$27)^0*(1-IF(9<=$G6,$F6,0)),0) | R6: =IF(10>=$C6,$B6/12*(1+'Assumptions'!$B$26)*(1+'Assumptions'!$B$27)^0*(1-IF(10<=$G6,$F6,0)),0) | S6: =IF(11>=$C6,$B6/12*(1+'Assumptions'!$B$26)*(1+'Assumptions'!$B$27)^0*(1-IF(11<=$G6,$F6,0)),0) | T6: =IF(12>=$C6,$B6/12*(1+'Assumptions'!$B$26)*(1+'Assumptions'!$B$27)^0*(1-IF(12<=$G6,$F6,0)),0) | U6: =IF(13>=$C6,$B6/12*(1+'Assumptions'!$B$26)*(1+'Assumptions'!$B$27)^1*(1-IF(13<=$G6,$F6,0)),0) | V6: =IF(14>=$C6,$B6/12*(1+'Assumptions'!$B$26)*(1+'Assumptions'!$B$27)^1*(1-IF(14<=$G6,$F6,0)),0) | W6: =IF(15>=$C6,$B6/12*(1+'Assumptions'!$B$26)*(1+'Assumptions'!$B$27)^1*(1-IF(15<=$G6,$F6,0)),0) | X6: =IF(16>=$C6,$B6/12*(1+'Assumptions'!$B$26)*(1+'Assumptions'!$B$27)^1*(1-IF(16<=$G6,$F6,0)),0) | Y6: =IF(17>=$C6,$B6/12*(1+'Assumptions'!$B$26)*(1+'Assumptions'!$B$27)^1*(1-IF(17<=$G6,$F6,0)),0) | Z6: =IF(18>=$C6,$B6/12*(1+'Assumptions'!$B$26)*(1+'Assumptions'!$B$27)^1*(1-IF(18<=$G6,$F6,0)),0) | AA6: =IF(19>=$C6,$B6/12*(1+'Assumptions'!$B$26)*(1+'Assumptions'!$B$27)^1*(1-IF(19<=$G6,$F6,0)),0) | AB6: =IF(20>=$C6,$B6/12*(1+'Assumptions'!$B$26)*(1+'Assumptions'!$B$27)^1*(1-IF(20<=$G6,$F6,0)),0) | AC6: =IF(21>=$C6,$B6/12*(1+'Assumptions'!$B$26)*(1+'Assumptions'!$B$27)^1*(1-IF(21<=$G6,$F6,0)),0) | AD6: =IF(22>=$C6,$B6/12*(1+'Assumptions'!$B$26)*(1+'Assumptions'!$B$27)^1*(1-IF(22<=$G6,$F6,0)),0) | AE6: =IF(23>=$C6,$B6/12*(1+'Assumptions'!$B$26)*(1+'Assumptions'!$B$27)^1*(1-IF(23<=$G6,$F6,0)),0) | AF6: =IF(24>=$C6,$B6/12*(1+'Assumptions'!$B$26)*(1+'Assumptions'!$B$27)^1*(1-IF(24<=$G6,$F6,0)),0) | AG6: =IF(25>=$C6,$B6/12*(1+'Assumptions'!$B$26)*(1+'Assumptions'!$B$27)^2*(1-IF(25<=$G6,$F6,0)),0) | AH6: =IF(26>=$C6,$B6/12*(1+'Assumptions'!$B$26)*(1+'Assumptions'!$B$27)^2*(1-IF(26<=$G6,$F6,0)),0) | AI6: =IF(27>=$C6,$B6/12*(1+'Assumptions'!$B$26)*(1+'Assumptions'!$B$27)^2*(1-IF(27<=$G6,$F6,0)),0) | AJ6: =IF(28>=$C6,$B6/12*(1+'Assumptions'!$B$26)*(1+'Assumptions'!$B$27)^2*(1-IF(28<=$G6,$F6,0)),0) | AK6: =IF(29>=$C6,$B6/12*(1+'Assumptions'!$B$26)*(1+'Assumptions'!$B$27)^2*(1-IF(29<=$G6,$F6,0)),0) | AL6: =IF(30>=$C6,$B6/12*(1+'Assumptions'!$B$26)*(1+'Assumptions'!$B$27)^2*(1-IF(30<=$G6,$F6,0)),0) | AM6: =IF(31>=$C6,$B6/12*(1+'Assumptions'!$B$26)*(1+'Assumptions'!$B$27)^2*(1-IF(31<=$G6,$F6,0)),0) | AN6: =IF(32>=$C6,$B6/12*(1+'Assumptions'!$B$26)*(1+'Assumptions'!$B$27)^2*(1-IF(32<=$G6,$F6,0)),0) | AO6: =IF(33>=$C6,$B6/12*(1+'Assumptions'!$B$26)*(1+'Assumptions'!$B$27)^2*(1-IF(33<=$G6,$F6,0)),0) | AP6: =IF(34>=$C6,$B6/12*(1+'Assumptions'!$B$26)*(1+'Assumptions'!$B$27)^2*(1-IF(34<=$G6,$F6,0)),0) | AQ6: =IF(35>=$C6,$B6/12*(1+'Assumptions'!$B$26)*(1+'Assumptions'!$B$27)^2*(1-IF(35<=$G6,$F6,0)),0) | AR6: =IF(36>=$C6,$B6/12*(1+'Assumptions'!$B$26)*(1+'Assumptions'!$B$27)^2*(1-IF(36<=$G6,$F6,0)),0)
A7: Angie Frost - RN Case Manager | B7: 77504 | C7: 1 | D7: D | E7: 3 | F7: =IF(0,'Assumptions'!$B$28,0) | G7: ='Assumptions'!$B$29 | I7: =IF(1>=$C7,$B7/12*(1+'Assumptions'!$B$26)*(1+'Assumptions'!$B$27)^0*(1-IF(1<=$G7,$F7,0)),0) | J7: =IF(2>=$C7,$B7/12*(1+'Assumptions'!$B$26)*(1+'Assumptions'!$B$27)^0*(1-IF(2<=$G7,$F7,0)),0) | K7: =IF(3>=$C7,$B7/12*(1+'Assumptions'!$B$26)*(1+'Assumptions'!$B$27)^0*(1-IF(3<=$G7,$F7,0)),0) | L7: =IF(4>=$C7,$B7/12*(1+'Assumptions'!$B$26)*(1+'Assumptions'!$B$27)^0*(1-IF(4<=$G7,$F7,0)),0) | M7: =IF(5>=$C7,$B7/12*(1+'Assumptions'!$B$26)*(1+'Assumptions'!$B$27)^0*(1-IF(5<=$G7,$F7,0)),0) | N7: =IF(6>=$C7,$B7/12*(1+'Assumptions'!$B$26)*(1+'Assumptions'!$B$27)^0*(1-IF(6<=$G7,$F7,0)),0) | O7: =IF(7>=$C7,$B7/12*(1+'Assumptions'!$B$26)*(1+'Assumptions'!$B$27)^0*(1-IF(7<=$G7,$F7,0)),0) | P7: =IF(8>=$C7,$B7/12*(1+'Assumptions'!$B$26)*(1+'Assumptions'!$B$27)^0*(1-IF(8<=$G7,$F7,0)),0) | Q7: =IF(9>=$C7,$B7/12*(1+'Assumptions'!$B$26)*(1+'Assumptions'!$B$27)^0*(1-IF(9<=$G7,$F7,0)),0) | R7: =IF(10>=$C7,$B7/12*(1+'Assumptions'!$B$26)*(1+'Assumptions'!$B$27)^0*(1-IF(10<=$G7,$F7,0)),0) | S7: =IF(11>=$C7,$B7/12*(1+'Assumptions'!$B$26)*(1+'Assumptions'!$B$27)^0*(1-IF(11<=$G7,$F7,0)),0) | T7: =IF(12>=$C7,$B7/12*(1+'Assumptions'!$B$26)*(1+'Assumptions'!$B$27)^0*(1-IF(12<=$G7,$F7,0)),0) | U7: =IF(13>=$C7,$B7/12*(1+'Assumptions'!$B$26)*(1+'Assumptions'!$B$27)^1*(1-IF(13<=$G7,$F7,0)),0) | V7: =IF(14>=$C7,$B7/12*(1+'Assumptions'!$B$26)*(1+'Assumptions'!$B$27)^1*(1-IF(14<=$G7,$F7,0)),0) | W7: =IF(15>=$C7,$B7/12*(1+'Assumptions'!$B$26)*(1+'Assumptions'!$B$27)^1*(1-IF(15<=$G7,$F7,0)),0) | X7: =IF(16>=$C7,$B7/12*(1+'Assumptions'!$B$26)*(1+'Assumptions'!$B$27)^1*(1-IF(16<=$G7,$F7,0)),0) | Y7: =IF(17>=$C7,$B7/12*(1+'Assumptions'!$B$26)*(1+'Assumptions'!$B$27)^1*(1-IF(17<=$G7,$F7,0)),0) | Z7: =IF(18>=$C7,$B7/12*(1+'Assumptions'!$B$26)*(1+'Assumptions'!$B$27)^1*(1-IF(18<=$G7,$F7,0)),0) | AA7: =IF(19>=$C7,$B7/12*(1+'Assumptions'!$B$26)*(1+'Assumptions'!$B$27)^1*(1-IF(19<=$G7,$F7,0)),0) | AB7: =IF(20>=$C7,$B7/12*(1+'Assumptions'!$B$26)*(1+'Assumptions'!$B$27)^1*(1-IF(20<=$G7,$F7,0)),0) | AC7: =IF(21>=$C7,$B7/12*(1+'Assumptions'!$B$26)*(1+'Assumptions'!$B$27)^1*(1-IF(21<=$G7,$F7,0)),0) | AD7: =IF(22>=$C7,$B7/12*(1+'Assumptions'!$B$26)*(1+'Assumptions'!$B$27)^1*(1-IF(22<=$G7,$F7,0)),0) | AE7: =IF(23>=$C7,$B7/12*(1+'Assumptions'!$B$26)*(1+'Assumptions'!$B$27)^1*(1-IF(23<=$G7,$F7,0)),0) | AF7: =IF(24>=$C7,$B7/12*(1+'Assumptions'!$B$26)*(1+'Assumptions'!$B$27)^1*(1-IF(24<=$G7,$F7,0)),0) | AG7: =IF(25>=$C7,$B7/12*(1+'Assumptions'!$B$26)*(1+'Assumptions'!$B$27)^2*(1-IF(25<=$G7,$F7,0)),0) | AH7: =IF(26>=$C7,$B7/12*(1+'Assumptions'!$B$26)*(1+'Assumptions'!$B$27)^2*(1-IF(26<=$G7,$F7,0)),0) | AI7: =IF(27>=$C7,$B7/12*(1+'Assumptions'!$B$26)*(1+'Assumptions'!$B$27)^2*(1-IF(27<=$G7,$F7,0)),0) | AJ7: =IF(28>=$C7,$B7/12*(1+'Assumptions'!$B$26)*(1+'Assumptions'!$B$27)^2*(1-IF(28<=$G7,$F7,0)),0) | AK7: =IF(29>=$C7,$B7/12*(1+'Assumptions'!$B$26)*(1+'Assumptions'!$B$27)^2*(1-IF(29<=$G7,$F7,0)),0) | AL7: =IF(30>=$C7,$B7/12*(1+'Assumptions'!$B$26)*(1+'Assumptions'!$B$27)^2*(1-IF(30<=$G7,$F7,0)),0) | AM7: =IF(31>=$C7,$B7/12*(1+'Assumptions'!$B$26)*(1+'Assumptions'!$B$27)^2*(1-IF(31<=$G7,$F7,0)),0) | AN7: =IF(32>=$C7,$B7/12*(1+'Assumptions'!$B$26)*(1+'Assumptions'!$B$27)^2*(1-IF(32<=$G7,$F7,0)),0) | AO7: =IF(33>=$C7,$B7/12*(1+'Assumptions'!$B$26)*(1+'Assumptions'!$B$27)^2*(1-IF(33<=$G7,$F7,0)),0) | AP7: =IF(34>=$C7,$B7/12*(1+'Assumptions'!$B$26)*(1+'Assumptions'!$B$27)^2*(1-IF(34<=$G7,$F7,0)),0) | AQ7: =IF(35>=$C7,$B7/12*(1+'Assumptions'!$B$26)*(1+'Assumptions'!$B$27)^2*(1-IF(35<=$G7,$F7,0)),0) | AR7: =IF(36>=$C7,$B7/12*(1+'Assumptions'!$B$26)*(1+'Assumptions'!$B$27)^2*(1-IF(36<=$G7,$F7,0)),0)
A8: Tanisha Robison - CNA / Hospice Aide | B8: 46511 | C8: 1 | D8: D | E8: 3 | F8: =IF(0,'Assumptions'!$B$28,0) | G8: ='Assumptions'!$B$29 | I8: =IF(1>=$C8,$B8/12*(1+'Assumptions'!$B$26)*(1+'Assumptions'!$B$27)^0*(1-IF(1<=$G8,$F8,0)),0) | J8: =IF(2>=$C8,$B8/12*(1+'Assumptions'!$B$26)*(1+'Assumptions'!$B$27)^0*(1-IF(2<=$G8,$F8,0)),0) | K8: =IF(3>=$C8,$B8/12*(1+'Assumptions'!$B$26)*(1+'Assumptions'!$B$27)^0*(1-IF(3<=$G8,$F8,0)),0) | L8: =IF(4>=$C8,$B8/12*(1+'Assumptions'!$B$26)*(1+'Assumptions'!$B$27)^0*(1-IF(4<=$G8,$F8,0)),0) | M8: =IF(5>=$C8,$B8/12*(1+'Assumptions'!$B$26)*(1+'Assumptions'!$B$27)^0*(1-IF(5<=$G8,$F8,0)),0) | N8: =IF(6>=$C8,$B8/12*(1+'Assumptions'!$B$26)*(1+'Assumptions'!$B$27)^0*(1-IF(6<=$G8,$F8,0)),0) | O8: =IF(7>=$C8,$B8/12*(1+'Assumptions'!$B$26)*(1+'Assumptions'!$B$27)^0*(1-IF(7<=$G8,$F8,0)),0) | P8: =IF(8>=$C8,$B8/12*(1+'Assumptions'!$B$26)*(1+'Assumptions'!$B$27)^0*(1-IF(8<=$G8,$F8,0)),0) | Q8: =IF(9>=$C8,$B8/12*(1+'Assumptions'!$B$26)*(1+'Assumptions'!$B$27)^0*(1-IF(9<=$G8,$F8,0)),0) | R8: =IF(10>=$C8,$B8/12*(1+'Assumptions'!$B$26)*(1+'Assumptions'!$B$27)^0*(1-IF(10<=$G8,$F8,0)),0) | S8: =IF(11>=$C8,$B8/12*(1+'Assumptions'!$B$26)*(1+'Assumptions'!$B$27)^0*(1-IF(11<=$G8,$F8,0)),0) | T8: =IF(12>=$C8,$B8/12*(1+'Assumptions'!$B$26)*(1+'Assumptions'!$B$27)^0*(1-IF(12<=$G8,$F8,0)),0) | U8: =IF(13>=$C8,$B8/12*(1+'Assumptions'!$B$26)*(1+'Assumptions'!$B$27)^1*(1-IF(13<=$G8,$F8,0)),0) | V8: =IF(14>=$C8,$B8/12*(1+'Assumptions'!$B$26)*(1+'Assumptions'!$B$27)^1*(1-IF(14<=$G8,$F8,0)),0) | W8: =IF(15>=$C8,$B8/12*(1+'Assumptions'!$B$26)*(1+'Assumptions'!$B$27)^1*(1-IF(15<=$G8,$F8,0)),0) | X8: =IF(16>=$C8,$B8/12*(1+'Assumptions'!$B$26)*(1+'Assumptions'!$B$27)^1*(1-IF(16<=$G8,$F8,0)),0) | Y8: =IF(17>=$C8,$B8/12*(1+'Assumptions'!$B$26)*(1+'Assumptions'!$B$27)^1*(1-IF(17<=$G8,$F8,0)),0) | Z8: =IF(18>=$C8,$B8/12*(1+'Assumptions'!$B$26)*(1+'Assumptions'!$B$27)^1*(1-IF(18<=$G8,$F8,0)),0) | AA8: =IF(19>=$C8,$B8/12*(1+'Assumptions'!$B$26)*(1+'Assumptions'!$B$27)^1*(1-IF(19<=$G8,$F8,0)),0) | AB8: =IF(20>=$C8,$B8/12*(1+'Assumptions'!$B$26)*(1+'Assumptions'!$B$27)^1*(1-IF(20<=$G8,$F8,0)),0) | AC8: =IF(21>=$C8,$B8/12*(1+'Assumptions'!$B$26)*(1+'Assumptions'!$B$27)^1*(1-IF(21<=$G8,$F8,0)),0) | AD8: =IF(22>=$C8,$B8/12*(1+'Assumptions'!$B$26)*(1+'Assumptions'!$B$27)^1*(1-IF(22<=$G8,$F8,0)),0) | AE8: =IF(23>=$C8,$B8/12*(1+'Assumptions'!$B$26)*(1+'Assumptions'!$B$27)^1*(1-IF(23<=$G8,$F8,0)),0) | AF8: =IF(24>=$C8,$B8/12*(1+'Assumptions'!$B$26)*(1+'Assumptions'!$B$27)^1*(1-IF(24<=$G8,$F8,0)),0) | AG8: =IF(25>=$C8,$B8/12*(1+'Assumptions'!$B$26)*(1+'Assumptions'!$B$27)^2*(1-IF(25<=$G8,$F8,0)),0) | AH8: =IF(26>=$C8,$B8/12*(1+'Assumptions'!$B$26)*(1+'Assumptions'!$B$27)^2*(1-IF(26<=$G8,$F8,0)),0) | AI8: =IF(27>=$C8,$B8/12*(1+'Assumptions'!$B$26)*(1+'Assumptions'!$B$27)^2*(1-IF(27<=$G8,$F8,0)),0) | AJ8: =IF(28>=$C8,$B8/12*(1+'Assumptions'!$B$26)*(1+'Assumptions'!$B$27)^2*(1-IF(28<=$G8,$F8,0)),0) | AK8: =IF(29>=$C8,$B8/12*(1+'Assumptions'!$B$26)*(1+'Assumptions'!$B$27)^2*(1-IF(29<=$G8,$F8,0)),0) | AL8: =IF(30>=$C8,$B8/12*(1+'Assumptions'!$B$26)*(1+'Assumptions'!$B$27)^2*(1-IF(30<=$G8,$F8,0)),0) | AM8: =IF(31>=$C8,$B8/12*(1+'Assumptions'!$B$26)*(1+'Assumptions'!$B$27)^2*(1-IF(31<=$G8,$F8,0)),0) | AN8: =IF(32>=$C8,$B8/12*(1+'Assumptions'!$B$26)*(1+'Assumptions'!$B$27)^2*(1-IF(32<=$G8,$F8,0)),0) | AO8: =IF(33>=$C8,$B8/12*(1+'Assumptions'!$B$26)*(1+'Assumptions'!$B$27)^2*(1-IF(33<=$G8,$F8,0)),0) | AP8: =IF(34>=$C8,$B8/12*(1+'Assumptions'!$B$26)*(1+'Assumptions'!$B$27)^2*(1-IF(34<=$G8,$F8,0)),0) | AQ8: =IF(35>=$C8,$B8/12*(1+'Assumptions'!$B$26)*(1+'Assumptions'!$B$27)^2*(1-IF(35<=$G8,$F8,0)),0) | AR8: =IF(36>=$C8,$B8/12*(1+'Assumptions'!$B$26)*(1+'Assumptions'!$B$27)^2*(1-IF(36<=$G8,$F8,0)),0)
A9: Dana Davenport - Director of Clinical Services | B9: 110000 | C9: 2 | D9: I | E9: 3 | F9: =IF(1,'Assumptions'!$B$28,0) | G9: ='Assumptions'!$B$29 | I9: =IF(1>=$C9,$B9/12*(1+'Assumptions'!$B$26)*(1+'Assumptions'!$B$27)^0*(1-IF(1<=$G9,$F9,0)),0) | J9: =IF(2>=$C9,$B9/12*(1+'Assumptions'!$B$26)*(1+'Assumptions'!$B$27)^0*(1-IF(2<=$G9,$F9,0)),0) | K9: =IF(3>=$C9,$B9/12*(1+'Assumptions'!$B$26)*(1+'Assumptions'!$B$27)^0*(1-IF(3<=$G9,$F9,0)),0) | L9: =IF(4>=$C9,$B9/12*(1+'Assumptions'!$B$26)*(1+'Assumptions'!$B$27)^0*(1-IF(4<=$G9,$F9,0)),0) | M9: =IF(5>=$C9,$B9/12*(1+'Assumptions'!$B$26)*(1+'Assumptions'!$B$27)^0*(1-IF(5<=$G9,$F9,0)),0) | N9: =IF(6>=$C9,$B9/12*(1+'Assumptions'!$B$26)*(1+'Assumptions'!$B$27)^0*(1-IF(6<=$G9,$F9,0)),0) | O9: =IF(7>=$C9,$B9/12*(1+'Assumptions'!$B$26)*(1+'Assumptions'!$B$27)^0*(1-IF(7<=$G9,$F9,0)),0) | P9: =IF(8>=$C9,$B9/12*(1+'Assumptions'!$B$26)*(1+'Assumptions'!$B$27)^0*(1-IF(8<=$G9,$F9,0)),0) | Q9: =IF(9>=$C9,$B9/12*(1+'Assumptions'!$B$26)*(1+'Assumptions'!$B$27)^0*(1-IF(9<=$G9,$F9,0)),0) | R9: =IF(10>=$C9,$B9/12*(1+'Assumptions'!$B$26)*(1+'Assumptions'!$B$27)^0*(1-IF(10<=$G9,$F9,0)),0) | S9: =IF(11>=$C9,$B9/12*(1+'Assumptions'!$B$26)*(1+'Assumptions'!$B$27)^0*(1-IF(11<=$G9,$F9,0)),0) | T9: =IF(12>=$C9,$B9/12*(1+'Assumptions'!$B$26)*(1+'Assumptions'!$B$27)^0*(1-IF(12<=$G9,$F9,0)),0) | U9: =IF(13>=$C9,$B9/12*(1+'Assumptions'!$B$26)*(1+'Assumptions'!$B$27)^1*(1-IF(13<=$G9,$F9,0)),0) | V9: =IF(14>=$C9,$B9/12*(1+'Assumptions'!$B$26)*(1+'Assumptions'!$B$27)^1*(1-IF(14<=$G9,$F9,0)),0) | W9: =IF(15>=$C9,$B9/12*(1+'Assumptions'!$B$26)*(1+'Assumptions'!$B$27)^1*(1-IF(15<=$G9,$F9,0)),0) | X9: =IF(16>=$C9,$B9/12*(1+'Assumptions'!$B$26)*(1+'Assumptions'!$B$27)^1*(1-IF(16<=$G9,$F9,0)),0) | Y9: =IF(17>=$C9,$B9/12*(1+'Assumptions'!$B$26)*(1+'Assumptions'!$B$27)^1*(1-IF(17<=$G9,$F9,0)),0) | Z9: =IF(18>=$C9,$B9/12*(1+'Assumptions'!$B$26)*(1+'Assumptions'!$B$27)^1*(1-IF(18<=$G9,$F9,0)),0) | AA9: =IF(19>=$C9,$B9/12*(1+'Assumptions'!$B$26)*(1+'Assumptions'!$B$27)^1*(1-IF(19<=$G9,$F9,0)),0) | AB9: =IF(20>=$C9,$B9/12*(1+'Assumptions'!$B$26)*(1+'Assumptions'!$B$27)^1*(1-IF(20<=$G9,$F9,0)),0) | AC9: =IF(21>=$C9,$B9/12*(1+'Assumptions'!$B$26)*(1+'Assumptions'!$B$27)^1*(1-IF(21<=$G9,$F9,0)),0) | AD9: =IF(22>=$C9,$B9/12*(1+'Assumptions'!$B$26)*(1+'Assumptions'!$B$27)^1*(1-IF(22<=$G9,$F9,0)),0) | AE9: =IF(23>=$C9,$B9/12*(1+'Assumptions'!$B$26)*(1+'Assumptions'!$B$27)^1*(1-IF(23<=$G9,$F9,0)),0) | AF9: =IF(24>=$C9,$B9/12*(1+'Assumptions'!$B$26)*(1+'Assumptions'!$B$27)^1*(1-IF(24<=$G9,$F9,0)),0) | AG9: =IF(25>=$C9,$B9/12*(1+'Assumptions'!$B$26)*(1+'Assumptions'!$B$27)^2*(1-IF(25<=$G9,$F9,0)),0) | AH9: =IF(26>=$C9,$B9/12*(1+'Assumptions'!$B$26)*(1+'Assumptions'!$B$27)^2*(1-IF(26<=$G9,$F9,0)),0) | AI9: =IF(27>=$C9,$B9/12*(1+'Assumptions'!$B$26)*(1+'Assumptions'!$B$27)^2*(1-IF(27<=$G9,$F9,0)),0) | AJ9: =IF(28>=$C9,$B9/12*(1+'Assumptions'!$B$26)*(1+'Assumptions'!$B$27)^2*(1-IF(28<=$G9,$F9,0)),0) | AK9: =IF(29>=$C9,$B9/12*(1+'Assumptions'!$B$26)*(1+'Assumptions'!$B$27)^2*(1-IF(29<=$G9,$F9,0)),0) | AL9: =IF(30>=$C9,$B9/12*(1+'Assumptions'!$B$26)*(1+'Assumptions'!$B$27)^2*(1-IF(30<=$G9,$F9,0)),0) | AM9: =IF(31>=$C9,$B9/12*(1+'Assumptions'!$B$26)*(1+'Assumptions'!$B$27)^2*(1-IF(31<=$G9,$F9,0)),0) | AN9: =IF(32>=$C9,$B9/12*(1+'Assumptions'!$B$26)*(1+'Assumptions'!$B$27)^2*(1-IF(32<=$G9,$F9,0)),0) | AO9: =IF(33>=$C9,$B9/12*(1+'Assumptions'!$B$26)*(1+'Assumptions'!$B$27)^2*(1-IF(33<=$G9,$F9,0)),0) | AP9: =IF(34>=$C9,$B9/12*(1+'Assumptions'!$B$26)*(1+'Assumptions'!$B$27)^2*(1-IF(34<=$G9,$F9,0)),0) | AQ9: =IF(35>=$C9,$B9/12*(1+'Assumptions'!$B$26)*(1+'Assumptions'!$B$27)^2*(1-IF(35<=$G9,$F9,0)),0) | AR9: =IF(36>=$C9,$B9/12*(1+'Assumptions'!$B$26)*(1+'Assumptions'!$B$27)^2*(1-IF(36<=$G9,$F9,0)),0)
A10: Silas Shelton - Administrator | B10: 130000 | C10: 3 | D10: I | E10: 3 | F10: =IF(1,'Assumptions'!$B$28,0) | G10: ='Assumptions'!$B$29 | I10: =IF(1>=$C10,$B10/12*(1+'Assumptions'!$B$26)*(1+'Assumptions'!$B$27)^0*(1-IF(1<=$G10,$F10,0)),0) | J10: =IF(2>=$C10,$B10/12*(1+'Assumptions'!$B$26)*(1+'Assumptions'!$B$27)^0*(1-IF(2<=$G10,$F10,0)),0) | K10: =IF(3>=$C10,$B10/12*(1+'Assumptions'!$B$26)*(1+'Assumptions'!$B$27)^0*(1-IF(3<=$G10,$F10,0)),0) | L10: =IF(4>=$C10,$B10/12*(1+'Assumptions'!$B$26)*(1+'Assumptions'!$B$27)^0*(1-IF(4<=$G10,$F10,0)),0) | M10: =IF(5>=$C10,$B10/12*(1+'Assumptions'!$B$26)*(1+'Assumptions'!$B$27)^0*(1-IF(5<=$G10,$F10,0)),0) | N10: =IF(6>=$C10,$B10/12*(1+'Assumptions'!$B$26)*(1+'Assumptions'!$B$27)^0*(1-IF(6<=$G10,$F10,0)),0) | O10: =IF(7>=$C10,$B10/12*(1+'Assumptions'!$B$26)*(1+'Assumptions'!$B$27)^0*(1-IF(7<=$G10,$F10,0)),0) | P10: =IF(8>=$C10,$B10/12*(1+'Assumptions'!$B$26)*(1+'Assumptions'!$B$27)^0*(1-IF(8<=$G10,$F10,0)),0) | Q10: =IF(9>=$C10,$B10/12*(1+'Assumptions'!$B$26)*(1+'Assumptions'!$B$27)^0*(1-IF(9<=$G10,$F10,0)),0) | R10: =IF(10>=$C10,$B10/12*(1+'Assumptions'!$B$26)*(1+'Assumptions'!$B$27)^0*(1-IF(10<=$G10,$F10,0)),0) | S10: =IF(11>=$C10,$B10/12*(1+'Assumptions'!$B$26)*(1+'Assumptions'!$B$27)^0*(1-IF(11<=$G10,$F10,0)),0) | T10: =IF(12>=$C10,$B10/12*(1+'Assumptions'!$B$26)*(1+'Assumptions'!$B$27)^0*(1-IF(12<=$G10,$F10,0)),0) | U10: =IF(13>=$C10,$B10/12*(1+'Assumptions'!$B$26)*(1+'Assumptions'!$B$27)^1*(1-IF(13<=$G10,$F10,0)),0) | V10: =IF(14>=$C10,$B10/12*(1+'Assumptions'!$B$26)*(1+'Assumptions'!$B$27)^1*(1-IF(14<=$G10,$F10,0)),0) | W10: =IF(15>=$C10,$B10/12*(1+'Assumptions'!$B$26)*(1+'Assumptions'!$B$27)^1*(1-IF(15<=$G10,$F10,0)),0) | X10: =IF(16>=$C10,$B10/12*(1+'Assumptions'!$B$26)*(1+'Assumptions'!$B$27)^1*(1-IF(16<=$G10,$F10,0)),0) | Y10: =IF(17>=$C10,$B10/12*(1+'Assumptions'!$B$26)*(1+'Assumptions'!$B$27)^1*(1-IF(17<=$G10,$F10,0)),0) | Z10: =IF(18>=$C10,$B10/12*(1+'Assumptions'!$B$26)*(1+'Assumptions'!$B$27)^1*(1-IF(18<=$G10,$F10,0)),0) | AA10: =IF(19>=$C10,$B10/12*(1+'Assumptions'!$B$26)*(1+'Assumptions'!$B$27)^1*(1-IF(19<=$G10,$F10,0)),0) | AB10: =IF(20>=$C10,$B10/12*(1+'Assumptions'!$B$26)*(1+'Assumptions'!$B$27)^1*(1-IF(20<=$G10,$F10,0)),0) | AC10: =IF(21>=$C10,$B10/12*(1+'Assumptions'!$B$26)*(1+'Assumptions'!$B$27)^1*(1-IF(21<=$G10,$F10,0)),0) | AD10: =IF(22>=$C10,$B10/12*(1+'Assumptions'!$B$26)*(1+'Assumptions'!$B$27)^1*(1-IF(22<=$G10,$F10,0)),0) | AE10: =IF(23>=$C10,$B10/12*(1+'Assumptions'!$B$26)*(1+'Assumptions'!$B$27)^1*(1-IF(23<=$G10,$F10,0)),0) | AF10: =IF(24>=$C10,$B10/12*(1+'Assumptions'!$B$26)*(1+'Assumptions'!$B$27)^1*(1-IF(24<=$G10,$F10,0)),0) | AG10: =IF(25>=$C10,$B10/12*(1+'Assumptions'!$B$26)*(1+'Assumptions'!$B$27)^2*(1-IF(25<=$G10,$F10,0)),0) | AH10: =IF(26>=$C10,$B10/12*(1+'Assumptions'!$B$26)*(1+'Assumptions'!$B$27)^2*(1-IF(26<=$G10,$F10,0)),0) | AI10: =IF(27>=$C10,$B10/12*(1+'Assumptions'!$B$26)*(1+'Assumptions'!$B$27)^2*(1-IF(27<=$G10,$F10,0)),0) | AJ10: =IF(28>=$C10,$B10/12*(1+'Assumptions'!$B$26)*(1+'Assumptions'!$B$27)^2*(1-IF(28<=$G10,$F10,0)),0) | AK10: =IF(29>=$C10,$B10/12*(1+'Assumptions'!$B$26)*(1+'Assumptions'!$B$27)^2*(1-IF(29<=$G10,$F10,0)),0) | AL10: =IF(30>=$C10,$B10/12*(1+'Assumptions'!$B$26)*(1+'Assumptions'!$B$27)^2*(1-IF(30<=$G10,$F10,0)),0) | AM10: =IF(31>=$C10,$B10/12*(1+'Assumptions'!$B$26)*(1+'Assumptions'!$B$27)^2*(1-IF(31<=$G10,$F10,0)),0) | AN10: =IF(32>=$C10,$B10/12*(1+'Assumptions'!$B$26)*(1+'Assumptions'!$B$27)^2*(1-IF(32<=$G10,$F10,0)),0) | AO10: =IF(33>=$C10,$B10/12*(1+'Assumptions'!$B$26)*(1+'Assumptions'!$B$27)^2*(1-IF(33<=$G10,$F10,0)),0) | AP10: =IF(34>=$C10,$B10/12*(1+'Assumptions'!$B$26)*(1+'Assumptions'!$B$27)^2*(1-IF(34<=$G10,$F10,0)),0) | AQ10: =IF(35>=$C10,$B10/12*(1+'Assumptions'!$B$26)*(1+'Assumptions'!$B$27)^2*(1-IF(35<=$G10,$F10,0)),0) | AR10: =IF(36>=$C10,$B10/12*(1+'Assumptions'!$B$26)*(1+'Assumptions'!$B$27)^2*(1-IF(36<=$G10,$F10,0)),0)
A11: Jodi McCollum - RN Case Manager (2nd seat) | B11: 75008 | C11: 4 | D11: D | E11: 3 | F11: =IF(0,'Assumptions'!$B$28,0) | G11: ='Assumptions'!$B$29 | I11: =IF(1>=$C11,$B11/12*(1+'Assumptions'!$B$26)*(1+'Assumptions'!$B$27)^0*(1-IF(1<=$G11,$F11,0)),0) | J11: =IF(2>=$C11,$B11/12*(1+'Assumptions'!$B$26)*(1+'Assumptions'!$B$27)^0*(1-IF(2<=$G11,$F11,0)),0) | K11: =IF(3>=$C11,$B11/12*(1+'Assumptions'!$B$26)*(1+'Assumptions'!$B$27)^0*(1-IF(3<=$G11,$F11,0)),0) | L11: =IF(4>=$C11,$B11/12*(1+'Assumptions'!$B$26)*(1+'Assumptions'!$B$27)^0*(1-IF(4<=$G11,$F11,0)),0) | M11: =IF(5>=$C11,$B11/12*(1+'Assumptions'!$B$26)*(1+'Assumptions'!$B$27)^0*(1-IF(5<=$G11,$F11,0)),0) | N11: =IF(6>=$C11,$B11/12*(1+'Assumptions'!$B$26)*(1+'Assumptions'!$B$27)^0*(1-IF(6<=$G11,$F11,0)),0) | O11: =IF(7>=$C11,$B11/12*(1+'Assumptions'!$B$26)*(1+'Assumptions'!$B$27)^0*(1-IF(7<=$G11,$F11,0)),0) | P11: =IF(8>=$C11,$B11/12*(1+'Assumptions'!$B$26)*(1+'Assumptions'!$B$27)^0*(1-IF(8<=$G11,$F11,0)),0) | Q11: =IF(9>=$C11,$B11/12*(1+'Assumptions'!$B$26)*(1+'Assumptions'!$B$27)^0*(1-IF(9<=$G11,$F11,0)),0) | R11: =IF(10>=$C11,$B11/12*(1+'Assumptions'!$B$26)*(1+'Assumptions'!$B$27)^0*(1-IF(10<=$G11,$F11,0)),0) | S11: =IF(11>=$C11,$B11/12*(1+'Assumptions'!$B$26)*(1+'Assumptions'!$B$27)^0*(1-IF(11<=$G11,$F11,0)),0) | T11: =IF(12>=$C11,$B11/12*(1+'Assumptions'!$B$26)*(1+'Assumptions'!$B$27)^0*(1-IF(12<=$G11,$F11,0)),0) | U11: =IF(13>=$C11,$B11/12*(1+'Assumptions'!$B$26)*(1+'Assumptions'!$B$27)^1*(1-IF(13<=$G11,$F11,0)),0) | V11: =IF(14>=$C11,$B11/12*(1+'Assumptions'!$B$26)*(1+'Assumptions'!$B$27)^1*(1-IF(14<=$G11,$F11,0)),0) | W11: =IF(15>=$C11,$B11/12*(1+'Assumptions'!$B$26)*(1+'Assumptions'!$B$27)^1*(1-IF(15<=$G11,$F11,0)),0) | X11: =IF(16>=$C11,$B11/12*(1+'Assumptions'!$B$26)*(1+'Assumptions'!$B$27)^1*(1-IF(16<=$G11,$F11,0)),0) | Y11: =IF(17>=$C11,$B11/12*(1+'Assumptions'!$B$26)*(1+'Assumptions'!$B$27)^1*(1-IF(17<=$G11,$F11,0)),0) | Z11: =IF(18>=$C11,$B11/12*(1+'Assumptions'!$B$26)*(1+'Assumptions'!$B$27)^1*(1-IF(18<=$G11,$F11,0)),0) | AA11: =IF(19>=$C11,$B11/12*(1+'Assumptions'!$B$26)*(1+'Assumptions'!$B$27)^1*(1-IF(19<=$G11,$F11,0)),0) | AB11: =IF(20>=$C11,$B11/12*(1+'Assumptions'!$B$26)*(1+'Assumptions'!$B$27)^1*(1-IF(20<=$G11,$F11,0)),0) | AC11: =IF(21>=$C11,$B11/12*(1+'Assumptions'!$B$26)*(1+'Assumptions'!$B$27)^1*(1-IF(21<=$G11,$F11,0)),0) | AD11: =IF(22>=$C11,$B11/12*(1+'Assumptions'!$B$26)*(1+'Assumptions'!$B$27)^1*(1-IF(22<=$G11,$F11,0)),0) | AE11: =IF(23>=$C11,$B11/12*(1+'Assumptions'!$B$26)*(1+'Assumptions'!$B$27)^1*(1-IF(23<=$G11,$F11,0)),0) | AF11: =IF(24>=$C11,$B11/12*(1+'Assumptions'!$B$26)*(1+'Assumptions'!$B$27)^1*(1-IF(24<=$G11,$F11,0)),0) | AG11: =IF(25>=$C11,$B11/12*(1+'Assumptions'!$B$26)*(1+'Assumptions'!$B$27)^2*(1-IF(25<=$G11,$F11,0)),0) | AH11: =IF(26>=$C11,$B11/12*(1+'Assumptions'!$B$26)*(1+'Assumptions'!$B$27)^2*(1-IF(26<=$G11,$F11,0)),0) | AI11: =IF(27>=$C11,$B11/12*(1+'Assumptions'!$B$26)*(1+'Assumptions'!$B$27)^2*(1-IF(27<=$G11,$F11,0)),0) | AJ11: =IF(28>=$C11,$B11/12*(1+'Assumptions'!$B$26)*(1+'Assumptions'!$B$27)^2*(1-IF(28<=$G11,$F11,0)),0) | AK11: =IF(29>=$C11,$B11/12*(1+'Assumptions'!$B$26)*(1+'Assumptions'!$B$27)^2*(1-IF(29<=$G11,$F11,0)),0) | AL11: =IF(30>=$C11,$B11/12*(1+'Assumptions'!$B$26)*(1+'Assumptions'!$B$27)^2*(1-IF(30<=$G11,$F11,0)),0) | AM11: =IF(31>=$C11,$B11/12*(1+'Assumptions'!$B$26)*(1+'Assumptions'!$B$27)^2*(1-IF(31<=$G11,$F11,0)),0) | AN11: =IF(32>=$C11,$B11/12*(1+'Assumptions'!$B$26)*(1+'Assumptions'!$B$27)^2*(1-IF(32<=$G11,$F11,0)),0) | AO11: =IF(33>=$C11,$B11/12*(1+'Assumptions'!$B$26)*(1+'Assumptions'!$B$27)^2*(1-IF(33<=$G11,$F11,0)),0) | AP11: =IF(34>=$C11,$B11/12*(1+'Assumptions'!$B$26)*(1+'Assumptions'!$B$27)^2*(1-IF(34<=$G11,$F11,0)),0) | AQ11: =IF(35>=$C11,$B11/12*(1+'Assumptions'!$B$26)*(1+'Assumptions'!$B$27)^2*(1-IF(35<=$G11,$F11,0)),0) | AR11: =IF(36>=$C11,$B11/12*(1+'Assumptions'!$B$26)*(1+'Assumptions'!$B$27)^2*(1-IF(36<=$G11,$F11,0)),0)
A12: Director of Business Development - Sales / referrals (growth driv | B12: 95000 | C12: 6 | D12: I | E12: 3 | F12: =IF(0,'Assumptions'!$B$28,0) | G12: ='Assumptions'!$B$29 | I12: =IF(1>=$C12,$B12/12*(1+'Assumptions'!$B$26)*(1+'Assumptions'!$B$27)^0*(1-IF(1<=$G12,$F12,0)),0) | J12: =IF(2>=$C12,$B12/12*(1+'Assumptions'!$B$26)*(1+'Assumptions'!$B$27)^0*(1-IF(2<=$G12,$F12,0)),0) | K12: =IF(3>=$C12,$B12/12*(1+'Assumptions'!$B$26)*(1+'Assumptions'!$B$27)^0*(1-IF(3<=$G12,$F12,0)),0) | L12: =IF(4>=$C12,$B12/12*(1+'Assumptions'!$B$26)*(1+'Assumptions'!$B$27)^0*(1-IF(4<=$G12,$F12,0)),0) | M12: =IF(5>=$C12,$B12/12*(1+'Assumptions'!$B$26)*(1+'Assumptions'!$B$27)^0*(1-IF(5<=$G12,$F12,0)),0) | N12: =IF(6>=$C12,$B12/12*(1+'Assumptions'!$B$26)*(1+'Assumptions'!$B$27)^0*(1-IF(6<=$G12,$F12,0)),0) | O12: =IF(7>=$C12,$B12/12*(1+'Assumptions'!$B$26)*(1+'Assumptions'!$B$27)^0*(1-IF(7<=$G12,$F12,0)),0) | P12: =IF(8>=$C12,$B12/12*(1+'Assumptions'!$B$26)*(1+'Assumptions'!$B$27)^0*(1-IF(8<=$G12,$F12,0)),0) | Q12: =IF(9>=$C12,$B12/12*(1+'Assumptions'!$B$26)*(1+'Assumptions'!$B$27)^0*(1-IF(9<=$G12,$F12,0)),0) | R12: =IF(10>=$C12,$B12/12*(1+'Assumptions'!$B$26)*(1+'Assumptions'!$B$27)^0*(1-IF(10<=$G12,$F12,0)),0) | S12: =IF(11>=$C12,$B12/12*(1+'Assumptions'!$B$26)*(1+'Assumptions'!$B$27)^0*(1-IF(11<=$G12,$F12,0)),0) | T12: =IF(12>=$C12,$B12/12*(1+'Assumptions'!$B$26)*(1+'Assumptions'!$B$27)^0*(1-IF(12<=$G12,$F12,0)),0) | U12: =IF(13>=$C12,$B12/12*(1+'Assumptions'!$B$26)*(1+'Assumptions'!$B$27)^1*(1-IF(13<=$G12,$F12,0)),0) | V12: =IF(14>=$C12,$B12/12*(1+'Assumptions'!$B$26)*(1+'Assumptions'!$B$27)^1*(1-IF(14<=$G12,$F12,0)),0) | W12: =IF(15>=$C12,$B12/12*(1+'Assumptions'!$B$26)*(1+'Assumptions'!$B$27)^1*(1-IF(15<=$G12,$F12,0)),0) | X12: =IF(16>=$C12,$B12/12*(1+'Assumptions'!$B$26)*(1+'Assumptions'!$B$27)^1*(1-IF(16<=$G12,$F12,0)),0) | Y12: =IF(17>=$C12,$B12/12*(1+'Assumptions'!$B$26)*(1+'Assumptions'!$B$27)^1*(1-IF(17<=$G12,$F12,0)),0) | Z12: =IF(18>=$C12,$B12/12*(1+'Assumptions'!$B$26)*(1+'Assumptions'!$B$27)^1*(1-IF(18<=$G12,$F12,0)),0) | AA12: =IF(19>=$C12,$B12/12*(1+'Assumptions'!$B$26)*(1+'Assumptions'!$B$27)^1*(1-IF(19<=$G12,$F12,0)),0) | AB12: =IF(20>=$C12,$B12/12*(1+'Assumptions'!$B$26)*(1+'Assumptions'!$B$27)^1*(1-IF(20<=$G12,$F12,0)),0) | AC12: =IF(21>=$C12,$B12/12*(1+'Assumptions'!$B$26)*(1+'Assumptions'!$B$27)^1*(1-IF(21<=$G12,$F12,0)),0) | AD12: =IF(22>=$C12,$B12/12*(1+'Assumptions'!$B$26)*(1+'Assumptions'!$B$27)^1*(1-IF(22<=$G12,$F12,0)),0) | AE12: =IF(23>=$C12,$B12/12*(1+'Assumptions'!$B$26)*(1+'Assumptions'!$B$27)^1*(1-IF(23<=$G12,$F12,0)),0) | AF12: =IF(24>=$C12,$B12/12*(1+'Assumptions'!$B$26)*(1+'Assumptions'!$B$27)^1*(1-IF(24<=$G12,$F12,0)),0) | AG12: =IF(25>=$C12,$B12/12*(1+'Assumptions'!$B$26)*(1+'Assumptions'!$B$27)^2*(1-IF(25<=$G12,$F12,0)),0) | AH12: =IF(26>=$C12,$B12/12*(1+'Assumptions'!$B$26)*(1+'Assumptions'!$B$27)^2*(1-IF(26<=$G12,$F12,0)),0) | AI12: =IF(27>=$C12,$B12/12*(1+'Assumptions'!$B$26)*(1+'Assumptions'!$B$27)^2*(1-IF(27<=$G12,$F12,0)),0) | AJ12: =IF(28>=$C12,$B12/12*(1+'Assumptions'!$B$26)*(1+'Assumptions'!$B$27)^2*(1-IF(28<=$G12,$F12,0)),0) | AK12: =IF(29>=$C12,$B12/12*(1+'Assumptions'!$B$26)*(1+'Assumptions'!$B$27)^2*(1-IF(29<=$G12,$F12,0)),0) | AL12: =IF(30>=$C12,$B12/12*(1+'Assumptions'!$B$26)*(1+'Assumptions'!$B$27)^2*(1-IF(30<=$G12,$F12,0)),0) | AM12: =IF(31>=$C12,$B12/12*(1+'Assumptions'!$B$26)*(1+'Assumptions'!$B$27)^2*(1-IF(31<=$G12,$F12,0)),0) | AN12: =IF(32>=$C12,$B12/12*(1+'Assumptions'!$B$26)*(1+'Assumptions'!$B$27)^2*(1-IF(32<=$G12,$F12,0)),0) | AO12: =IF(33>=$C12,$B12/12*(1+'Assumptions'!$B$26)*(1+'Assumptions'!$B$27)^2*(1-IF(33<=$G12,$F12,0)),0) | AP12: =IF(34>=$C12,$B12/12*(1+'Assumptions'!$B$26)*(1+'Assumptions'!$B$27)^2*(1-IF(34<=$G12,$F12,0)),0) | AQ12: =IF(35>=$C12,$B12/12*(1+'Assumptions'!$B$26)*(1+'Assumptions'!$B$27)^2*(1-IF(35<=$G12,$F12,0)),0) | AR12: =IF(36>=$C12,$B12/12*(1+'Assumptions'!$B$26)*(1+'Assumptions'!$B$27)^2*(1-IF(36<=$G12,$F12,0)),0)
A13: Capacity hire - 2nd CNA - CNA / Hospice Aide (capacity-d [census-triggered - slip if ramp lags] | B13: 46511 | C13: 2 | D13: D | E13: 3 | F13: =IF(0,'Assumptions'!$B$28,0) | G13: ='Assumptions'!$B$29 | I13: =IF(1>=$C13,$B13/12*(1+'Assumptions'!$B$26)*(1+'Assumptions'!$B$27)^0*(1-IF(1<=$G13,$F13,0)),0) | J13: =IF(2>=$C13,$B13/12*(1+'Assumptions'!$B$26)*(1+'Assumptions'!$B$27)^0*(1-IF(2<=$G13,$F13,0)),0) | K13: =IF(3>=$C13,$B13/12*(1+'Assumptions'!$B$26)*(1+'Assumptions'!$B$27)^0*(1-IF(3<=$G13,$F13,0)),0) | L13: =IF(4>=$C13,$B13/12*(1+'Assumptions'!$B$26)*(1+'Assumptions'!$B$27)^0*(1-IF(4<=$G13,$F13,0)),0) | M13: =IF(5>=$C13,$B13/12*(1+'Assumptions'!$B$26)*(1+'Assumptions'!$B$27)^0*(1-IF(5<=$G13,$F13,0)),0) | N13: =IF(6>=$C13,$B13/12*(1+'Assumptions'!$B$26)*(1+'Assumptions'!$B$27)^0*(1-IF(6<=$G13,$F13,0)),0) | O13: =IF(7>=$C13,$B13/12*(1+'Assumptions'!$B$26)*(1+'Assumptions'!$B$27)^0*(1-IF(7<=$G13,$F13,0)),0) | P13: =IF(8>=$C13,$B13/12*(1+'Assumptions'!$B$26)*(1+'Assumptions'!$B$27)^0*(1-IF(8<=$G13,$F13,0)),0) | Q13: =IF(9>=$C13,$B13/12*(1+'Assumptions'!$B$26)*(1+'Assumptions'!$B$27)^0*(1-IF(9<=$G13,$F13,0)),0) | R13: =IF(10>=$C13,$B13/12*(1+'Assumptions'!$B$26)*(1+'Assumptions'!$B$27)^0*(1-IF(10<=$G13,$F13,0)),0) | S13: =IF(11>=$C13,$B13/12*(1+'Assumptions'!$B$26)*(1+'Assumptions'!$B$27)^0*(1-IF(11<=$G13,$F13,0)),0) | T13: =IF(12>=$C13,$B13/12*(1+'Assumptions'!$B$26)*(1+'Assumptions'!$B$27)^0*(1-IF(12<=$G13,$F13,0)),0) | U13: =IF(13>=$C13,$B13/12*(1+'Assumptions'!$B$26)*(1+'Assumptions'!$B$27)^1*(1-IF(13<=$G13,$F13,0)),0) | V13: =IF(14>=$C13,$B13/12*(1+'Assumptions'!$B$26)*(1+'Assumptions'!$B$27)^1*(1-IF(14<=$G13,$F13,0)),0) | W13: =IF(15>=$C13,$B13/12*(1+'Assumptions'!$B$26)*(1+'Assumptions'!$B$27)^1*(1-IF(15<=$G13,$F13,0)),0) | X13: =IF(16>=$C13,$B13/12*(1+'Assumptions'!$B$26)*(1+'Assumptions'!$B$27)^1*(1-IF(16<=$G13,$F13,0)),0) | Y13: =IF(17>=$C13,$B13/12*(1+'Assumptions'!$B$26)*(1+'Assumptions'!$B$27)^1*(1-IF(17<=$G13,$F13,0)),0) | Z13: =IF(18>=$C13,$B13/12*(1+'Assumptions'!$B$26)*(1+'Assumptions'!$B$27)^1*(1-IF(18<=$G13,$F13,0)),0) | AA13: =IF(19>=$C13,$B13/12*(1+'Assumptions'!$B$26)*(1+'Assumptions'!$B$27)^1*(1-IF(19<=$G13,$F13,0)),0) | AB13: =IF(20>=$C13,$B13/12*(1+'Assumptions'!$B$26)*(1+'Assumptions'!$B$27)^1*(1-IF(20<=$G13,$F13,0)),0) | AC13: =IF(21>=$C13,$B13/12*(1+'Assumptions'!$B$26)*(1+'Assumptions'!$B$27)^1*(1-IF(21<=$G13,$F13,0)),0) | AD13: =IF(22>=$C13,$B13/12*(1+'Assumptions'!$B$26)*(1+'Assumptions'!$B$27)^1*(1-IF(22<=$G13,$F13,0)),0) | AE13: =IF(23>=$C13,$B13/12*(1+'Assumptions'!$B$26)*(1+'Assumptions'!$B$27)^1*(1-IF(23<=$G13,$F13,0)),0) | AF13: =IF(24>=$C13,$B13/12*(1+'Assumptions'!$B$26)*(1+'Assumptions'!$B$27)^1*(1-IF(24<=$G13,$F13,0)),0) | AG13: =IF(25>=$C13,$B13/12*(1+'Assumptions'!$B$26)*(1+'Assumptions'!$B$27)^2*(1-IF(25<=$G13,$F13,0)),0) | AH13: =IF(26>=$C13,$B13/12*(1+'Assumptions'!$B$26)*(1+'Assumptions'!$B$27)^2*(1-IF(26<=$G13,$F13,0)),0) | AI13: =IF(27>=$C13,$B13/12*(1+'Assumptions'!$B$26)*(1+'Assumptions'!$B$27)^2*(1-IF(27<=$G13,$F13,0)),0) | AJ13: =IF(28>=$C13,$B13/12*(1+'Assumptions'!$B$26)*(1+'Assumptions'!$B$27)^2*(1-IF(28<=$G13,$F13,0)),0) | AK13: =IF(29>=$C13,$B13/12*(1+'Assumptions'!$B$26)*(1+'Assumptions'!$B$27)^2*(1-IF(29<=$G13,$F13,0)),0) | AL13: =IF(30>=$C13,$B13/12*(1+'Assumptions'!$B$26)*(1+'Assumptions'!$B$27)^2*(1-IF(30<=$G13,$F13,0)),0) | AM13: =IF(31>=$C13,$B13/12*(1+'Assumptions'!$B$26)*(1+'Assumptions'!$B$27)^2*(1-IF(31<=$G13,$F13,0)),0) | AN13: =IF(32>=$C13,$B13/12*(1+'Assumptions'!$B$26)*(1+'Assumptions'!$B$27)^2*(1-IF(32<=$G13,$F13,0)),0) | AO13: =IF(33>=$C13,$B13/12*(1+'Assumptions'!$B$26)*(1+'Assumptions'!$B$27)^2*(1-IF(33<=$G13,$F13,0)),0) | AP13: =IF(34>=$C13,$B13/12*(1+'Assumptions'!$B$26)*(1+'Assumptions'!$B$27)^2*(1-IF(34<=$G13,$F13,0)),0) | AQ13: =IF(35>=$C13,$B13/12*(1+'Assumptions'!$B$26)*(1+'Assumptions'!$B$27)^2*(1-IF(35<=$G13,$F13,0)),0) | AR13: =IF(36>=$C13,$B13/12*(1+'Assumptions'!$B$26)*(1+'Assumptions'!$B$27)^2*(1-IF(36<=$G13,$F13,0)),0)
A14: FT Social Worker (MSW) - Core IDG MSW (converts PRN SW | B14: 58000 | C14: 6 | D14: D | E14: 3 | F14: =IF(0,'Assumptions'!$B$28,0) | G14: ='Assumptions'!$B$29 | I14: =IF(1>=$C14,$B14/12*(1+'Assumptions'!$B$26)*(1+'Assumptions'!$B$27)^0*(1-IF(1<=$G14,$F14,0)),0) | J14: =IF(2>=$C14,$B14/12*(1+'Assumptions'!$B$26)*(1+'Assumptions'!$B$27)^0*(1-IF(2<=$G14,$F14,0)),0) | K14: =IF(3>=$C14,$B14/12*(1+'Assumptions'!$B$26)*(1+'Assumptions'!$B$27)^0*(1-IF(3<=$G14,$F14,0)),0) | L14: =IF(4>=$C14,$B14/12*(1+'Assumptions'!$B$26)*(1+'Assumptions'!$B$27)^0*(1-IF(4<=$G14,$F14,0)),0) | M14: =IF(5>=$C14,$B14/12*(1+'Assumptions'!$B$26)*(1+'Assumptions'!$B$27)^0*(1-IF(5<=$G14,$F14,0)),0) | N14: =IF(6>=$C14,$B14/12*(1+'Assumptions'!$B$26)*(1+'Assumptions'!$B$27)^0*(1-IF(6<=$G14,$F14,0)),0) | O14: =IF(7>=$C14,$B14/12*(1+'Assumptions'!$B$26)*(1+'Assumptions'!$B$27)^0*(1-IF(7<=$G14,$F14,0)),0) | P14: =IF(8>=$C14,$B14/12*(1+'Assumptions'!$B$26)*(1+'Assumptions'!$B$27)^0*(1-IF(8<=$G14,$F14,0)),0) | Q14: =IF(9>=$C14,$B14/12*(1+'Assumptions'!$B$26)*(1+'Assumptions'!$B$27)^0*(1-IF(9<=$G14,$F14,0)),0) | R14: =IF(10>=$C14,$B14/12*(1+'Assumptions'!$B$26)*(1+'Assumptions'!$B$27)^0*(1-IF(10<=$G14,$F14,0)),0) | S14: =IF(11>=$C14,$B14/12*(1+'Assumptions'!$B$26)*(1+'Assumptions'!$B$27)^0*(1-IF(11<=$G14,$F14,0)),0) | T14: =IF(12>=$C14,$B14/12*(1+'Assumptions'!$B$26)*(1+'Assumptions'!$B$27)^0*(1-IF(12<=$G14,$F14,0)),0) | U14: =IF(13>=$C14,$B14/12*(1+'Assumptions'!$B$26)*(1+'Assumptions'!$B$27)^1*(1-IF(13<=$G14,$F14,0)),0) | V14: =IF(14>=$C14,$B14/12*(1+'Assumptions'!$B$26)*(1+'Assumptions'!$B$27)^1*(1-IF(14<=$G14,$F14,0)),0) | W14: =IF(15>=$C14,$B14/12*(1+'Assumptions'!$B$26)*(1+'Assumptions'!$B$27)^1*(1-IF(15<=$G14,$F14,0)),0) | X14: =IF(16>=$C14,$B14/12*(1+'Assumptions'!$B$26)*(1+'Assumptions'!$B$27)^1*(1-IF(16<=$G14,$F14,0)),0) | Y14: =IF(17>=$C14,$B14/12*(1+'Assumptions'!$B$26)*(1+'Assumptions'!$B$27)^1*(1-IF(17<=$G14,$F14,0)),0) | Z14: =IF(18>=$C14,$B14/12*(1+'Assumptions'!$B$26)*(1+'Assumptions'!$B$27)^1*(1-IF(18<=$G14,$F14,0)),0) | AA14: =IF(19>=$C14,$B14/12*(1+'Assumptions'!$B$26)*(1+'Assumptions'!$B$27)^1*(1-IF(19<=$G14,$F14,0)),0) | AB14: =IF(20>=$C14,$B14/12*(1+'Assumptions'!$B$26)*(1+'Assumptions'!$B$27)^1*(1-IF(20<=$G14,$F14,0)),0) | AC14: =IF(21>=$C14,$B14/12*(1+'Assumptions'!$B$26)*(1+'Assumptions'!$B$27)^1*(1-IF(21<=$G14,$F14,0)),0) | AD14: =IF(22>=$C14,$B14/12*(1+'Assumptions'!$B$26)*(1+'Assumptions'!$B$27)^1*(1-IF(22<=$G14,$F14,0)),0) | AE14: =IF(23>=$C14,$B14/12*(1+'Assumptions'!$B$26)*(1+'Assumptions'!$B$27)^1*(1-IF(23<=$G14,$F14,0)),0) | AF14: =IF(24>=$C14,$B14/12*(1+'Assumptions'!$B$26)*(1+'Assumptions'!$B$27)^1*(1-IF(24<=$G14,$F14,0)),0) | AG14: =IF(25>=$C14,$B14/12*(1+'Assumptions'!$B$26)*(1+'Assumptions'!$B$27)^2*(1-IF(25<=$G14,$F14,0)),0) | AH14: =IF(26>=$C14,$B14/12*(1+'Assumptions'!$B$26)*(1+'Assumptions'!$B$27)^2*(1-IF(26<=$G14,$F14,0)),0) | AI14: =IF(27>=$C14,$B14/12*(1+'Assumptions'!$B$26)*(1+'Assumptions'!$B$27)^2*(1-IF(27<=$G14,$F14,0)),0) | AJ14: =IF(28>=$C14,$B14/12*(1+'Assumptions'!$B$26)*(1+'Assumptions'!$B$27)^2*(1-IF(28<=$G14,$F14,0)),0) | AK14: =IF(29>=$C14,$B14/12*(1+'Assumptions'!$B$26)*(1+'Assumptions'!$B$27)^2*(1-IF(29<=$G14,$F14,0)),0) | AL14: =IF(30>=$C14,$B14/12*(1+'Assumptions'!$B$26)*(1+'Assumptions'!$B$27)^2*(1-IF(30<=$G14,$F14,0)),0) | AM14: =IF(31>=$C14,$B14/12*(1+'Assumptions'!$B$26)*(1+'Assumptions'!$B$27)^2*(1-IF(31<=$G14,$F14,0)),0) | AN14: =IF(32>=$C14,$B14/12*(1+'Assumptions'!$B$26)*(1+'Assumptions'!$B$27)^2*(1-IF(32<=$G14,$F14,0)),0) | AO14: =IF(33>=$C14,$B14/12*(1+'Assumptions'!$B$26)*(1+'Assumptions'!$B$27)^2*(1-IF(33<=$G14,$F14,0)),0) | AP14: =IF(34>=$C14,$B14/12*(1+'Assumptions'!$B$26)*(1+'Assumptions'!$B$27)^2*(1-IF(34<=$G14,$F14,0)),0) | AQ14: =IF(35>=$C14,$B14/12*(1+'Assumptions'!$B$26)*(1+'Assumptions'!$B$27)^2*(1-IF(35<=$G14,$F14,0)),0) | AR14: =IF(36>=$C14,$B14/12*(1+'Assumptions'!$B$26)*(1+'Assumptions'!$B$27)^2*(1-IF(36<=$G14,$F14,0)),0)
A15: FT LVN - visits / on-call - Core IDG LVN (converts PRN LVN | B15: 52000 | C15: 8 | D15: D | E15: 3 | F15: =IF(0,'Assumptions'!$B$28,0) | G15: ='Assumptions'!$B$29 | I15: =IF(1>=$C15,$B15/12*(1+'Assumptions'!$B$26)*(1+'Assumptions'!$B$27)^0*(1-IF(1<=$G15,$F15,0)),0) | J15: =IF(2>=$C15,$B15/12*(1+'Assumptions'!$B$26)*(1+'Assumptions'!$B$27)^0*(1-IF(2<=$G15,$F15,0)),0) | K15: =IF(3>=$C15,$B15/12*(1+'Assumptions'!$B$26)*(1+'Assumptions'!$B$27)^0*(1-IF(3<=$G15,$F15,0)),0) | L15: =IF(4>=$C15,$B15/12*(1+'Assumptions'!$B$26)*(1+'Assumptions'!$B$27)^0*(1-IF(4<=$G15,$F15,0)),0) | M15: =IF(5>=$C15,$B15/12*(1+'Assumptions'!$B$26)*(1+'Assumptions'!$B$27)^0*(1-IF(5<=$G15,$F15,0)),0) | N15: =IF(6>=$C15,$B15/12*(1+'Assumptions'!$B$26)*(1+'Assumptions'!$B$27)^0*(1-IF(6<=$G15,$F15,0)),0) | O15: =IF(7>=$C15,$B15/12*(1+'Assumptions'!$B$26)*(1+'Assumptions'!$B$27)^0*(1-IF(7<=$G15,$F15,0)),0) | P15: =IF(8>=$C15,$B15/12*(1+'Assumptions'!$B$26)*(1+'Assumptions'!$B$27)^0*(1-IF(8<=$G15,$F15,0)),0) | Q15: =IF(9>=$C15,$B15/12*(1+'Assumptions'!$B$26)*(1+'Assumptions'!$B$27)^0*(1-IF(9<=$G15,$F15,0)),0) | R15: =IF(10>=$C15,$B15/12*(1+'Assumptions'!$B$26)*(1+'Assumptions'!$B$27)^0*(1-IF(10<=$G15,$F15,0)),0) | S15: =IF(11>=$C15,$B15/12*(1+'Assumptions'!$B$26)*(1+'Assumptions'!$B$27)^0*(1-IF(11<=$G15,$F15,0)),0) | T15: =IF(12>=$C15,$B15/12*(1+'Assumptions'!$B$26)*(1+'Assumptions'!$B$27)^0*(1-IF(12<=$G15,$F15,0)),0) | U15: =IF(13>=$C15,$B15/12*(1+'Assumptions'!$B$26)*(1+'Assumptions'!$B$27)^1*(1-IF(13<=$G15,$F15,0)),0) | V15: =IF(14>=$C15,$B15/12*(1+'Assumptions'!$B$26)*(1+'Assumptions'!$B$27)^1*(1-IF(14<=$G15,$F15,0)),0) | W15: =IF(15>=$C15,$B15/12*(1+'Assumptions'!$B$26)*(1+'Assumptions'!$B$27)^1*(1-IF(15<=$G15,$F15,0)),0) | X15: =IF(16>=$C15,$B15/12*(1+'Assumptions'!$B$26)*(1+'Assumptions'!$B$27)^1*(1-IF(16<=$G15,$F15,0)),0) | Y15: =IF(17>=$C15,$B15/12*(1+'Assumptions'!$B$26)*(1+'Assumptions'!$B$27)^1*(1-IF(17<=$G15,$F15,0)),0) | Z15: =IF(18>=$C15,$B15/12*(1+'Assumptions'!$B$26)*(1+'Assumptions'!$B$27)^1*(1-IF(18<=$G15,$F15,0)),0) | AA15: =IF(19>=$C15,$B15/12*(1+'Assumptions'!$B$26)*(1+'Assumptions'!$B$27)^1*(1-IF(19<=$G15,$F15,0)),0) | AB15: =IF(20>=$C15,$B15/12*(1+'Assumptions'!$B$26)*(1+'Assumptions'!$B$27)^1*(1-IF(20<=$G15,$F15,0)),0) | AC15: =IF(21>=$C15,$B15/12*(1+'Assumptions'!$B$26)*(1+'Assumptions'!$B$27)^1*(1-IF(21<=$G15,$F15,0)),0) | AD15: =IF(22>=$C15,$B15/12*(1+'Assumptions'!$B$26)*(1+'Assumptions'!$B$27)^1*(1-IF(22<=$G15,$F15,0)),0) | AE15: =IF(23>=$C15,$B15/12*(1+'Assumptions'!$B$26)*(1+'Assumptions'!$B$27)^1*(1-IF(23<=$G15,$F15,0)),0) | AF15: =IF(24>=$C15,$B15/12*(1+'Assumptions'!$B$26)*(1+'Assumptions'!$B$27)^1*(1-IF(24<=$G15,$F15,0)),0) | AG15: =IF(25>=$C15,$B15/12*(1+'Assumptions'!$B$26)*(1+'Assumptions'!$B$27)^2*(1-IF(25<=$G15,$F15,0)),0) | AH15: =IF(26>=$C15,$B15/12*(1+'Assumptions'!$B$26)*(1+'Assumptions'!$B$27)^2*(1-IF(26<=$G15,$F15,0)),0) | AI15: =IF(27>=$C15,$B15/12*(1+'Assumptions'!$B$26)*(1+'Assumptions'!$B$27)^2*(1-IF(27<=$G15,$F15,0)),0) | AJ15: =IF(28>=$C15,$B15/12*(1+'Assumptions'!$B$26)*(1+'Assumptions'!$B$27)^2*(1-IF(28<=$G15,$F15,0)),0) | AK15: =IF(29>=$C15,$B15/12*(1+'Assumptions'!$B$26)*(1+'Assumptions'!$B$27)^2*(1-IF(29<=$G15,$F15,0)),0) | AL15: =IF(30>=$C15,$B15/12*(1+'Assumptions'!$B$26)*(1+'Assumptions'!$B$27)^2*(1-IF(30<=$G15,$F15,0)),0) | AM15: =IF(31>=$C15,$B15/12*(1+'Assumptions'!$B$26)*(1+'Assumptions'!$B$27)^2*(1-IF(31<=$G15,$F15,0)),0) | AN15: =IF(32>=$C15,$B15/12*(1+'Assumptions'!$B$26)*(1+'Assumptions'!$B$27)^2*(1-IF(32<=$G15,$F15,0)),0) | AO15: =IF(33>=$C15,$B15/12*(1+'Assumptions'!$B$26)*(1+'Assumptions'!$B$27)^2*(1-IF(33<=$G15,$F15,0)),0) | AP15: =IF(34>=$C15,$B15/12*(1+'Assumptions'!$B$26)*(1+'Assumptions'!$B$27)^2*(1-IF(34<=$G15,$F15,0)),0) | AQ15: =IF(35>=$C15,$B15/12*(1+'Assumptions'!$B$26)*(1+'Assumptions'!$B$27)^2*(1-IF(35<=$G15,$F15,0)),0) | AR15: =IF(36>=$C15,$B15/12*(1+'Assumptions'!$B$26)*(1+'Assumptions'!$B$27)^2*(1-IF(36<=$G15,$F15,0)),0)
