Workbook
Name rhc_tier1: Inputs!$B$5
Name rhc_tier2: Inputs!$B$6
Name wage_index: Inputs!$B$7
Name labor_share: Inputs!$B$8
Name tier1_pct: Inputs!$B$9
Name seq: Inputs!$B$10
Name writeoff_pct: Inputs!$B$11
Name blended_actual: Inputs!$B$12
Name medicare_cap: Inputs!$B$13
Name avg_days_month: Inputs!$B$24
Name capture_rate: Inputs!$B$27
Name census_scenario: Inputs!$B$28
Name rn_caseload: Inputs!$B$53
Name aide_caseload: Inputs!$B$54
Name visits_rn_day: Inputs!$B$55
Name visits_aide_day: Inputs!$B$56
Name merit: Inputs!$B$57
Name benefits_load: Inputs!$B$60
Name health_pm: Inputs!$B$61
Name med_director: Inputs!$B$64
Name supplies_pd: Inputs!$B$67
Name dme_pd: Inputs!$B$68
Name pharmacy_pd: Inputs!$B$69
Name ga_utilities: Inputs!$B$72
Name ga_internet: Inputs!$B$73
Name ga_telephone: Inputs!$B$74
Name ga_bvtm: Inputs!$B$75
Name ga_billing: Inputs!$B$76
Name ga_emr: Inputs!$B$77
Name ga_pcr: Inputs!$B$78
Name ga_cc: Inputs!$B$79
Name ga_liability: Inputs!$B$80
Name ga_training: Inputs!$B$81
Name ga_other: Inputs!$B$82
Name ga_bankfees: Inputs!$B$83
Name ga_rent: Inputs!$B$84
Name ga_marketing: Inputs!$B$85
Name qr_fee_pct: Inputs!$B$88
Name sba_principal: Inputs!$B$91
Name sba_rate: Inputs!$B$92
Name sba_term_mo: Inputs!$B$93
Name equity: Inputs!$B$94
Name loc_limit: Inputs!$B$95
Name loc_rate: Inputs!$B$96
Name min_cash: Inputs!$B$97
Name capex: Inputs!$B$98
Name deprec_yrs: Inputs!$B$99
Name tx_tax: Inputs!$B$100
Name su_enroll: Inputs!$B$103
Name su_accred: Inputs!$B$104
Name su_license: Inputs!$B$105
Name su_emr: Inputs!$B$106
Name su_supplies: Inputs!$B$107
Name su_legal: Inputs!$B$108
Name su_conting: Inputs!$B$109
Name ar_days: Inputs!$B$112
Name ap_days: Inputs!$B$113

Sheet Inputs
A1: AZALEA HOSPICE & PALLIATIVE CARE — Tyler, TX
A2: Assumptions Engine — single source of truth · blue = input · black = formula · green = cross-sheet link · cells noted to Paloma actuals
A4: A. GEOGRAPHY & MEDICARE RHC RATES (FY2026, 100% Medicare)
A5: RHC per-diem, days 1-60 ($/day) | B5: 230.83
A6: RHC per-diem, days 61+ ($/day) | B6: 182.36
A7: Tyler CBSA 46340 wage index | B7: 0.88
A8: RHC labor share | B8: 0.68
A9: % patient-days in Tier 1 (days 1-60) | B9: 0.4
A10: Sequestration reduction | B10: 0.02
A11: Write-offs (% of gross) | B11: 0.0015
A12: Blended NET rate per PD - ACTUAL ($/day) | B12: 181
A13: Medicare aggregate cap / beneficiary ($/yr) | B13: 35361.44
A15: A2. DERIVED RATE BUILD (formulas)
A16: Wage-index adjustment factor | B16: =Inputs!$B$8*Inputs!$B$7+(1-Inputs!$B$8)
A17: Wage-adjusted rate, days 1-60 | B17: =Inputs!$B$5*Inputs!$B$16
A18: Wage-adjusted rate, days 61+ | B18: =Inputs!$B$6*Inputs!$B$16
A19: Blended GROSS rate ($/PD) | B19: =Inputs!$B$9*Inputs!$B$17+(1-Inputs!$B$9)*Inputs!$B$18
A20: Blended NET rate ($/PD) [model] | B20: =Inputs!$B$19*(1-Inputs!$B$10-Inputs!$B$11)
A21: Validation: model net rate vs actual $181 | B21: =Inputs!$B$20-Inputs!$B$12 | C21: should be near $0
A23: B. TIMING
A24: Average days per month | B24: 30.4
A26: C. CENSUS — PATIENT-MIGRATION RAMP (front-loaded M1-M2)
A27: Patient-migration capture rate | B27: 1
A28: Census scenario (1=Base flat, 2=Upside growth) | B28: 1
A30: ADC path — BASE (100% capture, flat steady-state) | C30: 12 | D30: 19.8 | E30: 22 | F30: 22 | G30: 22 | H30: 22 | I30: 22 | J30: 22 | K30: 22 | L30: 22 | M30: 22 | N30: 22 | O30: 22 | P30: 22 | Q30: 22 | R30: 22 | S30: 22 | T30: 22 | U30: 22 | V30: 22
A31: ADC path — UPSIDE (referral growth) | C31: 12 | D31: 19.8 | E31: 22 | F31: 23 | G31: 24 | H31: 25 | I31: 26 | J31: 27 | K31: 28 | L31: 29 | M31: 30 | N31: 31 | O31: 33 | P31: 35 | Q31: 37 | R31: 39 | S31: 44 | T31: 50 | U31: 55 | V31: 60
A32: EFFECTIVE ADC = chosen path x capture | C32: =IF(Inputs!$B$28=2,C31,C30)*Inputs!$B$27 | D32: =IF(Inputs!$B$28=2,D31,D30)*Inputs!$B$27 | E32: =IF(Inputs!$B$28=2,E31,E30)*Inputs!$B$27 | F32: =IF(Inputs!$B$28=2,F31,F30)*Inputs!$B$27 | G32: =IF(Inputs!$B$28=2,G31,G30)*Inputs!$B$27 | H32: =IF(Inputs!$B$28=2,H31,H30)*Inputs!$B$27 | I32: =IF(Inputs!$B$28=2,I31,I30)*Inputs!$B$27 | J32: =IF(Inputs!$B$28=2,J31,J30)*Inputs!$B$27 | ... V32: =IF(Inputs!$B$28=2,V31,V30)*Inputs!$B$27
A34: D. STAGGERED FT ROSTER (named hires)
A35: Name | B35: Role | C35: Annual salary | D35: Start month | E35: Cost group | F35: Status
A36: Brad Woodard | B36: Administrator / Director | C36: 120000 | D36: 1 | E36: Indirect (SG&A) | F36: Filled
A37: Angie Frost | B37: RN Case Manager | C37: 77504 | D37: 1 | E37: Direct (COGS) | F37: Filled
A38: Tanisha Robison | B38: CNA / Hospice Aide | C38: 46511 | D38: 1 | E38: Direct (COGS) | F38: Filled
A39: Dana Davenport | B39: Director of Clinical Services | C39: 110000 | D39: 2 | E39: Indirect (SG&A) | F39: Filled
A40: Silas Shelton | B40: Administrator | C40: 130000 | D40: 3 | E40: Indirect (SG&A) | F40: Filled
A41: Jodi McCollum | B41: RN Case Manager (2nd seat) | C41: 75008 | D41: 4 | E41: Direct (COGS) | F41: OPEN REQ
A42: Rhonda Smith — Office Mgr (PRN, W-2) | B42: Per-visit / part-time office support | C42: 34000
A44: D2. PRN / PER-VISIT ROSTER (census-driven)
A45: Role | C45: Visits / pt / mo | D45: Rate / visit
A46: PRN On-Call LVN (Kendricks-Tuck, Foster) | C46: 0.6 | D46: 100
A47: PRN Chaplain (Ector, Johnson) | C47: 0.75 | D47: 75
...

Sheet Dashboard
A1: AZALEA HOSPICE & PALLIATIVE CARE — Tyler, TX
A2: Operations Dashboard — live KPIs (all formula-driven from the engine)
A4: KEY PERFORMANCE INDICATORS
A5: Y3 run-rate net revenue | C5: Y3 EBITDA margin | E5: Min cash balance
A6: =SUM('Operating Budget'!S6:V6) | C6: =SUM('Operating Budget'!S23:V23)/SUM('Operating Budget'!S6:V6) | E6: =MIN('Cash Flow & BS'!C20:V20)
A8: Min DSCR (Y1 monthly) | C8: Peak working-capital draw | E8: Blended net rate / PD
A9: =MIN('Debt Schedule'!C17:N17) | C9: =MAX('Cash Flow & BS'!C19:V19) | E9: =Inputs!$B$20

Sheet Actuals vs Budget
A1: AZALEA HOSPICE & PALLIATIVE CARE — Tyler, TX
A2: Monthly Actuals vs Budget — enter month actuals (blue); variance auto-flags > 10%
A4: Reporting month (1-12) | B4: 3
A6: Line | B6: Budget | C6: Actual | D6: Variance | E6: Flag
A7: Net revenue | B7: =INDEX('Operating Budget'!C6:N6,$B$4) | C7: 0 | D7: =IF(B7=0,0,(C7-B7)/B7) | E7: =IF(ABS(D7)>0.1,"FLAG >10%","ok")
A8: Total COGS | B8: =INDEX('Operating Budget'!C14:N14,$B$4) | C8: 0 | D8: =IF(B8=0,0,(C8-B8)/B8) | E8: =IF(ABS(D8)>0.1,"FLAG >10%","ok")
A9: Gross profit | B9: =INDEX('Operating Budget'!C15:N15,$B$4) | C9: 0 | D9: =IF(B9=0,0,(C9-B9)/B9) | E9: =IF(ABS(D9)>0.1,"FLAG >10%","ok")
A10: Total SG&A | B10: =INDEX('Operating Budget'!C22:N22,$B$4) | C10: 0 | D10: =IF(B10=0,0,(C10-B10)/B10) | E10: =IF(ABS(D10)>0.1,"FLAG >10%","ok")
A11: EBITDA | B11: =INDEX('Operating Budget'!C23:N23,$B$4) | C11: 0 | D11: =IF(B11=0,0,(C11-B11)/B11) | E11: =IF(ABS(D11)>0.1,"FLAG >10%","ok")
A12: Net income | B12: =INDEX('Operating Budget'!C32:N32,$B$4) | C12: 0 | D12: =IF(B12=0,0,(C12-B12)/B12) | E12: =IF(ABS(D12)>0.1,"FLAG >10%","ok")
A14: Budget pulls the selected month from the engine; enter actuals from the close. Flag fires when |variance| > 10%.

Sheet Staffing Tracker
A1: AZALEA HOSPICE & PALLIATIVE CARE — Tyler, TX
A2: Staffing Tracker — staggered-hire calendar · capacity vs demand · open requisitions
A4: HIRE CALENDAR
A5: Name | B5: Role | C5: Annual salary | D5: Start month | E5: Status
A6: Brad Woodard | B6: Administrator / Director | C6: =Inputs!$C$36 | D6: =Inputs!$D$36 | E6: Filled
A7: Angie Frost | B7: RN Case Manager | C7: =Inputs!$C$37 | D7: =Inputs!$D$37 | E7: Filled
A8: Tanisha Robison | B8: CNA / Hospice Aide | C8: =Inputs!$C$38 | D8: =Inputs!$D$38 | E8: Filled
A9: Dana Davenport | B9: Director of Clinical Services | C9: =Inputs!$C$39 | D9: =Inputs!$D$39 | E9: Filled
A10: Silas Shelton | B10: Administrator | C10: =Inputs!$C$40 | D10: =Inputs!$D$40 | E10: Filled
A11: Jodi McCollum | B11: RN Case Manager (2nd seat) | C11: =Inputs!$C$41 | D11: =Inputs!$D$41 | E11: OPEN REQ
A13: CAPACITY vs DEMAND (steady-state ADC 22)
A14: RN case managers needed = ADC ÷ caseload | C14: =ROUNDUP('Revenue Model'!E10/Inputs!$B$53,0)
A15: Aides needed = ADC ÷ caseload | C15: =ROUNDUP('Revenue Model'!E10/Inputs!$B$54,0)
A16: Target visits / RN / day | C16: =Inputs!$B$55
A17: Target visits / aide / day | C17: =Inputs!$B$56
A19: Jodi McCollum's 2nd RN-CM seat is funded but vacant — modeled to start M4 as census coverage requires. Track real churn beyond this one open req.

Sheet Cap & Payroll
A1: AZALEA HOSPICE & PALLIATIVE CARE — Tyler, TX
A2: Medicare Cap Monitor (inherited day-counts) + Payroll Reconciliation
A4: MEDICARE AGGREGATE CAP — by year
C5: Year 1 | D5: Year 2 | E5: Year 3
A6: Unique beneficiaries (est.) | C6: 40 | D6: 55 | E6: 60
A7: Cap allowable = beneficiaries × cap | C7: =C6*Inputs!$B$13 | D7: =D6*Inputs!$B$13 | E7: =E6*Inputs!$B$13
A8: Gross Medicare revenue | C8: =SUM('Revenue Model'!C13:N13) | D8: =SUM('Revenue Model'!O13:R13) | E8: =SUM('Revenue Model'!S13:V13)
A9: Cap headroom (allowable − gross) | C9: =C7-C8 | D9: =D7-D8 | E9: =E7-E8
A11: PAYROLL RECONCILIATION (actual semi-monthly vs model)
A12: Run | B12: 1st half | C12: 2nd half | D12: Month total
A13: Apr 2025 | B13: 22921.54 | C13: 22765.1 | D13: =B13+C13
A14: May 2025 | B14: 22117.27 | C14: 21499.29 | D14: =B14+C14
A15: Jun 2025 | B15: 31000 | C15: 27000 | D15: =B15+C15
A16: Model total labor (M3 steady) | D16: ='Staffing & Payroll'!E37+'Staffing & Payroll'!E38
A18: Cap monitor uses inherited mid-episode day-counts (estimate beneficiaries), not fresh admits. Payroll ties the 3 actual semi-monthly runs to the model's loaded labor.

Sheet Revenue Model
A1: AZALEA HOSPICE & PALLIATIVE CARE — Tyler, TX
A2: Revenue Model — 100% Medicare RHC · accrual basis
A4: RHC RATE (per patient-day) — linked from Inputs
A5: Blended GROSS rate ($/PD) | B5: =Inputs!$B$19
A6: Blended NET rate ($/PD) | B6: =Inputs!$B$20
A8: ($ per period) | C8: YEAR 1 — monthly | O8: YEAR 2 — quarterly | S8: YEAR 3 — quarterly
C9: M1 | D9: M2 | E9: M3 | F9: M4 | G9: M5 | H9: M6 | I9: M7 | J9: M8 | K9: M9 | L9: M10 | M9: M11 | N9: M12 | O9: Y2 Q1 | P9: Y2 Q2 | Q9: Y2 Q3 | R9: Y2 Q4 | S9: Y3 Q1 | T9: Y3 Q2 | U9: Y3 Q3 | V9: Y3 Q4
A10: Average daily census (ADC) | C10: =Inputs!C$32 | D10: =Inputs!D$32 | E10: =Inputs!E$32 | F10: =Inputs!F$32 | G10: =Inputs!G$32 | H10: =Inputs!H$32 | I10: =Inputs!I$32 | J10: =Inputs!J$32 | ... V10: =Inputs!V$32
A11: Days in period | C11: =Inputs!$B$24*1 | D11: =Inputs!$B$24*1 | E11: =Inputs!$B$24*1 | F11: =Inputs!$B$24*1 | G11: =Inputs!$B$24*1 | H11: =Inputs!$B$24*1 | I11: =Inputs!$B$24*1 | J11: =Inputs!$B$24*1 | ... N11: =Inputs!$B$24*1 | O11: =Inputs!$B$24*3 | P11: =Inputs!$B$24*3 | Q11: =Inputs!$B$24*3 | R11: =Inputs!$B$24*3 | S11: =Inputs!$B$24*3 | T11: =Inputs!$B$24*3 | U11: =Inputs!$B$24*3 | V11: =Inputs!$B$24*3
A12: Patient-days | C12: =C10*C11 | D12: =D10*D11 | E12: =E10*E11 | F12: =F10*F11 | G12: =G10*G11 | H12: =H10*H11 | I12: =I10*I11 | J12: =J10*J11 | ... V12: =V10*V11
A13: Gross Medicare revenue | C13: =C12*Inputs!$B$19 | D13: =D12*Inputs!$B$19 | E13: =E12*Inputs!$B$19 | F13: =F12*Inputs!$B$19 | G13: =G12*Inputs!$B$19 | H13: =H12*Inputs!$B$19 | I13: =I12*Inputs!$B$19 | J13: =J12*Inputs!$B$19 | ... V13: =V12*Inputs!$B$19
A14: Less: sequestration | C14: =-C13*Inputs!$B$10 | D14: =-D13*Inputs!$B$10 | E14: =-E13*Inputs!$B$10 | F14: =-F13*Inputs!$B$10 | G14: =-G13*Inputs!$B$10 | H14: =-H13*Inputs!$B$10 | I14: =-I13*Inputs!$B$10 | J14: =-J13*Inputs!$B$10 | ... V14: =-V13*Inputs!$B$10
A15: Less: write-offs | C15: =-C13*Inputs!$B$11 | D15: =-D13*Inputs!$B$11 | E15: =-E13*Inputs!$B$11 | F15: =-F13*Inputs!$B$11 | G15: =-G13*Inputs!$B$11 | H15: =-H13*Inputs!$B$11 | I15: =-I13*Inputs!$B$11 | J15: =-J13*Inputs!$B$11 | ... V15: =-V13*Inputs!$B$11
A16: NET REVENUE | C16: =C13*(1-Inputs!$B$10-Inputs!$B$11) | D16: =D13*(1-Inputs!$B$10-Inputs!$B$11) | E16: =E13*(1-Inputs!$B$10-Inputs!$B$11) | F16: =F13*(1-Inputs!$B$10-Inputs!$B$11) | G16: =G13*(1-Inputs!$B$10-Inputs!$B$11) | H16: =H13*(1-Inputs!$B$10-Inputs!$B$11) | I16: =I13*(1-Inputs!$B$10-Inputs!$B$11) | J16: =J13*(1-Inputs!$B$10-Inputs!$B$11) | ... V16: =V13*(1-Inputs!$B$10-Inputs!$B$11)
A18: Memo: net revenue per patient-day | C18: =IF(C12=0,0,C16/C12) | D18: =IF(D12=0,0,D16/D12) | E18: =IF(E12=0,0,E16/E12) | F18: =IF(F12=0,0,F16/F12) | G18: =IF(G12=0,0,G16/G12) | H18: =IF(H12=0,0,H16/H12) | I18: =IF(I12=0,0,I16/I12) | J18: =IF(J12=0,0,J16/J12) | ... V18: =IF(V12=0,0,V16/V12)

Sheet Staffing & Payroll
A1: AZALEA HOSPICE & PALLIATIVE CARE — Tyler, TX
A2: Staffing & Payroll — staggered hires + census-driven PRN · burden on W-2 only · Med Director 1099 (no benefits)
A4: ($ per period) | C4: YEAR 1 — monthly | O4: YEAR 2 — quarterly | S4: YEAR 3 — quarterly
C5: M1 | D5: M2 | E5: M3 | F5: M4 | G5: M5 | H5: M6 | I5: M7 | J5: M8 | K5: M9 | L5: M10 | M5: M11 | N5: M12 | O5: Y2 Q1 | P5: Y2 Q2 | Q5: Y2 Q3 | R5: Y2 Q4 | S5: Y3 Q1 | T5: Y3 Q2 | U5: Y3 Q3 | V5: Y3 Q4
A6: ADC (driver) | C6: ='Revenue Model'!C10 | D6: ='Revenue Model'!D10 | E6: ='Revenue Model'!E10 | F6: ='Revenue Model'!F10 | G6: ='Revenue Model'!G10 | H6: ='Revenue Model'!H10 | I6: ='Revenue Model'!I10 | J6: ='Revenue Model'!J10 | ... V6: ='Revenue Model'!V10
A7: DIRECT-CARE FT SALARIES (Cost of Care)
A8: Brad Woodard — Administrator / Director | C8: =IF(1>=Inputs!$D$36,Inputs!$C$36/12*1*1,0) | D8: =IF(2>=Inputs!$D$36,Inputs!$C$36/12*1*1,0) | E8: =IF(3>=Inputs!$D$36,Inputs!$C$36/12*1*1,0) | F8: =IF(4>=Inputs!$D$36,Inputs!$C$36/12*1*1,0) | G8: =IF(5>=Inputs!$D$36,Inputs!$C$36/12*1*1,0) | H8: =IF(6>=Inputs!$D$36,Inputs!$C$36/12*1*1,0) | I8: =IF(7>=Inputs!$D$36,Inputs!$C$36/12*1*1,0) | J8: =IF(8>=Inputs!$D$36,Inputs!$C$36/12*1*1,0) | K8: =IF(9>=Inputs!$D$36,Inputs!$C$36/12*1*1,0) | L8: =IF(10>=Inputs!$D$36,Inputs!$C$36/12*1*1,0) | M8: =IF(11>=Inputs!$D$36,Inputs!$C$36/12*1*1,0) | N8: =IF(12>=Inputs!$D$36,Inputs!$C$36/12*1*1,0) | O8: =IF(15>=Inputs!$D$36,Inputs!$C$36/12*3*(1+Inputs!$B$57)^1,0) | P8: =IF(18>=Inputs!$D$36,Inputs!$C$36/12*3*(1+Inputs!$B$57)^1,0) | Q8: =IF(21>=Inputs!$D$36,Inputs!$C$36/12*3*(1+Inputs!$B$57)^1,0) | R8: =IF(24>=Inputs!$D$36,Inputs!$C$36/12*3*(1+Inputs!$B$57)^1,0) | S8: =IF(27>=Inputs!$D$36,Inputs!$C$36/12*3*(1+Inputs!$B$57)^2,0) | T8: =IF(30>=Inputs!$D$36,Inputs!$C$36/12*3*(1+Inputs!$B$57)^2,0) | U8: =IF(33>=Inputs!$D$36,Inputs!$C$36/12*3*(1+Inputs!$B$57)^2,0) | V8: =IF(36>=Inputs!$D$36,Inputs!$C$36/12*3*(1+Inputs!$B$57)^2,0)
A9: Angie Frost — RN Case Manager | C9: =IF(1>=Inputs!$D$37,Inputs!$C$37/12*1*1,0) | D9: =IF(2>=Inputs!$D$37,Inputs!$C$37/12*1*1,0) | E9: =IF(3>=Inputs!$D$37,Inputs!$C$37/12*1*1,0) | F9: =IF(4>=Inputs!$D$37,Inputs!$C$37/12*1*1,0) | G9: =IF(5>=Inputs!$D$37,Inputs!$C$37/12*1*1,0) | H9: =IF(6>=Inputs!$D$37,Inputs!$C$37/12*1*1,0) | I9: =IF(7>=Inputs!$D$37,Inputs!$C$37/12*1*1,0) | J9: =IF(8>=Inputs!$D$37,Inputs!$C$37/12*1*1,0) | K9: =IF(9>=Inputs!$D$37,Inputs!$C$37/12*1*1,0) | L9: =IF(10>=Inputs!$D$37,Inputs!$C$37/12*1*1,0) | M9: =IF(11>=Inputs!$D$37,Inputs!$C$37/12*1*1,0) | N9: =IF(12>=Inputs!$D$37,Inputs!$C$37/12*1*1,0) | O9: =IF(15>=Inputs!$D$37,Inputs!$C$37/12*3*(1+Inputs!$B$57)^1,0) | P9: =IF(18>=Inputs!$D$37,Inputs!$C$37/12*3*(1+Inputs!$B$57)^1,0) | Q9: =IF(21>=Inputs!$D$37,Inputs!$C$37/12*3*(1+Inputs!$B$57)^1,0) | R9: =IF(24>=Inputs!$D$37,Inputs!$C$37/12*3*(1+Inputs!$B$57)^1,0) | S9: =IF(27>=Inputs!$D$37,Inputs!$C$37/12*3*(1+Inputs!$B$57)^2,0) | T9: =IF(30>=Inputs!$D$37,Inputs!$C$37/12*3*(1+Inputs!$B$57)^2,0) | U9: =IF(33>=Inputs!$D$37,Inputs!$C$37/12*3*(1+Inputs!$B$57)^2,0) | V9: =IF(36>=Inputs!$D$37,Inputs!$C$37/12*3*(1+Inputs!$B$57)^2,0)
A10: Tanisha Robison — CNA / Hospice Aide | C10: =IF(1>=Inputs!$D$38,Inputs!$C$38/12*1*1,0) | D10: =IF(2>=Inputs!$D$38,Inputs!$C$38/12*1*1,0) | E10: =IF(3>=Inputs!$D$38,Inputs!$C$38/12*1*1,0) | F10: =IF(4>=Inputs!$D$38,Inputs!$C$38/12*1*1,0) | G10: =IF(5>=Inputs!$D$38,Inputs!$C$38/12*1*1,0) | H10: =IF(6>=Inputs!$D$38,Inputs!$C$38/12*1*1,0) | I10: =IF(7>=Inputs!$D$38,Inputs!$C$38/12*1*1,0) | J10: =IF(8>=Inputs!$D$38,Inputs!$C$38/12*1*1,0) | K10: =IF(9>=Inputs!$D$38,Inputs!$C$38/12*1*1,0) | L10: =IF(10>=Inputs!$D$38,Inputs!$C$38/12*1*1,0) | M10: =IF(11>=Inputs!$D$38,Inputs!$C$38/12*1*1,0) | N10: =IF(12>=Inputs!$D$38,Inputs!$C$38/12*1*1,0) | O10: =IF(15>=Inputs!$D$38,Inputs!$C$38/12*3*(1+Inputs!$B$57)^1,0) | P10: =IF(18>=Inputs!$D$38,Inputs!$C$38/12*3*(1+Inputs!$B$57)^1,0) | Q10: =IF(21>=Inputs!$D$38,Inputs!$C$38/12*3*(1+Inputs!$B$57)^1,0) | R10: =IF(24>=Inputs!$D$38,Inputs!$C$38/12*3*(1+Inputs!$B$57)^1,0) | S10: =IF(27>=Inputs!$D$38,Inputs!$C$38/12*3*(1+Inputs!$B$57)^2,0) | T10: =IF(30>=Inputs!$D$38,Inputs!$C$38/12*3*(1+Inputs!$B$57)^2,0) | U10: =IF(33>=Inputs!$D$38,Inputs!$C$38/12*3*(1+Inputs!$B$57)^2,0) | V10: =IF(36>=Inputs!$D$38,Inputs!$C$38/12*3*(1+Inputs!$B$57)^2,0)
A11: Dana Davenport — Director of Clinical Services | C11: =IF(1>=Inputs!$D$39,Inputs!$C$39/12*1*1,0) | D11: =IF(2>=Inputs!$D$39,Inputs!$C$39/12*1*1,0) | E11: =IF(3>=Inputs!$D$39,Inputs!$C$39/12*1*1,0) | F11: =IF(4>=Inputs!$D$39,Inputs!$C$39/12*1*1,0) | G11: =IF(5>=Inputs!$D$39,Inputs!$C$39/12*1*1,0) | H11: =IF(6>=Inputs!$D$39,Inputs!$C$39/12*1*1,0) | I11: =IF(7>=Inputs!$D$39,Inputs!$C$39/12*1*1,0) | J11: =IF(8>=Inputs!$D$39,Inputs!$C$39/12*1*1,0) | K11: =IF(9>=Inputs!$D$39,Inputs!$C$39/12*1*1,0) | L11: =IF(10>=Inputs!$D$39,Inputs!$C$39/12*1*1,0) | M11: =IF(11>=Inputs!$D$39,Inputs!$C$39/12*1*1,0) | N11: =IF(12>=Inputs!$D$39,Inputs!$C$39/12*1*1,0) | O11: =IF(15>=Inputs!$D$39,Inputs!$C$39/12*3*(1+Inputs!$B$57)^1,0) | P11: =IF(18>=Inputs!$D$39,Inputs!$C$39/12*3*(1+Inputs!$B$57)^1,0) | Q11: =IF(21>=Inputs!$D$39,Inputs!$C$39/12*3*(1+Inputs!$B$57)^1,0) | R11: =IF(24>=Inputs!$D$39,Inputs!$C$39/12*3*(1+Inputs!$B$57)^1,0) | S11: =IF(27>=Inputs!$D$39,Inputs!$C$39/12*3*(1+Inputs!$B$57)^2,0) | T11: =IF(30>=Inputs!$D$39,Inputs!$C$39/12*3*(1+Inputs!$B$57)^2,0) | U11: =IF(33>=Inputs!$D$39,Inputs!$C$39/12*3*(1+Inputs!$B$57)^2,0) | V11: =IF(36>=Inputs!$D$39,Inputs!$C$39/12*3*(1+Inputs!$B$57)^2,0)
A12: Silas Shelton — Administrator | C12: =IF(1>=Inputs!$D$40,Inputs!$C$40/12*1*1,0) | D12: =IF(2>=Inputs!$D$40,Inputs!$C$40/12*1*1,0) | E12: =IF(3>=Inputs!$D$40,Inputs!$C$40/12*1*1,0) | F12: =IF(4>=Inputs!$D$40,Inputs!$C$40/12*1*1,0) | G12: =IF(5>=Inputs!$D$40,Inputs!$C$40/12*1*1,0) | H12: =IF(6>=Inputs!$D$40,Inputs!$C$40/12*1*1,0) | I12: =IF(7>=Inputs!$D$40,Inputs!$C$40/12*1*1,0) | J12: =IF(8>=Inputs!$D$40,Inputs!$C$40/12*1*1,0) | K12: =IF(9>=Inputs!$D$40,Inputs!$C$40/12*1*1,0) | L12: =IF(10>=Inputs!$D$40,Inputs!$C$40/12*1*1,0) | M12: =IF(11>=Inputs!$D$40,Inputs!$C$40/12*1*1,0) | N12: =IF(12>=Inputs!$D$40,Inputs!$C$40/12*1*1,0) | O12: =IF(15>=Inputs!$D$40,Inputs!$C$40/12*3*(1+Inputs!$B$57)^1,0) | P12: =IF(18>=Inputs!$D$40,Inputs!$C$40/12*3*(1+Inputs!$B$57)^1,0) | Q12: =IF(21>=Inputs!$D$40,Inputs!$C$40/12*3*(1+Inputs!$B$57)^1,0) | R12: =IF(24>=Inputs!$D$40,Inputs!$C$40/12*3*(1+Inputs!$B$57)^1,0) | S12: =IF(27>=Inputs!$D$40,Inputs!$C$40/12*3*(1+Inputs!$B$57)^2,0) | T12: =IF(30>=Inputs!$D$40,Inputs!$C$40/12*3*(1+Inputs!$B$57)^2,0) | U12: =IF(33>=Inputs!$D$40,Inputs!$C$40/12*3*(1+Inputs!$B$57)^2,0) | V12: =IF(36>=Inputs!$D$40,Inputs!$C$40/12*3*(1+Inputs!$B$57)^2,0)
A13: Jodi McCollum — RN Case Manager (2nd seat) [OPEN REQ] | C13: =IF(1>=Inputs!$D$41,Inputs!$C$41/12*1*1,0) | D13: =IF(2>=Inputs!$D$41,Inputs!$C$41/12*1*1,0) | E13: =IF(3>=Inputs!$D$41,Inputs!$C$41/12*1*1,0) | F13: =IF(4>=Inputs!$D$41,Inputs!$C$41/12*1*1,0) | G13: =IF(5>=Inputs!$D$41,Inputs!$C$41/12*1*1,0) | H13: =IF(6>=Inputs!$D$41,Inputs!$C$41/12*1*1,0) | I13: =IF(7>=Inputs!$D$41,Inputs!$C$41/12*1*1,0) | J13: =IF(8>=Inputs!$D$41,Inputs!$C$41/12*1*1,0) | K13: =IF(9>=Inputs!$D$41,Inputs!$C$41/12*1*1,0) | L13: =IF(10>=Inputs!$D$41,Inputs!$C$41/12*1*1,0) | M13: =IF(11>=Inputs!$D$41,Inputs!$C$41/12*1*1,0) | N13: =IF(12>=Inputs!$D$41,Inputs!$C$41/12*1*1,0) | O13: =IF(15>=Inputs!$D$41,Inputs!$C$41/12*3*(1+Inputs!$B$57)^1,0) | P13: =IF(18>=Inputs!$D$41,Inputs!$C$41/12*3*(1+Inputs!$B$57)^1,0) | Q13: =IF(21>=Inputs!$D$41,Inputs!$C$41/12*3*(1+Inputs!$B$57)^1,0) | R13: =IF(24>=Inputs!$D$41,Inputs!$C$41/12*3*(1+Inputs!$B$57)^1,0) | S13: =IF(27>=Inputs!$D$41,Inputs!$C$41/12*3*(1+Inputs!$B$57)^2,0) | T13: =IF(30>=Inputs!$D$41,Inputs!$C$41/12*3*(1+Inputs!$B$57)^2,0) | U13: =IF(33>=Inputs!$D$41,Inputs!$C$41/12*3*(1+Inputs!$B$57)^2,0) | V13: =IF(36>=Inputs!$D$41,Inputs!$C$41/12*3*(1+Inputs!$B$57)^2,0)
A14: Subtotal — direct-care FT salaries | C14: =C9+C10+C13 | D14: =D9+D10+D13 | E14: =E9+E10+E13 | F14: =F9+F10+F13 | G14: =G9+G10+G13 | H14: =H9+H10+H13 | I14: =I9+I10+I13 | J14: =J9+J10+J13 | ... V14: =V9+V10+V13
A16: PRN / PER-VISIT DIRECT CARE (census-driven)
A17: PRN On-Call LVN (Kendricks-Tuck, Foster) | C17: =C6*Inputs!$C$46*Inputs!$D$46*1 | D17: =D6*Inputs!$C$46*Inputs!$D$46*1 | E17: =E6*Inputs!$C$46*Inputs!$D$46*1 | F17: =F6*Inputs!$C$46*Inputs!$D$46*1 | G17: =G6*Inputs!$C$46*Inputs!$D$46*1 | H17: =H6*Inputs!$C$46*Inputs!$D$46*1 | I17: =I6*Inputs!$C$46*Inputs!$D$46*1 | J17: =J6*Inputs!$C$46*Inputs!$D$46*1 | ... N17: =N6*Inputs!$C$46*Inputs!$D$46*1 | O17: =O6*Inputs!$C$46*Inputs!$D$46*3 | P17: =P6*Inputs!$C$46*Inputs!$D$46*3 | Q17: =Q6*Inputs!$C$46*Inputs!$D$46*3 | R17: =R6*Inputs!$C$46*Inputs!$D$46*3 | S17: =S6*Inputs!$C$46*Inputs!$D$46*3 | T17: =T6*Inputs!$C$46*Inputs!$D$46*3 | U17: =U6*Inputs!$C$46*Inputs!$D$46*3 | V17: =V6*Inputs!$C$46*Inputs!$D$46*3
A18: PRN Chaplain (Ector, Johnson) | C18: =C6*Inputs!$C$47*Inputs!$D$47*1 | D18: =D6*Inputs!$C$47*Inputs!$D$47*1 | E18: =E6*Inputs!$C$47*Inputs!$D$47*1 | F18: =F6*Inputs!$C$47*Inputs!$D$47*1 | G18: =G6*Inputs!$C$47*Inputs!$D$47*1 | H18: =H6*Inputs!$C$47*Inputs!$D$47*1 | I18: =I6*Inputs!$C$47*Inputs!$D$47*1 | J18: =J6*Inputs!$C$47*Inputs!$D$47*1 | ... N18: =N6*Inputs!$C$47*Inputs!$D$47*1 | O18: =O6*Inputs!$C$47*Inputs!$D$47*3 | P18: =P6*Inputs!$C$47*Inputs!$D$47*3 | Q18: =Q6*Inputs!$C$47*Inputs!$D$47*3 | R18: =R6*Inputs!$C$47*Inputs!$D$47*3 | S18: =S6*Inputs!$C$47*Inputs!$D$47*3 | T18: =T6*Inputs!$C$47*Inputs!$D$47*3 | U18: =U6*Inputs!$C$47*Inputs!$D$47*3 | V18: =V6*Inputs!$C$47*Inputs!$D$47*3
A19: PRN Social Worker (Sanders) | C19: =C6*Inputs!$C$48*Inputs!$D$48*1 | D19: =D6*Inputs!$C$48*Inputs!$D$48*1 | E19: =E6*Inputs!$C$48*Inputs!$D$48*1 | F19: =F6*Inputs!$C$48*Inputs!$D$48*1 | G19: =G6*Inputs!$C$48*Inputs!$D$48*1 | H19: =H6*Inputs!$C$48*Inputs!$D$48*1 | I19: =I6*Inputs!$C$48*Inputs!$D$48*1 | J19: =J6*Inputs!$C$48*Inputs!$D$48*1 | ... N19: =N6*Inputs!$C$48*Inputs!$D$48*1 | O19: =O6*Inputs!$C$48*Inputs!$D$48*3 | P19: =P6*Inputs!$C$48*Inputs!$D$48*3 | Q19: =Q6*Inputs!$C$48*Inputs!$D$48*3 | R19: =R6*Inputs!$C$48*Inputs!$D$48*3 | S19: =S6*Inputs!$C$48*Inputs!$D$48*3 | T19: =T6*Inputs!$C$48*Inputs!$D$48*3 | U19: =U6*Inputs!$C$48*Inputs!$D$48*3 | V19: =V6*Inputs!$C$48*Inputs!$D$48*3
A20: PRN Nurse Practitioner (Rogers) | C20: =C6*Inputs!$C$49*Inputs!$D$49*1 | D20: =D6*Inputs!$C$49*Inputs!$D$49*1 | E20: =E6*Inputs!$C$49*Inputs!$D$49*1 | F20: =F6*Inputs!$C$49*Inputs!$D$49*1 | G20: =G6*Inputs!$C$49*Inputs!$D$49*1 | H20: =H6*Inputs!$C$49*Inputs!$D$49*1 | I20: =I6*Inputs!$C$49*Inputs!$D$49*1 | J20: =J6*Inputs!$C$49*Inputs!$D$49*1 | ... N20: =N6*Inputs!$C$49*Inputs!$D$49*1 | O20: =O6*Inputs!$C$49*Inputs!$D$49*3 | P20: =P6*Inputs!$C$49*Inputs!$D$49*3 | Q20: =Q6*Inputs!$C$49*Inputs!$D$49*3 | R20: =R6*Inputs!$C$49*Inputs!$D$49*3 | S20: =S6*Inputs!$C$49*Inputs!$D$49*3 | T20: =T6*Inputs!$C$49*Inputs!$D$49*3 | U20: =U6*Inputs!$C$49*Inputs!$D$49*3 | V20: =V6*Inputs!$C$49*Inputs!$D$49*3
A21: PRN CNA / per-visit (Henson, Mills) | C21: =C6*Inputs!$C$50*Inputs!$D$50*1 | D21: =D6*Inputs!$C$50*Inputs!$D$50*1 | E21: =E6*Inputs!$C$50*Inputs!$D$50*1 | F21: =F6*Inputs!$C$50*Inputs!$D$50*1 | G21: =G6*Inputs!$C$50*Inputs!$D$50*1 | H21: =H6*Inputs!$C$50*Inputs!$D$50*1 | I21: =I6*Inputs!$C$50*Inputs!$D$50*1 | J21: =J6*Inputs!$C$50*Inputs!$D$50*1 | ... N21: =N6*Inputs!$C$50*Inputs!$D$50*1 | O21: =O6*Inputs!$C$50*Inputs!$D$50*3 | P21: =P6*Inputs!$C$50*Inputs!$D$50*3 | Q21: =Q6*Inputs!$C$50*Inputs!$D$50*3 | R21: =R6*Inputs!$C$50*Inputs!$D$50*3 | S21: =S6*Inputs!$C$50*Inputs!$D$50*3 | T21: =T6*Inputs!$C$50*Inputs!$D$50*3 | U21: =U6*Inputs!$C$50*Inputs!$D$50*3 | V21: =V6*Inputs!$C$50*Inputs!$D$50*3
A22: Subtotal — PRN visit wages | C22: =C17+C18+C19+C20+C21 | D22: =D17+D18+D19+D20+D21 | E22: =E17+E18+E19+E20+E21 | F22: =F17+F18+F19+F20+F21 | G22: =G17+G18+G19+G20+G21 | H22: =H17+H18+H19+H20+H21 | I22: =I17+I18+I19+I20+I21 | J22: =J17+J18+J19+J20+J21 | ... V22: =V17+V18+V19+V20+V21
A23: Medical Director (1099) | C23: =Inputs!$B$64*1 | D23: =Inputs!$B$64*1 | E23: =Inputs!$B$64*1 | F23: =Inputs!$B$64*1 | G23: =Inputs!$B$64*1 | H23: =Inputs!$B$64*1 | I23: =Inputs!$B$64*1 | J23: =Inputs!$B$64*1 | ... N23: =Inputs!$B$64*1 | O23: =Inputs!$B$64*3 | P23: =Inputs!$B$64*3 | Q23: =Inputs!$B$64*3 | R23: =Inputs!$B$64*3 | S23: =Inputs!$B$64*3 | T23: =Inputs!$B$64*3 | U23: =Inputs!$B$64*3 | V23: =Inputs!$B$64*3
A25: INDIRECT LABOR (SG&A overhead)
A26: Subtotal — indirect FT salaries | C26: =C8+C11+C12 | D26: =D8+D11+D12 | E26: =E8+E11+E12 | F26: =F8+F11+F12 | G26: =G8+G11+G12 | H26: =H8+H11+H12 | I26: =I8+I11+I12 | J26: =J8+J11+J12 | ... V26: =V8+V11+V12
A27: Rhonda Smith — Office Mgr (PRN, W-2) | C27: =Inputs!$C$42/12*1*1 | D27: =Inputs!$C$42/12*1*1 | E27: =Inputs!$C$42/12*1*1 | F27: =Inputs!$C$42/12*1*1 | G27: =Inputs!$C$42/12*1*1 | H27: =Inputs!$C$42/12*1*1 | I27: =Inputs!$C$42/12*1*1 | J27: =Inputs!$C$42/12*1*1 | ... N27: =Inputs!$C$42/12*1*1 | O27: =Inputs!$C$42/12*3*(1+Inputs!$B$57)^1 | P27: =Inputs!$C$42/12*3*(1+Inputs!$B$57)^1 | Q27: =Inputs!$C$42/12*3*(1+Inputs!$B$57)^1 | R27: =Inputs!$C$42/12*3*(1+Inputs!$B$57)^1 | S27: =Inputs!$C$42/12*3*(1+Inputs!$B$57)^2 | T27: =Inputs!$C$42/12*3*(1+Inputs!$B$57)^2 | U27: =Inputs!$C$42/12*3*(1+Inputs!$B$57)^2 | V27: =Inputs!$C$42/12*3*(1+Inputs!$B$57)^2
A29: EMPLOYER BURDEN & BENEFITS (W-2 only)
A30: Direct W-2 wage base (FT direct + PRN) | C30: =C14+C22 | D30: =D14+D22 | E30: =E14+E22 | F30: =F14+F22 | G30: =G14+G22 | H30: =H14+H22 | I30: =I14+I22 | J30: =J14+J22 | ... V30: =V14+V22
A31: Indirect W-2 wage base (FT indirect + Rhonda) | C31: =C26+C27 | D31: =D26+D27 | E31: =E26+E27 | F31: =F26+F27 | G31: =G26+G27 | H31: =H26+H27 | I31: =I26+I27 | J31: =J26+J27 | ... V31: =V26+V27
A32: Burden — direct (load %) | C32: =C30*Inputs!$B$60 | D32: =D30*Inputs!$B$60 | E32: =E30*Inputs!$B$60 | F32: =F30*Inputs!$B$60 | G32: =G30*Inputs!$B$60 | H32: =H30*Inputs!$B$60 | I32: =I30*Inputs!$B$60 | J32: =J30*Inputs!$B$60 | ... V32: =V30*Inputs!$B$60
A33: Burden — indirect (load %) | C33: =C31*Inputs!$B$60 | D33: =D31*Inputs!$B$60 | E33: =E31*Inputs!$B$60 | F33: =F31*Inputs!$B$60 | G33: =G31*Inputs!$B$60 | H33: =H31*Inputs!$B$60 | I33: =I31*Inputs!$B$60 | J33: =J31*Inputs!$B$60 | ... V33: =V31*Inputs!$B$60
A34: Health insurance — direct FT | C34: =Inputs!$B$61*(IF(1>=Inputs!$D$37,1,0)+IF(1>=Inputs!$D$38,1,0)+IF(1>=Inputs!$D$41,1,0))*1 | D34: =Inputs!$B$61*(IF(2>=Inputs!$D$37,1,0)+IF(2>=Inputs!$D$38,1,0)+IF(2>=Inputs!$D$41,1,0))*1 | E34: =Inputs!$B$61*(IF(3>=Inputs!$D$37,1,0)+IF(3>=Inputs!$D$38,1,0)+IF(3>=Inputs!$D$41,1,0))*1 | F34: =Inputs!$B$61*(IF(4>=Inputs!$D$37,1,0)+IF(4>=Inputs!$D$38,1,0)+IF(4>=Inputs!$D$41,1,0))*1 | G34: =Inputs!$B$61*(IF(5>=Inputs!$D$37,1,0)+IF(5>=Inputs!$D$38,1,0)+IF(5>=Inputs!$D$41,1,0))*1 | H34: =Inputs!$B$61*(IF(6>=Inputs!$D$37,1,0)+IF(6>=Inputs!$D$38,1,0)+IF(6>=Inputs!$D$41,1,0))*1 | I34: =Inputs!$B$61*(IF(7>=Inputs!$D$37,1,0)+IF(7>=Inputs!$D$38,1,0)+IF(7>=Inputs!$D$41,1,0))*1 | J34: =Inputs!$B$61*(IF(8>=Inputs!$D$37,1,0)+IF(8>=Inputs!$D$38,1,0)+IF(8>=Inputs!$D$41,1,0))*1 | K34: =Inputs!$B$61*(IF(9>=Inputs!$D$37,1,0)+IF(9>=Inputs!$D$38,1,0)+IF(9>=Inputs!$D$41,1,0))*1 | L34: =Inputs!$B$61*(IF(10>=Inputs!$D$37,1,0)+IF(10>=Inputs!$D$38,1,0)+IF(10>=Inputs!$D$41,1,0))*1 | M34: =Inputs!$B$61*(IF(11>=Inputs!$D$37,1,0)+IF(11>=Inputs!$D$38,1,0)+IF(11>=Inputs!$D$41,1,0))*1 | N34: =Inputs!$B$61*(IF(12>=Inputs!$D$37,1,0)+IF(12>=Inputs!$D$38,1,0)+IF(12>=Inputs!$D$41,1,0))*1 | O34: =Inputs!$B$61*(IF(15>=Inputs!$D$37,1,0)+IF(15>=Inputs!$D$38,1,0)+IF(15>=Inputs!$D$41,1,0))*3 | P34: =Inputs!$B$61*(IF(18>=Inputs!$D$37,1,0)+IF(18>=Inputs!$D$38,1,0)+IF(18>=Inputs!$D$41,1,0))*3 | Q34: =Inputs!$B$61*(IF(21>=Inputs!$D$37,1,0)+IF(21>=Inputs!$D$38,1,0)+IF(21>=Inputs!$D$41,1,0))*3 | R34: =Inputs!$B$61*(IF(24>=Inputs!$D$37,1,0)+IF(24>=Inputs!$D$38,1,0)+IF(24>=Inputs!$D$41,1,0))*3 | S34: =Inputs!$B$61*(IF(27>=Inputs!$D$37,1,0)+IF(27>=Inputs!$D$38,1,0)+IF(27>=Inputs!$D$41,1,0))*3 | T34: =Inputs!$B$61*(IF(30>=Inputs!$D$37,1,0)+IF(30>=Inputs!$D$38,1,0)+IF(30>=Inputs!$D$41,1,0))*3 | U34: =Inputs!$B$61*(IF(33>=Inputs!$D$37,1,0)+IF(33>=Inputs!$D$38,1,0)+IF(33>=Inputs!$D$41,1,0))*3 | V34: =Inputs!$B$61*(IF(36>=Inputs!$D$37,1,0)+IF(36>=Inputs!$D$38,1,0)+IF(36>=Inputs!$D$41,1,0))*3
A35: Health insurance — indirect FT | C35: =Inputs!$B$61*(IF(1>=Inputs!$D$36,1,0)+IF(1>=Inputs!$D$39,1,0)+IF(1>=Inputs!$D$40,1,0))*1 | D35: =Inputs!$B$61*(IF(2>=Inputs!$D$36,1,0)+IF(2>=Inputs!$D$39,1,0)+IF(2>=Inputs!$D$40,1,0))*1 | E35: =Inputs!$B$61*(IF(3>=Inputs!$D$36,1,0)+IF(3>=Inputs!$D$39,1,0)+IF(3>=Inputs!$D$40,1,0))*1 | F35: =Inputs!$B$61*(IF(4>=Inputs!$D$36,1,0)+IF(4>=Inputs!$D$39,1,0)+IF(4>=Inputs!$D$40,1,0))*1 | G35: =Inputs!$B$61*(IF(5>=Inputs!$D$36,1,0)+IF(5>=Inputs!$D$39,1,0)+IF(5>=Inputs!$D$40,1,0))*1 | H35: =Inputs!$B$61*(IF(6>=Inputs!$D$36,1,0)+IF(6>=Inputs!$D$39,1,0)+IF(6>=Inputs!$D$40,1,0))*1 | I35: =Inputs!$B$61*(IF(7>=Inputs!$D$36,1,0)+IF(7>=Inputs!$D$39,1,0)+IF(7>=Inputs!$D$40,1,0))*1 | J35: =Inputs!$B$61*(IF(8>=Inputs!$D$36,1,0)+IF(8>=Inputs!$D$39,1,0)+IF(8>=Inputs!$D$40,1,0))*1 | K35: =Inputs!$B$61*(IF(9>=Inputs!$D$36,1,0)+IF(9>=Inputs!$D$39,1,0)+IF(9>=Inputs!$D$40,1,0))*1 | L35: =Inputs!$B$61*(IF(10>=Inputs!$D$36,1,0)+IF(10>=Inputs!$D$39,1,0)+IF(10>=Inputs!$D$40,1,0))*1 | M35: =Inputs!$B$61*(IF(11>=Inputs!$D$36,1,0)+IF(11>=Inputs!$D$39,1,0)+IF(11>=Inputs!$D$40,1,0))*1 | N35: =Inputs!$B$61*(IF(12>=Inputs!$D$36,1,0)+IF(12>=Inputs!$D$39,1,0)+IF(12>=Inputs!$D$40,1,0))*1 | O35: =Inputs!$B$61*(IF(15>=Inputs!$D$36,1,0)+IF(15>=Inputs!$D$39,1,0)+IF(15>=Inputs!$D$40,1,0))*3 | P35: =Inputs!$B$61*(IF(18>=Inputs!$D$36,1,0)+IF(18>=Inputs!$D$39,1,0)+IF(18>=Inputs!$D$40,1,0))*3 | Q35: =Inputs!$B$61*(IF(21>=Inputs!$D$36,1,0)+IF(21>=Inputs!$D$39,1,0)+IF(21>=Inputs!$D$40,1,0))*3 | R35: =Inputs!$B$61*(IF(24>=Inputs!$D$36,1,0)+IF(24>=Inputs!$D$39,1,0)+IF(24>=Inputs!$D$40,1,0))*3 | S35: =Inputs!$B$61*(IF(27>=Inputs!$D$36,1,0)+IF(27>=Inputs!$D$39,1,0)+IF(27>=Inputs!$D$40,1,0))*3 | T35: =Inputs!$B$61*(IF(30>=Inputs!$D$36,1,0)+IF(30>=Inputs!$D$39,1,0)+IF(30>=Inputs!$D$40,1,0))*3 | U35: =Inputs!$B$61*(IF(33>=Inputs!$D$36,1,0)+IF(33>=Inputs!$D$39,1,0)+IF(33>=Inputs!$D$40,1,0))*3 | V35: =Inputs!$B$61*(IF(36>=Inputs!$D$36,1,0)+IF(36>=Inputs!$D$39,1,0)+IF(36>=Inputs!$D$40,1,0))*3
A37: TOTAL DIRECT-CARE LABOR (COGS) | C37: =C14+C22+C23+C32+C34 | D37: =D14+D22+D23+D32+D34 | E37: =E14+E22+E23+E32+E34 | F37: =F14+F22+F23+F32+F34 | G37: =G14+G22+G23+G32+G34 | H37: =H14+H22+H23+H32+H34 | I37: =I14+I22+I23+I32+I34 | J37: =J14+J22+J23+J32+J34 | ... V37: =V14+V22+V23+V32+V34
A38: TOTAL INDIRECT LABOR (SG&A) | C38: =C26+C27+C33+C35 | D38: =D26+D27+D33+D35 | E38: =E26+E27+E33+E35 | F38: =F26+F27+F33+F35 | G38: =G26+G27+G33+G35 | H38: =H26+H27+H33+H35 | I38: =I26+I27+I33+I35 | J38: =J26+J27+J33+J35 | ... V38: =V26+V27+V33+V35

Sheet Operating Budget
A1: AZALEA HOSPICE & PALLIATIVE CARE — Tyler, TX
A2: Operating Budget — P&L · Net Rev − COGS = Gross Profit − SG&A = EBITDA − D&A − Interest = Net Income
A4: ($ per period) | C4: YEAR 1 — monthly | O4: YEAR 2 — quarterly | S4: YEAR 3 — quarterly
C5: M1 | D5: M2 | E5: M3 | F5: M4 | G5: M5 | H5: M6 | I5: M7 | J5: M8 | K5: M9 | L5: M10 | M5: M11 | N5: M12 | O5: Y2 Q1 | P5: Y2 Q2 | Q5: Y2 Q3 | R5: Y2 Q4 | S5: Y3 Q1 | T5: Y3 Q2 | U5: Y3 Q3 | V5: Y3 Q4
A6: NET REVENUE | C6: ='Revenue Model'!C16 | D6: ='Revenue Model'!D16 | E6: ='Revenue Model'!E16 | F6: ='Revenue Model'!F16 | G6: ='Revenue Model'!G16 | H6: ='Revenue Model'!H16 | I6: ='Revenue Model'!I16 | J6: ='Revenue Model'!J16 | ... V6: ='Revenue Model'!V16
A8: COST OF SERVICES
A9: Direct-care labor | C9: ='Staffing & Payroll'!C37 | D9: ='Staffing & Payroll'!D37 | E9: ='Staffing & Payroll'!E37 | F9: ='Staffing & Payroll'!F37 | G9: ='Staffing & Payroll'!G37 | H9: ='Staffing & Payroll'!H37 | I9: ='Staffing & Payroll'!I37 | J9: ='Staffing & Payroll'!J37 | ... V9: ='Staffing & Payroll'!V37
A10: Medical supplies | C10: ='Revenue Model'!C12*Inputs!$B$67 | D10: ='Revenue Model'!D12*Inputs!$B$67 | E10: ='Revenue Model'!E12*Inputs!$B$67 | F10: ='Revenue Model'!F12*Inputs!$B$67 | G10: ='Revenue Model'!G12*Inputs!$B$67 | H10: ='Revenue Model'!H12*Inputs!$B$67 | I10: ='Revenue Model'!I12*Inputs!$B$67 | J10: ='Revenue Model'!J12*Inputs!$B$67 | ... V10: ='Revenue Model'!V12*Inputs!$B$67
A11: DME | C11: ='Revenue Model'!C12*Inputs!$B$68 | D11: ='Revenue Model'!D12*Inputs!$B$68 | E11: ='Revenue Model'!E12*Inputs!$B$68 | F11: ='Revenue Model'!F12*Inputs!$B$68 | G11: ='Revenue Model'!G12*Inputs!$B$68 | H11: ='Revenue Model'!H12*Inputs!$B$68 | I11: ='Revenue Model'!I12*Inputs!$B$68 | J11: ='Revenue Model'!J12*Inputs!$B$68 | ... V11: ='Revenue Model'!V12*Inputs!$B$68
A12: Pharmacy | C12: ='Revenue Model'!C12*Inputs!$B$69 | D12: ='Revenue Model'!D12*Inputs!$B$69 | E12: ='Revenue Model'!E12*Inputs!$B$69 | F12: ='Revenue Model'!F12*Inputs!$B$69 | G12: ='Revenue Model'!G12*Inputs!$B$69 | H12: ='Revenue Model'!H12*Inputs!$B$69 | I12: ='Revenue Model'!I12*Inputs!$B$69 | J12: ='Revenue Model'!J12*Inputs!$B$69 | ... V12: ='Revenue Model'!V12*Inputs!$B$69
A13: Patient-related COGS subtotal | C13: =C10+C11+C12 | D13: =D10+D11+D12 | E13: =E10+E11+E12 | F13: =F10+F11+F12 | G13: =G10+G11+G12 | H13: =H10+H11+H12 | I13: =I10+I11+I12 | J13: =J10+J11+J12 | ... V13: =V10+V11+V12
A14: TOTAL COST OF SERVICES | C14: =C9+C13 | D14: =D9+D13 | E14: =E9+E13 | F14: =F9+F13 | G14: =G9+G13 | H14: =H9+H13 | I14: =I9+I13 | J14: =J9+J13 | ... V14: =V9+V13
A15: GROSS PROFIT | C15: =C6-C14 | D15: =D6-D14 | E15: =E6-E14 | F15: =F6-F14 | G15: =G6-G14 | H15: =H6-H14 | I15: =I6-I14 | J15: =J6-J14 | ... V15: =V6-V14
A16: Gross margin % | C16: =IF(C6=0,0,C15/C6) | D16: =IF(D6=0,0,D15/D6) | E16: =IF(E6=0,0,E15/E6) | F16: =IF(F6=0,0,F15/F6) | G16: =IF(G6=0,0,G15/G6) | H16: =IF(H6=0,0,H15/H6) | I16: =IF(I6=0,0,I15/I6) | J16: =IF(J6=0,0,J15/J6) | ... V16: =IF(V6=0,0,V15/V6)
A18: SELLING, GENERAL & ADMINISTRATIVE
A19: Indirect labor | C19: ='Staffing & Payroll'!C38 | D19: ='Staffing & Payroll'!D38 | E19: ='Staffing & Payroll'!E38 | F19: ='Staffing & Payroll'!F38 | G19: ='Staffing & Payroll'!G38 | H19: ='Staffing & Payroll'!H38 | I19: ='Staffing & Payroll'!I38 | J19: ='Staffing & Payroll'!J38 | ... V19: ='Staffing & Payroll'!V38
A20: Fixed G&A (utilities, EMR, billing, rent, mktg…) | C20: =SUM(Inputs!$B$72:$B$85)*1 | D20: =SUM(Inputs!$B$72:$B$85)*1 | E20: =SUM(Inputs!$B$72:$B$85)*1 | F20: =SUM(Inputs!$B$72:$B$85)*1 | G20: =SUM(Inputs!$B$72:$B$85)*1 | H20: =SUM(Inputs!$B$72:$B$85)*1 | I20: =SUM(Inputs!$B$72:$B$85)*1 | J20: =SUM(Inputs!$B$72:$B$85)*1 | ... N20: =SUM(Inputs!$B$72:$B$85)*1 | O20: =SUM(Inputs!$B$72:$B$85)*3 | P20: =SUM(Inputs!$B$72:$B$85)*3 | Q20: =SUM(Inputs!$B$72:$B$85)*3 | R20: =SUM(Inputs!$B$72:$B$85)*3 | S20: =SUM(Inputs!$B$72:$B$85)*3 | T20: =SUM(Inputs!$B$72:$B$85)*3 | U20: =SUM(Inputs!$B$72:$B$85)*3 | V20: =SUM(Inputs!$B$72:$B$85)*3
A21: QR payment fee (% of gross) | C21: ='Revenue Model'!C13*Inputs!$B$88 | D21: ='Revenue Model'!D13*Inputs!$B$88 | E21: ='Revenue Model'!E13*Inputs!$B$88 | F21: ='Revenue Model'!F13*Inputs!$B$88 | G21: ='Revenue Model'!G13*Inputs!$B$88 | H21: ='Revenue Model'!H13*Inputs!$B$88 | I21: ='Revenue Model'!I13*Inputs!$B$88 | J21: ='Revenue Model'!J13*Inputs!$B$88 | ... V21: ='Revenue Model'!V13*Inputs!$B$88
A22: TOTAL SG&A | C22: =C19+C20+C21 | D22: =D19+D20+D21 | E22: =E19+E20+E21 | F22: =F19+F20+F21 | G22: =G19+G20+G21 | H22: =H19+H20+H21 | I22: =I19+I20+I21 | J22: =J19+J20+J21 | ... V22: =V19+V20+V21
A23: EBITDA | C23: =C15-C22 | D23: =D15-D22 | E23: =E15-E22 | F23: =F15-F22 | G23: =G15-G22 | H23: =H15-H22 | I23: =I15-I22 | J23: =J15-J22 | ... V23: =V15-V22
A24: EBITDA margin % | C24: =IF(C6=0,0,C23/C6) | D24: =IF(D6=0,0,D23/D6) | E24: =IF(E6=0,0,E23/E6) | F24: =IF(F6=0,0,F23/F6) | G24: =IF(G6=0,0,G23/G6) | H24: =IF(H6=0,0,H23/H6) | I24: =IF(I6=0,0,I23/I6) | J24: =IF(J6=0,0,J23/J6) | ... V24: =IF(V6=0,0,V23/V6)
A26: BELOW EBITDA
A27: Depreciation & amortization | C27: =Inputs!$B$118*1 | D27: =Inputs!$B$118*1 | E27: =Inputs!$B$118*1 | F27: =Inputs!$B$118*1 | G27: =Inputs!$B$118*1 | H27: =Inputs!$B$118*1 | I27: =Inputs!$B$118*1 | J27: =Inputs!$B$118*1 | ... N27: =Inputs!$B$118*1 | O27: =Inputs!$B$118*3 | P27: =Inputs!$B$118*3 | Q27: =Inputs!$B$118*3 | R27: =Inputs!$B$118*3 | S27: =Inputs!$B$118*3 | T27: =Inputs!$B$118*3 | U27: =Inputs!$B$118*3 | V27: =Inputs!$B$118*3
A28: Interest — SBA loan | C28: ='Debt Schedule'!C11 | D28: ='Debt Schedule'!D11 | E28: ='Debt Schedule'!E11 | F28: ='Debt Schedule'!F11 | G28: ='Debt Schedule'!G11 | H28: ='Debt Schedule'!H11 | I28: ='Debt Schedule'!I11 | J28: ='Debt Schedule'!J11 | ... V28: ='Debt Schedule'!V11
A29: Interest — working-capital line | C29: ='Cash Flow & BS'!C15 | D29: ='Cash Flow & BS'!D15 | E29: ='Cash Flow & BS'!E15 | F29: ='Cash Flow & BS'!F15 | G29: ='Cash Flow & BS'!G15 | H29: ='Cash Flow & BS'!H15 | I29: ='Cash Flow & BS'!I15 | J29: ='Cash Flow & BS'!J15 | ... V29: ='Cash Flow & BS'!V15
A30: PRE-TAX INCOME | C30: =C23-C27-C28-C29 | D30: =D23-D27-D28-D29 | E30: =E23-E27-E28-E29 | F30: =F23-F27-F28-F29 | G30: =G23-G27-G28-G29 | H30: =H23-H27-H28-H29 | I30: =I23-I27-I28-I29 | J30: =J23-J27-J28-J29 | ... V30: =V23-V27-V28-V29
A31: TX franchise / margin tax | C31: =IF(C30>0,C6*Inputs!$B$100,0) | D31: =IF(D30>0,D6*Inputs!$B$100,0) | E31: =IF(E30>0,E6*Inputs!$B$100,0) | F31: =IF(F30>0,F6*Inputs!$B$100,0) | G31: =IF(G30>0,G6*Inputs!$B$100,0) | H31: =IF(H30>0,H6*Inputs!$B$100,0) | I31: =IF(I30>0,I6*Inputs!$B$100,0) | J31: =IF(J30>0,J6*Inputs!$B$100,0) | ... V31: =IF(V30>0,V6*Inputs!$B$100,0)
A32: NET INCOME | C32: =C30-C31 | D32: =D30-D31 | E32: =E30-E31 | F32: =F30-F31 | G32: =G30-G31 | H32: =H30-H31 | I32: =I30-I31 | J32: =J30-J31 | ... V32: =V30-V31

Sheet Detailed P&L
A1: Azalea Hospice & Palliative Care — Tyler, TX
A2: Profit and Loss
A3: Year 1 (monthly) · Years 2–3 (annual) · model data, cash basis
B5: M1 | C5: M2 | D5: M3 | E5: M4 | F5: M5 | G5: M6 | H5: M7 | I5: M8 | J5: M9 | K5: M10 | L5: M11 | M5: M12 | N5: Year 2 | O5: Year 3 | P5: TOTAL
A6: Income
A7: Gross Billed Revenue | B7: ='Revenue Model'!C13 | C7: ='Revenue Model'!D13 | D7: ='Revenue Model'!E13 | E7: ='Revenue Model'!F13 | F7: ='Revenue Model'!G13 | G7: ='Revenue Model'!H13 | H7: ='Revenue Model'!I13 | I7: ='Revenue Model'!J13 | ... M7: ='Revenue Model'!N13 | N7: =SUM('Revenue Model'!O13:R13) | O7: =SUM('Revenue Model'!S13:V13) | P7: =SUM(B7:M7)+N7+O7
A8: Less: CDAs Adjustment | B8: =0 | C8: =0 | D8: =0 | E8: =0 | F8: =0 | G8: =0 | H8: =0 | I8: =0 | ... O8: =0 | P8: =SUM(B8:M8)+N8+O8
A9: Less: Net Due Zero (Write-offs) | B9: ='Revenue Model'!C13*Inputs!$B$11 | C9: ='Revenue Model'!D13*Inputs!$B$11 | D9: ='Revenue Model'!E13*Inputs!$B$11 | E9: ='Revenue Model'!F13*Inputs!$B$11 | F9: ='Revenue Model'!G13*Inputs!$B$11 | G9: ='Revenue Model'!H13*Inputs!$B$11 | H9: ='Revenue Model'!I13*Inputs!$B$11 | I9: ='Revenue Model'!J13*Inputs!$B$11 | ... M9: ='Revenue Model'!N13*Inputs!$B$11 | N9: =SUM('Revenue Model'!O13:R13)*Inputs!$B$11 | O9: =SUM('Revenue Model'!S13:V13)*Inputs!$B$11 | P9: =SUM(B9:M9)+N9+O9
A10: Less: Sequestration | B10: ='Revenue Model'!C13*Inputs!$B$10 | C10: ='Revenue Model'!D13*Inputs!$B$10 | D10: ='Revenue Model'!E13*Inputs!$B$10 | E10: ='Revenue Model'!F13*Inputs!$B$10 | F10: ='Revenue Model'!G13*Inputs!$B$10 | G10: ='Revenue Model'!H13*Inputs!$B$10 | H10: ='Revenue Model'!I13*Inputs!$B$10 | I10: ='Revenue Model'!J13*Inputs!$B$10 | ... M10: ='Revenue Model'!N13*Inputs!$B$10 | N10: =SUM('Revenue Model'!O13:R13)*Inputs!$B$10 | O10: =SUM('Revenue Model'!S13:V13)*Inputs!$B$10 | P10: =SUM(B10:M10)+N10+O10
A11: Less: Medication Adjustments | B11: =0 | C11: =0 | D11: =0 | E11: =0 | F11: =0 | G11: =0 | H11: =0 | I11: =0 | ... O11: =0 | P11: =SUM(B11:M11)+N11+O11
A12: Total Income | B12: =B7-B8-B9-B10-B11 | C12: =C7-C8-C9-C10-C11 | D12: =D7-D8-D9-D10-D11 | E12: =E7-E8-E9-E10-E11 | F12: =F7-F8-F9-F10-F11 | G12: =G7-G8-G9-G10-G11 | H12: =H7-H8-H9-H10-H11 | I12: =I7-I8-I9-I10-I11 | ... P12: =P7-P8-P9-P10-P11
A14: Cost of Services
A15: Pharmacy | B15: ='Revenue Model'!C12*Inputs!$B$69 | C15: ='Revenue Model'!D12*Inputs!$B$69 | D15: ='Revenue Model'!E12*Inputs!$B$69 | E15: ='Revenue Model'!F12*Inputs!$B$69 | F15: ='Revenue Model'!G12*Inputs!$B$69 | G15: ='Revenue Model'!H12*Inputs!$B$69 | H15: ='Revenue Model'!I12*Inputs!$B$69 | I15: ='Revenue Model'!J12*Inputs!$B$69 | ... M15: ='Revenue Model'!N12*Inputs!$B$69 | N15: =SUM('Revenue Model'!O12:R12)*Inputs!$B$69 | O15: =SUM('Revenue Model'!S12:V12)*Inputs!$B$69 | P15: =SUM(B15:M15)+N15+O15
A16: Medical Supplies | B16: ='Revenue Model'!C12*Inputs!$B$67 | C16: ='Revenue Model'!D12*Inputs!$B$67 | D16: ='Revenue Model'!E12*Inputs!$B$67 | E16: ='Revenue Model'!F12*Inputs!$B$67 | F16: ='Revenue Model'!G12*Inputs!$B$67 | G16: ='Revenue Model'!H12*Inputs!$B$67 | H16: ='Revenue Model'!I12*Inputs!$B$67 | I16: ='Revenue Model'!J12*Inputs!$B$67 | ... M16: ='Revenue Model'!N12*Inputs!$B$67 | N16: =SUM('Revenue Model'!O12:R12)*Inputs!$B$67 | O16: =SUM('Revenue Model'!S12:V12)*Inputs!$B$67 | P16: =SUM(B16:M16)+N16+O16
A17: Durable Medical Equipment (DME) | B17: ='Revenue Model'!C12*Inputs!$B$68 | C17: ='Revenue Model'!D12*Inputs!$B$68 | D17: ='Revenue Model'!E12*Inputs!$B$68 | E17: ='Revenue Model'!F12*Inputs!$B$68 | F17: ='Revenue Model'!G12*Inputs!$B$68 | G17: ='Revenue Model'!H12*Inputs!$B$68 | H17: ='Revenue Model'!I12*Inputs!$B$68 | I17: ='Revenue Model'!J12*Inputs!$B$68 | ... M17: ='Revenue Model'!N12*Inputs!$B$68 | N17: =SUM('Revenue Model'!O12:R12)*Inputs!$B$68 | O17: =SUM('Revenue Model'!S12:V12)*Inputs!$B$68 | P17: =SUM(B17:M17)+N17+O17
A18: Respite Care | B18: =0 | C18: =0 | D18: =0 | E18: =0 | F18: =0 | G18: =0 | H18: =0 | I18: =0 | ... O18: =0 | P18: =SUM(B18:M18)+N18+O18
A19: Transportation | B19: =0 | C19: =0 | D19: =0 | E19: =0 | F19: =0 | G19: =0 | H19: =0 | I19: =0 | ... O19: =0 | P19: =SUM(B19:M19)+N19+O19
A20: Infusion / Labs | B20: =0 | C20: =0 | D20: =0 | E20: =0 | F20: =0 | G20: =0 | H20: =0 | I20: =0 | ... O20: =0 | P20: =SUM(B20:M20)+N20+O20
A21: PT / OT / ST | B21: =0 | C21: =0 | D21: =0 | E21: =0 | F21: =0 | G21: =0 | H21: =0 | I21: =0 | ... O21: =0 | P21: =SUM(B21:M21)+N21+O21
A22: Total Cost of Services | B22: =SUM(B15:B21) | C22: =SUM(C15:C21) | D22: =SUM(D15:D21) | E22: =SUM(E15:E21) | F22: =SUM(F15:F21) | G22: =SUM(G15:G21) | H22: =SUM(H15:H21) | I22: =SUM(I15:I21) | ... P22: =SUM(P15:P21)
A24: Gross Profit | B24: =B12-B22 | C24: =C12-C22 | D24: =D12-D22 | E24: =E12-E22 | F24: =F12-F22 | G24: =G12-G22 | H24: =H12-H22 | I24: =I12-I22 | ... P24: =P12-P22
A26: Operating Expenses
A27: Payroll & Related
A28: Payroll — 1st Half | B28: =('Staffing & Payroll'!C14+'Staffing & Payroll'!C26+'Staffing & Payroll'!C22+'Staffing & Payroll'!C27)/2 | C28: =('Staffing & Payroll'!D14+'Staffing & Payroll'!D26+'Staffing & Payroll'!D22+'Staffing & Payroll'!D27)/2 | D28: =('Staffing & Payroll'!E14+'Staffing & Payroll'!E26+'Staffing & Payroll'!E22+'Staffing & Payroll'!E27)/2 | E28: =('Staffing & Payroll'!F14+'Staffing & Payroll'!F26+'Staffing & Payroll'!F22+'Staffing & Payroll'!F27)/2 | F28: =('Staffing & Payroll'!G14+'Staffing & Payroll'!G26+'Staffing & Payroll'!G22+'Staffing & Payroll'!G27)/2 | G28: =('Staffing & Payroll'!H14+'Staffing & Payroll'!H26+'Staffing & Payroll'!H22+'Staffing & Payroll'!H27)/2 | H28: =('Staffing & Payroll'!I14+'Staffing & Payroll'!I26+'Staffing & Payroll'!I22+'Staffing & Payroll'!I27)/2 | I28: =('Staffing & Payroll'!J14+'Staffing & Payroll'!J26+'Staffing & Payroll'!J22+'Staffing & Payroll'!J27)/2 | ... M28: =('Staffing & Payroll'!N14+'Staffing & Payroll'!N26+'Staffing & Payroll'!N22+'Staffing & Payroll'!N27)/2 | N28: =(SUM('Staffing & Payroll'!O14:R14)+SUM('Staffing & Payroll'!O26:R26)+SUM('Staffing & Payroll'!O22:R22)+SUM('Staffing & Payroll'!O27:R27))/2 | O28: =(SUM('Staffing & Payroll'!S14:V14)+SUM('Staffing & Payroll'!S26:V26)+SUM('Staffing & Payroll'!S22:V22)+SUM('Staffing & Payroll'!S27:V27))/2 | P28: =SUM(B28:M28)+N28+O28
A29: Payroll — 2nd Half | B29: =('Staffing & Payroll'!C14+'Staffing & Payroll'!C26+'Staffing & Payroll'!C22+'Staffing & Payroll'!C27)/2 | C29: =('Staffing & Payroll'!D14+'Staffing & Payroll'!D26+'Staffing & Payroll'!D22+'Staffing & Payroll'!D27)/2 | D29: =('Staffing & Payroll'!E14+'Staffing & Payroll'!E26+'Staffing & Payroll'!E22+'Staffing & Payroll'!E27)/2 | E29: =('Staffing & Payroll'!F14+'Staffing & Payroll'!F26+'Staffing & Payroll'!F22+'Staffing & Payroll'!F27)/2 | F29: =('Staffing & Payroll'!G14+'Staffing & Payroll'!G26+'Staffing & Payroll'!G22+'Staffing & Payroll'!G27)/2 | G29: =('Staffing & Payroll'!H14+'Staffing & Payroll'!H26+'Staffing & Payroll'!H22+'Staffing & Payroll'!H27)/2 | H29: =('Staffing & Payroll'!I14+'Staffing & Payroll'!I26+'Staffing & Payroll'!I22+'Staffing & Payroll'!I27)/2 | I29: =('Staffing & Payroll'!J14+'Staffing & Payroll'!J26+'Staffing & Payroll'!J22+'Staffing & Payroll'!J27)/2 | ... M29: =('Staffing & Payroll'!N14+'Staffing & Payroll'!N26+'Staffing & Payroll'!N22+'Staffing & Payroll'!N27)/2 | N29: =(SUM('Staffing & Payroll'!O14:R14)+SUM('Staffing & Payroll'!O26:R26)+SUM('Staffing & Payroll'!O22:R22)+SUM('Staffing & Payroll'!O27:R27))/2 | O29: =(SUM('Staffing & Payroll'!S14:V14)+SUM('Staffing & Payroll'!S26:V26)+SUM('Staffing & Payroll'!S22:V22)+SUM('Staffing & Payroll'!S27:V27))/2 | P29: =SUM(B29:M29)+N29+O29
A30: Payroll YTD Adjustments | B30: =0 | C30: =0 | D30: =0 | E30: =0 | F30: =0 | G30: =0 | H30: =0 | I30: =0 | ... O30: =0 | P30: =SUM(B30:M30)+N30+O30
A31: Employer Taxes (FUTA/SUI/FICA/WC) | B31: ='Staffing & Payroll'!C32+'Staffing & Payroll'!C33 | C31: ='Staffing & Payroll'!D32+'Staffing & Payroll'!D33 | D31: ='Staffing & Payroll'!E32+'Staffing & Payroll'!E33 | E31: ='Staffing & Payroll'!F32+'Staffing & Payroll'!F33 | F31: ='Staffing & Payroll'!G32+'Staffing & Payroll'!G33 | G31: ='Staffing & Payroll'!H32+'Staffing & Payroll'!H33 | H31: ='Staffing & Payroll'!I32+'Staffing & Payroll'!I33 | I31: ='Staffing & Payroll'!J32+'Staffing & Payroll'!J33 | ... M31: ='Staffing & Payroll'!N32+'Staffing & Payroll'!N33 | N31: =SUM('Staffing & Payroll'!O32:R32)+SUM('Staffing & Payroll'!O33:R33) | O31: =SUM('Staffing & Payroll'!S32:V32)+SUM('Staffing & Payroll'!S33:V33) | P31: =SUM(B31:M31)+N31+O31
A32: Contract Labor | B32: =0 | C32: =0 | D32: =0 | E32: =0 | F32: =0 | G32: =0 | H32: =0 | I32: =0 | ... O32: =0 | P32: =SUM(B32:M32)+N32+O32
A33: Medical Director | B33: ='Staffing & Payroll'!C23 | C33: ='Staffing & Payroll'!D23 | D33: ='Staffing & Payroll'!E23 | E33: ='Staffing & Payroll'!F23 | F33: ='Staffing & Payroll'!G23 | G33: ='Staffing & Payroll'!H23 | H33: ='Staffing & Payroll'!I23 | I33: ='Staffing & Payroll'!J23 | ... M33: ='Staffing & Payroll'!N23 | N33: =SUM('Staffing & Payroll'!O23:R23) | O33: =SUM('Staffing & Payroll'!S23:V23) | P33: =SUM(B33:M33)+N33+O33
A34: Medical Director 2 | B34: =0 | C34: =0 | D34: =0 | E34: =0 | F34: =0 | G34: =0 | H34: =0 | I34: =0 | ... O34: =0 | P34: =SUM(B34:M34)+N34+O34
A35: Intercompany Transfer | B35: =0 | C35: =0 | D35: =0 | E35: =0 | F35: =0 | G35: =0 | H35: =0 | I35: =0 | ... O35: =0 | P35: =SUM(B35:M35)+N35+O35
A36: Staff Other (health insurance) | B36: ='Staffing & Payroll'!C34+'Staffing & Payroll'!C35 | C36: ='Staffing & Payroll'!D34+'Staffing & Payroll'!D35 | D36: ='Staffing & Payroll'!E34+'Staffing & Payroll'!E35 | E36: ='Staffing & Payroll'!F34+'Staffing & Payroll'!F35 | F36: ='Staffing & Payroll'!G34+'Staffing & Payroll'!G35 | G36: ='Staffing & Payroll'!H34+'Staffing & Payroll'!H35 | H36: ='Staffing & Payroll'!I34+'Staffing & Payroll'!I35 | I36: ='Staffing & Payroll'!J34+'Staffing & Payroll'!J35 | ... M36: ='Staffing & Payroll'!N34+'Staffing & Payroll'!N35 | N36: =SUM('Staffing & Payroll'!O34:R34)+SUM('Staffing & Payroll'!O35:R35) | O36: =SUM('Staffing & Payroll'!S34:V34)+SUM('Staffing & Payroll'!S35:V35) | P36: =SUM(B36:M36)+N36+O36
A37: Total Payroll & Related | B37: =SUM(B28:B36) | C37: =SUM(C28:C36) | D37: =SUM(D28:D36) | E37: =SUM(E28:E36) | F37: =SUM(F28:F36) | G37: =SUM(G28:G36) | H37: =SUM(H28:H36) | I37: =SUM(I28:I36) | ... P37: =SUM(P28:P36)
A39: General & Administrative
A40: Bank / Payroll Fees | B40: =Inputs!$B$83 | C40: =Inputs!$B$83 | D40: =Inputs!$B$83 | E40: =Inputs!$B$83 | F40: =Inputs!$B$83 | G40: =Inputs!$B$83 | H40: =Inputs!$B$83 | I40: =Inputs!$B$83 | ... M40: =Inputs!$B$83 | N40: =Inputs!$B$83*12 | O40: =Inputs!$B$83*12 | P40: =SUM(B40:M40)+N40+O40
A41: Triple Net Rent | B41: =Inputs!$B$84 | C41: =Inputs!$B$84 | D41: =Inputs!$B$84 | E41: =Inputs!$B$84 | F41: =Inputs!$B$84 | G41: =Inputs!$B$84 | H41: =Inputs!$B$84 | I41: =Inputs!$B$84 | ... M41: =Inputs!$B$84 | N41: =Inputs!$B$84*12 | O41: =Inputs!$B$84*12 | P41: =SUM(B41:M41)+N41+O41
A42: Utilities | B42: =Inputs!$B$72 | C42: =Inputs!$B$72 | D42: =Inputs!$B$72 | E42: =Inputs!$B$72 | F42: =Inputs!$B$72 | G42: =Inputs!$B$72 | H42: =Inputs!$B$72 | I42: =Inputs!$B$72 | ... M42: =Inputs!$B$72 | N42: =Inputs!$B$72*12 | O42: =Inputs!$B$72*12 | P42: =SUM(B42:M42)+N42+O42
A43: Internet | B43: =Inputs!$B$73 | C43: =Inputs!$B$73 | D43: =Inputs!$B$73 | E43: =Inputs!$B$73 | F43: =Inputs!$B$73 | G43: =Inputs!$B$73 | H43: =Inputs!$B$73 | I43: =Inputs!$B$73 | ... M43: =Inputs!$B$73 | N43: =Inputs!$B$73*12 | O43: =Inputs!$B$73*12 | P43: =SUM(B43:M43)+N43+O43
A44: Telephone / Fax | B44: =Inputs!$B$74 | C44: =Inputs!$B$74 | D44: =Inputs!$B$74 | E44: =Inputs!$B$74 | F44: =Inputs!$B$74 | G44: =Inputs!$B$74 | H44: =Inputs!$B$74 | I44: =Inputs!$B$74 | ... M44: =Inputs!$B$74 | N44: =Inputs!$B$74*12 | O44: =Inputs!$B$74*12 | P44: =SUM(B44:M44)+N44+O44
A45: After Hours Messaging (BVTM) | B45: =Inputs!$B$75 | C45: =Inputs!$B$75 | D45: =Inputs!$B$75 | E45: =Inputs!$B$75 | F45: =Inputs!$B$75 | G45: =Inputs!$B$75 | H45: =Inputs!$B$75 | I45: =Inputs!$B$75 | ... M45: =Inputs!$B$75 | N45: =Inputs!$B$75*12 | O45: =Inputs!$B$75*12 | P45: =SUM(B45:M45)+N45+O45
...

Sheet Debt Schedule
A1: AZALEA HOSPICE & PALLIATIVE CARE — Tyler, TX
A2: Debt Schedule — SBA 7(a) amortization · DSCR = EBITDA / debt service (target ≥ 1.25x)
A4: LOAN TERMS (from Inputs)
A5: Monthly payment (PMT) | B5: =PMT(Inputs!$B$92/12,Inputs!$B$93,-Inputs!$B$91)
A7: ($ per period) | C7: YEAR 1 — monthly | O7: YEAR 2 — quarterly | S7: YEAR 3 — quarterly
C8: M1 | D8: M2 | E8: M3 | F8: M4 | G8: M5 | H8: M6 | I8: M7 | J8: M8 | K8: M9 | L8: M10 | M8: M11 | N8: M12 | O8: Y2 Q1 | P8: Y2 Q2 | Q8: Y2 Q3 | R8: Y2 Q4 | S8: Y3 Q1 | T8: Y3 Q2 | U8: Y3 Q3 | V8: Y3 Q4
A9: Beginning balance | C9: =Inputs!$B$91 | D9: =C13 | E9: =D13 | F9: =E13 | G9: =F13 | H9: =G13 | I9: =H13 | J9: =I13 | K9: =J13 | ... V9: =U13
A10: Payment | C10: =$B$5*1 | D10: =$B$5*1 | E10: =$B$5*1 | F10: =$B$5*1 | G10: =$B$5*1 | H10: =$B$5*1 | I10: =$B$5*1 | J10: =$B$5*1 | ... N10: =$B$5*1 | O10: =$B$5*3 | P10: =$B$5*3 | Q10: =$B$5*3 | R10: =$B$5*3 | S10: =$B$5*3 | T10: =$B$5*3 | U10: =$B$5*3 | V10: =$B$5*3
A11: Interest | C11: =C9*Inputs!$B$92/12*1 | D11: =D9*Inputs!$B$92/12*1 | E11: =E9*Inputs!$B$92/12*1 | F11: =F9*Inputs!$B$92/12*1 | G11: =G9*Inputs!$B$92/12*1 | H11: =H9*Inputs!$B$92/12*1 | I11: =I9*Inputs!$B$92/12*1 | J11: =J9*Inputs!$B$92/12*1 | ... N11: =N9*Inputs!$B$92/12*1 | O11: =O9*Inputs!$B$92/12*3 | P11: =P9*Inputs!$B$92/12*3 | Q11: =Q9*Inputs!$B$92/12*3 | R11: =R9*Inputs!$B$92/12*3 | S11: =S9*Inputs!$B$92/12*3 | T11: =T9*Inputs!$B$92/12*3 | U11: =U9*Inputs!$B$92/12*3 | V11: =V9*Inputs!$B$92/12*3
A12: Principal | C12: =C10-C11 | D12: =D10-D11 | E12: =E10-E11 | F12: =F10-F11 | G12: =G10-G11 | H12: =H10-H11 | I12: =I10-I11 | J12: =J10-J11 | ... V12: =V10-V11
A13: Ending balance | C13: =C9-C12 | D13: =D9-D12 | E13: =E9-E12 | F13: =F9-F12 | G13: =G9-G12 | H13: =H9-H12 | I13: =I9-I12 | J13: =J9-J12 | ... V13: =V9-V12
A15: Debt service (P+I) | C15: =C11+C12 | D15: =D11+D12 | E15: =E11+E12 | F15: =F11+F12 | G15: =G11+G12 | H15: =H11+H12 | I15: =I11+I12 | J15: =J11+J12 | ... V15: =V11+V12
A16: EBITDA (link) | C16: ='Operating Budget'!C23 | D16: ='Operating Budget'!D23 | E16: ='Operating Budget'!E23 | F16: ='Operating Budget'!F23 | G16: ='Operating Budget'!G23 | H16: ='Operating Budget'!H23 | I16: ='Operating Budget'!I23 | J16: ='Operating Budget'!J23 | ... V16: ='Operating Budget'!V23
A17: DSCR (period) | C17: =IF(C15=0,0,C16/C15) | D17: =IF(D15=0,0,D16/D15) | E17: =IF(E15=0,0,E16/E15) | F17: =IF(F15=0,0,F16/F15) | G17: =IF(G15=0,0,G16/G15) | H17: =IF(H15=0,0,H16/H15) | I17: =IF(I15=0,0,I16/I15) | J17: =IF(J15=0,0,J16/J15) | ... V17: =IF(V15=0,0,V16/V15)

Sheet Cash Flow & BS
A1: AZALEA HOSPICE & PALLIATIVE CARE — Tyler, TX
A2: Cash Flow (indirect) & Balance Sheet — BS balances through real AR/AP/LOC, never a plug
A4: ($ per period) | B4: Opening | C4: YEAR 1 — monthly | O4: YEAR 2 — quarterly | S4: YEAR 3 — quarterly
C5: M1 | D5: M2 | E5: M3 | F5: M4 | G5: M5 | H5: M6 | I5: M7 | J5: M8 | K5: M9 | L5: M10 | M5: M11 | N5: M12 | O5: Y2 Q1 | P5: Y2 Q2 | Q5: Y2 Q3 | R5: Y2 Q4 | S5: Y3 Q1 | T5: Y3 Q2 | U5: Y3 Q3 | V5: Y3 Q4
A6: CASH FLOW (indirect method)
A7: Net income | C7: ='Operating Budget'!C32 | D7: ='Operating Budget'!D32 | E7: ='Operating Budget'!E32 | F7: ='Operating Budget'!F32 | G7: ='Operating Budget'!G32 | H7: ='Operating Budget'!H32 | I7: ='Operating Budget'!I32 | J7: ='Operating Budget'!J32 | ... V7: ='Operating Budget'!V32
A8: + Depreciation & amortization | C8: ='Operating Budget'!C27 | D8: ='Operating Budget'!D27 | E8: ='Operating Budget'!E27 | F8: ='Operating Budget'!F27 | G8: ='Operating Budget'!G27 | H8: ='Operating Budget'!H27 | I8: ='Operating Budget'!I27 | J8: ='Operating Budget'!J27 | ... V8: ='Operating Budget'!V27
A9: Accounts receivable (balance) | B9: =0 | C9: ='Revenue Model'!C16*Inputs!$B$112/'Revenue Model'!C11 | D9: ='Revenue Model'!D16*Inputs!$B$112/'Revenue Model'!D11 | E9: ='Revenue Model'!E16*Inputs!$B$112/'Revenue Model'!E11 | F9: ='Revenue Model'!F16*Inputs!$B$112/'Revenue Model'!F11 | G9: ='Revenue Model'!G16*Inputs!$B$112/'Revenue Model'!G11 | H9: ='Revenue Model'!H16*Inputs!$B$112/'Revenue Model'!H11 | I9: ='Revenue Model'!I16*Inputs!$B$112/'Revenue Model'!I11 | J9: ='Revenue Model'!J16*Inputs!$B$112/'Revenue Model'!J11 | ... V9: ='Revenue Model'!V16*Inputs!$B$112/'Revenue Model'!V11
A10: Accounts payable (balance) | B10: =0 | C10: =('Operating Budget'!C20+'Operating Budget'!C21+'Operating Budget'!C13)*Inputs!$B$113/'Revenue Model'!C11 | D10: =('Operating Budget'!D20+'Operating Budget'!D21+'Operating Budget'!D13)*Inputs!$B$113/'Revenue Model'!D11 | E10: =('Operating Budget'!E20+'Operating Budget'!E21+'Operating Budget'!E13)*Inputs!$B$113/'Revenue Model'!E11 | F10: =('Operating Budget'!F20+'Operating Budget'!F21+'Operating Budget'!F13)*Inputs!$B$113/'Revenue Model'!F11 | G10: =('Operating Budget'!G20+'Operating Budget'!G21+'Operating Budget'!G13)*Inputs!$B$113/'Revenue Model'!G11 | H10: =('Operating Budget'!H20+'Operating Budget'!H21+'Operating Budget'!H13)*Inputs!$B$113/'Revenue Model'!H11 | I10: =('Operating Budget'!I20+'Operating Budget'!I21+'Operating Budget'!I13)*Inputs!$B$113/'Revenue Model'!I11 | J10: =('Operating Budget'!J20+'Operating Budget'!J21+'Operating Budget'!J13)*Inputs!$B$113/'Revenue Model'!J11 | ... V10: =('Operating Budget'!V20+'Operating Budget'!V21+'Operating Budget'!V13)*Inputs!$B$113/'Revenue Model'!V11
A11: − Δ Accounts receivable | C11: =-(C9-B9) | D11: =-(D9-C9) | E11: =-(E9-D9) | F11: =-(F9-E9) | G11: =-(G9-F9) | H11: =-(H9-G9) | I11: =-(I9-H9) | J11: =-(J9-I9) | ... V11: =-(V9-U9)
A12: + Δ Accounts payable | C12: =C10-B10 | D12: =D10-C10 | E12: =E10-D10 | F12: =F10-E10 | G12: =G10-F10 | H12: =H10-G10 | I12: =I10-H10 | J12: =J10-I10 | ... V12: =V10-U10
A13: Cash flow from operations | C13: =C7+C8+C11+C12 | D13: =D7+D8+D11+D12 | E13: =E7+E8+E11+E12 | F13: =F7+F8+F11+F12 | G13: =G7+G8+G11+G12 | H13: =H7+H8+H11+H12 | I13: =I7+I8+I11+I12 | J13: =J7+J8+J11+J12 | ... V13: =V7+V8+V11+V12
A14: − SBA principal repayment | C14: =-'Debt Schedule'!C12 | D14: =-'Debt Schedule'!D12 | E14: =-'Debt Schedule'!E12 | F14: =-'Debt Schedule'!F12 | G14: =-'Debt Schedule'!G12 | H14: =-'Debt Schedule'!H12 | I14: =-'Debt Schedule'!I12 | J14: =-'Debt Schedule'!J12 | ... V14: =-'Debt Schedule'!V12
A15: Working-capital line interest | B15: =0 | C15: =B19*Inputs!$B$96*1/12 | D15: =C19*Inputs!$B$96*1/12 | E15: =D19*Inputs!$B$96*1/12 | F15: =E19*Inputs!$B$96*1/12 | G15: =F19*Inputs!$B$96*1/12 | H15: =G19*Inputs!$B$96*1/12 | I15: =H19*Inputs!$B$96*1/12 | J15: =I19*Inputs!$B$96*1/12 | ... N15: =M19*Inputs!$B$96*1/12 | O15: =N19*Inputs!$B$96*3/12 | P15: =O19*Inputs!$B$96*3/12 | Q15: =P19*Inputs!$B$96*3/12 | R15: =Q19*Inputs!$B$96*3/12 | S15: =R19*Inputs!$B$96*3/12 | T15: =S19*Inputs!$B$96*3/12 | U15: =T19*Inputs!$B$96*3/12 | V15: =U19*Inputs!$B$96*3/12
A16: Beginning cash | B16: =0 | C16: =Inputs!$B$117 | D16: =C20 | E16: =D20 | F16: =E20 | G16: =F20 | H16: =G20 | I16: =H20 | J16: =I20 | K16: =J20 | ... V16: =U20
A17: Cash before LOC sweep | C17: =C16+C13+C14 | D17: =D16+D13+D14 | E17: =E16+E13+E14 | F17: =F16+F13+F14 | G17: =G16+G13+G14 | H17: =H16+H13+H14 | I17: =I16+I13+I14 | J17: =J16+J13+J14 | ... V17: =V16+V13+V14
A18: LOC draw / (repay) | C18: =IF(C17<Inputs!$B$97,Inputs!$B$97-C17,-MIN(B19,MAX(0,C17-Inputs!$B$97))) | D18: =IF(D17<Inputs!$B$97,Inputs!$B$97-D17,-MIN(C19,MAX(0,D17-Inputs!$B$97))) | E18: =IF(E17<Inputs!$B$97,Inputs!$B$97-E17,-MIN(D19,MAX(0,E17-Inputs!$B$97))) | F18: =IF(F17<Inputs!$B$97,Inputs!$B$97-F17,-MIN(E19,MAX(0,F17-Inputs!$B$97))) | G18: =IF(G17<Inputs!$B$97,Inputs!$B$97-G17,-MIN(F19,MAX(0,G17-Inputs!$B$97))) | H18: =IF(H17<Inputs!$B$97,Inputs!$B$97-H17,-MIN(G19,MAX(0,H17-Inputs!$B$97))) | I18: =IF(I17<Inputs!$B$97,Inputs!$B$97-I17,-MIN(H19,MAX(0,I17-Inputs!$B$97))) | J18: =IF(J17<Inputs!$B$97,Inputs!$B$97-J17,-MIN(I19,MAX(0,J17-Inputs!$B$97))) | ... V18: =IF(V17<Inputs!$B$97,Inputs!$B$97-V17,-MIN(U19,MAX(0,V17-Inputs!$B$97)))
A19: Working-capital line balance | B19: =0 | C19: =B19+C18 | D19: =C19+D18 | E19: =D19+E18 | F19: =E19+F18 | G19: =F19+G18 | H19: =G19+H18 | I19: =H19+I18 | J19: =I19+J18 | ... V19: =U19+V18
A20: ENDING CASH | C20: =C17+C18 | D20: =D17+D18 | E20: =E17+E18 | F20: =F17+F18 | G20: =G17+G18 | H20: =H17+H18 | I20: =I17+I18 | J20: =J17+J18 | ... V20: =V17+V18
A22: BALANCE SHEET
A23: Cash | B23: =Inputs!$B$117 | C23: =C20 | D23: =D20 | E23: =E20 | F23: =F20 | G23: =G20 | H23: =H20 | I23: =I20 | J23: =J20 | ... V23: =V20
A24: Accounts receivable | B24: =0 | C24: =C9 | D24: =D9 | E24: =E9 | F24: =F9 | G24: =G9 | H24: =H9 | I24: =I9 | J24: =J9 | ... V24: =V9
A25: PP&E, net | B25: =Inputs!$B$98 | C25: =MAX(0,B25-C8*(Inputs!$B$98/(Inputs!$B$98+Inputs!$B$116))) | D25: =MAX(0,C25-D8*(Inputs!$B$98/(Inputs!$B$98+Inputs!$B$116))) | E25: =MAX(0,D25-E8*(Inputs!$B$98/(Inputs!$B$98+Inputs!$B$116))) | F25: =MAX(0,E25-F8*(Inputs!$B$98/(Inputs!$B$98+Inputs!$B$116))) | G25: =MAX(0,F25-G8*(Inputs!$B$98/(Inputs!$B$98+Inputs!$B$116))) | H25: =MAX(0,G25-H8*(Inputs!$B$98/(Inputs!$B$98+Inputs!$B$116))) | I25: =MAX(0,H25-I8*(Inputs!$B$98/(Inputs!$B$98+Inputs!$B$116))) | J25: =MAX(0,I25-J8*(Inputs!$B$98/(Inputs!$B$98+Inputs!$B$116))) | ... V25: =MAX(0,U25-V8*(Inputs!$B$98/(Inputs!$B$98+Inputs!$B$116)))
