Workbook

Sheet Prompt Pack
A1: Azalea Hospice — Sequenced Prompt Pack
A2: Copy each prompt below into chat ONE AT A TIME, in order. Wait for me to confirm completion of each before triggering the next. Each prompt has a stop point and acceptance criteria.
A3: Stage: Pre-launch | Audience: SBA + Equity + Internal Ops | Payer: 100% Medicare RHC | Horizon: 3yr (Y1 monthly, Y2-3 quarterly) | Geo: Single CBSA | Staff: Named hires
A5: PROMPT 1 — Archive old sheets + build Inputs tab
A6: Archive all 9 existing sheets (Control Tower, COA Mapping, Census Waterfall, Revenue Model, Staffing Summary, Operating Budget, P&L, Reconciliation, Stress Tests) into a collapsed group at the back of the workbook — prefix each with 'ARCHIVE_' and group them so they're collapsed by default. Then build a new 'Inputs' tab as the primary input sheet for the rebuild, with nine labeled blocks: A) Geography & Rates (CBSA, FY26 RHC base rate, wage index, BNAF, SBI status), B) Payer Mix & Timing (100% Medicare RHC, billing lag days, sequential billing toggle), C) Census Ramp (36 months of ADC targets, average LOS, admit/discharge cadence), D) Named Staff Roster (one row per hire: name, role, start month, annual salary, FT/PT, OT eligibility — leave 20 blank rows), E) Staffing Ratios for Y2-3 (RN caseload, aide ratio, on-call coverage, indirect overhead %), F) Benefits & ER Taxes (FICA, FUTA, SUTA with wage base, WC, health $/mo per FTE, retirement %), G) Opex (mileage $/visit, med supplies $/PPD, DME $/PPD, meds $/PPD, rent, IT, insurance, licenses), H) SBA & Capital Structure (loan amount, rate, amort term, equity injection, founder contribution, LOC limit, opening cash), I) Working Capital (AR days, AP days, PPEO accrual rate, cap year start month). Yellow-fill all cells the user needs to fill. Create named ranges for every key input. Acceptance: archived sheets are collapsed at back, Inputs tab is fully laid out with empty yellow input cells, all named ranges created. STOP after this is built and confirm with me before Prompt 2.
A8: PROMPT 2 — Build Revenue tab
A9: I've filled in the Inputs tab. Build the Revenue tab now. Layout: Year 1 in monthly columns (36 columns total = Y1 12 monthly, Y2-3 8 quarters). Rows: (1) ADC pulled from Inputs Block C, (2) Patient Days = ADC × days in period, (3) RHC wage-adjusted rate = base rate × (labor share × wage index + non-labor share) + BNAF, (4) SBI adjustment if applicable, (5) Gross Revenue = Patient Days × adjusted rate, (6) Sequential Billing timing (NOE filing month vs. service month — first claim delayed if Sequential Billing on), (7) Net cash receipts with 30-day Medicare RAP-to-final lag, (8) Cap exposure tracker (cumulative payments vs. cap limit × beneficiaries served per cap year starting at Inputs Block I cap-year-start). All formulas — zero hardcoded numbers on this tab, everything references Inputs named ranges. Add a small summary block at top: Y1/Y2/Y3 gross revenue, net revenue, avg ADC, cap exposure %. Format: blue inputs (none expected here), black formulas, green cross-sheet links. Acceptance: Revenue tab built, summary block populated, no #REF/#VALUE errors, cap tracker shows running exposure. STOP and confirm with me before Prompt 3.
A11: PROMPT 3 — Build Staffing + Payroll & Benefits tabs
A12: Revenue is approved. Build the Staffing tab and the Payroll & Benefits tab. STAFFING: Y1 monthly — each named hire from Inputs Block D gets a row, FTE = 1 starting at their start month, 0 before; salary populates from their start month forward. Y2-Y3 quarterly — named roster carries forward, then a 'generic ladder' block adds positions driven by ADC and the ratios in Block E (e.g., RN FTE needed = CEILING(ADC / RN caseload), Aide FTE = CEILING(ADC × aide ratio), On-call coverage fixed by Block E). Show total FTE by role and grand total at bottom. PAYROLL & BENEFITS: pulls FTE × salary from Staffing, then calculates: ER FICA 7.65% (capped at SS wage base), FUTA (cap $7K × 0.6%), SUTA per Block F with state wage base, WC %, health $ × FTE-months, retirement %. Output gross payroll per period + fully-loaded payroll per period. Add semi-monthly payroll cash-timing offset (lag accrued-to-paid). Add GL prefix column on each row (use 4000-series for direct care wages, 4005 performance pay, 4020 contract labor, 4110/4120/4124/4125 benefits, 4130 FICA, 4131 SUTA-proposed, 4135 WC-proposed). All formulas reference Inputs and Staffing named ranges. Acceptance: Staffing FTE ramps correctly through named roster then generic ladder, Payroll totals tie to FTE×salary plus loaded benefits, GL prefixes shown. STOP and confirm before Prompt 4.
A14: PROMPT 4 — Build Operating Expenses tab
A15: Staffing + Payroll approved. Build Operating Expenses tab. Two sections: VARIABLE (keyed to ADC or Patient Days) — mileage $/visit × visits per ADC, medical supplies $/PPD × patient days, medications $/PPD × patient days, DME $/PPD × patient days, all rates from Inputs Block G. FIXED (by month/quarter) — rent, IT/EMR, liability/property/malpractice insurance, state licenses, professional fees, marketing. Add GL prefix column: 5050 DME, 5090 supplies, 5100 meds, 5110 mileage, 6010-6150 facility, 6505-6716 indirect ops, 6800 marketing. Show total opex per period at bottom, split between Direct Care COGS (5000-series + facility-allocable) and Indirect SG&A (6000-series). All formulas reference Inputs named ranges. Acceptance: variable opex scales with ADC, fixed opex stable, GL prefixes shown, COGS-vs-SG&A split clear. STOP and confirm before Prompt 5.
A17: PROMPT 5 — Build P&L + Cash Flow + Balance Sheet (3-statement)
... A27: 1. Trigger Prompt 1 first — it builds the Inputs tab. Then YOU fill in the yellow input cells (CBSA wage data, named roster, ADC ramp, SBA terms, etc.) BEFORE triggering Prompt 2. 2. After Prompt 1, the only manual data entry happens on the Inputs tab. Every downstream calculation is formulas. 3. If a prompt result looks wrong, say 'audit Prompt N output' — I'll re-check formulas before moving on. 4. To change any assumption later, edit the Inputs tab — the entire model recalculates. 5. Iterative calculation needs to be ON for the LOC auto-balance in Prompt 5 (Excel → File → Options → Formulas → Enable iterative calculation, 100 iterations, 0.001 max change). I'll remind you when we get there. 6. Old sheets (ARCHIVE_*) stay collapsed at the back — don't delete them until the new model is fully signed off by SBA + equity.

Sheet Inputs

Sheet ARCHIVE_Control Tower
A1: AZALEA HOSPICE & PALLIATIVE CARE — CONTROL TOWER (Assumptions Engine)
A2: Tyler Hospice OpCo, LLC · Lindale, TX · Go-Live June 2026 · All model values flow from this tab
A4: A. PAYROLL BURDEN (each maps to a GL account)
A5: Employer FICA / SS / Medicare | B5: 0.0765 | C5: 4130-0-Z-0 | D5: 7.65% statutory; on all W-2 wages
A6: FUTA + TX SUTA (unemployment) | B6: 0.0185 | C6: 4131-0-Z-0 ADD | D6: ~1.85% blended; on W-2 wages
A7: Workers' Compensation | B7: 0.03 | C7: 4135-0-Z-0 ADD | D7: 3% of W-2 wages; broken out per request
A8: Health Insurance ($/mo per FT employee) | B8: 500 | C8: 4110-0-Z-0 | D8: FT benefits-eligible only; PRN excluded
A10: B. TRAVEL / MILEAGE (replaces flat vehicle allowance)
A11: IRS Mileage Rate ($/mile) | B11: 0.5 | C11: 5110-R-6-X | D11: Per payroll records
A12: Visits per day (FT field clinician) | B12: 5.5 | D12: RN & CNA route productivity
A13: Round-trip miles per visit | B13: 7 | D13: Calibrated -> mileage = 2% of revenue
A14: Working days per month | B14: 21 | D14: Standard
A16: C. CASELOAD & GROWTH
A17: RN Case Manager caseload (1 : N) | B17: 15 | D17: Drives RN FTE requirement
A18: CNA / Aide caseload (1 : N) | B18: 12 | D18: Drives Aide FTE requirement
A19: Annual Merit / COL increase | B19: 0.03 | D19: Applied start of Y2 and Y3
A20: Monthly Discharge Rate | B20: 0.15 | D20: Industry standard
A21: Avg Days per Month | B21: 30.4 | D21: For per-patient-day metrics
A23: D. PRN VISIT ASSUMPTIONS (visits per patient per month x rate)
A24: On-Call LVN - visits/pt/mo | B24: 0.6 | C24: 4000-R-6-4 | D24: After-hours coverage
A25: On-Call LVN - rate per visit | B25: 100 | D25: Confirm: payroll showed $75
A26: Chaplain (SC) - visits/pt/mo | B26: 0.75 | C26: 4000-R-6-7 | D26: NHPCO 1-2/mo; conservative
A27: Chaplain - rate per visit | B27: 75 | D27: Per payroll
A28: Social Worker (MSW) - visits/pt/mo | B28: 1 | C28: 4000-R-6-6 | D28: Required assessments
A29: Social Worker - rate per visit | B29: 75 | D29: Per payroll
A30: Nurse Practitioner - visits/pt/mo | B30: 0.15 | C30: 4000-R-6-N | D30: F2F recert visits
A31: Nurse Practitioner - rate per visit | B31: 200 | D31: Per payroll
A33: E. CONTRACTED & PRN-RETAINER ROLES
A34: Medical Director ($/mo) | B34: 4000 | C34: 4020-R-6-M | D34: CoP req Day 1; contracted, no burden
A35: Silas - PRN Admin retainer ($/mo, M1-M2) | B35: 2500 | C35: 4020-0-A-0 | D35: Administrator of record; PRN
A36: Dana - PRN Clinical contract ($/mo, M1) | B36: 1500 | C36: 4020-0-C-0 | D36: DON oversight; PRN month 1
A38: F. ANNUAL BASE SALARIES - FT (Year 1) · Source: Payroll Jan-Mar 2026
A39: Brad Woodard - Marketing (M1) | B39: 120000 | C39: 4000-0-M-0 | D39: Director of Sales / Marketer
A40: Jodi McCollum - RN-CM (M1) | B40: 75005 | C40: 4000-R-6-1
A41: Tanisha Robison - Aide (M1) | B41: 46510 | C41: 4000-R-6-5
A42: Angie Frost - RN-CM (M2) | B42: 77503 | C42: 4000-R-6-1
A43: Rhonda Smith - Intake/Office (M2) | B43: 50000 | C43: 4000-0-I-0 | D43: PT; intake+admissions+office
A44: Dana Davenport - FT Clinical Admin (M2) | B44: 120000 | C44: 4000-0-C-0 | D44: Converts from PRN
A45: Clarenca Wooten - Aide (M3) | B45: 45771 | C45: 4000-R-6-5
A46: Silas Shelton - FT Administrator (M3) | B46: 150000 | C46: 4000-0-A-0 | D46: Converts from PRN retainer
...

Sheet ARCHIVE_COA Mapping
A1: COA MAPPING — Staffing Lines to QuickBooks Accounts
A3: GL Account | B3: Account Name | C3: Model Line | D3: Notes
A4: 4000-R-6-1 | B4: Direct Care:Wages-RN-RHC | C4: Jodi, Angie, Generic RN | D4: Salaried RN case managers
A5: 4000-R-6-5 | B5: Direct Care:Wages-Aide-RHC | C5: Tanisha, Clarenca, Generic Aide | D5: Salaried hospice aides
A6: 4000-R-6-4 | B6: Direct Care:Wages-LVN On Call-RHC | C6: PRN On-Call LVN | D6: Per-visit, after-hours
A7: 4000-R-6-6 | B7: Direct Care:Wages-MSW-RHC | C7: PRN Social Worker | D7: Per-visit
A8: 4000-R-6-7 | B8: Direct Care:Wages-SC-RHC | C8: PRN Chaplain | D8: Per-visit spiritual care
A9: 4000-R-6-N | B9: Direct Care:Wages-Nurse Practitioner-RHC | C9: PRN NP | D9: F2F recert visits
A10: 4000-0-M-0 | B10: Indirect Expense:Wages-Marketing | C10: Brad Woodard | D10: Director of Sales
A11: 4000-0-I-0 | B11: Allocable:Intake:Wages-Intake/Admit | C11: Rhonda Smith | D11: Intake+admissions+office
A12: 4000-0-A-0 | B12: Indirect Expense:Wages-Administrative | C12: Silas (FT, M3+) | D12: Administrator
A13: 4000-0-C-0 | B13: Indirect Expense:Wages-Clinical Administration | C13: Dana (FT, M2+) | D13: DON / Clinical Services
A14: 4020-0-A-0 | B14: Indirect Expense:Contract Labor-Administrative | C14: Silas PRN retainer (M1-M2) | D14: Admin of record, PRN
... A27: 6620-0-M-0 | B27: Indirect Expense:Mileage-Marketing | C27: Brad marketing mileage | D27: Non-patient; flat budget

Sheet ARCHIVE_Census Waterfall
A1: CENSUS WATERFALL — 36-Month ADC Ramp · 15% Monthly Discharge
A2: Target ADC drives staffing & revenue. Admits = ADC growth + discharges. M1-M3 inputs; M4+ ramp.
A4: Month | B4: Year | C4: Target ADC | D4: Beg.Census | E4: Disch.Rate | F4: Discharges | G4: Admits Req'd | H4: End.Census | I4: Notes
A5: M1 | B5: Year 1 | C5: 15 | D5: 15 | E5: ='ARCHIVE_Control Tower'!$B$20 -> 0.15 | F5: =D5*E5 -> 2.25 | G5: =MAX(0,C5-D5+F5) -> 2.25 | H5: =D5+G5-F5 -> 15 | I5: CHOW transfer patients (Avant MIPA)
A6: M2 | B6: Year 1 | C6: 17 | D6: =H5 -> 15 | E6: ='ARCHIVE_Control Tower'!$B$20 -> 0.15 | F6: =D6*E6 -> 2.25 | G6: =MAX(0,C6-D6+F6) -> 4.25 | H6: =D6+G6-F6 -> 17 | I6: Referral network build
A7: M3 | B7: Year 1 | C7: 18 | D7: =H6 -> 17 | E7: ='ARCHIVE_Control Tower'!$B$20 -> 0.15 | F7: =D7*E7 -> 2.55 | G7: =MAX(0,C7-D7+F7) -> 3.55 | H7: =D7+G7-F7 -> 18
A8: M4 | B8: Year 1 | C8: 20 | D8: =H7 -> 18 | E8: ='ARCHIVE_Control Tower'!$B$20 -> 0.15 | F8: =D8*E8 -> 2.7 | G8: =MAX(0,C8-D8+F8) -> 4.7 | H8: =D8+G8-F8 -> 20
A9: M5 | B9: Year 1 | C9: 22 | D9: =H8 -> 20 | E9: ='ARCHIVE_Control Tower'!$B$20 -> 0.15 | F9: =D9*E9 -> 3 | G9: =MAX(0,C9-D9+F9) -> 5 | H9: =D9+G9-F9 -> 22
A10: M6 | B10: Year 1 | C10: 23 | D10: =H9 -> 22 | E10: ='ARCHIVE_Control Tower'!$B$20 -> 0.15 | F10: =D10*E10 -> 3.3 | G10: =MAX(0,C10-D10+F10) -> 4.3 | H10: =D10+G10-F10 -> 23
A11: M7 | B11: Year 1 | C11: 25 | D11: =H10 -> 23 | E11: ='ARCHIVE_Control Tower'!$B$20 -> 0.15 | F11: =D11*E11 -> 3.45 | G11: =MAX(0,C11-D11+F11) -> 5.45 | H11: =D11+G11-F11 -> 25
A12: M8 | B12: Year 1 | C12: 26 | D12: =H11 -> 25 | E12: ='ARCHIVE_Control Tower'!$B$20 -> 0.15 | F12: =D12*E12 -> 3.75 | G12: =MAX(0,C12-D12+F12) -> 4.75 | H12: =D12+G12-F12 -> 26
A13: M9 | B13: Year 1 | C13: 28 | D13: =H12 -> 26 | E13: ='ARCHIVE_Control Tower'!$B$20 -> 0.15 | F13: =D13*E13 -> 3.9 | G13: =MAX(0,C13-D13+F13) -> 5.9 | H13: =D13+G13-F13 -> 28
A14: M10 | B14: Year 1 | C14: 30 | D14: =H13 -> 28 | E14: ='ARCHIVE_Control Tower'!$B$20 -> 0.15 | F14: =D14*E14 -> 4.2 | G14: =MAX(0,C14-D14+F14) -> 6.2 | H14: =D14+G14-F14 -> 30
A15: M11 | B15: Year 1 | C15: 31 | D15: =H14 -> 30 | E15: ='ARCHIVE_Control Tower'!$B$20 -> 0.15 | F15: =D15*E15 -> 4.5 | G15: =MAX(0,C15-D15+F15) -> 5.5 | H15: =D15+G15-F15 -> 31
A16: M12 | B16: Year 1 | C16: 33 | D16: =H15 -> 31 | E16: ='ARCHIVE_Control Tower'!$B$20 -> 0.15 | F16: =D16*E16 -> 4.65 | G16: =MAX(0,C16-D16+F16) -> 6.65 | H16: =D16+G16-F16 -> 33 | I16: Y1 target 33 ADC (avg ~24)
A17: M13 | B17: Year 2 | C17: 34 | D17: =H16 -> 33 | E17: ='ARCHIVE_Control Tower'!$B$20 -> 0.15 | F17: =D17*E17 -> 4.95 | G17: =MAX(0,C17-D17+F17) -> 5.95 | H17: =D17+G17-F17 -> 34
A18: M14 | B18: Year 2 | C18: 36 | D18: =H17 -> 34 | E18: ='ARCHIVE_Control Tower'!$B$20 -> 0.15 | F18: =D18*E18 -> 5.1 | G18: =MAX(0,C18-D18+F18) -> 7.1 | H18: =D18+G18-F18 -> 36
A19: M15 | B19: Year 2 | C19: 37 | D19: =H18 -> 36 | E19: ='ARCHIVE_Control Tower'!$B$20 -> 0.15 | F19: =D19*E19 -> 5.4 | G19: =MAX(0,C19-D19+F19) -> 6.4 | H19: =D19+G19-F19 -> 37
A20: M16 | B20: Year 2 | C20: 39 | D20: =H19 -> 37 | E20: ='ARCHIVE_Control Tower'!$B$20 -> 0.15 | F20: =D20*E20 -> 5.55 | G20: =MAX(0,C20-D20+F20) -> 7.55 | H20: =D20+G20-F20 -> 39
A21: M17 | B21: Year 2 | C21: 40 | D21: =H20 -> 39 | E21: ='ARCHIVE_Control Tower'!$B$20 -> 0.15 | F21: =D21*E21 -> 5.85 | G21: =MAX(0,C21-D21+F21) -> 6.85 | H21: =D21+G21-F21 -> 40
A22: M18 | B22: Year 2 | C22: 42 | D22: =H21 -> 40 | E22: ='ARCHIVE_Control Tower'!$B$20 -> 0.15 | F22: =D22*E22 -> 6 | G22: =MAX(0,C22-D22+F22) -> 8 | H22: =D22+G22-F22 -> 42
A23: M19 | B23: Year 2 | C23: 43 | D23: =H22 -> 42 | E23: ='ARCHIVE_Control Tower'!$B$20 -> 0.15 | F23: =D23*E23 -> 6.3 | G23: =MAX(0,C23-D23+F23) -> 7.3 | H23: =D23+G23-F23 -> 43
A24: M20 | B24: Year 2 | C24: 44 | D24: =H23 -> 43 | E24: ='ARCHIVE_Control Tower'!$B$20 -> 0.15 | F24: =D24*E24 -> 6.45 | G24: =MAX(0,C24-D24+F24) -> 7.45 | H24: =D24+G24-F24 -> 44
A25: M21 | B25: Year 2 | C25: 46 | D25: =H24 -> 44 | E25: ='ARCHIVE_Control Tower'!$B$20 -> 0.15 | F25: =D25*E25 -> 6.6 | G25: =MAX(0,C25-D25+F25) -> 8.6 | H25: =D25+G25-F25 -> 46
A26: M22 | B26: Year 2 | C26: 47 | D26: =H25 -> 46 | E26: ='ARCHIVE_Control Tower'!$B$20 -> 0.15 | F26: =D26*E26 -> 6.9 | G26: =MAX(0,C26-D26+F26) -> 7.9 | H26: =D26+G26-F26 -> 47
A27: M23 | B27: Year 2 | C27: 49 | D27: =H26 -> 47 | E27: ='ARCHIVE_Control Tower'!$B$20 -> 0.15 | F27: =D27*E27 -> 7.05 | G27: =MAX(0,C27-D27+F27) -> 9.05 | H27: =D27+G27-F27 -> 49
A28: M24 | B28: Year 2 | C28: 50 | D28: =H27 -> 49 | E28: ='ARCHIVE_Control Tower'!$B$20 -> 0.15 | F28: =D28*E28 -> 7.35 | G28: =MAX(0,C28-D28+F28) -> 8.35 | H28: =D28+G28-F28 -> 50 | I28: Y2 target 50 ADC
A29: M25 | B29: Year 3 | C29: 51 | D29: =H28 -> 50 | E29: ='ARCHIVE_Control Tower'!$B$20 -> 0.15 | F29: =D29*E29 -> 7.5 | G29: =MAX(0,C29-D29+F29) -> 8.5 | H29: =D29+G29-F29 -> 51
A30: M26 | B30: Year 3 | C30: 52 | D30: =H29 -> 51 | E30: ='ARCHIVE_Control Tower'!$B$20 -> 0.15 | F30: =D30*E30 -> 7.65 | G30: =MAX(0,C30-D30+F30) -> 8.65 | H30: =D30+G30-F30 -> 52
A31: M27 | B31: Year 3 | C31: 52 | D31: =H30 -> 52 | E31: ='ARCHIVE_Control Tower'!$B$20 -> 0.15 | F31: =D31*E31 -> 7.8 | G31: =MAX(0,C31-D31+F31) -> 7.8 | H31: =D31+G31-F31 -> 52
A32: M28 | B32: Year 3 | C32: 53 | D32: =H31 -> 52 | E32: ='ARCHIVE_Control Tower'!$B$20 -> 0.15 | F32: =D32*E32 -> 7.8 | G32: =MAX(0,C32-D32+F32) -> 8.8 | H32: =D32+G32-F32 -> 53
A33: M29 | B33: Year 3 | C33: 54 | D33: =H32 -> 53 | E33: ='ARCHIVE_Control Tower'!$B$20 -> 0.15 | F33: =D33*E33 -> 7.95 | G33: =MAX(0,C33-D33+F33) -> 8.95 | H33: =D33+G33-F33 -> 54
A34: M30 | B34: Year 3 | C34: 55 | D34: =H33 -> 54 | E34: ='ARCHIVE_Control Tower'!$B$20 -> 0.15 | F34: =D34*E34 -> 8.1 | G34: =MAX(0,C34-D34+F34) -> 9.1 | H34: =D34+G34-F34 -> 55
A35: M31 | B35: Year 3 | C35: 56 | D35: =H34 -> 55 | E35: ='ARCHIVE_Control Tower'!$B$20 -> 0.15 | F35: =D35*E35 -> 8.25 | G35: =MAX(0,C35-D35+F35) -> 9.25 | H35: =D35+G35-F35 -> 56
A36: M32 | B36: Year 3 | C36: 57 | D36: =H35 -> 56 | E36: ='ARCHIVE_Control Tower'!$B$20 -> 0.15 | F36: =D36*E36 -> 8.4 | G36: =MAX(0,C36-D36+F36) -> 9.4 | H36: =D36+G36-F36 -> 57
A37: M33 | B37: Year 3 | C37: 58 | D37: =H36 -> 57 | E37: ='ARCHIVE_Control Tower'!$B$20 -> 0.15 | F37: =D37*E37 -> 8.55 | G37: =MAX(0,C37-D37+F37) -> 9.55 | H37: =D37+G37-F37 -> 58
A38: M34 | B38: Year 3 | C38: 58 | D38: =H37 -> 58 | E38: ='ARCHIVE_Control Tower'!$B$20 -> 0.15 | F38: =D38*E38 -> 8.7 | G38: =MAX(0,C38-D38+F38) -> 8.7 | H38: =D38+G38-F38 -> 58
A39: M35 | B39: Year 3 | C39: 59 | D39: =H38 -> 58 | E39: ='ARCHIVE_Control Tower'!$B$20 -> 0.15 | F39: =D39*E39 -> 8.7 | G39: =MAX(0,C39-D39+F39) -> 9.7 | H39: =D39+G39-F39 -> 59
A40: M36 | B40: Year 3 | C40: 60 | D40: =H39 -> 59 | E40: ='ARCHIVE_Control Tower'!$B$20 -> 0.15 | F40: =D40*E40 -> 8.85 | G40: =MAX(0,C40-D40+F40) -> 9.85 | H40: =D40+G40-F40 -> 60 | I40: Y3 target 60 ADC
A42: ANNUAL AVERAGE ADC
...

Sheet ARCHIVE_Revenue Model
A1: REVENUE MODEL — 100% Medicare RHC · FY2026 Rates · Bottom-Up with Validation
A2: Wage-adjusted FY2026 RHC rates · 2% sequestration · SIA excluded · 1.5% billing fee · all rates flow from Control Tower Section G
A4: A. RATE BUILD (per patient day)
A5: RHC rate, days 1-60 ($/day) | B5: ='ARCHIVE_Control Tower'!$B$57 -> 230.83 | C5: national, FY2026
A6: RHC rate, days 61+ ($/day) | B6: ='ARCHIVE_Control Tower'!$B$58 -> 182.36 | C6: national, FY2026
A7: Tyler CBSA 46340 wage index | B7: ='ARCHIVE_Control Tower'!$B$59 -> 0.88 | C7: confirm WI addendum
A8: Wage-index adjustment factor | B8: ='ARCHIVE_Control Tower'!$B$60*B7+(1-'ARCHIVE_Control Tower'!$B$60) -> 0.9208
A9: Wage-adjusted rate, days 1-60 | B9: =B5*B8 -> 212.54826 | C9: labor share x WI + non-labor
A10: Wage-adjusted rate, days 61+ | B10: =B6*B8 -> 167.91709
A11: % patient-days in tier 1 (1-60) | B11: ='ARCHIVE_Control Tower'!$B$61 -> 0.45 | C11: LOS mix — tune to validate
A12: Blended gross rate ($/day) | B12: =B11*B9+(1-B11)*B10 -> 188.00112 | C12: weighted by LOS mix
A13: After 2% sequestration ($/day) | B13: =B12*(1-'ARCHIVE_Control Tower'!$B$62) -> 184.24109 | C13: Medicare payment/day
A14: Net rate after billing fee ($/day) | B14: =B13*(1-'ARCHIVE_Control Tower'!$B$64) -> 181.47748 | C14: net revenue per patient day
A16: B. MONTHLY BILLED REVENUE
A17: Line | C17: M1 | D17: M2 | E17: M3 | F17: M4 | G17: M5 | H17: M6 | I17: M7 | J17: M8 | K17: M9 | L17: M10 | M17: M11 | N17: M12 | O17: M13 | P17: M14 | Q17: M15 | R17: M16 | S17: M17 | T17: M18 | U17: M19 | V17: M20 | W17: M21 | X17: M22 | Y17: M23 | Z17: M24 | AA17: M25 | AB17: M26 | AC17: M27 | AD17: M28 | AE17: M29 | AF17: M30 | AG17: M31 | AH17: M32 | AI17: M33 | AJ17: M34 | AK17: M35 | AL17: M36 | AM17: Y1 | AN17: Y2 | AO17: Y3
A18: ADC (from Census Waterfall) | C18: ='ARCHIVE_Census Waterfall'!$C$5 -> 15 | D18: ='ARCHIVE_Census Waterfall'!$C$6 -> 17 | E18: ='ARCHIVE_Census Waterfall'!$C$7 -> 18 | F18: ='ARCHIVE_Census Waterfall'!$C$8 -> 20 | G18: ='ARCHIVE_Census Waterfall'!$C$9 -> 22 | H18: ='ARCHIVE_Census Waterfall'!$C$10 -> 23 | I18: ='ARCHIVE_Census Waterfall'!$C$11 -> 25 | J18: ='ARCHIVE_Census Waterfall'!$C$12 -> 26 | K18: ='ARCHIVE_Census Waterfall'!$C$13 -> 28 | L18: ='ARCHIVE_Census Waterfall'!$C$14 -> 30 | M18: ='ARCHIVE_Census Waterfall'!$C$15 -> 31 | N18: ='ARCHIVE_Census Waterfall'!$C$16 -> 33 | O18: ='ARCHIVE_Census Waterfall'!$C$17 -> 34 | P18: ='ARCHIVE_Census Waterfall'!$C$18 -> 36 | Q18: ='ARCHIVE_Census Waterfall'!$C$19 -> 37 | R18: ='ARCHIVE_Census Waterfall'!$C$20 -> 39 | S18: ='ARCHIVE_Census Waterfall'!$C$21 -> 40 | T18: ='ARCHIVE_Census Waterfall'!$C$22 -> 42 | U18: ='ARCHIVE_Census Waterfall'!$C$23 -> 43 | V18: ='ARCHIVE_Census Waterfall'!$C$24 -> 44 | W18: ='ARCHIVE_Census Waterfall'!$C$25 -> 46 | X18: ='ARCHIVE_Census Waterfall'!$C$26 -> 47 | Y18: ='ARCHIVE_Census Waterfall'!$C$27 -> 49 | Z18: ='ARCHIVE_Census Waterfall'!$C$28 -> 50 | AA18: ='ARCHIVE_Census Waterfall'!$C$29 -> 51 | AB18: ='ARCHIVE_Census Waterfall'!$C$30 -> 52 | AC18: ='ARCHIVE_Census Waterfall'!$C$31 -> 52 | AD18: ='ARCHIVE_Census Waterfall'!$C$32 -> 53 | AE18: ='ARCHIVE_Census Waterfall'!$C$33 -> 54 | AF18: ='ARCHIVE_Census Waterfall'!$C$34 -> 55 | AG18: ='ARCHIVE_Census Waterfall'!$C$35 -> 56 | AH18: ='ARCHIVE_Census Waterfall'!$C$36 -> 57 | AI18: ='ARCHIVE_Census Waterfall'!$C$37 -> 58 | AJ18: ='ARCHIVE_Census Waterfall'!$C$38 -> 58 | AK18: ='ARCHIVE_Census Waterfall'!$C$39 -> 59 | AL18: ='ARCHIVE_Census Waterfall'!$C$40 -> 60
A19: Days in month | C19: ='ARCHIVE_Control Tower'!$B$21 -> 30.4 | D19: ='ARCHIVE_Control Tower'!$B$21 -> 30.4 | E19: ='ARCHIVE_Control Tower'!$B$21 -> 30.4 | F19: ='ARCHIVE_Control Tower'!$B$21 -> 30.4 | G19: ='ARCHIVE_Control Tower'!$B$21 -> 30.4 | H19: ='ARCHIVE_Control Tower'!$B$21 -> 30.4 | I19: ='ARCHIVE_Control Tower'!$B$21 -> 30.4 | J19: ='ARCHIVE_Control Tower'!$B$21 -> 30.4 | ... AL19: ='ARCHIVE_Control Tower'!$B$21 -> 30.4
A20: Patient-days | C20: =C18*C19 -> 456 | D20: =D18*D19 -> 516.8 | E20: =E18*E19 -> 547.2 | F20: =F18*F19 -> 608 | G20: =G18*G19 -> 668.8 | H20: =H18*H19 -> 699.2 | I20: =I18*I19 -> 760 | J20: =J18*J19 -> 790.4 | ... AL20: =AL18*AL19 -> 1824 | AM20: =SUM(C20:N20) -> 8755.2 | AN20: =SUM(O20:Z20) -> 15412.8 | AO20: =SUM(AA20:AL20) -> 20216
A21: Gross Medicare (post-sequestration) | C21: =C20*$B$13 -> 84013.939 | D21: =D20*$B$13 -> 95215.798 | E21: =E20*$B$13 -> 100816.73 | F21: =F20*$B$13 -> 112018.59 | G21: =G20*$B$13 -> 123220.44 | H21: =H20*$B$13 -> 128821.37 | I21: =I20*$B$13 -> 140023.23 | J21: =J20*$B$13 -> 145624.16 | ... AL21: =AL20*$B$13 -> 336055.76 | AM21: =SUM(C21:N21) -> 1613067.6 | AN21: =SUM(O21:Z21) -> 2839671.1 | AO21: =SUM(AA21:AL21) -> 3724618
A22: Less: billing fee (1.5%) | C22: =-C21*'ARCHIVE_Control Tower'!$B$64 -> -1260.2091 | D22: =-D21*'ARCHIVE_Control Tower'!$B$64 -> -1428.237 | E22: =-E21*'ARCHIVE_Control Tower'!$B$64 -> -1512.2509 | F22: =-F21*'ARCHIVE_Control Tower'!$B$64 -> -1680.2788 | G22: =-G21*'ARCHIVE_Control Tower'!$B$64 -> -1848.3067 | H22: =-H21*'ARCHIVE_Control Tower'!$B$64 -> -1932.3206 | I22: =-I21*'ARCHIVE_Control Tower'!$B$64 -> -2100.3485 | J22: =-J21*'ARCHIVE_Control Tower'!$B$64 -> -2184.3624 | ... AL22: =-AL21*'ARCHIVE_Control Tower'!$B$64 -> -5040.8364 | AM22: =SUM(C22:N22) -> -24196.015 | AN22: =SUM(O22:Z22) -> -42595.067 | AO22: =SUM(AA22:AL22) -> -55869.27
A23: NET REVENUE | C23: =C21+C22 -> 82753.73 | D23: =D21+D22 -> 93787.561 | E23: =E21+E22 -> 99304.476 | F23: =F21+F22 -> 110338.31 | G23: =G21+G22 -> 121372.14 | H23: =H21+H22 -> 126889.05 | I23: =I21+I22 -> 137922.88 | J23: =J21+J22 -> 143439.8 | ... AL23: =AL21+AL22 -> 331014.92 | AM23: =SUM(C23:N23) -> 1588871.6 | AN23: =SUM(O23:Z23) -> 2797076.1 | AO23: =SUM(AA23:AL23) -> 3668748.7
A25: C. VALIDATION vs HANDOFF BRIEF
A26: Net Revenue | C26: Bottom-Up (model) | D26: Brief Target | E26: Variance
A27: Year 1 | C27: =AM23 -> 1588871.6 | D27: 1605199 | E27: =(C27-D27)/D27 -> -0.010171562
A28: Year 2 | C28: =AN23 -> 2797076.1 | D28: 2628166 | E28: =(C28-D28)/D28 -> 0.064269182
A29: Year 3 | C29: =AO23 -> 3668748.7 | D29: 3580092 | E29: =(C29-D29)/D29 -> 0.024763806
A30: D. MEDICARE AGGREGATE CAP CHECK (FY2026 cap $35,361.44 / beneficiary)
B31: Beneficiaries | C31: Cap Allowable | D31: Gross Medicare | E31: Headroom | F31: Rev/Benef.
A32: Year 1 | B32: ='ARCHIVE_Census Waterfall'!D5+SUM('ARCHIVE_Census Waterfall'!G5:G16) -> 73.5 | C32: =B32*'ARCHIVE_Control Tower'!$B$65 -> 2599065.8 | D32: =AM21 -> 1613067.6 | E32: =C32-D32 -> 985998.21 | F32: =D32/B32 -> 21946.498
A33: Year 2 | B33: ='ARCHIVE_Census Waterfall'!D17+SUM('ARCHIVE_Census Waterfall'!G17:G28) -> 123.5 | C33: =B33*'ARCHIVE_Control Tower'!$B$65 -> 4367137.8 | D33: =AN21 -> 2839671.1 | E33: =C33-D33 -> 1527466.7 | F33: =D33/B33 -> 22993.289
A34: Year 3 | B34: ='ARCHIVE_Census Waterfall'!D29+SUM('ARCHIVE_Census Waterfall'!G29:G40) -> 158.25 | C34: =B34*'ARCHIVE_Control Tower'!$B$65 -> 5595947.9 | D34: =AO21 -> 3724618 | E34: =C34-D34 -> 1871329.9 | F34: =D34/B34 -> 23536.291
A35: Headroom positive = no cap liability. Note: sensitive to ALOS; 15%/mo discharge implies long stays — validate.
A37: E. COLLECTIONS TIMING — BASE CASE (first claim M2/Jul 1 · ~2-mo lag · PPEO hold M6-M8, released M9)
A38: Line | C38: M1 | D38: M2 | E38: M3 | F38: M4 | G38: M5 | H38: M6 | I38: M7 | J38: M8 | K38: M9 | L38: M10 | M38: M11 | N38: M12 | O38: M13 | P38: M14 | Q38: M15 | R38: M16 | S38: M17 | T38: M18 | U38: M19 | V38: M20 | W38: M21 | X38: M22 | Y38: M23 | Z38: M24 | AA38: M25 | AB38: M26 | AC38: M27 | AD38: M28 | AE38: M29 | AF38: M30 | AG38: M31 | AH38: M32 | AI38: M33 | AJ38: M34 | AK38: M35 | AL38: M36 | AM38: Y1 | AN38: Y2 | AO38: Y3
A39: Net revenue billed | C39: =C23 -> 82753.73 | D39: =D23 -> 93787.561 | E39: =E23 -> 99304.476 | F39: =F23 -> 110338.31 | G39: =G23 -> 121372.14 | H39: =H23 -> 126889.05 | I39: =I23 -> 137922.88 | J39: =J23 -> 143439.8 | ... AL39: =AL23 -> 331014.92 | AM39: =SUM(C39:N39) -> 1588871.6 | AN39: =SUM(O39:Z39) -> 2797076.1 | AO39: =SUM(AA39:AL39) -> 3668748.7
A40: Medicare cash collected (w/ PPEO hold) | C40: =0 -> 0 | D40: =0 -> 0 | E40: =C39 -> 82753.73 | F40: =D39 -> 93787.561 | G40: =E39 -> 99304.476 | H40: =0 -> 0 | I40: =0 -> 0 | J40: =0 -> 0 | K40: =I39+F39+G39+H39 -> 496522.38 | L40: =J39 -> 143439.8 | M40: =K39 -> 154473.63 | N40: =L39 -> 165507.46 | O40: =M39 -> 171024.38 | P40: =N39 -> 182058.21 | Q40: =O39 -> 187575.12 | R40: =P39 -> 198608.95 | S40: =Q39 -> 204125.87 | ... AL40: =AJ39 -> 319981.09 | AM40: =SUM(C40:N40) -> 1235789 | AN40: =SUM(O40:Z40) -> 2603984 | AO40: =SUM(AA40:AL40) -> 3558410.4
A41: Cumulative cash vs billed (gap) | C41: =C40-C39 -> -82753.73 | D41: =C41+D40-D39 -> -176541.29 | E41: =D41+E40-E39 -> -193092.04 | F41: =E41+F40-F39 -> -209642.78 | G41: =F41+G40-G39 -> -231710.44 | H41: =G41+H40-H39 -> -358599.5 | I41: =H41+I40-I39 -> -496522.38 | J41: =I41+J40-J39 -> -639962.18 | K41: =J41+K40-K39 -> -297913.43 | ... AL41: =AK41+AL40-AL39 -> -656512.93
A42: Max cumulative gap = working-capital bridge the $500K SBA funds.

Sheet ARCHIVE_Staffing Summary
A1: STAFFING SUMMARY — 36-Month Engine · COA-Tagged · Census-Ratio Driven
A2: Burden: FICA 7.65% + FUTA/SUTA 1.85% + WC 3% on W-2 wages · Health $500/mo per FT · Mileage $0.50/mi · Merit 3% Y2/Y3
A4: Line Item | B4: GL Account | C4: Start | D4: M1 | E4: M2 | F4: M3 | G4: M4 | H4: M5 | I4: M6 | J4: M7 | K4: M8 | L4: M9 | M4: M10 | N4: M11 | O4: M12 | P4: M13 | Q4: M14 | R4: M15 | S4: M16 | T4: M17 | U4: M18 | V4: M19 | W4: M20 | X4: M21 | Y4: M22 | Z4: M23 | AA4: M24 | AB4: M25 | AC4: M26 | AD4: M27 | AE4: M28 | AF4: M29 | AG4: M30 | AH4: M31 | AI4: M32 | AJ4: M33 | AK4: M34 | AL4: M35 | AM4: M36 | AN4: Y1 Tot | AO4: Y2 Tot | AP4: Y3 Tot
A5: DRIVERS
A6: Month Index | D6: 1 | E6: 2 | F6: 3 | G6: 4 | H6: 5 | I6: 6 | J6: 7 | K6: 8 | L6: 9 | M6: 10 | N6: 11 | O6: 12 | P6: 13 | Q6: 14 | R6: 15 | S6: 16 | T6: 17 | U6: 18 | V6: 19 | W6: 20 | X6: 21 | Y6: 22 | Z6: 23 | AA6: 24 | AB6: 25 | AC6: 26 | AD6: 27 | AE6: 28 | AF6: 29 | AG6: 30 | AH6: 31 | AI6: 32 | AJ6: 33 | AK6: 34 | AL6: 35 | AM6: 36
A7: ADC (from Census Waterfall) | D7: ='ARCHIVE_Census Waterfall'!$C$5 -> 15 | E7: ='ARCHIVE_Census Waterfall'!$C$6 -> 17 | F7: ='ARCHIVE_Census Waterfall'!$C$7 -> 18 | G7: ='ARCHIVE_Census Waterfall'!$C$8 -> 20 | H7: ='ARCHIVE_Census Waterfall'!$C$9 -> 22 | I7: ='ARCHIVE_Census Waterfall'!$C$10 -> 23 | J7: ='ARCHIVE_Census Waterfall'!$C$11 -> 25 | K7: ='ARCHIVE_Census Waterfall'!$C$12 -> 26 | L7: ='ARCHIVE_Census Waterfall'!$C$13 -> 28 | M7: ='ARCHIVE_Census Waterfall'!$C$14 -> 30 | N7: ='ARCHIVE_Census Waterfall'!$C$15 -> 31 | O7: ='ARCHIVE_Census Waterfall'!$C$16 -> 33 | P7: ='ARCHIVE_Census Waterfall'!$C$17 -> 34 | Q7: ='ARCHIVE_Census Waterfall'!$C$18 -> 36 | R7: ='ARCHIVE_Census Waterfall'!$C$19 -> 37 | S7: ='ARCHIVE_Census Waterfall'!$C$20 -> 39 | T7: ='ARCHIVE_Census Waterfall'!$C$21 -> 40 | U7: ='ARCHIVE_Census Waterfall'!$C$22 -> 42 | V7: ='ARCHIVE_Census Waterfall'!$C$23 -> 43 | W7: ='ARCHIVE_Census Waterfall'!$C$24 -> 44 | X7: ='ARCHIVE_Census Waterfall'!$C$25 -> 46 | Y7: ='ARCHIVE_Census Waterfall'!$C$26 -> 47 | Z7: ='ARCHIVE_Census Waterfall'!$C$27 -> 49 | AA7: ='ARCHIVE_Census Waterfall'!$C$28 -> 50 | AB7: ='ARCHIVE_Census Waterfall'!$C$29 -> 51 | AC7: ='ARCHIVE_Census Waterfall'!$C$30 -> 52 | AD7: ='ARCHIVE_Census Waterfall'!$C$31 -> 52 | AE7: ='ARCHIVE_Census Waterfall'!$C$32 -> 53 | AF7: ='ARCHIVE_Census Waterfall'!$C$33 -> 54 | AG7: ='ARCHIVE_Census Waterfall'!$C$34 -> 55 | AH7: ='ARCHIVE_Census Waterfall'!$C$35 -> 56 | AI7: ='ARCHIVE_Census Waterfall'!$C$36 -> 57 | AJ7: ='ARCHIVE_Census Waterfall'!$C$37 -> 58 | AK7: ='ARCHIVE_Census Waterfall'!$C$38 -> 58 | AL7: ='ARCHIVE_Census Waterfall'!$C$39 -> 59 | AM7: ='ARCHIVE_Census Waterfall'!$C$40 -> 60
A8: Salary Escalation Factor | D8: =(1+'ARCHIVE_Control Tower'!$B$19)^0 -> 1 | E8: =(1+'ARCHIVE_Control Tower'!$B$19)^0 -> 1 | F8: =(1+'ARCHIVE_Control Tower'!$B$19)^0 -> 1 | G8: =(1+'ARCHIVE_Control Tower'!$B$19)^0 -> 1 | H8: =(1+'ARCHIVE_Control Tower'!$B$19)^0 -> 1 | I8: =(1+'ARCHIVE_Control Tower'!$B$19)^0 -> 1 | J8: =(1+'ARCHIVE_Control Tower'!$B$19)^0 -> 1 | K8: =(1+'ARCHIVE_Control Tower'!$B$19)^0 -> 1 | ... O8: =(1+'ARCHIVE_Control Tower'!$B$19)^0 -> 1 | P8: =(1+'ARCHIVE_Control Tower'!$B$19)^1 -> 1.03 | Q8: =(1+'ARCHIVE_Control Tower'!$B$19)^1 -> 1.03 | R8: =(1+'ARCHIVE_Control Tower'!$B$19)^1 -> 1.03 | S8: =(1+'ARCHIVE_Control Tower'!$B$19)^1 -> 1.03 | T8: =(1+'ARCHIVE_Control Tower'!$B$19)^1 -> 1.03 | U8: =(1+'ARCHIVE_Control Tower'!$B$19)^1 -> 1.03 | V8: =(1+'ARCHIVE_Control Tower'!$B$19)^1 -> 1.03 | W8: =(1+'ARCHIVE_Control Tower'!$B$19)^1 -> 1.03 | ... AA8: =(1+'ARCHIVE_Control Tower'!$B$19)^1 -> 1.03 | AB8: =(1+'ARCHIVE_Control Tower'!$B$19)^2 -> 1.0609 | AC8: =(1+'ARCHIVE_Control Tower'!$B$19)^2 -> 1.0609 | AD8: =(1+'ARCHIVE_Control Tower'!$B$19)^2 -> 1.0609 | AE8: =(1+'ARCHIVE_Control Tower'!$B$19)^2 -> 1.0609 | AF8: =(1+'ARCHIVE_Control Tower'!$B$19)^2 -> 1.0609 | AG8: =(1+'ARCHIVE_Control Tower'!$B$19)^2 -> 1.0609 | AH8: =(1+'ARCHIVE_Control Tower'!$B$19)^2 -> 1.0609 | AI8: =(1+'ARCHIVE_Control Tower'!$B$19)^2 -> 1.0609 | ... AM8: =(1+'ARCHIVE_Control Tower'!$B$19)^2 -> 1.0609
A9: RN-CM FTEs required | D9: =ROUNDUP(D7/'ARCHIVE_Control Tower'!$B$17,0) -> 1 | E9: =ROUNDUP(E7/'ARCHIVE_Control Tower'!$B$17,0) -> 2 | F9: =ROUNDUP(F7/'ARCHIVE_Control Tower'!$B$17,0) -> 2 | G9: =ROUNDUP(G7/'ARCHIVE_Control Tower'!$B$17,0) -> 2 | H9: =ROUNDUP(H7/'ARCHIVE_Control Tower'!$B$17,0) -> 2 | I9: =ROUNDUP(I7/'ARCHIVE_Control Tower'!$B$17,0) -> 2 | J9: =ROUNDUP(J7/'ARCHIVE_Control Tower'!$B$17,0) -> 2 | K9: =ROUNDUP(K7/'ARCHIVE_Control Tower'!$B$17,0) -> 2 | ... AM9: =ROUNDUP(AM7/'ARCHIVE_Control Tower'!$B$17,0) -> 4
A10: Aide FTEs required | D10: =ROUNDUP(D7/'ARCHIVE_Control Tower'!$B$18,0) -> 2 | E10: =ROUNDUP(E7/'ARCHIVE_Control Tower'!$B$18,0) -> 2 | F10: =ROUNDUP(F7/'ARCHIVE_Control Tower'!$B$18,0) -> 2 | G10: =ROUNDUP(G7/'ARCHIVE_Control Tower'!$B$18,0) -> 2 | H10: =ROUNDUP(H7/'ARCHIVE_Control Tower'!$B$18,0) -> 2 | I10: =ROUNDUP(I7/'ARCHIVE_Control Tower'!$B$18,0) -> 2 | J10: =ROUNDUP(J7/'ARCHIVE_Control Tower'!$B$18,0) -> 3 | K10: =ROUNDUP(K7/'ARCHIVE_Control Tower'!$B$18,0) -> 3 | ... AM10: =ROUNDUP(AM7/'ARCHIVE_Control Tower'!$B$18,0) -> 5
A11: DIRECT CARE — WAGES (Cost of Care)
A12: Jodi McCollum — RN-CM | B12: 4000-R-6-1 | C12: M1 | D12: =IF(D6>=1,'ARCHIVE_Control Tower'!$B$40/12*D8,0) -> 6250.4167 | E12: =IF(E6>=1,'ARCHIVE_Control Tower'!$B$40/12*E8,0) -> 6250.4167 | F12: =IF(F6>=1,'ARCHIVE_Control Tower'!$B$40/12*F8,0) -> 6250.4167 | G12: =IF(G6>=1,'ARCHIVE_Control Tower'!$B$40/12*G8,0) -> 6250.4167 | H12: =IF(H6>=1,'ARCHIVE_Control Tower'!$B$40/12*H8,0) -> 6250.4167 | I12: =IF(I6>=1,'ARCHIVE_Control Tower'!$B$40/12*I8,0) -> 6250.4167 | J12: =IF(J6>=1,'ARCHIVE_Control Tower'!$B$40/12*J8,0) -> 6250.4167 | K12: =IF(K6>=1,'ARCHIVE_Control Tower'!$B$40/12*K8,0) -> 6250.4167 | ... AM12: =IF(AM6>=1,'ARCHIVE_Control Tower'!$B$40/12*AM8,0) -> 6631.067 | AN12: =SUM(D12:O12) -> 75005 | AO12: =SUM(P12:AA12) -> 77255.15 | AP12: =SUM(AB12:AM12) -> 79572.805
A13: Angie Frost — RN-CM | B13: 4000-R-6-1 | C13: M2 | D13: =IF(D6>=2,'ARCHIVE_Control Tower'!$B$42/12*D8,0) -> 0 | E13: =IF(E6>=2,'ARCHIVE_Control Tower'!$B$42/12*E8,0) -> 6458.5833 | F13: =IF(F6>=2,'ARCHIVE_Control Tower'!$B$42/12*F8,0) -> 6458.5833 | G13: =IF(G6>=2,'ARCHIVE_Control Tower'!$B$42/12*G8,0) -> 6458.5833 | H13: =IF(H6>=2,'ARCHIVE_Control Tower'!$B$42/12*H8,0) -> 6458.5833 | I13: =IF(I6>=2,'ARCHIVE_Control Tower'!$B$42/12*I8,0) -> 6458.5833 | J13: =IF(J6>=2,'ARCHIVE_Control Tower'!$B$42/12*J8,0) -> 6458.5833 | K13: =IF(K6>=2,'ARCHIVE_Control Tower'!$B$42/12*K8,0) -> 6458.5833 | ... AM13: =IF(AM6>=2,'ARCHIVE_Control Tower'!$B$42/12*AM8,0) -> 6851.9111 | AN13: =SUM(D13:O13) -> 71044.417 | AO13: =SUM(P13:AA13) -> 79828.09 | AP13: =SUM(AB13:AM13) -> 82222.933
A14: Generic RN hire(s) — ratio | B14: 4000-R-6-1 | C14: ADC>30 | D14: =MAX(0,D9-((IF(D6>=1,1,0))+(IF(D6>=2,1,0))))*'ARCHIVE_Control Tower'!$B$47/12*D8 -> 0 | E14: =MAX(0,E9-((IF(E6>=1,1,0))+(IF(E6>=2,1,0))))*'ARCHIVE_Control Tower'!$B$47/12*E8 -> 0 | F14: =MAX(0,F9-((IF(F6>=1,1,0))+(IF(F6>=2,1,0))))*'ARCHIVE_Control Tower'!$B$47/12*F8 -> 0 | G14: =MAX(0,G9-((IF(G6>=1,1,0))+(IF(G6>=2,1,0))))*'ARCHIVE_Control Tower'!$B$47/12*G8 -> 0 | H14: =MAX(0,H9-((IF(H6>=1,1,0))+(IF(H6>=2,1,0))))*'ARCHIVE_Control Tower'!$B$47/12*H8 -> 0 | I14: =MAX(0,I9-((IF(I6>=1,1,0))+(IF(I6>=2,1,0))))*'ARCHIVE_Control Tower'!$B$47/12*I8 -> 0 | J14: =MAX(0,J9-((IF(J6>=1,1,0))+(IF(J6>=2,1,0))))*'ARCHIVE_Control Tower'!$B$47/12*J8 -> 0 | K14: =MAX(0,K9-((IF(K6>=1,1,0))+(IF(K6>=2,1,0))))*'ARCHIVE_Control Tower'!$B$47/12*K8 -> 0 | ... AM14: =MAX(0,AM9-((IF(AM6>=1,1,0))+(IF(AM6>=2,1,0))))*'ARCHIVE_Control Tower'!$B$47/12*AM8 -> 13482.978 | AN14: =SUM(D14:O14) -> 12709 | AO14: =SUM(P14:AA14) -> 104722.16 | AP14: =SUM(AB14:AM14) -> 161795.74
A15: Tanisha Robison — Aide | B15: 4000-R-6-5 | C15: M1 | D15: =IF(D6>=1,'ARCHIVE_Control Tower'!$B$41/12*D8,0) -> 3875.8333 | E15: =IF(E6>=1,'ARCHIVE_Control Tower'!$B$41/12*E8,0) -> 3875.8333 | F15: =IF(F6>=1,'ARCHIVE_Control Tower'!$B$41/12*F8,0) -> 3875.8333 | G15: =IF(G6>=1,'ARCHIVE_Control Tower'!$B$41/12*G8,0) -> 3875.8333 | H15: =IF(H6>=1,'ARCHIVE_Control Tower'!$B$41/12*H8,0) -> 3875.8333 | I15: =IF(I6>=1,'ARCHIVE_Control Tower'!$B$41/12*I8,0) -> 3875.8333 | J15: =IF(J6>=1,'ARCHIVE_Control Tower'!$B$41/12*J8,0) -> 3875.8333 | K15: =IF(K6>=1,'ARCHIVE_Control Tower'!$B$41/12*K8,0) -> 3875.8333 | ... AM15: =IF(AM6>=1,'ARCHIVE_Control Tower'!$B$41/12*AM8,0) -> 4111.8716 | AN15: =SUM(D15:O15) -> 46510 | AO15: =SUM(P15:AA15) -> 47905.3 | AP15: =SUM(AB15:AM15) -> 49342.459
A16: Clarenca Wooten — Aide | B16: 4000-R-6-5 | C16: M3 | D16: =IF(D6>=3,'ARCHIVE_Control Tower'!$B$45/12*D8,0) -> 0 | E16: =IF(E6>=3,'ARCHIVE_Control Tower'!$B$45/12*E8,0) -> 0 | F16: =IF(F6>=3,'ARCHIVE_Control Tower'!$B$45/12*F8,0) -> 3814.25 | G16: =IF(G6>=3,'ARCHIVE_Control Tower'!$B$45/12*G8,0) -> 3814.25 | H16: =IF(H6>=3,'ARCHIVE_Control Tower'!$B$45/12*H8,0) -> 3814.25 | I16: =IF(I6>=3,'ARCHIVE_Control Tower'!$B$45/12*I8,0) -> 3814.25 | J16: =IF(J6>=3,'ARCHIVE_Control Tower'!$B$45/12*J8,0) -> 3814.25 | K16: =IF(K6>=3,'ARCHIVE_Control Tower'!$B$45/12*K8,0) -> 3814.25 | ... AM16: =IF(AM6>=3,'ARCHIVE_Control Tower'!$B$45/12*AM8,0) -> 4046.5378 | AN16: =SUM(D16:O16) -> 38142.5 | AO16: =SUM(P16:AA16) -> 47144.13 | AP16: =SUM(AB16:AM16) -> 48558.454
A17: Generic Aide hire(s) — ratio | B17: 4000-R-6-5 | C17: ADC>24 | D17: =MAX(0,D10-((IF(D6>=1,1,0))+(IF(D6>=3,1,0))))*'ARCHIVE_Control Tower'!$B$48/12*D8 -> 3845.0417 | E17: =MAX(0,E10-((IF(E6>=1,1,0))+(IF(E6>=3,1,0))))*'ARCHIVE_Control Tower'!$B$48/12*E8 -> 3845.0417 | F17: =MAX(0,F10-((IF(F6>=1,1,0))+(IF(F6>=3,1,0))))*'ARCHIVE_Control Tower'!$B$48/12*F8 -> 0 | G17: =MAX(0,G10-((IF(G6>=1,1,0))+(IF(G6>=3,1,0))))*'ARCHIVE_Control Tower'!$B$48/12*G8 -> 0 | H17: =MAX(0,H10-((IF(H6>=1,1,0))+(IF(H6>=3,1,0))))*'ARCHIVE_Control Tower'!$B$48/12*H8 -> 0 | I17: =MAX(0,I10-((IF(I6>=1,1,0))+(IF(I6>=3,1,0))))*'ARCHIVE_Control Tower'!$B$48/12*I8 -> 0 | J17: =MAX(0,J10-((IF(J6>=1,1,0))+(IF(J6>=3,1,0))))*'ARCHIVE_Control Tower'!$B$48/12*J8 -> 3845.0417 | K17: =MAX(0,K10-((IF(K6>=1,1,0))+(IF(K6>=3,1,0))))*'ARCHIVE_Control Tower'!$B$48/12*K8 -> 3845.0417 | ... AM17: =MAX(0,AM10-((IF(AM6>=1,1,0))+(IF(AM6>=3,1,0))))*'ARCHIVE_Control Tower'!$B$48/12*AM8 -> 12237.614 | AN17: =SUM(D17:O17) -> 30760.333 | AO17: =SUM(P17:AA17) -> 95049.43 | AP17: =SUM(AB17:AM17) -> 146851.37
A18: Subtotal — Direct Care Salaried Wages | D18: =SUM(D12:D17) -> 13971.292 | E18: =SUM(E12:E17) -> 20429.875 | F18: =SUM(F12:F17) -> 20399.083 | G18: =SUM(G12:G17) -> 20399.083 | H18: =SUM(H12:H17) -> 20399.083 | I18: =SUM(I12:I17) -> 20399.083 | J18: =SUM(J12:J17) -> 24244.125 | K18: =SUM(K12:K17) -> 24244.125 | ... AM18: =SUM(AM12:AM17) -> 47361.98 | AN18: =SUM(D18:O18) -> 274171.25 | AO18: =SUM(P18:AA18) -> 451904.26 | AP18: =SUM(AB18:AM18) -> 568343.76
A19: DIRECT CARE — PRN VISIT WAGES (volume = ADC x visits/pt/mo x rate)
A20: PRN On-Call LVN | B20: 4000-R-6-4 | C20: M1 | D20: =D7*'ARCHIVE_Control Tower'!$B$24*'ARCHIVE_Control Tower'!$B$25 -> 900 | E20: =E7*'ARCHIVE_Control Tower'!$B$24*'ARCHIVE_Control Tower'!$B$25 -> 1020 | F20: =F7*'ARCHIVE_Control Tower'!$B$24*'ARCHIVE_Control Tower'!$B$25 -> 1080 | G20: =G7*'ARCHIVE_Control Tower'!$B$24*'ARCHIVE_Control Tower'!$B$25 -> 1200 | H20: =H7*'ARCHIVE_Control Tower'!$B$24*'ARCHIVE_Control Tower'!$B$25 -> 1320 | I20: =I7*'ARCHIVE_Control Tower'!$B$24*'ARCHIVE_Control Tower'!$B$25 -> 1380 | J20: =J7*'ARCHIVE_Control Tower'!$B$24*'ARCHIVE_Control Tower'!$B$25 -> 1500 | K20: =K7*'ARCHIVE_Control Tower'!$B$24*'ARCHIVE_Control Tower'!$B$25 -> 1560 | ... AM20: =AM7*'ARCHIVE_Control Tower'!$B$24*'ARCHIVE_Control Tower'!$B$25 -> 3600 | AN20: =SUM(D20:O20) -> 17280 | AO20: =SUM(P20:AA20) -> 30420 | AP20: =SUM(AB20:AM20) -> 39900
A21: PRN Chaplain (SC) | B21: 4000-R-6-7 | C21: M1 | D21: =D7*'ARCHIVE_Control Tower'!$B$26*'ARCHIVE_Control Tower'!$B$27 -> 843.75 | E21: =E7*'ARCHIVE_Control Tower'!$B$26*'ARCHIVE_Control Tower'!$B$27 -> 956.25 | F21: =F7*'ARCHIVE_Control Tower'!$B$26*'ARCHIVE_Control Tower'!$B$27 -> 1012.5 | G21: =G7*'ARCHIVE_Control Tower'!$B$26*'ARCHIVE_Control Tower'!$B$27 -> 1125 | H21: =H7*'ARCHIVE_Control Tower'!$B$26*'ARCHIVE_Control Tower'!$B$27 -> 1237.5 | I21: =I7*'ARCHIVE_Control Tower'!$B$26*'ARCHIVE_Control Tower'!$B$27 -> 1293.75 | J21: =J7*'ARCHIVE_Control Tower'!$B$26*'ARCHIVE_Control Tower'!$B$27 -> 1406.25 | K21: =K7*'ARCHIVE_Control Tower'!$B$26*'ARCHIVE_Control Tower'!$B$27 -> 1462.5 | ... AM21: =AM7*'ARCHIVE_Control Tower'!$B$26*'ARCHIVE_Control Tower'!$B$27 -> 3375 | AN21: =SUM(D21:O21) -> 16200 | AO21: =SUM(P21:AA21) -> 28518.75 | AP21: =SUM(AB21:AM21) -> 37406.25
A22: PRN Social Worker (MSW) | B22: 4000-R-6-6 | C22: M1 | D22: =D7*'ARCHIVE_Control Tower'!$B$28*'ARCHIVE_Control Tower'!$B$29 -> 1125 | E22: =E7*'ARCHIVE_Control Tower'!$B$28*'ARCHIVE_Control Tower'!$B$29 -> 1275 | F22: =F7*'ARCHIVE_Control Tower'!$B$28*'ARCHIVE_Control Tower'!$B$29 -> 1350 | G22: =G7*'ARCHIVE_Control Tower'!$B$28*'ARCHIVE_Control Tower'!$B$29 -> 1500 | H22: =H7*'ARCHIVE_Control Tower'!$B$28*'ARCHIVE_Control Tower'!$B$29 -> 1650 | I22: =I7*'ARCHIVE_Control Tower'!$B$28*'ARCHIVE_Control Tower'!$B$29 -> 1725 | J22: =J7*'ARCHIVE_Control Tower'!$B$28*'ARCHIVE_Control Tower'!$B$29 -> 1875 | K22: =K7*'ARCHIVE_Control Tower'!$B$28*'ARCHIVE_Control Tower'!$B$29 -> 1950 | ... AM22: =AM7*'ARCHIVE_Control Tower'!$B$28*'ARCHIVE_Control Tower'!$B$29 -> 4500 | AN22: =SUM(D22:O22) -> 21600 | AO22: =SUM(P22:AA22) -> 38025 | AP22: =SUM(AB22:AM22) -> 49875
A23: PRN Nurse Practitioner | B23: 4000-R-6-N | C23: M1 | D23: =D7*'ARCHIVE_Control Tower'!$B$30*'ARCHIVE_Control Tower'!$B$31 -> 450 | E23: =E7*'ARCHIVE_Control Tower'!$B$30*'ARCHIVE_Control Tower'!$B$31 -> 510 | F23: =F7*'ARCHIVE_Control Tower'!$B$30*'ARCHIVE_Control Tower'!$B$31 -> 540 | G23: =G7*'ARCHIVE_Control Tower'!$B$30*'ARCHIVE_Control Tower'!$B$31 -> 600 | H23: =H7*'ARCHIVE_Control Tower'!$B$30*'ARCHIVE_Control Tower'!$B$31 -> 660 | I23: =I7*'ARCHIVE_Control Tower'!$B$30*'ARCHIVE_Control Tower'!$B$31 -> 690 | J23: =J7*'ARCHIVE_Control Tower'!$B$30*'ARCHIVE_Control Tower'!$B$31 -> 750 | K23: =K7*'ARCHIVE_Control Tower'!$B$30*'ARCHIVE_Control Tower'!$B$31 -> 780 | ... AM23: =AM7*'ARCHIVE_Control Tower'!$B$30*'ARCHIVE_Control Tower'!$B$31 -> 1800 | AN23: =SUM(D23:O23) -> 8640 | AO23: =SUM(P23:AA23) -> 15210 | AP23: =SUM(AB23:AM23) -> 19950
A24: Subtotal — PRN Visit Wages | D24: =SUM(D20:D23) -> 3318.75 | E24: =SUM(E20:E23) -> 3761.25 | F24: =SUM(F20:F23) -> 3982.5 | G24: =SUM(G20:G23) -> 4425 | H24: =SUM(H20:H23) -> 4867.5 | I24: =SUM(I20:I23) -> 5088.75 | J24: =SUM(J20:J23) -> 5531.25 | K24: =SUM(K20:K23) -> 5752.5 | ... AM24: =SUM(AM20:AM23) -> 13275 | AN24: =SUM(D24:O24) -> 63720 | AO24: =SUM(P24:AA24) -> 112173.75 | AP24: =SUM(AB24:AM24) -> 147131.25
A25: INDIRECT — WAGES (Overhead)
A26: Brad Woodard — Marketing | B26: 4000-0-M-0 | C26: M1 | D26: =IF(D6>=1,'ARCHIVE_Control Tower'!$B$39/12*D8,0) -> 10000 | E26: =IF(E6>=1,'ARCHIVE_Control Tower'!$B$39/12*E8,0) -> 10000 | F26: =IF(F6>=1,'ARCHIVE_Control Tower'!$B$39/12*F8,0) -> 10000 | G26: =IF(G6>=1,'ARCHIVE_Control Tower'!$B$39/12*G8,0) -> 10000 | H26: =IF(H6>=1,'ARCHIVE_Control Tower'!$B$39/12*H8,0) -> 10000 | I26: =IF(I6>=1,'ARCHIVE_Control Tower'!$B$39/12*I8,0) -> 10000 | J26: =IF(J6>=1,'ARCHIVE_Control Tower'!$B$39/12*J8,0) -> 10000 | K26: =IF(K6>=1,'ARCHIVE_Control Tower'!$B$39/12*K8,0) -> 10000 | ... AM26: =IF(AM6>=1,'ARCHIVE_Control Tower'!$B$39/12*AM8,0) -> 10609 | AN26: =SUM(D26:O26) -> 120000 | AO26: =SUM(P26:AA26) -> 123600 | AP26: =SUM(AB26:AM26) -> 127308
A27: Rhonda Smith — Intake/Office | B27: 4000-0-I-0 | C27: M2 | D27: =IF(D6>=2,'ARCHIVE_Control Tower'!$B$43/12*D8,0) -> 0 | E27: =IF(E6>=2,'ARCHIVE_Control Tower'!$B$43/12*E8,0) -> 4166.6667 | F27: =IF(F6>=2,'ARCHIVE_Control Tower'!$B$43/12*F8,0) -> 4166.6667 | G27: =IF(G6>=2,'ARCHIVE_Control Tower'!$B$43/12*G8,0) -> 4166.6667 | H27: =IF(H6>=2,'ARCHIVE_Control Tower'!$B$43/12*H8,0) -> 4166.6667 | I27: =IF(I6>=2,'ARCHIVE_Control Tower'!$B$43/12*I8,0) -> 4166.6667 | J27: =IF(J6>=2,'ARCHIVE_Control Tower'!$B$43/12*J8,0) -> 4166.6667 | K27: =IF(K6>=2,'ARCHIVE_Control Tower'!$B$43/12*K8,0) -> 4166.6667 | ... AM27: =IF(AM6>=2,'ARCHIVE_Control Tower'!$B$43/12*AM8,0) -> 4420.4167 | AN27: =SUM(D27:O27) -> 45833.333 | AO27: =SUM(P27:AA27) -> 51500 | AP27: =SUM(AB27:AM27) -> 53045
A28: Silas Shelton — Administrator (FT) | B28: 4000-0-A-0 | C28: M3 | D28: =IF(D6>=3,'ARCHIVE_Control Tower'!$B$46/12*D8,0) -> 0 | E28: =IF(E6>=3,'ARCHIVE_Control Tower'!$B$46/12*E8,0) -> 0 | F28: =IF(F6>=3,'ARCHIVE_Control Tower'!$B$46/12*F8,0) -> 12500 | G28: =IF(G6>=3,'ARCHIVE_Control Tower'!$B$46/12*G8,0) -> 12500 | H28: =IF(H6>=3,'ARCHIVE_Control Tower'!$B$46/12*H8,0) -> 12500 | I28: =IF(I6>=3,'ARCHIVE_Control Tower'!$B$46/12*I8,0) -> 12500 | J28: =IF(J6>=3,'ARCHIVE_Control Tower'!$B$46/12*J8,0) -> 12500 | K28: =IF(K6>=3,'ARCHIVE_Control Tower'!$B$46/12*K8,0) -> 12500 | ... AM28: =IF(AM6>=3,'ARCHIVE_Control Tower'!$B$46/12*AM8,0) -> 13261.25 | AN28: =SUM(D28:O28) -> 125000 | AO28: =SUM(P28:AA28) -> 154500 | AP28: =SUM(AB28:AM28) -> 159135
A29: Dana Davenport — Clinical Admin (FT) | B29: 4000-0-C-0 | C29: M2 | D29: =IF(D6>=2,'ARCHIVE_Control Tower'!$B$44/12*D8,0) -> 0 | E29: =IF(E6>=2,'ARCHIVE_Control Tower'!$B$44/12*E8,0) -> 10000 | F29: =IF(F6>=2,'ARCHIVE_Control Tower'!$B$44/12*F8,0) -> 10000 | G29: =IF(G6>=2,'ARCHIVE_Control Tower'!$B$44/12*G8,0) -> 10000 | H29: =IF(H6>=2,'ARCHIVE_Control Tower'!$B$44/12*H8,0) -> 10000 | I29: =IF(I6>=2,'ARCHIVE_Control Tower'!$B$44/12*I8,0) -> 10000 | J29: =IF(J6>=2,'ARCHIVE_Control Tower'!$B$44/12*J8,0) -> 10000 | K29: =IF(K6>=2,'ARCHIVE_Control Tower'!$B$44/12*K8,0) -> 10000 | ... AM29: =IF(AM6>=2,'ARCHIVE_Control Tower'!$B$44/12*AM8,0) -> 10609 | AN29: =SUM(D29:O29) -> 110000 | AO29: =SUM(P29:AA29) -> 123600 | AP29: =SUM(AB29:AM29) -> 127308
A30: Subtotal — Indirect Wages | D30: =SUM(D26:D29) -> 10000 | E30: =SUM(E26:E29) -> 24166.667 | F30: =SUM(F26:F29) -> 36666.667 | G30: =SUM(G26:G29) -> 36666.667 | H30: =SUM(H26:H29) -> 36666.667 | I30: =SUM(I26:I29) -> 36666.667 | J30: =SUM(J26:J29) -> 36666.667 | K30: =SUM(K26:K29) -> 36666.667 | ... AM30: =SUM(AM26:AM29) -> 38899.667 | AN30: =SUM(D30:O30) -> 400833.33 | AO30: =SUM(P30:AA30) -> 453200 | AP30: =SUM(AB30:AM30) -> 466796
A31: CONTRACT LABOR (no employer burden)
A32: Silas — PRN Admin retainer | B32: 4020-0-A-0 | C32: M1-2 | D32: =IF(AND(D6>=1,D6<=2),'ARCHIVE_Control Tower'!$B$35,0) -> 2500 | E32: =IF(AND(E6>=1,E6<=2),'ARCHIVE_Control Tower'!$B$35,0) -> 2500 | F32: =IF(AND(F6>=1,F6<=2),'ARCHIVE_Control Tower'!$B$35,0) -> 0 | G32: =IF(AND(G6>=1,G6<=2),'ARCHIVE_Control Tower'!$B$35,0) -> 0 | H32: =IF(AND(H6>=1,H6<=2),'ARCHIVE_Control Tower'!$B$35,0) -> 0 | I32: =IF(AND(I6>=1,I6<=2),'ARCHIVE_Control Tower'!$B$35,0) -> 0 | J32: =IF(AND(J6>=1,J6<=2),'ARCHIVE_Control Tower'!$B$35,0) -> 0 | K32: =IF(AND(K6>=1,K6<=2),'ARCHIVE_Control Tower'!$B$35,0) -> 0 | ... AM32: =IF(AND(AM6>=1,AM6<=2),'ARCHIVE_Control Tower'!$B$35,0) -> 0 | AN32: =SUM(D32:O32) -> 5000 | AO32: =SUM(P32:AA32) -> 0 | AP32: =SUM(AB32:AM32) -> 0
A33: Dana — PRN Clinical contract | B33: 4020-0-C-0 | C33: M1 | D33: =IF(D6=1,'ARCHIVE_Control Tower'!$B$36,0) -> 1500 | E33: =IF(E6=1,'ARCHIVE_Control Tower'!$B$36,0) -> 0 | F33: =IF(F6=1,'ARCHIVE_Control Tower'!$B$36,0) -> 0 | G33: =IF(G6=1,'ARCHIVE_Control Tower'!$B$36,0) -> 0 | H33: =IF(H6=1,'ARCHIVE_Control Tower'!$B$36,0) -> 0 | I33: =IF(I6=1,'ARCHIVE_Control Tower'!$B$36,0) -> 0 | J33: =IF(J6=1,'ARCHIVE_Control Tower'!$B$36,0) -> 0 | K33: =IF(K6=1,'ARCHIVE_Control Tower'!$B$36,0) -> 0 | ... AM33: =IF(AM6=1,'ARCHIVE_Control Tower'!$B$36,0) -> 0 | AN33: =SUM(D33:O33) -> 1500 | AO33: =SUM(P33:AA33) -> 0 | AP33: =SUM(AB33:AM33) -> 0
A34: Medical Director | B34: 4020-R-6-M | C34: M1 | D34: ='ARCHIVE_Control Tower'!$B$34 -> 4000 | E34: ='ARCHIVE_Control Tower'!$B$34 -> 4000 | F34: ='ARCHIVE_Control Tower'!$B$34 -> 4000 | G34: ='ARCHIVE_Control Tower'!$B$34 -> 4000 | H34: ='ARCHIVE_Control Tower'!$B$34 -> 4000 | I34: ='ARCHIVE_Control Tower'!$B$34 -> 4000 | J34: ='ARCHIVE_Control Tower'!$B$34 -> 4000 | K34: ='ARCHIVE_Control Tower'!$B$34 -> 4000 | ... AM34: ='ARCHIVE_Control Tower'!$B$34 -> 4000 | AN34: =SUM(D34:O34) -> 48000 | AO34: =SUM(P34:AA34) -> 48000 | AP34: =SUM(AB34:AM34) -> 48000
A35: Subtotal — Contract Labor | D35: =SUM(D32:D34) -> 8000 | E35: =SUM(E32:E34) -> 6500 | F35: =SUM(F32:F34) -> 4000 | G35: =SUM(G32:G34) -> 4000 | H35: =SUM(H32:H34) -> 4000 | I35: =SUM(I32:I34) -> 4000 | J35: =SUM(J32:J34) -> 4000 | K35: =SUM(K32:K34) -> 4000 | ... AM35: =SUM(AM32:AM34) -> 4000 | AN35: =SUM(D35:O35) -> 54500 | AO35: =SUM(P35:AA35) -> 48000 | AP35: =SUM(AB35:AM35) -> 48000
A36: PAYROLL BURDEN (on W-2 wages: salaried + PRN visit)
A37: W-2 Wage Base (Direct salaried + PRN + Indirect) | D37: =D18+D24+D30 -> 27290.042 | E37: =E18+E24+E30 -> 48357.792 | F37: =F18+F24+F30 -> 61048.25 | G37: =G18+G24+G30 -> 61490.75 | H37: =H18+H24+H30 -> 61933.25 | I37: =I18+I24+I30 -> 62154.5 | J37: =J18+J24+J30 -> 66442.042 | K37: =K18+K24+K30 -> 66663.292 | ... AM37: =AM18+AM24+AM30 -> 99536.646
A38: Employer FICA | B38: 4130-0-Z-0 | D38: =D37*'ARCHIVE_Control Tower'!$B$5 -> 2087.6882 | E38: =E37*'ARCHIVE_Control Tower'!$B$5 -> 3699.3711 | F38: =F37*'ARCHIVE_Control Tower'!$B$5 -> 4670.1911 | G38: =G37*'ARCHIVE_Control Tower'!$B$5 -> 4704.0424 | H38: =H37*'ARCHIVE_Control Tower'!$B$5 -> 4737.8936 | I38: =I37*'ARCHIVE_Control Tower'!$B$5 -> 4754.8192 | J38: =J37*'ARCHIVE_Control Tower'!$B$5 -> 5082.8162 | K38: =K37*'ARCHIVE_Control Tower'!$B$5 -> 5099.7418 | ... AM38: =AM37*'ARCHIVE_Control Tower'!$B$5 -> 7614.5534 | AN38: =SUM(D38:O38) -> 56512.431 | AO38: =SUM(P38:AA38) -> 77821.768 | AP38: =SUM(AB38:AM38) -> 90443.732
A39: FUTA/SUTA Unemployment | B39: 4131-0-Z-0 | D39: =D37*'ARCHIVE_Control Tower'!$B$6 -> 504.86577 | E39: =E37*'ARCHIVE_Control Tower'!$B$6 -> 894.61915 | F39: =F37*'ARCHIVE_Control Tower'!$B$6 -> 1129.3926 | G39: =G37*'ARCHIVE_Control Tower'!$B$6 -> 1137.5789 | H39: =H37*'ARCHIVE_Control Tower'!$B$6 -> 1145.7651 | I39: =I37*'ARCHIVE_Control Tower'!$B$6 -> 1149.8582 | J39: =J37*'ARCHIVE_Control Tower'!$B$6 -> 1229.1778 | K39: =K37*'ARCHIVE_Control Tower'!$B$6 -> 1233.2709 | ... AM39: =AM37*'ARCHIVE_Control Tower'!$B$6 -> 1841.428 | AN39: =SUM(D39:O39) -> 13666.405 | AO39: =SUM(P39:AA39) -> 18819.643 | AP39: =SUM(AB39:AM39) -> 21872.014
A40: Workers' Compensation | B40: 4135-0-Z-0 | D40: =D37*'ARCHIVE_Control Tower'!$B$7 -> 818.70125 | E40: =E37*'ARCHIVE_Control Tower'!$B$7 -> 1450.7338 | F40: =F37*'ARCHIVE_Control Tower'!$B$7 -> 1831.4475 | G40: =G37*'ARCHIVE_Control Tower'!$B$7 -> 1844.7225 | H40: =H37*'ARCHIVE_Control Tower'!$B$7 -> 1857.9975 | I40: =I37*'ARCHIVE_Control Tower'!$B$7 -> 1864.635 | J40: =J37*'ARCHIVE_Control Tower'!$B$7 -> 1993.2613 | K40: =K37*'ARCHIVE_Control Tower'!$B$7 -> 1999.8988 | ... AM40: =AM37*'ARCHIVE_Control Tower'!$B$7 -> 2986.0994 | AN40: =SUM(D40:O40) -> 22161.737 | AO40: =SUM(P40:AA40) -> 30518.34 | AP40: =SUM(AB40:AM40) -> 35468.13
A41: Health Insurance | B41: 4110-0-Z-0 | D41: =('ARCHIVE_Control Tower'!$B$8)*(IF(D6>=1,3,0)+IF(D6>=2,3,0)+IF(D6>=3,2,0)+MAX(0,D9-((IF(D6>=1,1,0))+(IF(D6>=2,1,0))))+MAX(0,D10-((IF(D6>=1,1,0))+(IF(D6>=3,1,0))))) -> 2000 | E41: =('ARCHIVE_Control Tower'!$B$8)*(IF(E6>=1,3,0)+IF(E6>=2,3,0)+IF(E6>=3,2,0)+MAX(0,E9-((IF(E6>=1,1,0))+(IF(E6>=2,1,0))))+MAX(0,E10-((IF(E6>=1,1,0))+(IF(E6>=3,1,0))))) -> 3500 | F41: =('ARCHIVE_Control Tower'!$B$8)*(IF(F6>=1,3,0)+IF(F6>=2,3,0)+IF(F6>=3,2,0)+MAX(0,F9-((IF(F6>=1,1,0))+(IF(F6>=2,1,0))))+MAX(0,F10-((IF(F6>=1,1,0))+(IF(F6>=3,1,0))))) -> 4000 | G41: =('ARCHIVE_Control Tower'!$B$8)*(IF(G6>=1,3,0)+IF(G6>=2,3,0)+IF(G6>=3,2,0)+MAX(0,G9-((IF(G6>=1,1,0))+(IF(G6>=2,1,0))))+MAX(0,G10-((IF(G6>=1,1,0))+(IF(G6>=3,1,0))))) -> 4000 | H41: =('ARCHIVE_Control Tower'!$B$8)*(IF(H6>=1,3,0)+IF(H6>=2,3,0)+IF(H6>=3,2,0)+MAX(0,H9-((IF(H6>=1,1,0))+(IF(H6>=2,1,0))))+MAX(0,H10-((IF(H6>=1,1,0))+(IF(H6>=3,1,0))))) -> 4000 | I41: =('ARCHIVE_Control Tower'!$B$8)*(IF(I6>=1,3,0)+IF(I6>=2,3,0)+IF(I6>=3,2,0)+MAX(0,I9-((IF(I6>=1,1,0))+(IF(I6>=2,1,0))))+MAX(0,I10-((IF(I6>=1,1,0))+(IF(I6>=3,1,0))))) -> 4000 | J41: =('ARCHIVE_Control Tower'!$B$8)*(IF(J6>=1,3,0)+IF(J6>=2,3,0)+IF(J6>=3,2,0)+MAX(0,J9-((IF(J6>=1,1,0))+(IF(J6>=2,1,0))))+MAX(0,J10-((IF(J6>=1,1,0))+(IF(J6>=3,1,0))))) -> 4500 | K41: =('ARCHIVE_Control Tower'!$B$8)*(IF(K6>=1,3,0)+IF(K6>=2,3,0)+IF(K6>=3,2,0)+MAX(0,K9-((IF(K6>=1,1,0))+(IF(K6>=2,1,0))))+MAX(0,K10-((IF(K6>=1,1,0))+(IF(K6>=3,1,0))))) -> 4500 | ... AM41: =('ARCHIVE_Control Tower'!$B$8)*(IF(AM6>=1,3,0)+IF(AM6>=2,3,0)+IF(AM6>=3,2,0)+MAX(0,AM9-((IF(AM6>=1,1,0))+(IF(AM6>=2,1,0))))+MAX(0,AM10-((IF(AM6>=1,1,0))+(IF(AM6>=3,1,0))))) -> 6500 | AN41: =SUM(D41:O41) -> 49500 | AO41: =SUM(P41:AA41) -> 68000 | AP41: =SUM(AB41:AM41) -> 78000
...

Sheet ARCHIVE_Operating Budget
A1: OPERATING BUDGET
A2: 36-Month GL Detail
B3: GL Code | C3: Year 1 | O3: Year 2 | AA3: Year 3 | AM3: Annual | AP3: % Rev
C4: M1 | D4: M2 | E4: M3 | F4: M4 | G4: M5 | H4: M6 | I4: M7 | J4: M8 | K4: M9 | L4: M10 | M4: M11 | N4: M12 | O4: M13 | P4: M14 | Q4: M15 | R4: M16 | S4: M17 | T4: M18 | U4: M19 | V4: M20 | W4: M21 | X4: M22 | Y4: M23 | Z4: M24 | AA4: M25 | AB4: M26 | AC4: M27 | AD4: M28 | AE4: M29 | AF4: M30 | AG4: M31 | AH4: M32 | AI4: M33 | AJ4: M34 | AK4: M35 | AL4: M36 | AM4: Year 1 | AN4: Year 2 | AO4: Year 3 | AP4: (Y3)
A5: REVENUE
A6: Avg Daily Census | C6: ='ARCHIVE_Revenue Model'!C18 -> 15 | D6: ='ARCHIVE_Revenue Model'!D18 -> 17 | E6: ='ARCHIVE_Revenue Model'!E18 -> 18 | F6: ='ARCHIVE_Revenue Model'!F18 -> 20 | G6: ='ARCHIVE_Revenue Model'!G18 -> 22 | H6: ='ARCHIVE_Revenue Model'!H18 -> 23 | I6: ='ARCHIVE_Revenue Model'!I18 -> 25 | J6: ='ARCHIVE_Revenue Model'!J18 -> 26 | ... AL6: ='ARCHIVE_Revenue Model'!AL18 -> 60 | AM6: =AVERAGE(C6:N6) -> 24 | AN6: =AVERAGE(O6:Z6) -> 42.25 | AO6: =AVERAGE(AA6:AL6) -> 55.416667
A7: Total Patient Days | C7: ='ARCHIVE_Revenue Model'!C20 -> 456 | D7: ='ARCHIVE_Revenue Model'!D20 -> 516.8 | E7: ='ARCHIVE_Revenue Model'!E20 -> 547.2 | F7: ='ARCHIVE_Revenue Model'!F20 -> 608 | G7: ='ARCHIVE_Revenue Model'!G20 -> 668.8 | H7: ='ARCHIVE_Revenue Model'!H20 -> 699.2 | I7: ='ARCHIVE_Revenue Model'!I20 -> 760 | J7: ='ARCHIVE_Revenue Model'!J20 -> 790.4 | ... AO7: ='ARCHIVE_Revenue Model'!AO20 -> 20216
A8: Gross Patient Revenue | B8: 3000 | C8: ='ARCHIVE_Revenue Model'!C21 -> 84013.939 | D8: ='ARCHIVE_Revenue Model'!D21 -> 95215.798 | E8: ='ARCHIVE_Revenue Model'!E21 -> 100816.73 | F8: ='ARCHIVE_Revenue Model'!F21 -> 112018.59 | G8: ='ARCHIVE_Revenue Model'!G21 -> 123220.44 | H8: ='ARCHIVE_Revenue Model'!H21 -> 128821.37 | I8: ='ARCHIVE_Revenue Model'!I21 -> 140023.23 | J8: ='ARCHIVE_Revenue Model'!J21 -> 145624.16 | ... AO8: ='ARCHIVE_Revenue Model'!AO21 -> 3724618 | AP8: =IF(AO$10=0,0,AO8/AO$10) -> 1.0152284
A9: Billing / Collection Fee (-1.5%) | B9: 3900 | C9: ='ARCHIVE_Revenue Model'!C22 -> -1260.2091 | D9: ='ARCHIVE_Revenue Model'!D22 -> -1428.237 | E9: ='ARCHIVE_Revenue Model'!E22 -> -1512.2509 | F9: ='ARCHIVE_Revenue Model'!F22 -> -1680.2788 | G9: ='ARCHIVE_Revenue Model'!G22 -> -1848.3067 | H9: ='ARCHIVE_Revenue Model'!H22 -> -1932.3206 | I9: ='ARCHIVE_Revenue Model'!I22 -> -2100.3485 | J9: ='ARCHIVE_Revenue Model'!J22 -> -2184.3624 | ... AO9: ='ARCHIVE_Revenue Model'!AO22 -> -55869.27 | AP9: =IF(AO$10=0,0,AO9/AO$10) -> -0.015228426
A10: Net Patient Revenue | C10: ='ARCHIVE_Revenue Model'!C23 -> 82753.73 | D10: ='ARCHIVE_Revenue Model'!D23 -> 93787.561 | E10: ='ARCHIVE_Revenue Model'!E23 -> 99304.476 | F10: ='ARCHIVE_Revenue Model'!F23 -> 110338.31 | G10: ='ARCHIVE_Revenue Model'!G23 -> 121372.14 | H10: ='ARCHIVE_Revenue Model'!H23 -> 126889.05 | I10: ='ARCHIVE_Revenue Model'!I23 -> 137922.88 | J10: ='ARCHIVE_Revenue Model'!J23 -> 143439.8 | ... AO10: ='ARCHIVE_Revenue Model'!AO23 -> 3668748.7 | AP10: =IF(AO$10=0,0,AO10/AO$10) -> 1
A12: COST OF GOODS SOLD
A13: DIRECT LABOR
A14: 4000R61 Wages-RN | B14: 4000R61 | C14: ='ARCHIVE_Staffing Summary'!D12+'ARCHIVE_Staffing Summary'!D13+'ARCHIVE_Staffing Summary'!D14 -> 6250.4167 | D14: ='ARCHIVE_Staffing Summary'!E12+'ARCHIVE_Staffing Summary'!E13+'ARCHIVE_Staffing Summary'!E14 -> 12709 | E14: ='ARCHIVE_Staffing Summary'!F12+'ARCHIVE_Staffing Summary'!F13+'ARCHIVE_Staffing Summary'!F14 -> 12709 | F14: ='ARCHIVE_Staffing Summary'!G12+'ARCHIVE_Staffing Summary'!G13+'ARCHIVE_Staffing Summary'!G14 -> 12709 | G14: ='ARCHIVE_Staffing Summary'!H12+'ARCHIVE_Staffing Summary'!H13+'ARCHIVE_Staffing Summary'!H14 -> 12709 | H14: ='ARCHIVE_Staffing Summary'!I12+'ARCHIVE_Staffing Summary'!I13+'ARCHIVE_Staffing Summary'!I14 -> 12709 | I14: ='ARCHIVE_Staffing Summary'!J12+'ARCHIVE_Staffing Summary'!J13+'ARCHIVE_Staffing Summary'!J14 -> 12709 | J14: ='ARCHIVE_Staffing Summary'!K12+'ARCHIVE_Staffing Summary'!K13+'ARCHIVE_Staffing Summary'!K14 -> 12709 | ... AO14: ='ARCHIVE_Staffing Summary'!AP12+'ARCHIVE_Staffing Summary'!AP13+'ARCHIVE_Staffing Summary'!AP14 -> 323591.47 | AP14: =IF(AO$10=0,0,AO14/AO$10) -> 0.088202137
A15: 4000R62 Wages-LVN | B15: 4000R62 | C15: ='ARCHIVE_Staffing Summary'!D20 -> 900 | D15: ='ARCHIVE_Staffing Summary'!E20 -> 1020 | E15: ='ARCHIVE_Staffing Summary'!F20 -> 1080 | F15: ='ARCHIVE_Staffing Summary'!G20 -> 1200 | G15: ='ARCHIVE_Staffing Summary'!H20 -> 1320 | H15: ='ARCHIVE_Staffing Summary'!I20 -> 1380 | I15: ='ARCHIVE_Staffing Summary'!J20 -> 1500 | J15: ='ARCHIVE_Staffing Summary'!K20 -> 1560 | ... AO15: ='ARCHIVE_Staffing Summary'!AP20 -> 39900 | AP15: =IF(AO$10=0,0,AO15/AO$10) -> 0.010875643
A16: 4000R65 Wages-Aide | B16: 4000R65 | C16: ='ARCHIVE_Staffing Summary'!D15+'ARCHIVE_Staffing Summary'!D16+'ARCHIVE_Staffing Summary'!D17 -> 7720.875 | D16: ='ARCHIVE_Staffing Summary'!E15+'ARCHIVE_Staffing Summary'!E16+'ARCHIVE_Staffing Summary'!E17 -> 7720.875 | E16: ='ARCHIVE_Staffing Summary'!F15+'ARCHIVE_Staffing Summary'!F16+'ARCHIVE_Staffing Summary'!F17 -> 7690.0833 | F16: ='ARCHIVE_Staffing Summary'!G15+'ARCHIVE_Staffing Summary'!G16+'ARCHIVE_Staffing Summary'!G17 -> 7690.0833 | G16: ='ARCHIVE_Staffing Summary'!H15+'ARCHIVE_Staffing Summary'!H16+'ARCHIVE_Staffing Summary'!H17 -> 7690.0833 | H16: ='ARCHIVE_Staffing Summary'!I15+'ARCHIVE_Staffing Summary'!I16+'ARCHIVE_Staffing Summary'!I17 -> 7690.0833 | I16: ='ARCHIVE_Staffing Summary'!J15+'ARCHIVE_Staffing Summary'!J16+'ARCHIVE_Staffing Summary'!J17 -> 11535.125 | J16: ='ARCHIVE_Staffing Summary'!K15+'ARCHIVE_Staffing Summary'!K16+'ARCHIVE_Staffing Summary'!K17 -> 11535.125 | ... AO16: ='ARCHIVE_Staffing Summary'!AP15+'ARCHIVE_Staffing Summary'!AP16+'ARCHIVE_Staffing Summary'!AP17 -> 244752.28 | AP16: =IF(AO$10=0,0,AO16/AO$10) -> 0.066712741
A17: 4000R66 Wages-MSW | B17: 4000R66 | C17: ='ARCHIVE_Staffing Summary'!D22 -> 1125 | D17: ='ARCHIVE_Staffing Summary'!E22 -> 1275 | E17: ='ARCHIVE_Staffing Summary'!F22 -> 1350 | F17: ='ARCHIVE_Staffing Summary'!G22 -> 1500 | G17: ='ARCHIVE_Staffing Summary'!H22 -> 1650 | H17: ='ARCHIVE_Staffing Summary'!I22 -> 1725 | I17: ='ARCHIVE_Staffing Summary'!J22 -> 1875 | J17: ='ARCHIVE_Staffing Summary'!K22 -> 1950 | ... AO17: ='ARCHIVE_Staffing Summary'!AP22 -> 49875 | AP17: =IF(AO$10=0,0,AO17/AO$10) -> 0.013594553
A18: 4000R67 Wages-SC | B18: 4000R67 | C18: ='ARCHIVE_Staffing Summary'!D21 -> 843.75 | D18: ='ARCHIVE_Staffing Summary'!E21 -> 956.25 | E18: ='ARCHIVE_Staffing Summary'!F21 -> 1012.5 | F18: ='ARCHIVE_Staffing Summary'!G21 -> 1125 | G18: ='ARCHIVE_Staffing Summary'!H21 -> 1237.5 | H18: ='ARCHIVE_Staffing Summary'!I21 -> 1293.75 | I18: ='ARCHIVE_Staffing Summary'!J21 -> 1406.25 | J18: ='ARCHIVE_Staffing Summary'!K21 -> 1462.5 | ... AO18: ='ARCHIVE_Staffing Summary'!AP21 -> 37406.25 | AP18: =IF(AO$10=0,0,AO18/AO$10) -> 0.010195915
A19: 4000R6N Wages-NP | B19: 4000R6N | C19: ='ARCHIVE_Staffing Summary'!D23 -> 450 | D19: ='ARCHIVE_Staffing Summary'!E23 -> 510 | E19: ='ARCHIVE_Staffing Summary'!F23 -> 540 | F19: ='ARCHIVE_Staffing Summary'!G23 -> 600 | G19: ='ARCHIVE_Staffing Summary'!H23 -> 660 | H19: ='ARCHIVE_Staffing Summary'!I23 -> 690 | I19: ='ARCHIVE_Staffing Summary'!J23 -> 750 | J19: ='ARCHIVE_Staffing Summary'!K23 -> 780 | ... AO19: ='ARCHIVE_Staffing Summary'!AP23 -> 19950 | AP19: =IF(AO$10=0,0,AO19/AO$10) -> 0.0054378213
A20: Total Direct Labor | C20: =SUM(C14:C19) -> 17290.042 | D20: =SUM(D14:D19) -> 24191.125 | E20: =SUM(E14:E19) -> 24381.583 | F20: =SUM(F14:F19) -> 24824.083 | G20: =SUM(G14:G19) -> 25266.583 | H20: =SUM(H14:H19) -> 25487.833 | I20: =SUM(I14:I19) -> 29775.375 | J20: =SUM(J14:J19) -> 29996.625 | ... AO20: =SUM(AO14:AO19) -> 715475.01 | AP20: =IF(AO$10=0,0,AO20/AO$10) -> 0.19501881
A21: DIRECT BENEFITS
